Workbook
Name projectStatus: #REF!
Name projectStatus: #REF!

Sheet Construction DASHBOARD
A1: Daily Progress Report
A2: Project Name | B2: 300MW SECI Solar Project Ramagiri | N2: Week | O2: Month
A3: Project Capacity (in MWp) | B3: 390 | N3: 45852 | O3: 45839
A4: Project Start Date | B4: 45694 | N4: =N3+5 -> 45857 | O4: 45869
A5: Project Finish Date | B5: 46058 | K5: Week Cycle | L5: Month Cycle
A6: Date | B6: 45853 | K6: =N3 -> 45852 | L6: 45839
K7: =N4 -> 45857 | L7: =L6+30 -> 45869
A8: Description | B8: Scope | C8: UoM | D8: Completed | E8: Balance | F8: Weightage (in %) | G8: Progress as per weightage (in %) | H8: Actual Progress (in %) | I8: Day- Actual | J8: Today-Plan | K8: Week- Actual | L8: Month-Actual
A10: Land Development
A11: Bush removal | B11: 1033 | C11: Acre | D11: ='Construction Status'!S4 -> 872 | E11: =B11-D11 -> 161 | F11: 0.01 | G11: =F11*H11 -> 0.0084414327 | H11: =D11/B11 -> 0.84414327 | I11: =SUMIF('Construction Status'!$U$2:$DF$2,'Construction DASHBOARD'!$B$6,'Construction Status'!U4:DF4) -> 0 | J11: 5 | K11: {=SUMPRODUCT(('Construction Status'!$U$4:$DF$120)*('Construction Status'!$D$4:$D$120='Construction DASHBOARD'!A11)*('Construction Status'!$U$2:$DF$2>='Construction DASHBOARD'!$N$3)*('Construction Status'!$U$2:$DF$2<='Construction DASHBOARD'!$N$4))} -> 0 | L11: {=SUMPRODUCT(('Construction Status'!$U$4:$DF$120)*('Construction Status'!$D$4:$D$120='Construction DASHBOARD'!A11)*('Construction Status'!$U$2:$DF$2>='Construction DASHBOARD'!$O$3)*('Construction Status'!$U$2:$DF$2<='Construction DASHBOARD'!$O$4))} -> 0 | N11: 45754 | O11: 1
A12: Land grading | B12: 1033 | C12: Acre | D12: ='Construction Status'!S5 -> 872 | E12: =B12-D12 -> 161 | F12: 0.01 | G12: =F12*H12 -> 0.0084414327 | H12: =D12/B12 -> 0.84414327 | I12: =SUMIF('Construction Status'!$U$2:$DF$2,'Construction DASHBOARD'!$B$6,'Construction Status'!U5:DF5) -> 0 | J12: 5 | K12: {=SUMPRODUCT(('Construction Status'!$U$4:$DF$120)*('Construction Status'!$D$4:$D$120='Construction DASHBOARD'!A12)*('Construction Status'!$U$2:$DF$2>='Construction DASHBOARD'!$N$3)*('Construction Status'!$U$2:$DF$2<='Construction DASHBOARD'!$N$4))} -> 0 | L12: {=SUMPRODUCT(('Construction Status'!$U$4:$DF$120)*('Construction Status'!$D$4:$D$120='Construction DASHBOARD'!A12)*('Construction Status'!$U$2:$DF$2>='Construction DASHBOARD'!$O$3)*('Construction Status'!$U$2:$DF$2<='Construction DASHBOARD'!$O$4))} -> 0
A13: Site Initials | N13: 45755 | O13: 1
A14: Boundry Coordinate capturing | B14: ='Construction Status'!K6 -> 1 | C14: Lot | D14: ='Construction Status'!Q6 -> 1 | E14: =B14-D14 -> 0 | F14: 0.006 | G14: =F14*H14 -> 0.006 | H14: =D14/B14 -> 1 | I14: =SUMIF('Construction Status'!$U$2:$DF$2,'Construction DASHBOARD'!$B$6,'Construction Status'!U6:DF6) -> 0 | K14: {=SUMPRODUCT(('Construction Status'!$U$4:$DF$120)*('Construction Status'!$D$4:$D$120='Construction DASHBOARD'!A14)*('Construction Status'!$U$2:$DF$2>='Construction DASHBOARD'!$N$3)*('Construction Status'!$U$2:$DF$2<='Construction DASHBOARD'!$N$4))} -> 0 | L14: {=SUMPRODUCT(('Construction Status'!$U$4:$DF$120)*('Construction Status'!$D$4:$D$120='Construction DASHBOARD'!A14)*('Construction Status'!$U$2:$DF$2>='Construction DASHBOARD'!$O$3)*('Construction Status'!$U$2:$DF$2<='Construction DASHBOARD'!$O$4))} -> 0 | N14: 45756 | O14: 1
A15: Topo Survey | B15: ='Construction Status'!K7 -> 1 | C15: Lot | D15: ='Construction Status'!Q7 -> 1 | E15: =B15-D15 -> 0 | F15: 0.0075 | G15: =F15*H15 -> 0.0075 | H15: =D15/B15 -> 1 | I15: =SUMIF('Construction Status'!$U$2:$DF$2,'Construction DASHBOARD'!$B$6,'Construction Status'!U7:DF7) -> 0 | K15: {=SUMPRODUCT(('Construction Status'!$U$4:$DF$120)*('Construction Status'!$D$4:$D$120='Construction DASHBOARD'!A15)*('Construction Status'!$U$2:$DF$2>='Construction DASHBOARD'!$N$3)*('Construction Status'!$U$2:$DF$2<='Construction DASHBOARD'!$N$4))} -> 0 | L15: {=SUMPRODUCT(('Construction Status'!$U$4:$DF$120)*('Construction Status'!$D$4:$D$120='Construction DASHBOARD'!A15)*('Construction Status'!$U$2:$DF$2>='Construction DASHBOARD'!$O$3)*('Construction Status'!$U$2:$DF$2<='Construction DASHBOARD'!$O$4))} -> 0 | N15: 45757 | O15: 1
A16: Soil Investigation | B16: 79 | C16: Lot | D16: ='Construction Status'!Q8 -> 79 | E16: =B16-D16 -> 0 | F16: 0.005 | G16: =F16*H16 -> 0.005 | H16: =D16/B16 -> 1 | I16: =SUMIF('Construction Status'!$U$2:$DF$2,'Construction DASHBOARD'!$B$6,'Construction Status'!U8:DF8) -> 0 | K16: {=SUMPRODUCT(('Construction Status'!$U$4:$DF$120)*('Construction Status'!$D$4:$D$120='Construction DASHBOARD'!A16)*('Construction Status'!$U$2:$DF$2>='Construction DASHBOARD'!$N$3)*('Construction Status'!$U$2:$DF$2<='Construction DASHBOARD'!$N$4))} -> 0 | L16: {=SUMPRODUCT(('Construction Status'!$U$4:$DF$120)*('Construction Status'!$D$4:$D$120='Construction DASHBOARD'!A16)*('Construction Status'!$U$2:$DF$2>='Construction DASHBOARD'!$O$3)*('Construction Status'!$U$2:$DF$2<='Construction DASHBOARD'!$O$4))} -> 0 | N16: 45758 | O16: 2
A17: ERT Test | B17: ='Construction Status'!K9 -> 36 | C17: Lot | D17: ='Construction Status'!Q9 -> 36 | E17: =B17-D17 -> 0 | F17: 0.0025 | G17: =F17*H17 -> 0.0025 | H17: =D17/B17 -> 1 | I17: =SUMIF('Construction Status'!$U$2:$DF$2,'Construction DASHBOARD'!$B$6,'Construction Status'!U9:DF9) -> 0 | K17: {=SUMPRODUCT(('Construction Status'!$U$4:$DF$120)*('Construction Status'!$D$4:$D$120='Construction DASHBOARD'!A17)*('Construction Status'!$U$2:$DF$2>='Construction DASHBOARD'!$N$3)*('Construction Status'!$U$2:$DF$2<='Construction DASHBOARD'!$N$4))} -> 0 | L17: {=SUMPRODUCT(('Construction Status'!$U$4:$DF$120)*('Construction Status'!$D$4:$D$120='Construction DASHBOARD'!A17)*('Construction Status'!$U$2:$DF$2>='Construction DASHBOARD'!$O$3)*('Construction Status'!$U$2:$DF$2<='Construction DASHBOARD'!$O$4))} -> 0 | N17: 45759 | O17: 2
A18: Test Pile Casting | B18: ='Construction Status'!K10 -> 240 | C18: Lot | D18: ='Construction Status'!Q10 -> 240 | E18: =B18-D18 -> 0 | F18: 0.002 | G18: =F18*H18 -> 0.002 | H18: =D18/B18 -> 1 | I18: =SUMIF('Construction Status'!$U$2:$DF$2,'Construction DASHBOARD'!$B$6,'Construction Status'!U10:DF10) -> 0 | K18: {=SUMPRODUCT(('Construction Status'!$U$4:$DF$120)*('Construction Status'!$D$4:$D$120='Construction DASHBOARD'!A18)*('Construction Status'!$U$2:$DF$2>='Construction DASHBOARD'!$N$3)*('Construction Status'!$U$2:$DF$2<='Construction DASHBOARD'!$N$4))} -> 0 | L18: {=SUMPRODUCT(('Construction Status'!$U$4:$DF$120)*('Construction Status'!$D$4:$D$120='Construction DASHBOARD'!A18)*('Construction Status'!$U$2:$DF$2>='Construction DASHBOARD'!$O$3)*('Construction Status'!$U$2:$DF$2<='Construction DASHBOARD'!$O$4))} -> 0 | N18: 45760 | O18: 1
A19: Pile Testing | B19: ='Construction Status'!K11 -> 240 | C19: Lot | D19: ='Construction Status'!Q11 -> 63 | E19: =B19-D19 -> 177 | F19: 0.002 | G19: =F19*H19 -> 0.000525 | H19: =D19/B19 -> 0.2625 | I19: =SUMIF('Construction Status'!$U$2:$DF$2,'Construction DASHBOARD'!$B$6,'Construction Status'!U11:DF11) -> 0 | J19: 4 | K19: {=SUMPRODUCT(('Construction Status'!$U$4:$DF$120)*('Construction Status'!$D$4:$D$120='Construction DASHBOARD'!A19)*('Construction Status'!$U$2:$DF$2>='Construction DASHBOARD'!$N$3)*('Construction Status'!$U$2:$DF$2<='Construction DASHBOARD'!$N$4))} -> 0 | L19: {=SUMPRODUCT(('Construction Status'!$U$4:$DF$120)*('Construction Status'!$D$4:$D$120='Construction DASHBOARD'!A19)*('Construction Status'!$U$2:$DF$2>='Construction DASHBOARD'!$O$3)*('Construction Status'!$U$2:$DF$2<='Construction DASHBOARD'!$O$4))} -> 0 | N19: 45761 | O19: 1
A20: Civil | N20: 45762
A21: Pile - Marking, Drilling & Casting | C21: Nos. | F21: 0.21 | N21: 45763
A22: Equipments Foundation | B22: 24 | C22: Block | F22: 0.05 | N22: 45764 | O22: 4
A23: Excavation For Trenches | B23: 24 | C23: Block | F23: 0.05 | N23: 45765 | O23: 4
A24: MCR Civil Works | B24: 1 | C24: Lot | F24: 0.06 | N24: 45766 | O24: 4
A25: Road Work | C25: km | F25: 0.02 | N25: 45767 | O25: 4
A26: Fencing | B26: 21000 | C26: km | F26: 0.02 | N26: 45768 | O26: 4
A27: MMS | N27: 45769 | O27: 6
A28: Module Mounting Structures | B28: 24 | C28: Block | F28: 0.08 | N28: 45770 | O28: 6
A29: PV Modules | B29: 24 | C29: Block | F29: 0.06 | N29: 45771 | O29: 6
A30: DC | N30: 45772 | O30: 6
A31: Solar Cables (Interconnection after module installation) | B31: 1360 | C31: SCB | F31: 0.02 | N31: 45773 | O31: 4
A32: SCB-MOUNTING | B32: 1360 | C32: SCB | F32: 0.02 | N32: 45774
A33: Array & Module Earthing | B33: 1360 | C33: SCB | F33: 0.03
A34: SCB Installation | B34: 1360 | C34: SCB | F34: 0.025
A35: DC Power Cables | B35: 1360 | C35: SCB | F35: 0.04
A36: DC Power Cables Terminations | B36: 1360 | C36: SCB | F36: 0.02
A37: DC Earthing | B37: 1360 | C37: SCB | F37: 0.02
A38: AC
A39: Equipment Installation | B39: 24 | C39: Block | F39: 0.02
A40: Cable Tray Works | B40: 24 | C40: Block | F40: 0.02
A41: HT&LT Cable Laying | B41: 24 | C41: Block | F41: 0.04
...

Sheet Sheet1
A2: Date | B2: 45754 | C2: 45755 | D2: 45756 | E2: 45757 | F2: 45758 | G2: 45759 | H2: 45760 | I2: 45761 | J2: 45762 | K2: 45763 | L2: 45764 | M2: 45765 | N2: 45766 | O2: 45767 | P2: 45768 | Q2: 45769 | R2: 45770 | S2: 45771 | T2: 45772 | U2: 45773 | V2: 45774 | W2: 45775 | X2: 45776 | Y2: 45777 | Z2: 45778 | AA2: 45779 | AB2: 45780 | AC2: 45781 | AD2: 45782 | AE2: 45783 | AF2: 45784 | AG2: 45785 | AH2: 45786 | AI2: 45787 | AJ2: 45788 | AK2: 45789 | AL2: 45790 | AM2: 45791
A3: No. of JCBs | B3: 1 | C3: 1 | D3: 1 | E3: 1 | F3: 2 | G3: 2 | H3: 1 | I3: 1 | L3: 4 | M3: 4 | N3: 4 | O3: 4 | P3: 4 | Q3: 6 | R3: 6 | S3: 6 | T3: 6 | U3: 4 | V3: 4 | W3: 4 | X3: 6 | Y3: 6 | Z3: 4 | AA3: 4 | AB3: 6 | AC3: 6 | AD3: 6 | AE3: 5 | AF3: 4 | AG3: 3 | AH3: 5 | AI3: 5 | AJ3: 5 | AK3: 4 | AL3: 6 | AP3: =SUM(B3:AK3) -> 135
A4: Bush Cutting | B4: ='Construction Status'!Z4 -> 1.5 | C4: ='Construction Status'!AA4 -> 3.5 | D4: ='Construction Status'!AB4 -> 4 | E4: ='Construction Status'!AC4 -> 4 | F4: ='Construction Status'!AD4 -> 4 | G4: ='Construction Status'!AE4 -> 4 | H4: ='Construction Status'!AF4 -> 3 | I4: ='Construction Status'!AG4 -> 2 | J4: ='Construction Status'!AH4 -> 0 | K4: ='Construction Status'!AI4-10 -> 0 | L4: ='Construction Status'!AJ4 -> 20 | M4: ='Construction Status'!AK4 -> 20 | N4: ='Construction Status'!AL4+5 -> 25 | O4: ='Construction Status'!AM4+5 -> 26 | P4: ='Construction Status'!AN4 -> 40 | Q4: ='Construction Status'!AO4 -> 40 | R4: ='Construction Status'!AP4 -> 40 | S4: ='Construction Status'!AQ4 -> 38 | T4: ='Construction Status'!AR4 -> 0 | U4: ='Construction Status'!AS4 -> 0 | V4: ='Construction Status'!AT4 -> 0 | W4: ='Construction Status'!AU4 -> 0 | ... AC4: ='Construction Status'!BA4 -> 0 | AF4: 5 | AG4: 10 | AH4: 10 | AI4: 5 | AJ4: 7 | AK4: 5 | AP4: =SUM(B4:AK4) -> 317 | AQ4: =AP4/AP3 -> 2.3481481
A5: Land Grading | B5: ='Construction Status'!Z5 -> 0 | C5: ='Construction Status'!AA5 -> 0 | D5: ='Construction Status'!AB5 -> 0 | E5: ='Construction Status'!AC5 -> 0 | F5: ='Construction Status'!AD5 -> 0 | G5: ='Construction Status'!AE5 -> 0 | H5: ='Construction Status'!AF5 -> 0 | I5: ='Construction Status'!AG5 -> 0 | ... AC5: ='Construction Status'!BA5 -> 20 | AD5: 14 | AE5: 16 | AF5: 16 | AG5: 10 | AH5: 10 | AI5: 5 | AJ5: 7 | AK5: 5 | AP5: =SUM(T3:AK3) -> 87
A6: Per Day Producticity | AP6: =SUM(B5:AK5) -> 201 | AQ6: =AP6/AP5 -> 2.3103448
A7: Bush Cutting | B7: =B4/B3 -> 1.5 | C7: =C4/C3 -> 3.5 | D7: =D4/D3 -> 4 | E7: =E4/E3 -> 4 | F7: =F4/F3 -> 2 | G7: =G4/G3 -> 2 | H7: =H4/H3 -> 3 | I7: =I4/I3 -> 2 | L7: =L4/L3 -> 5 | M7: =M4/M3 -> 5 | N7: =N4/N3 -> 6.25 | O7: =O4/O3 -> 6.5 | P7: =P4/P3 -> 10 | Q7: =Q4/Q3 -> 6.6666667 | R7: =R4/R3 -> 6.6666667 | S7: =S4/S3 -> 6.3333333
A8: Land Grading | T8: =T5/T3 -> 1.6666667 | U8: =U5/U3 -> 2.5 | V8: =V5/V3 -> 2.5 | W8: =W5/W3 -> 2.5 | X8: =X5/X3 -> 2 | Y8: =Y5/Y3 -> 2.1666667 | Z8: =Z5/Z3 -> 2.5 | AA8: =AA5/AA3 -> 3 | ... AM8: =AM5/AM3 -> #DIV/0!
A10: Manpower
A11: Land Development | AA11: 6 | AB11: 8 | AC11: 8 | AD11: 8 | AE11: 6 | AF11: 6 | AG11: 6 | AH11: 5 | AI11: 8 | AJ11: 8 | AK11: 7 | AL11: 9
AC13: Bushing | AE13: Balance | AF13: Remaining days | AG13: Per day requirement
J14: 250 | K14: 47 | AC14: 250 | AD14: 47 | AE14: =AC14-AD14 -> 203 | AF14: 19 | AG14: =AE14/AF14 -> 10.684211
AC16: Grading
AC17: 250 | AD17: 121 | AE17: =AC17-AD17 -> 129 | AF17: =AF14 -> 19 | AG17: =AE17/AF17 -> 6.7894737

Sheet Preliminary Activity
A1: # | B1: Contract Signing & Key Preliminary Activities | C1: Planned | D1: Actual/ Expected | E1: Status
A2: 1 | B2: Project Start Date | C2: 45694 | D2: 45694
A3: 2 | B3: Contract Agreement Signing | C3: 45698 | D3: 45698 | E3: Completed
A4: 3 | B4: Kick Off meeting_SECI HO | C4: 45698 | D4: 45698 | E4: Completed
A5: 4 | B5: PBG Submission | C5: 45721 | D5: 45721 | E5: Completed
A6: 5 | B6: ABG Submission | C6: 45730 | D6: 45730 | E6: Completed
A7: 6 | B7: Boundary Coordinates Capturing | C7: 45709 | D7: 45709 | E7: Completed
A8: 7 | B8: Labor License related documents (Form 2, Form 5) | C8: 45733 | D8: 45733 | E8: Completed
A9: 8 | B9: Labor License | C9: 45758 | D9: 45749 | E9: Completed
A10: 9 | B10: Customer GST commercial registration & Address (Billing & Delivery) Details | C10: 45754 | D10: 45793 | E10: Completed
A11: 10 | B11: Topography Survey | C11: 45730 | D11: 45730 | E11: Completed
A12: 11 | B12: Soil Test (5m) | C12: 45735 | D12: 45735 | E12: Completed
A13: 12 | B13: Soil Test (10m) | C13: 45762 | D13: 45777 | E13: Completed
A14: 13 | B14: ERT Test | C14: 45760 | D14: 45757 | E14: Completed
A15: 14 | B15: Test Pile Casting | C15: 45773 | D15: 45815 | E15: Completed
A16: 15 | B16: Pull out test | C16: =C15+28 -> 45801 | D16: 45837 | E16: Work in Progress
A17: # | B17: Site Establishment | C17: Planned | D17: Actual/ Expected | E17: Status
A18: 1 | B18: Area development | C18: 45760 | D18: 45752 | E18: Completed
A19: =+SUM(A18+1) -> 2 | B19: Store Yard Fencing Work | C19: 45833 | D19: 45837 | E19: Completed
A20: =+SUM(A19+1) -> 3 | B20: Delivery of office cabins/ Toilets/ Security cabins | C20: 45783 | D20: 45838 | E20: Completed
A21: =+SUM(A20+1) -> 4 | B21: Construction Power arrangement | C21: 45767 | D21: 45767 | E21: Completed
A22: =+SUM(A21+1) -> 5 | B22: Internet availability | C22: 45767 | D22: 45752 | E22: Completed
A23: =+SUM(A22+1) -> 6 | B23: Placement of security personnel | C23: 45762 | D23: 45740 | E23: Security personal deployed at Site
A24: =+SUM(A23+1) -> 7 | B24: Set up of Quality Lab | C24: 45774 | D24: 45844 | E24: Completed
A25: =+SUM(A24+1) -> 8 | B25: Set up of safety induction room | C25: 45774 | D25: 45838 | E25: Completed
A26: =+SUM(A25+1) -> 9 | B26: Set up of material storage | C26: 45764 | D26: 45838 | E26: Work in Progress
A27: # | B27: Civil Activities | C27: Planned | D27: Actual/ Expected | E27: Status
A28: 1 | B28: Periphery Boundary Fencing | D28: 45836 | E28: Work in Progress

Sheet Manpower
A1: Project Name : | B1: 300MW SECI RAMAGIRI PROJECT
A2: Project Size : | B2: 300MW AC Capacity & 390 Mwp DC Capacity
A3: Date of Report: | B3: ='[1]Project Overview'!P1 -> 45702
A5: S No. | B5: Contractor Name | C5: Resources Category | D5: Manpower Description | E5: =B3 -> 45702 | F5: Cum. Nos | G5: 45703 | H5: =G5+1 -> 45704 | I5: =H5+1 -> 45705 | J5: =I5+1 -> 45706 | K5: =J5+1 -> 45707 | L5: =K5+1 -> 45708 | M5: =L5+1 -> 45709 | N5: =M5+1 -> 45710 | O5: =N5+1 -> 45711 | ... MM5: =ML5+1 -> 46047
E6: =SUM(E7:E139) -> 1 | F6: =SUM(G6:MM6) -> 0 | G6: =SUM(G7:G139) -> 0 | H6: =SUM(H7:H139) -> 0 | I6: =SUM(I7:I139) -> 0 | J6: =SUM(J7:J139) -> 0 | K6: =SUM(K7:K139) -> 0 | L6: =SUM(L7:L139) -> 0 | M6: =SUM(M7:M139) -> 0 | N6: =SUM(N7:N139) -> 0 | ... BZ6: =SUM(BZ7:BZ139) -> 0 | CA6: =SUM(CA8:CA139) -> 0 | CB6: =SUM(CB8:CB139) -> 0 | CC6: =SUM(CC8:CC139) -> 0 | CD6: =SUM(CD8:CD139) -> 0 | CE6: =SUM(CE8:CE139) -> 0 | CF6: =SUM(CF8:CF139) -> 0 | CG6: =SUM(CG9:CG139) -> 0 | CH6: =SUM(CH8:CH139) -> 0 | CI6: =SUM(CI8:CI139) -> 0 | CJ6: =SUM(CJ8:CJ139) -> 0 | CK6: =SUM(CK8:CK139) -> 0 | CL6: =SUM(CL8:CL139) -> 0 | CM6: =SUM(CM8:CM139) -> 0 | CN6: =SUM(CN8:CN139) -> 0 | CO6: =SUM(CO8:CO139) -> 0 | ... DC6: =SUM(DC8:DC139) -> 0 | DD6: =SUM(DD8:DD141) -> 0 | DE6: =SUM(DE8:DE141) -> 0 | DF6: =SUM(DF8:DF141) -> 0 | DG6: =SUM(DG8:DG141) -> 0 | DH6: =SUM(DH8:DH141) -> 0 | DI6: =SUM(DI8:DI141) -> 0 | DJ6: =SUM(DJ8:DJ141) -> 0 | DK6: =SUM(DK8:DK141) -> 0 | ... FT6: =SUM(FT8:FT141) -> 0 | FU6: =SUM(FU8:FU139) -> 0 | FV6: =SUM(FV8:FV139) -> 0 | FW6: =SUM(FW8:FW139) -> 0 | FX6: =SUM(FX8:FX139) -> 0 | FY6: =SUM(FY8:FY139) -> 0 | FZ6: =SUM(FZ8:FZ139) -> 0 | GA6: =SUM(GA8:GA139) -> 0 | GB6: =SUM(GB8:GB139) -> 0 | ... MM6: =SUM(MM8:MM139) -> 0
A7: 1 | D7: Staff | E7: =SUMIFS(G7:XFD7,$G$5:$XFD$5,$E$5) -> 0 | F7: =SUM(G7:MM7) -> 0
A8: 2 | C8: Surveying | D8: Suveryor | E8: =SUMIFS(G8:XFD8,$G$5:$XFD$5,$E$5) -> 0
A9: 3 | D9: Suveryor | E9: =SUMIFS(G9:XFD9,$G$5:$XFD$5,$E$5) -> 0 | F9: =SUM(G9:MM9) -> 0
A10: 4 | C10: Surveying | D10: Suveryor | E10: =SUMIFS(G10:XFD10,$G$5:$XFD$5,$E$5) -> 0 | F10: =SUM(G10:MM10) -> 0
A11: 5 | D11: Suveryor | E11: =SUMIFS(G11:XFD11,$G$5:$XFD$5,$E$5) -> 0 | F11: =SUM(G11:MM11) -> 0
A12: 6 | C12: Security | D12: Security | E12: 1 | F12: =SUM(G12:MM12) -> 0
A13: 7 | C13: Grading | D13: Engineers / Supervisors | E13: =SUMIFS(G13:XFD13,$G$5:$XFD$5,$E$5) -> 0 | F13: =SUM(G13:MM13) -> 0
A14: 8 | D14: Workers - Skilled | E14: =SUMIFS(G14:XFD14,$G$5:$XFD$5,$E$5) -> 0 | F14: =SUM(G14:MM14) -> 0
A15: 9 | D15: Workers - Unskilled | E15: =SUMIFS(G15:XFD15,$G$5:$XFD$5,$E$5) -> 0 | F15: =SUM(G15:MM15) -> 0
A16: 10 | C16: Piling | D16: Engineers / Supervisors | E16: =SUMIFS(G16:XFD16,$G$5:$XFD$5,$E$5) -> 0 | F16: =SUM(G16:MM16) -> 0
A17: 11 | D17: Workers - Skilled | E17: =SUMIFS(G17:XFD17,$G$5:$XFD$5,$E$5) -> 0 | F17: =SUM(G17:MM17) -> 0
A18: 12 | D18: Workers - Unskilled | E18: =SUMIFS(G18:XFD18,$G$5:$XFD$5,$E$5) -> 0 | F18: =SUM(G18:MM18) -> 0
A19: 13 | C19: Grading | D19: Engineers / Supervisors | E19: =SUMIFS(G19:XFD19,$G$5:$XFD$5,$E$5) -> 0 | F19: =SUM(G19:MM19) -> 0
A20: 14 | D20: Workers - Skilled | E20: =SUMIFS(G20:XFD20,$G$5:$XFD$5,$E$5) -> 0 | F20: =SUM(G20:MM20) -> 0
A21: 15 | D21: Workers - Unskilled | E21: =SUMIFS(G21:XFD21,$G$5:$XFD$5,$E$5) -> 0 | F21: =SUM(G21:MM21) -> 0
A22: 16 | C22: Piling | D22: Engineers / Supervisors | E22: =SUMIFS(G22:XFD22,$G$5:$XFD$5,$E$5) -> 0 | F22: =SUM(G22:MM22) -> 0
A23: 17 | D23: Workers - Skilled | E23: =SUMIFS(G23:XFD23,$G$5:$XFD$5,$E$5) -> 0 | F23: =SUM(G23:MM23) -> 0
A24: 18 | D24: Workers - Unskilled | E24: =SUMIFS(G24:XFD24,$G$5:$XFD$5,$E$5) -> 0 | F24: =SUM(G24:MM24) -> 0
A25: 19 | C25: Grading | D25: Engineers / Supervisors | E25: =SUMIFS(G25:XFD25,$G$5:$XFD$5,$E$5) -> 0 | F25: =SUM(G25:MM25) -> 0
A26: 20 | D26: Workers - Skilled | E26: =SUMIFS(G26:XFD26,$G$5:$XFD$5,$E$5) -> 0 | F26: =SUM(G26:MM26) -> 0
A27: 21 | D27: Workers - Unskilled | E27: =SUMIFS(G27:XFD27,$G$5:$XFD$5,$E$5) -> 0 | F27: =SUM(G27:MM27) -> 0
A28: 22 | C28: Piling | D28: Engineers / Supervisors | E28: =SUMIFS(G28:XFD28,$G$5:$XFD$5,$E$5) -> 0 | F28: =SUM(G28:MM28) -> 0
A29: 23 | D29: Workers - Skilled | E29: =SUMIFS(G29:XFD29,$G$5:$XFD$5,$E$5) -> 0 | F29: =SUM(G29:MM29) -> 0
A30: 24 | D30: Workers - Unskilled | E30: =SUMIFS(G30:XFD30,$G$5:$XFD$5,$E$5) -> 0 | F30: =SUM(G30:MM30) -> 0
A31: 25 | C31: Grading | D31: Engineers / Supervisors | E31: =SUMIFS(G31:XFD31,$G$5:$XFD$5,$E$5) -> 0 | F31: =SUM(G31:MM31) -> 0
A32: 26 | D32: Workers - Skilled | E32: =SUMIFS(G32:XFD32,$G$5:$XFD$5,$E$5) -> 0 | F32: =SUM(G32:MM32) -> 0
A33: 27 | D33: Workers - Unskilled | E33: =SUMIFS(G33:XFD33,$G$5:$XFD$5,$E$5) -> 0 | F33: =SUM(G33:MM33) -> 0
A34: 28 | C34: Piling | D34: Engineers / Supervisors | E34: =SUMIFS(G34:XFD34,$G$5:$XFD$5,$E$5) -> 0 | F34: =SUM(G34:MM34) -> 0
A35: 29 | D35: Workers - Skilled | E35: =SUMIFS(G35:XFD35,$G$5:$XFD$5,$E$5) -> 0 | F35: =SUM(G35:MM35) -> 0
A36: 30 | D36: Workers - Unskilled | E36: =SUMIFS(G36:XFD36,$G$5:$XFD$5,$E$5) -> 0 | F36: =SUM(G36:MM36) -> 0
A37: 31 | C37: Grading | D37: Engineers / Supervisors | E37: =SUMIFS(G37:XFD37,$G$5:$XFD$5,$E$5) -> 0 | F37: =SUM(G37:MM37) -> 0
A38: 32 | D38: Workers - Skilled | E38: =SUMIFS(G38:XFD38,$G$5:$XFD$5,$E$5) -> 0 | F38: =SUM(G38:MM38) -> 0
A39: 33 | D39: Workers - Unskilled | E39: =SUMIFS(G39:XFD39,$G$5:$XFD$5,$E$5) -> 0 | F39: =SUM(G39:MM39) -> 0
A40: 34 | C40: Piling | D40: Engineers / Supervisors | E40: =SUMIFS(G40:XFD40,$G$5:$XFD$5,$E$5) -> 0 | F40: =SUM(G40:MM40) -> 0
A41: 35 | D41: Workers - Skilled | E41: =SUMIFS(G41:XFD41,$G$5:$XFD$5,$E$5) -> 0 | F41: =SUM(G41:MM41) -> 0
...

Sheet Machinery
A1: Project Name : | B1: 300MW SECI RAMAGIRI PROJECT
A2: Project Size : | B2: 300MW AC Capacity & 390 Mwp DC Capacity
A3: Date of Report: | B3: 45703
A5: S No. | B5: Contractor Name | C5: Resources Category | D5: Resources Description | E5: =B3 -> 45703 | F5: Cum. Nos | G5: 45703 | H5: =G5+1 -> 45704 | I5: =H5+1 -> 45705 | J5: =I5+1 -> 45706 | K5: =J5+1 -> 45707 | L5: =K5+1 -> 45708 | M5: =L5+1 -> 45709 | N5: =M5+1 -> 45710 | O5: =N5+1 -> 45711 | ... LN5: =LM5+1 -> 46022
E6: =SUM(E10:E42) -> 0 | F6: =SUM(G6:LN6) -> 0 | G6: =SUM(G10:G42) -> 0 | H6: =SUM(H10:H42) -> 0 | I6: =SUM(I10:I42) -> 0 | J6: =SUM(J10:J42) -> 0 | K6: =SUM(K10:K42) -> 0 | L6: =SUM(L10:L42) -> 0 | M6: =SUM(M10:M42) -> 0 | N6: =SUM(N10:N42) -> 0 | ... BZ6: =SUM(BZ10:BZ42) -> 0 | CA6: =SUM(CA11:CA42) -> 0 | CB6: =SUM(CB11:CB42) -> 0 | CC6: =SUM(CC11:CC42) -> 0 | CD6: =SUM(CD11:CD42) -> 0 | CE6: =SUM(CE11:CE42) -> 0 | CF6: =SUM(CF11:CF42) -> 0 | CG6: =SUM(CG11:CG42) -> 0 | CH6: =SUM(CH11:CH42) -> 0 | ... DC6: =SUM(DC11:DC42) -> 0 | DD6: =SUM(DD11:DD44) -> 0 | DE6: =SUM(DE11:DE44) -> 0 | DF6: =SUM(DF11:DF44) -> 0 | DG6: =SUM(DG11:DG44) -> 0 | DH6: =SUM(DH11:DH44) -> 0 | DI6: =SUM(DI11:DI44) -> 0 | DJ6: =SUM(DJ11:DJ44) -> 0 | DK6: =SUM(DK11:DK44) -> 0 | ... FT6: =SUM(FT11:FT44) -> 0 | FU6: =SUM(FU11:FU42) -> 0 | FV6: =SUM(FV11:FV42) -> 0 | FW6: =SUM(FW11:FW42) -> 0 | FX6: =SUM(FX11:FX42) -> 0 | FY6: =SUM(FY11:FY42) -> 0 | FZ6: =SUM(FZ11:FZ42) -> 0 | GA6: =SUM(GA11:GA42) -> 0 | GB6: =SUM(GB11:GB42) -> 0 | ... LN6: =SUM(LN11:LN42) -> 0
A7: 1 | B7: PR Construction | D7: JCB | F7: =SUM(G7:LN7) -> 58 | BF7: 1 | BG7: 1 | BH7: 1 | BI7: 1 | BJ7: 2 | BK7: 2 | BL7: 1 | BM7: 1 | BP7: 4 | BQ7: 4 | BR7: 4 | BS7: 4 | BT7: 4 | BU7: 6 | BV7: 6 | BW7: 6 | BX7: 6 | BY7: 4
A8: =A7+1 -> 2 | D8: Tractor | F8: =SUM(G8:LN8) -> 0
A9: =A8+1 -> 3 | D9: Farana | F9: =SUM(G9:LN9) -> 0
A10: =ROW()-8 -> 2 | D10: Hire Vehicle | E10: =SUMIFS(G10:XFD10,$G$5:$XFD$5,$E$5) -> 0 | F10: =SUM(G10:LN10) -> 0
A11: =A10+1 -> 3 | B11: Boundary wall works | D11: Manual Loading Transit mixer | F11: =SUM(G11:LN11) -> 0
A12: =A11+1 -> 4 | D12: Tractor mounted auger | F12: =SUM(G12:LN12) -> 0
A13: =A12+1 -> 5 | D13: Tractor with trolly | F13: =SUM(G13:LN13) -> 0
A14: =A13+1 -> 6 | D14: Water tanker | F14: =SUM(G14:LN14) -> 0
A15: =A14+1 -> 7 | D15: Pickup | F15: =SUM(G15:LN15) -> 0
A16: 13 | B16: Bush cleaning | D16: JCB | F16: =SUM(G16:LN16) -> 0
A17: 14 | D17: Tractor with trolly | F17: =SUM(G17:LN17) -> 0
A18: 18 | B18: Internal Road works | D18: JCB / Grader | F18: =SUM(G18:LN18) -> 0
A19: 19 | D19: Tractor Trolley | F19: =SUM(G19:LN19) -> 0
A20: 20 | D20: Roller | F20: =SUM(G20:LN20) -> 0
A21: 21 | D21: Dumper | F21: =SUM(G21:LN21) -> 0
A22: 22 | D22: Water tanker | F22: =SUM(G22:LN22) -> 0
A23: 23 | B23: Approach Road works | D23: JCB / Grader | F23: =SUM(G23:LN23) -> 0
A24: 24 | D24: Tractor Trolley | F24: =SUM(G24:LN24) -> 0
A25: 25 | D25: Roller | F25: =SUM(G25:LN25) -> 0
A26: 26 | D26: DG | F26: =SUM(G26:LN26) -> 0
A27: 27 | D27: Water tanker | F27: =SUM(G27:LN27) -> 0
A28: 33 | B28: Piling | D28: DTH | F28: =SUM(G28:LN28) -> 0
A29: 34 | D29: Tractor Augur | F29: =SUM(G29:LN29) -> 0
A30: 35 | D30: Water tanker | F30: =SUM(G30:LN30) -> 0
A31: 36 | D31: Tractor with trolly | F31: =SUM(G31:LN31) -> 0
A32: 37 | D32: JCB | F32: =SUM(G32:LN32) -> 0
A33: 38 | D33: DG | F33: =SUM(G33:LN33) -> 0
A34: 77 | B34: ICR Building | D34: Total Station | F34: =SUM(G34:LN34) -> 0
A35: 78 | D35: Tractor with trolly | F35: =SUM(G35:LN35) -> 0
A36: 79 | D36: Water tanker | F36: =SUM(G36:LN36) -> 0
A37: 80 | D37: Tractor mounted auger | F37: =SUM(G37:LN37) -> 0
A38: 68 | B38: MCR CIVIL | D38: Tractor mounted auger | F38: =SUM(G38:LN38) -> 0
A39: 69 | D39: Water tanker | F39: =SUM(G39:LN39) -> 0
A40: 70 | D40: Tractor with trolly | F40: =SUM(G40:LN40) -> 0
A41: 71 | D41: JCB | F41: =SUM(G41:LN41) -> 0
...

Sheet Ordering
A1: # | B1: Ordering | C1: Make/ OEM | D1: Planned | E1: Actual/ Expected | F1: Remarks
A3: 1 | B3: Module Mounting Structure | C3: Pennar | D3: 45757 | E3: 45759 | F3: Completed
A4: 2 | B4: Inverter Duty Transformer | C4: T&R | D4: 45757 | E4: 45747 | F4: Completed
A5: 3 | B5: NIFPS | D5: 45780 | E5: 45838
A6: 4 | B6: ICOG/RMU PANEL | C6: Trisquare | D6: 45768 | E6: 45797 | F6: Completed
A7: 5 | B7: Main HT Switchgear Panel | C7: Trisquare | D7: 45768 | E7: 45797 | F7: Completed
A8: 6 | B8: Auxiliary LT Panel | D8: 45784 | E8: 45835
A9: 7 | B9: Auxiliary Transformer | D9: 45784 | E9: 45835
A10: 8 | B10: Central Inverter(PCU) | C10: Fimer | D10: 45760 | E10: 45747 | F10: Completed
A11: 9 | B11: String Combiner Box (SCB) | C11: Trinity Touch | D11: 45757 | E11: 45838 | F11: Completed
A12: 10 | B12: DC string cable | D12: 45783 | E12: 45845
A13: 11 | B13: DC power cable | D13: 45768 | E13: 45845
A14: 12 | B14: LT AC power cable | D14: 45768 | E14: 45845
A15: 13 | B15: HT AC power cable | D15: 45783 | E15: 45845
A16: 14 | B16: LT power and control cables | D16: 45783 | E16: 45845
A17: 15 | B17: Communication cables | D17: 45783 | E17: 45845
A18: 16 | B18: SCADA system | C18: Adaptive | D18: 45768 | E18: 45815 | F18: Completed
A19: 17 | B19: UPS and Battery System | D19: 45783 | E19: 45835
A20: 18 | B20: SVG | D20: 45784 | E20: 45853
A21: 19 | B21: Harmonic Filter and its Acessories | D21: 45803 | E21: 45853
A22: 20 | B22: Other BOQ (Lighting, Gland, Lungs, HT termination KIT etc.) | D22: 45839 | E22: 45839

Sheet MDL (2)
A1: MDL SUMMARY - 300MW SECI PV | L1: Data Date | M1: 45830 | O1: =TODAY() -> 45853 | U1: =TODAY() -> 45853
A2: Sl.No. | B2: Discipline | C2: Discipline | D2: Document Title | E2: Document Number | F2: Approval Catogery | G2: Planned Submission Date (EPCC) | H2: Submitted/Expected Submission | I2: Other drawing linked | J2: Tentative approval date- linked docs. | K2: Revision | L2: Submission Date | M2: Response date | N2: CLIENT Comments / Approval(CAT-I,CAT-II CAT-III & CAT-IV) | O2: No.of Days Reviwed by SECI | P2: No.of Days Reviwed by ARIPL | Q2: Approved date | R2: Submission/Review By | S2: Approved Category | T2: Status | U2: Days taken for review/re-submission
A3: 1 | B3: General | C3: Survey & Studies | D3: SoW & Method Statement for Topography and Contour Survey | E3: SECI-RG300-PL-CIV-001 | F3: Approval | G3: 45698 | H3: 45698 | K3: R0 | L3: 45698 | R3: Approved | S3: CAT - III | T3: Approved
K4: R1 | L4: 45700 | M4: 45700 | O4: =M4-L4 -> 0 | P4: =L5-M4 -> 2 | X4: Submitted - Under Review
K5: R2 | L5: 45702 | M5: 45705 | O5: =M5-L5 -> 3 | P5: =L6-M5 -> 2 | X5: Approved
K6: R3 | L6: 45707 | X6: Re-Submission
A7: 2 | B7: General | C7: Survey & Studies | D7: Topography and Contour Report | E7: SECI-RG300-PL-CIV-002 | F7: Information | G7: 45740 | H7: 45740 | K7: R0 | L7: 45740 | M7: 45743 | N7: CAT -IV R | O7: =M7-L7 -> 3 | P7: =L8-M7 -> 6 | Q7: =M8 -> 45755 | R7: =T7 -> Approved | S7: =N8 -> CAT -IV | T7: Approved | U7: =M8-L8 -> 6 | X7: Yet to be submitted
K8: R1 | L8: 45749 | M8: 45755 | N8: CAT -IV | O8: =M8-L8 -> 6
A9: 3 | B9: General | C9: Survey & Studies | D9: SoW & Method Statement for Geotechnical Investigation | E9: SECI-RG300-PL-CIV-003 | F9: Approval | K9: R0 | S9: CAT - I | T9: Approved
A10: 4 | B10: General | C10: Survey & Studies | D10: Geotechnical Investigation Report (Soil Test, CBR, Chemical Analysis & Thermal Resistivity) | E10: SECI-RG300-PL-CIV-004 | F10: Information | G10: 45768 | H10: 45768 | K10: R0 | L10: 45768 | M10: 45776 | N10: CAT -IV R | O10: =M10-L10 -> 8 | Q10: =M10 -> 45776 | R10: Approved | S10: =N10 -> CAT -IV R | T10: Approved
K11: R1 | L11: 45827
A12: 5 | B12: General | C12: Survey & Studies | D12: SoW & Method Statement for Hydrology Investigation | E12: SECI-RG300-PL-CIV-005 | F12: Information | G12: 45814 | H12: 45820 | R12: SECI | T12: Submitted - Under Review
A13: 6 | B13: General | C13: Survey & Studies | D13: Hydrology Investigation Report | E13: SECI-RG300-PL-CIV-006 | F13: Information | G13: 45814 | H13: 45815 | K13: R0 | L13: 45815 | M13: 45828 | N13: CAT -IV R | R13: ARIPL | S13: =N13 -> CAT -IV R | T13: Approved | U13: =U1-L13 -> 38
A14: 7 | B14: General | C14: Survey & Studies | D14: SoW & Method Statement for Soil resistivity test (ERT) | E14: SECI-RG300-PL-CIV-007 | F14: Approval | G14: 45742 | H14: 45742 | K14: R0 | L14: 45742 | M14: 45751 | N14: CAT - II | O14: =M14-L14 -> 9 | P14: =L15-M14 -> 0 | R14: SECI | S14: =N14 -> CAT - II | T14: Approved | U14: =U1-L15 -> 102
K15: R1 | L15: 45751 | O15: =O1-L15 -> 102
A16: 8 | B16: General | C16: Survey & Studies | D16: Soil resistivity test report (ERT) | E16: SECI-RG300-PL-CIV-008 | F16: Information | G16: 45771 | H16: 45771 | K16: R0 | L16: 45772 | O16: =O1-L16 -> 81 | R16: SECI | T16: Submitted - Under Review | U16: =U1-L16 -> 81
A17: 9 | B17: General | C17: Survey & Studies | D17: Water Test Report | E17: SECI-RG300-PL-CIV-009 | F17: Information | K17: R0 | R17: Approved | S17: CAT - I | T17: Approved
A18: 10 | B18: General | C18: Survey & Studies | D18: Concrete Mix Design Report | E18: SECI-RG300-PL-CIV-010 | F18: Information | G18: 45772 | H18: 45772 | K18: R0 | L18: 45772 | M18: 45778 | N18: CAT -IV R | O18: =M18-L18 -> 6 | R18: ARIPL | S18: =N18 -> CAT -IV R | T18: Re-Submission | U18: =U1-M18 -> 75
A19: 11 | B19: General | C19: Survey & Studies | D19: Pile Pull out and Lateral Test Layout & Procedure | E19: SECI-RG300-PL-CIV-011 | F19: Approval | G19: 45769 | H19: =L19 -> 45769 | K19: R0 | L19: 45769 | M19: 45771 | N19: CAT - III | O19: =M19-L19 -> 2 | P19: =L20-M19 -> 6 | Q19: =M21 -> 45793 | R19: SECI | S19: =N21 -> CAT - I | T19: Approved | U19: =M21-L21 -> 7
K20: R1 | L20: 45777 | M20: 45778 | N20: CAT - II | O20: =M20-L20 -> 1 | P20: =L21-M20 -> 8
K21: R2 | L21: 45786 | M21: 45793 | N21: CAT - I | O21: =M21-L21 -> 7
A22: 12 | B22: General | C22: Survey & Studies | D22: Pile Pull out and Lateral Test Report | E22: SECI-RG300-PL-CIV-012 | F22: Information | G22: 45801 | H22: 45843
A23: 13 | B23: General | C23: Survey & Studies | D23: SoP for Site Cleaning & Grading | E23: SECI-RG300-PL-CIV-013 | F23: Information
A24: 14 | B24: General | C24: Survey & Studies | D24: Design Basis Study Report for Civil & Structural | E24: SECI-RG300-PL-CIV-014 | F24: Approval
A25: 1 | B25: Civil | C25: Civil & Structural (MMS) | D25: MMS - Structural Design Calculations & Staad report (2PX26) | E25: SECI-RG300-PL-CIV-101 | F25: Approval | G25: 45727 | H25: =L25 -> 45727 | K25: R0 | L25: 45727 | M25: 45736 | N25: CAT - III | O25: =M25-L25 -> 9 | P25: =L26-M25 -> 19 | R25: Approved | S25: =N27 -> CAT - I | T25: Approved | U25: =U1-L27 -> 48
K26: R1 | L26: 45755 | M26: 45758 | N26: CAT - II | O26: =M26-L26 -> 3 | P26: =L27-M26 -> 47
K27: R2 | L27: 45805 | M27: 45810 | N27: CAT - I | O27: =M27-L27 -> 5
A28: 2 | B28: Civil | C28: Civil & Structural (MMS) | D28: MMS - Structural Design Calculations & Staad report (2PX14 & 2PX28) | E28: SECI-RG300-PL-CIV-102 | F28: Approval | G28: 45805 | H28: =L28 -> 45811 | K28: R0 | L28: 45811 | M28: 45818 | N28: CAT - III | O28: =O1-L28 -> 42 | R28: ARIPL | S28: =N28 -> CAT - III | T28: Re-Submission | U28: =U1-L28 -> 42
A29: 3 | B29: Civil | C29: Civil & Structural (MMS) | D29: MMS - Pile Foundation Design Calculation | E29: SECI-RG300-PL-CIV-103 | F29: Approval | G29: 45795 | H29: =L29 -> 45813 | K29: R0 | L29: 45813 | M29: 45828 | N29: CAT - III | O29: =O1-L29 -> 40 | R29: ARIPL | S29: =N29 -> CAT - III | T29: Re-Submission | U29: =U1-L29 -> 40
A30: 4 | B30: Civil | C30: Civil & Structural (MMS) | D30: MMS - Structure GA drawings(2PX26) | E30: SECI-RG300-PL-CIV-104 | F30: Approval | G30: 45751 | H30: =L30 -> 45727 | K30: R0 | L30: 45727 | M30: 45736 | N30: CAT - II | O30: =M30-L30 -> 9 | P30: =L31-M30 -> 19 | Q30: =M34 -> 45825 | R30: SECI | S30: =N34 -> CAT - I | T30: Approved | U30: =M32-L32 -> 1
K31: R1 | L31: 45755 | M31: 45758 | N31: CAT - I | O31: =M31-L31 -> 3 | P31: =L32-M31 -> 25
K32: R2 | L32: 45783 | M32: 45784 | N32: CAT - I | O32: =M32-L32 -> 1 | P32: =L33-M32 -> 21
K33: R3 | L33: 45805 | M33: 45807 | N33: CAT - II | O33: =M33-L33 -> 2
K34: R4 | L34: 45825 | M34: 45825 | N34: CAT - I | O34: =M34-L34 -> 0
A35: 5 | B35: Civil | C35: Civil & Structural (MMS) | D35: MMS - Structure GA drawings(2PX14 & 2PX28) | E35: SECI-RG300-PL-CIV-104A | F35: Approval | G35: 45811 | H35: =L35 -> 45811 | K35: R0 | L35: 45811 | M35: 45818 | N35: CAT - III | O35: =O1-L35 -> 42 | R35: ARIPL | S35: =N35 -> CAT - III | T35: Approved | U35: =U1-L35 -> 42
A36: 6 | B36: Civil | C36: Civil & Structural (MMS) | D36: MMS - Structure GA drawings(2PX13) | E36: SECI-RG300-PL-CIV-105 | F36: Approval | G36: 45751 | H36: =L36 -> 45727 | K36: R0 | L36: 45727 | M36: 45736 | N36: CAT - III | O36: =M36-L36 -> 9 | P36: =L37-M36 -> 19 | Q36: 45758 | R36: ARIPL | S36: =N37 -> CAT - I | T36: Approved
K37: R1 | L37: 45755 | M37: 45758 | N37: CAT - I | O37: =M37-L37 -> 3
A38: 7 | B38: Civil | C38: Civil & Structural (MMS) | D38: MMS - Structural Fabrication drawings(2PX28) | E38: SECI-RG300-PL-CIV-106 | F38: Information | G38: 45769 | H38: =L38 -> 45769 | K38: R0 | L38: 45769 | M38: 45779 | N38: CAT -IV | O38: =M38-L38 -> 10 | P38: =L39-M38 -> 3 | Q38: =M38 -> 45779 | R38: SECI | S38: =N39 -> CAT -IV | T38: Approved
K39: R1 | L39: 45782 | M39: 45784 | N39: CAT -IV | O39: =M39-L39 -> 2 | P39: =L41-M39 -> 41
K40: R2 | L40: 45805 | M40: 45807 | N40: CAT -IV | O40: =M40-L40 -> 2
...

Sheet Construction Status
C1: Date | D1: ='Construction DASHBOARD'!B6 -> 45853
B2: Section | C2: S.No | D2: Site Activity | E2: Planned Start | F2: Planned Finish | G2: No. of Days | H2: Actual/ Expected Start | I2: Actual/ Expected Finish | J2: UoM | K2: Qty | L2: Start Date | M2: Actual/ Expected Finish Date | N2: No of Days | O2: Avg/Day | P2: Actual as on Date (%) | Q2: Comp. | R2: Bal | S2: Actual as on date | T2: Till Last Month | U2: 45746 | V2: 45750 | W2: 45751 | X2: 45752 | Y2: 45753 | Z2: 45754 | AA2: 45755 | AB2: 45756 | AC2: 45757 | AD2: 45758 | AE2: 45759 | AF2: 45760 | AG2: 45761 | AH2: 45762 | AI2: 45763 | AJ2: 45764 | AK2: 45765 | AL2: 45766 | AM2: 45767 | AN2: 45768 | AO2: 45769 | AP2: 45770 | AQ2: 45771 | AR2: 45772 | AS2: 45773 | AT2: 45774 | AU2: 45775 | AV2: 45776 | AW2: 45777 | AX2: 45778 | AY2: 45779 | AZ2: 45780 | BA2: 45781 | BB2: 45782 | BC2: 45783 | BD2: 45784 | BE2: 45785 | BF2: 45786 | BG2: 45787 | BH2: 45788 | BI2: 45789 | BJ2: 45790 | BK2: 45791 | BL2: 45792 | BM2: 45793 | BN2: 45794 | BO2: 45795 | BP2: 45796 | BQ2: 45797 | BR2: 45798 | BS2: 45799 | BT2: 45800 | BU2: 45801 | BV2: 45802 | BW2: 45803 | BX2: 45804 | BY2: 45805 | BZ2: 45806 | CA2: 45807 | CB2: 45808 | CC2: 45809 | CD2: 45810 | CE2: 45811 | CF2: 45812 | CG2: 45813 | CH2: 45814 | CI2: 45815 | CJ2: 45816 | CK2: 45817 | CL2: 45818 | CM2: 45819 | CN2: 45820 | CO2: 45821 | CP2: 45822 | CQ2: 45823 | CR2: 45824 | CS2: 45825 | CT2: 45826 | CU2: 45827 | CV2: 45828 | CW2: 45829 | CX2: 45830 | CY2: 45831 | CZ2: 45832 | DA2: 45833 | DB2: 45834 | DC2: 45835 | DD2: 45836 | DE2: 45837 | DF2: 45838 | DG2: 45839 | DH2: 45840 | DI2: 45841 | DJ2: 45842 | DK2: 45843 | DL2: 45844 | DM2: 45845 | DN2: 45846 | DO2: 45847 | DP2: 45848 | DQ2: 45849 | DR2: 45850 | DS2: 45851 | DT2: 45852 | DU2: 45853 | DV2: 45854 | DW2: 45855 | DX2: 45856 | DY2: 45857 | DZ2: 45858 | EA2: 45859 | EB2: 45860 | EC2: 45861 | ED2: 45862 | EE2: 45863 | EF2: 45864 | EG2: 45865 | EH2: 45866 | EI2: 45867 | EJ2: 45868 | EK2: 45869 | EL2: 45870 | EM2: 45871 | EN2: 45872 | EO2: 45873 | EP2: 45874 | EQ2: 45875
U3: =TEXT(U2,"ddd") -> Sun | V3: =TEXT(V2,"ddd") -> Thu | W3: =TEXT(W2,"ddd") -> Fri | X3: =TEXT(X2,"ddd") -> Sat | Y3: =TEXT(Y2,"ddd") -> Sun | Z3: =TEXT(Z2,"ddd") -> Mon | AA3: =TEXT(AA2,"ddd") -> Tue | AB3: =TEXT(AB2,"ddd") -> Wed | ... EK3: =TEXT(EK2,"ddd") -> Thu
B4: L & G | C4: 1 | D4: Bush removal | E4: 45750 | F4: 45870 | G4: =F4-E4 -> 120 | H4: 45754 | I4: 45870 | J4: Acre | K4: 1033 | L4: 45754 | M4: 45796 | N4: =IF(OR(M4="",L4=""),"",INT(M4-L4+1)) -> 43 | O4: =IFERROR(K4/N4,"-") -> 24.023256 | P4: =Q4/K4 -> 0.84414327 | Q4: =S4 -> 872 | R4: =K4-Q4 -> 161 | S4: =SUM(U4:XFD4) -> 872 | T4: =SUM(U4:CB4) -> 486 | U4: 0 | V4: 0 | Z4: 1.5 | AA4: 3.5 | AB4: 4 | AC4: 4 | AD4: 4 | AE4: 4 | AF4: 3 | AG4: 2 | AI4: 10 | AJ4: 20 | AK4: 20 | AL4: 20 | AM4: 21 | AN4: 40 | AO4: 40 | AP4: 40 | AQ4: 38 | BC4: 5 | BD4: 10 | BE4: 10 | BF4: 10 | BG4: 5 | BH4: 7 | BI4: 5 | BJ4: 0 | BK4: 0 | BL4: 7 | BM4: 0 | BN4: 17 | BO4: 19 | BP4: 24 | BQ4: 9 | BR4: 12 | BS4: 0 | BT4: 16 | BU4: 0 | BV4: 0 | BW4: 0 | BX4: 0 | BY4: 6 | BZ4: 16 | CA4: 15 | CB4: 18 | CC4: 14 | CD4: 16 | CE4: 15 | CF4: 14 | CG4: 18 | CH4: 14 | CI4: 15 | CJ4: 10 | CK4: 11 | CL4: 16 | CM4: 13 | CN4: 15 | CO4: 17 | CP4: 5 | CQ4: 14 | CR4: 16 | CS4: 13 | CT4: 13 | CU4: 11 | CV4: 7 | CW4: 5 | CX4: 5 | CY4: 5 | CZ4: 5 | DA4: 5 | DB4: 7 | DC4: 10 | DD4: 7 | DE4: 6 | DF4: 5 | DG4: 7 | DH4: 12 | DI4: 9 | DJ4: 8 | DK4: 7 | DL4: 7 | DM4: 9 | DN4: 0 | DO4: 0 | DP4: 0 | DQ4: 0 | DR4: 0 | DS4: 0 | DT4: 0
C5: 2 | D5: Land grading | E5: 45750 | F5: 45870 | G5: =F5-E5 -> 120 | H5: 45754 | I5: 45870 | J5: Acre | K5: 1033 | L5: 45754 | M5: 45796 | N5: =IF(OR(M5="",L5=""),"",INT(M5-L5+1)) -> 43 | O5: =IFERROR(K5/N5,"-") -> 24.023256 | P5: =Q5/K5 -> 0.84414327 | Q5: =S5 -> 872 | R5: =K5-Q5 -> 161 | S5: =SUM(U5:XFD5) -> 872 | T5: =SUM(U5:CB5) -> 486 | AR5: 10 | AS5: 10 | AT5: 10 | AU5: 10 | AV5: 12 | AW5: 13 | AX5: 10 | AY5: 12 | AZ5: 11 | BA5: 20 | BB5: 14 | BC5: 16 | BD5: 10 | BE5: 6 | BF5: 10 | BG5: 5 | BH5: 7 | BI5: 5 | BJ5: 7 | BK5: 7 | BL5: 7 | BM5: 12 | BN5: 17 | BO5: 19 | BP5: 24 | BQ5: 9 | BR5: 12 | BS5: 18 | BT5: 16 | BU5: 15 | BV5: 23 | BW5: 22 | BX5: 20 | BY5: 18 | BZ5: 16 | CA5: 15 | CB5: 18 | CC5: 14 | CD5: 16 | CE5: 15 | CF5: 14 | CG5: 18 | CH5: 14 | CI5: 15 | CJ5: 10 | CK5: 11 | CL5: 16 | CM5: 13 | CN5: 15 | CO5: 17 | CP5: 5 | CQ5: 14 | CR5: 16 | CS5: 13 | CT5: 13 | CU5: 11 | CV5: 7 | CW5: 5 | CX5: 5 | CY5: 5 | CZ5: 5 | DA5: 5 | DB5: 7 | DC5: 10 | DD5: 7 | DE5: 6 | DF5: 5 | DG5: 7 | DH5: 12 | DI5: 9 | DJ5: 8 | DK5: 7 | DL5: 7 | DM5: 9 | DN5: 0 | DO5: 0 | DP5: 0 | DQ5: 0 | DR5: 0 | DS5: 0 | DT5: 0
B6: Site Initials | C6: 3 | D6: Boundry Coordinate capturing | E6: 45700 | F6: 45709 | G6: =F6-E6 -> 9 | H6: 45700 | I6: 45709 | J6: Lot. | K6: 1 | L6: 45700 | M6: 45710 | N6: =IF(OR(M6="",L6=""),"",INT(M6-L6+1)) -> 11 | O6: =IFERROR(K6/N6,"-") -> 0.090909091 | P6: =IFERROR(SUMIF($U$2:$AT$2,"<="&$D$1,U6:BN6)/K6,"-") -> 1 | Q6: =SUMIF($U$2:$CC$2,"<="&$D$1,U6:CC6) -> 1 | R6: =K6-Q6 -> 0 | S6: =SUM(U6:XFD6) -> 1 | T6: =SUM(U6:CB6) -> 1 | U6: 1
C7: 4 | D7: Topo Survey | E7: 45711 | F7: 45730 | G7: =F7-E7 -> 19 | H7: 45711 | I7: 45730 | J7: Lot. | K7: 1 | L7: 45703 | M7: 45730 | N7: =IF(OR(M7="",L7=""),"",INT(M7-L7+1)) -> 28 | O7: =IFERROR(K7/N7,"-") -> 0.035714286 | P7: =IFERROR(SUMIF($U$2:$AT$2,"<="&$D$1,U7:BN7)/K7,"-") -> 1 | Q7: =SUMIF($U$2:$CC$2,"<="&$D$1,U7:CC7) -> 1 | R7: =K7-Q7 -> 0 | S7: =SUM(U7:XFD7) -> 1 | T7: =SUM(U7:CB7) -> 1 | U7: 1
C8: 5 | D8: Soil Investigation | E8: 45703 | F8: 45762 | G8: =F8-E8 -> 59 | H8: 45703 | I8: 45776 | J8: Nos. | K8: 79 | L8: 45711 | M8: 45778 | N8: =IF(OR(M8="",L8=""),"",INT(M8-L8+1)) -> 68 | O8: =IFERROR(K8/N8,"-") -> 1.1617647 | P8: =Q8/K8 -> 1 | Q8: =SUMIF($U$2:$CC$2,"<="&$D$1,U8:CC8) -> 79 | R8: =K8-Q8 -> 0 | S8: =SUM(U8:XFD8) -> 79 | T8: =SUM(U8:CB8) -> 79 | U8: 52 | V8: 2 | W8: 2 | X8: 2 | Y8: 2 | Z8: 2 | AA8: 1 | AB8: 1 | AC8: 1 | AD8: 1 | AE8: 1 | AF8: 1 | AH8: 1 | AI8: 1 | AL8: 1 | AM8: 1 | AN8: 1 | AO8: 1 | AP8: 1 | AS8: 1 | AT8: 1 | AU8: 1 | AV8: 1
C9: 6 | D9: ERT Test | E9: 45749 | F9: 45760 | G9: =F9-E9 -> 11 | H9: 45753 | I9: 45757 | J9: Lot. | K9: 36 | L9: 45753 | M9: 45757 | N9: =IF(OR(M9="",L9=""),"",INT(M9-L9+1)) -> 5 | O9: =IFERROR(K9/N9,"-") -> 7.2 | P9: =IFERROR(SUMIF($U$2:$AT$2,"<="&$D$1,U9:BN9)/K9,"-") -> 1 | Q9: =SUMIF($U$2:$CC$2,"<="&$D$1,U9:CC9) -> 36 | R9: =K9-Q9 -> 0 | S9: =SUM(U9:XFD9) -> 36 | T9: =SUM(U9:CB9) -> 36 | U9: 0 | V9: 0 | Y9: 4 | Z9: 8 | AA9: 8 | AB9: 10 | AC9: 6
C10: 7 | D10: Test Pile Casting | E10: 45759 | F10: 45773 | G10: =F10-E10 -> 14 | H10: 45806 | I10: 45811 | J10: Lot. | K10: 240 | N10: =IF(OR(M10="",L10=""),"",INT(M10-L10+1)) | O10: =IFERROR(K10/N10,"-") -> - | P10: =Q10/K10 -> 1 | Q10: =S10 -> 240 | R10: =K10-Q10 -> 0 | S10: =SUM(U10:XFD10) -> 240 | T10: =SUM(U10:CB10) -> 108 | U10: 0 | V10: 0 | BZ10: 34 | CA10: 38 | CB10: 36 | CC10: 40 | CG10: 40 | CH10: 32 | CI10: 20
C11: 8 | D11: Pile Testing | E11: =F10+28 -> 45801 | F11: =E11+G11-1 -> 45807 | G11: 7 | H11: 45824 | I11: =H11+60 -> 45884 | J11: Lot. | K11: 240 | N11: =IF(OR(M11="",L11=""),"",INT(M11-L11+1)) | O11: =IFERROR(K11/N11,"-") -> - | P11: =Q11/K11 -> 0.2625 | Q11: =S11 -> 63 | R11: =K11-Q11 -> 177 | S11: =SUM(U11:XFD11) -> 63 | T11: =SUM(U11:CB11) -> 0 | U11: 0 | V11: 0 | CV11: 3 | CW11: 4 | CX11: 4 | CY11: 4 | CZ11: 0 | DA11: 6 | DB11: 2 | DC11: 2 | DD11: 0 | DE11: 7 | DF11: 4 | DG11: 4 | DH11: 3 | DI11: 6 | DJ11: 0 | DK11: 3 | DL11: 0 | DM11: 1 | DN11: 1 | DO11: 0 | DP11: 0 | DQ11: 0 | DR11: 0 | DS11: 2 | DT11: 7
B12: Array Yard Civil Works | C12: 9 | D12: Pile Marking | E12: 45824 | F12: 45971 | G12: =F12-E12 -> 147 | H12: 45838 | I12: 45971 | J12: Table | K12: 13322 | N12: =IF(OR(M12="",L12=""),"",INT(M12-L12+1)) | O12: =IFERROR(K12/N12,"-") -> - | P12: =Q12/K12 -> 0 | Q12: =SUMIF($U$2:$AT$2,"<="&$D$1,U12:AT12) -> 0 | R12: =K12-Q12 -> 13322 | S12: =SUM(U12:XFD12) -> 77 | T12: =SUM(U12:CB12) -> 0 | DS12: 30 | DT12: 47
C13: 10 | D13: Pile -Drilling | E13: 45848 | F13: 45976 | G13: =F13-E13 -> 128 | H13: =E13 -> 45848 | I13: =F13 -> 45976 | J13: Table | K13: 13322 | N13: =IF(OR(M13="",L13=""),"",INT(M13-L13+1)) | O13: =IFERROR(K13/N13,"-") -> - | P13: =IFERROR(SUMIF($U$2:$AT$2,"<="&$D$1,U13:BN13)/K13,"-") -> 0 | Q13: =SUMIF($U$2:$AT$2,"<="&$D$1,U13:BN13) -> 0 | R13: =K13-Q13 -> 13322 | S13: =SUM(U13:XFD13) -> 0 | T13: =SUM(U13:CB13) -> 0
C14: 11 | D14: Pile- Casting | E14: 45858 | F14: 45986 | G14: =F14-E14 -> 128 | H14: =E14 -> 45858 | I14: =F14 -> 45986 | J14: Table | K14: 13322 | N14: =IF(OR(M14="",L14=""),"",INT(M14-L14+1)) | O14: =IFERROR(K14/N14,"-") -> - | P14: =IFERROR(SUMIF($U$2:$AT$2,"<="&$D$1,U14:BN14)/K14,"-") -> 0 | Q14: =SUMIF($U$2:$AT$2,"<="&$D$1,U14:BN14) -> 0 | R14: =K14-Q14 -> 13322 | S14: =SUM(U14:XFD14) -> 0 | T14: =SUM(U14:CB14) -> 0
C15: 12 | D15: Pile-Capping | E15: 45863 | F15: 45995 | G15: =F15-E15 -> 132 | H15: =E15 -> 45863 | I15: =F15 -> 45995 | J15: Table | K15: 13322 | N15: =IF(OR(M15="",L15=""),"",INT(M15-L15+1)) | O15: =IFERROR(K15/N15,"-") -> - | P15: =IFERROR(SUMIF($U$2:$AT$2,"<="&$D$1,U15:BN15)/K15,"-") -> 0 | Q15: =SUMIF($U$2:$AT$2,"<="&$D$1,U15:AT15) -> 0 | R15: =K15-Q15 -> 13322 | S15: =SUM(U15:XFD15) -> 0 | T15: =SUM(U15:CB15) -> 0
B16: ICR Civil Works | C16: 13 | D16: ICR Marking & Excavation | E16: 45821 | F16: 45923 | G16: =F16-E16 -> 102 | H16: =E16 -> 45821 | I16: =F16 -> 45923 | J16: Block | K16: 26 | N16: =IF(OR(M16="",L16=""),"",INT(M16-L16+1)) | O16: =IFERROR(K16/N16,"-") -> - | P16: =IFERROR(SUMIF($U$2:$AT$2,"<="&$D$1,U16:BN16)/K16,"-") -> 0 | Q16: =SUMIF($U$2:$AT$2,"<="&$D$1,U16:AT16) -> 0 | R16: =K16-Q16 -> 26 | S16: =SUM(U16:XFD16) -> 0 | T16: =SUM(U16:CB16) -> 0
C17: 14 | D17: ICR PCC | E17: 45840 | F17: =F16+6 -> 45929 | G17: =F17-E17 -> 89 | H17: =E17 -> 45840 | I17: =F17 -> 45929 | J17: Block | K17: 26 | N17: =IF(OR(M17="",L17=""),"",INT(M17-L17+1)) | O17: =IFERROR(K17/N17,"-") -> - | P17: =IFERROR(SUMIF($U$2:$AT$2,"<="&$D$1,U17:BN17)/K17,"-") -> 0 | Q17: =SUMIF($U$2:$AT$2,"<="&$D$1,U17:AT17) -> 0 | R17: =K17-Q17 -> 26 | S17: =SUM(U17:XFD17) -> 0 | T17: =SUM(U17:CB17) -> 0
C18: 15 | D18: ICR Footing Casting | E18: =E17+7 -> 45847 | F18: =F17+7 -> 45936 | G18: =F18-E18 -> 89 | H18: =E18 -> 45847 | I18: =F18 -> 45936 | J18: Block | K18: 26 | N18: =IF(OR(M18="",L18=""),"",INT(M18-L18+1)) | O18: =IFERROR(K18/N18,"-") -> - | P18: =IFERROR(SUMIF($U$2:$AT$2,"<="&$D$1,U18:BN18)/K18,"-") -> 0 | Q18: =SUMIF($U$2:$AT$2,"<="&$D$1,U18:AT18) -> 0 | R18: =K18-Q18 -> 26 | S18: =SUM(U18:XFD18) -> 0 | T18: =SUM(U18:CB18) -> 0
C19: 16 | D19: ICR Column Casting | E19: =E18+15 -> 45862 | F19: =F18+15 -> 45951 | G19: =F19-E19 -> 89 | H19: =E19 -> 45862 | I19: =F19 -> 45951 | J19: Block | K19: 26 | N19: =IF(OR(M19="",L19=""),"",INT(M19-L19+1)) | O19: =IFERROR(K19/N19,"-") -> - | P19: =IFERROR(SUMIF($U$2:$AT$2,"<="&$D$1,U19:BN19)/K19,"-") -> 0 | Q19: =SUMIF($U$2:$AT$2,"<="&$D$1,U19:AT19) -> 0 | R19: =K19-Q19 -> 26 | S19: =SUM(U19:XFD19) -> 0 | T19: =SUM(U19:CB19) -> 0
C20: 17 | D20: ICR Beam Slab Casting | E20: =E19+21 -> 45883 | F20: =F19+21 -> 45972 | G20: =F20-E20 -> 89 | H20: =E20 -> 45883 | I20: =F20 -> 45972 | J20: Block | K20: 26 | N20: =IF(OR(M20="",L20=""),"",INT(M20-L20+1)) | O20: =IFERROR(K20/N20,"-") -> - | P20: =IFERROR(SUMIF($U$2:$AT$2,"<="&$D$1,U20:BN20)/K20,"-") -> 0 | Q20: =SUMIF($U$2:$AT$2,"<="&$D$1,U20:AT20) -> 0 | R20: =K20-Q20 -> 26 | S20: =SUM(U20:XFD20) -> 0 | T20: =SUM(U20:CB20) -> 0
C21: 18 | D21: Transformer Marking & Excavation | E21: 45838 | F21: 45925 | G21: =F21-E21 -> 87 | H21: =E21 -> 45838 | I21: =F21 -> 45925 | J21: Block | K21: 26 | N21: =IF(OR(M21="",L21=""),"",INT(M21-L21+1)) | O21: =IFERROR(K21/N21,"-") -> - | P21: =IFERROR(SUMIF($U$2:$AT$2,"<="&$D$1,U21:BN21)/K21,"-") -> 0 | Q21: =SUMIF($U$2:$AT$2,"<="&$D$1,U21:AT21) -> 0 | R21: =K21-Q21 -> 26 | S21: =SUM(U21:XFD21) -> 0 | T21: =SUM(U21:CB21) -> 0
C22: 19 | D22: Transformer PCC | E22: =E21+2 -> 45840 | F22: =F21+2 -> 45927 | G22: =F22-E22 -> 87 | H22: =E22 -> 45840 | I22: =F22 -> 45927 | J22: Block | K22: 26 | N22: =IF(OR(M22="",L22=""),"",INT(M22-L22+1)) | O22: =IFERROR(K22/N22,"-") -> - | P22: =IFERROR(SUMIF($U$2:$AT$2,"<="&$D$1,U22:BN22)/K22,"-") -> 0 | Q22: =SUMIF($U$2:$AT$2,"<="&$D$1,U22:AT22) -> 0 | R22: =K22-Q22 -> 26 | S22: =SUM(U22:XFD22) -> 0 | T22: =SUM(U22:CB22) -> 0
C23: 20 | D23: Transformer Footing Casting | E23: =E22+7 -> 45847 | F23: =F22+7 -> 45934 | G23: =F23-E23 -> 87 | H23: =E23 -> 45847 | I23: =F23 -> 45934 | J23: Block | K23: 26 | N23: =IF(OR(M23="",L23=""),"",INT(M23-L23+1)) | O23: =IFERROR(K23/N23,"-") -> - | P23: =IFERROR(SUMIF($U$2:$AT$2,"<="&$D$1,U23:BN23)/K23,"-") -> 0 | Q23: =SUMIF($U$2:$AT$2,"<="&$D$1,U23:AT23) -> 0 | R23: =K23-Q23 -> 26 | S23: =SUM(U23:XFD23) -> 0 | T23: =SUM(U23:CB23) -> 0
C24: 21 | D24: Transformer Pedestal Casting | E24: =E23+7 -> 45854 | F24: =F23+7 -> 45941 | G24: =F24-E24 -> 87 | H24: =E24 -> 45854 | I24: =F24 -> 45941 | J24: Block | K24: 26 | N24: =IF(OR(M24="",L24=""),"",INT(M24-L24+1)) | O24: =IFERROR(K24/N24,"-") -> - | P24: =IFERROR(SUMIF($U$2:$AT$2,"<="&$D$1,U24:BN24)/K24,"-") -> 0 | Q24: =SUMIF($U$2:$AT$2,"<="&$D$1,U24:AT24) -> 0 | R24: =K24-Q24 -> 26 | S24: =SUM(U24:XFD24) -> 0 | T24: =SUM(U24:CB24) -> 0
C25: 22 | D25: Transformer Support Foundation | E25: =E24+7 -> 45861 | F25: =F24+7 -> 45948 | G25: =F25-E25 -> 87 | H25: =E25 -> 45861 | I25: =F25 -> 45948 | J25: Block | K25: 26 | N25: =IF(OR(M25="",L25=""),"",INT(M25-L25+1)) | O25: =IFERROR(K25/N25,"-") -> - | P25: =IFERROR(SUMIF($U$2:$AT$2,"<="&$D$1,U25:BN25)/K25,"-") -> 0 | Q25: =SUMIF($U$2:$AT$2,"<="&$D$1,U25:AT25) -> 0 | R25: =K25-Q25 -> 26 | S25: =SUM(U25:XFD25) -> 0 | T25: =SUM(U25:CB25) -> 0
C26: 23 | D26: Transformer Grade Slab | E26: =E25+15 -> 45876 | F26: =F25+15 -> 45963 | G26: =F26-E26 -> 87 | H26: =E26 -> 45876 | I26: =F26 -> 45963 | J26: Block | K26: 26 | N26: =IF(OR(M26="",L26=""),"",INT(M26-L26+1)) | O26: =IFERROR(K26/N26,"-") -> - | P26: =IFERROR(SUMIF($U$2:$AT$2,"<="&$D$1,U26:BN26)/K26,"-") -> 0 | Q26: =SUMIF($U$2:$AT$2,"<="&$D$1,U26:AT26) -> 0 | R26: =K26-Q26 -> 26 | S26: =SUM(U26:XFD26) -> 0 | T26: =SUM(U26:CB26) -> 0
C27: 24 | D27: Transformer Fencing | E27: =F27-30 -> 45942 | F27: 45972 | G27: =F27-E27 -> 30 | H27: =E27 -> 45942 | I27: =F27 -> 45972 | J27: Block | K27: 26 | N27: =IF(OR(M27="",L27=""),"",INT(M27-L27+1)) | O27: =IFERROR(K27/N27,"-") -> - | P27: =IFERROR(SUMIF($U$2:$AT$2,"<="&$D$1,U27:BN27)/K27,"-") -> 0 | Q27: =SUMIF($U$2:$AT$2,"<="&$D$1,U27:AT27) -> 0 | R27: =K27-Q27 -> 26 | S27: =SUM(U27:XFD27) -> 0 | T27: =SUM(U27:CB27) -> 0
B28: Allied Civil Works | C28: 49 | D28: Road-Marking & Excavation | E28: 45858 | F28: 45945 | G28: =F28-E28 -> 87 | H28: =E28 -> 45858 | I28: =F28 -> 45945 | J28: Mtrs | N28: =IF(OR(M28="",L28=""),"",INT(M28-L28+1)) | O28: =IFERROR(K28/N28,"-") -> - | P28: =IFERROR(SUMIF($U$2:$AT$2,"<="&$D$1,U28:BN28)/K28,"-") -> - | Q28: =SUMIF($U$2:$AT$2,"<="&$D$1,U28:AT28) -> 0 | R28: =K28-Q28 -> 0 | S28: =SUM(U28:XFD28) -> 0 | T28: =SUM(U28:CB28) -> 0
C29: 50 | D29: Road-GSB Filling | E29: 45863 | F29: 45950 | G29: =F29-E29 -> 87 | H29: =E29 -> 45863 | I29: =F29 -> 45950 | J29: Mtrs | N29: =IF(OR(M29="",L29=""),"",INT(M29-L29+1)) | O29: =IFERROR(K29/N29,"-") -> - | P29: =IFERROR(SUMIF($U$2:$AT$2,"<="&$D$1,U29:BN29)/K29,"-") -> - | Q29: =SUMIF($U$2:$AT$2,"<="&$D$1,U29:AT29) -> 0 | R29: =K29-Q29 -> 0 | S29: =SUM(U29:XFD29) -> 0 | T29: =SUM(U29:CB29) -> 0
C30: 51 | D30: Road-WBM Layer-1 | E30: 45966 | F30: 46001 | G30: =F30-E30 -> 35 | H30: =E30 -> 45966 | I30: =F30 -> 46001 | J30: Mtrs | N30: =IF(OR(M30="",L30=""),"",INT(M30-L30+1)) | O30: =IFERROR(K30/N30,"-") -> - | P30: =IFERROR(SUMIF($U$2:$AT$2,"<="&$D$1,U30:BN30)/K30,"-") -> - | Q30: =SUMIF($U$2:$AT$2,"<="&$D$1,U30:AT30) -> 0 | R30: =K30-Q30 -> 0 | S30: =SUM(U30:XFD30) -> 0 | T30: =SUM(U30:CB30) -> 0
C31: 52 | D31: Road-WBM Layer-2 | E31: 45981 | F31: 46009 | G31: =F31-E31 -> 28 | H31: =E31 -> 45981 | I31: =F31 -> 46009 | J31: Mtrs | N31: =IF(OR(M31="",L31=""),"",INT(M31-L31+1)) | O31: =IFERROR(K31/N31,"-") -> - | P31: =IFERROR(SUMIF($U$2:$AT$2,"<="&$D$1,U31:BN31)/K31,"-") -> - | Q31: =SUMIF($U$2:$AT$2,"<="&$D$1,U31:AT31) -> 0 | R31: =K31-Q31 -> 0 | S31: =SUM(U31:XFD31) -> 0 | T31: =SUM(U31:CB31) -> 0
C32: 53 | D32: Periphary Road-Marking and Grading | E32: 45971 | F32: 46006 | G32: =F32-E32 -> 35 | H32: =E32 -> 45971 | I32: =F32 -> 46006 | J32: Mtrs | N32: =IF(OR(M32="",L32=""),"",INT(M32-L32+1)) | O32: =IFERROR(K32/N32,"-") -> - | P32: =IFERROR(SUMIF($U$2:$AT$2,"<="&$D$1,U32:BN32)/K32,"-") -> - | Q32: =SUMIF($U$2:$AT$2,"<="&$D$1,U32:AT32) -> 0 | R32: =K32-Q32 -> 0 | S32: =SUM(U32:XFD32) -> 0 | T32: =SUM(U32:CB32) -> 0
C33: 54 | D33: Periphary Road-Compaction | E33: 45996 | F33: 46008 | G33: =F33-E33 -> 12 | H33: =E33 -> 45996 | I33: =F33 -> 46008 | J33: Mtrs | N33: =IF(OR(M33="",L33=""),"",INT(M33-L33+1)) | O33: =IFERROR(K33/N33,"-") -> - | P33: =IFERROR(SUMIF($U$2:$AT$2,"<="&$D$1,U33:BN33)/K33,"-") -> - | Q33: =SUMIF($U$2:$AT$2,"<="&$D$1,U33:AT33) -> 0 | R33: =K33-Q33 -> 0 | S33: =SUM(U33:XFD33) -> 0 | T33: =SUM(U33:CB33) -> 0
C34: 55 | D34: Chain Link Fencing- Marking & Drilling | E34: 45772 | F34: 45823 | G34: =F34-E34 -> 51 | H34: 45819 | I34: =H34+G34 -> 45870 | J34: Mtrs | K34: 21000 | N34: =IF(OR(M34="",L34=""),"",INT(M34-L34+1)) | O34: =IFERROR(K34/N34,"-") -> - | P34: =IFERROR(SUMIF($U$2:$AT$2,"<="&$D$1,U34:BN34)/K34,"-") -> 0 | Q34: =SUMIF($U$2:$AT$2,"<="&$D$1,U34:AT34) -> 0 | R34: =K34-Q34 -> 21000 | S34: =SUM(U34:XFD34) -> 0 | T34: =SUM(U34:CB34) -> 0
C35: 56 | D35: Chain Link Fencing-Pole Casting | E35: 45773 | F35: 45824 | G35: =F35-E35 -> 51 | H35: 45820 | I35: 45871 | J35: Mtrs | K35: 21000 | N35: =IF(OR(M35="",L35=""),"",INT(M35-L35+1)) | O35: =IFERROR(K35/N35,"-") -> - | P35: =IFERROR(SUMIF($U$2:$AT$2,"<="&$D$1,U35:BN35)/K35,"-") -> 0 | Q35: =SUMIF($U$2:$AT$2,"<="&$D$1,U35:AT35) -> 0 | R35: =K35-Q35 -> 21000 | S35: =SUM(U35:XFD35) -> 0 | T35: =SUM(U35:CB35) -> 0
C36: 57 | D36: Chain Link Fincing- Mesh Fixing | E36: 45797 | F36: 45828 | G36: =F36-E36 -> 31 | H36: 45833 | I36: 45874 | J36: Mtrs | K36: 21000 | N36: =IF(OR(M36="",L36=""),"",INT(M36-L36+1)) | O36: =IFERROR(K36/N36,"-") -> - | P36: =IFERROR(SUMIF($U$2:$AT$2,"<="&$D$1,U36:BN36)/K36,"-") -> 0 | Q36: =SUMIF($U$2:$AT$2,"<="&$D$1,U36:AT36) -> 0 | R36: =K36-Q36 -> 21000 | S36: =SUM(U36:XFD36) -> 0 | T36: =SUM(U36:CB36) -> 0
C37: 58 | D37: Chain Link Fencing-Barbed Wire Fixing | E37: 45802 | F37: 45832 | G37: =F37-E37 -> 30 | H37: 45838 | I37: 45877 | J37: Mtrs | K37: 21000 | N37: =IF(OR(M37="",L37=""),"",INT(M37-L37+1)) | O37: =IFERROR(K37/N37,"-") -> - | P37: =IFERROR(SUMIF($U$2:$AT$2,"<="&$D$1,U37:BN37)/K37,"-") -> 0 | Q37: =SUMIF($U$2:$AT$2,"<="&$D$1,U37:AT37) -> 0 | R37: =K37-Q37 -> 21000 | S37: =SUM(U37:XFD37) -> 0 | T37: =SUM(U37:CB37) -> 0
C38: 59 | D38: Drain Excavation | E38: 45874 | F38: 45950 | G38: =F38-E38 -> 76 | H38: =E38 -> 45874 | I38: =F38 -> 45950 | J38: Mtrs | N38: =IF(OR(M38="",L38=""),"",INT(M38-L38+1)) | O38: =IFERROR(K38/N38,"-") -> - | P38: =IFERROR(SUMIF($U$2:$AT$2,"<="&$D$1,U38:BN38)/K38,"-") -> - | Q38: =SUMIF($U$2:$AT$2,"<="&$D$1,U38:AT38) -> 0 | R38: =K38-Q38 -> 0 | S38: =SUM(U38:XFD38) -> 0 | T38: =SUM(U38:CB38) -> 0
C39: 60 | D39: Drain Works | E39: 45885 | F39: 45958 | G39: =F39-E39 -> 73 | H39: =E39 -> 45885 | I39: =F39 -> 45958 | J39: Mtrs | N39: =IF(OR(M39="",L39=""),"",INT(M39-L39+1)) | O39: =IFERROR(K39/N39,"-") -> - | P39: =IFERROR(SUMIF($U$2:$AT$2,"<="&$D$1,U39:BN39)/K39,"-") -> - | Q39: =SUMIF($U$2:$AT$2,"<="&$D$1,U39:AT39) -> 0 | R39: =K39-Q39 -> 0 | S39: =SUM(U39:XFD39) -> 0 | T39: =SUM(U39:CB39) -> 0
C40: 61 | D40: Drain Finishing | E40: 45905 | F40: 45976 | G40: =F40-E40 -> 71 | H40: =E40 -> 45905 | I40: =F40 -> 45976 | J40: Mtrs | N40: =IF(OR(M40="",L40=""),"",INT(M40-L40+1)) | O40: =IFERROR(K40/N40,"-") -> - | P40: =IFERROR(SUMIF($U$2:$AT$2,"<="&$D$1,U40:BN40)/K40,"-") -> - | Q40: =SUMIF($U$2:$AT$2,"<="&$D$1,U40:AT40) -> 0 | R40: =K40-Q40 -> 0 | S40: =SUM(U40:XFD40) -> 0 | T40: =SUM(U40:CB40) -> 0
...

Sheet MDL
A1: MDL SUMMARY - 300MW SECI PV | O1: =TODAY() -> 45853 | U1: =TODAY() -> 45853
A2: Sl.No. | B2: Discipline | C2: Discipline | D2: Document Title | E2: Document Number | F2: Approval Catogery | G2: Planned Submission Date (EPCC) | H2: Submitted/Expected Submission | I2: Other drawing linked | J2: Tentative approval date- linked docs. | K2: Revision | L2: Submission Date | M2: Response date | N2: CLIENT Comments / Approval(CAT-I,CAT-II CAT-III & CAT-IV) | O2: No.of Days Reviwed by SECI | P2: No.of Days Reviwed by ARIPL | Q2: Approved date | R2: Submission/Review By | S2: Approved Category | T2: Status | U2: Days taken for review/re-submission
A3: 1 | B3: General | C3: Survey & Studies | D3: SoW & Method Statement for Topography and Contour Survey | E3: SECI-RG300-PL-CIV-001 | F3: Approval | G3: 45698 | H3: 45698 | K3: R0 | L3: 45698 | R3: Approved | S3: CAT - III | T3: Approved
K4: R1 | L4: 45700 | M4: 45700 | O4: =M4-L4 -> 0 | P4: =L5-M4 -> 2 | X4: Submitted - Under Review
K5: R2 | L5: 45702 | M5: 45705 | O5: =M5-L5 -> 3 | P5: =L6-M5 -> 2 | X5: Approved
K6: R3 | L6: 45707 | X6: Re-Submission
A7: 2 | B7: General | C7: Survey & Studies | D7: Topography and Contour Report | E7: SECI-RG300-PL-CIV-002 | F7: Information | G7: 45740 | H7: 45740 | K7: R0 | L7: 45740 | M7: 45743 | N7: CAT -IV R | O7: =M7-L7 -> 3 | P7: =L8-M7 -> 6 | Q7: =M8 -> 45755 | R7: =T7 -> Approved | S7: =N8 -> CAT -IV | T7: Approved | U7: =M8-L8 -> 6 | X7: Yet to be submitted
K8: R1 | L8: 45749 | M8: 45755 | N8: CAT -IV | O8: =M8-L8 -> 6
A9: 3 | B9: General | C9: Survey & Studies | D9: SoW & Method Statement for Geotechnical Investigation | E9: SECI-RG300-PL-CIV-003 | F9: Approval | K9: R0 | S9: CAT - I | T9: Approved
A10: 4 | B10: General | C10: Survey & Studies | D10: Geotechnical Investigation Report (Soil Test, CBR, Chemical Analysis & Thermal Resistivity) | E10: SECI-RG300-PL-CIV-004 | F10: Information | G10: 45768 | H10: 45768 | K10: R0 | L10: 45768 | M10: 45776 | N10: CAT -IV R | O10: =M10-L10 -> 8 | Q10: =M10 -> 45776 | R10: Approved | S10: =N10 -> CAT -IV R | T10: Approved
A11: 5 | B11: General | C11: Survey & Studies | D11: SoW & Method Statement for Hydrology Investigation | E11: SECI-RG300-PL-CIV-005 | F11: Information | G11: 45814 | H11: 45820 | R11: SECI | T11: Submitted - Under Review
A12: 6 | B12: General | C12: Survey & Studies | D12: Hydrology Investigation Report | E12: SECI-RG300-PL-CIV-006 | F12: Information | G12: 45814 | H12: 45820
A13: 7 | B13: General | C13: Survey & Studies | D13: SoW & Method Statement for Soil resistivity test (ERT) | E13: SECI-RG300-PL-CIV-007 | F13: Approval | G13: 45742 | H13: 45742 | K13: R0 | L13: 45742 | M13: 45751 | N13: CAT - II | O13: =M13-L13 -> 9 | P13: =L14-M13 -> 0 | R13: SECI | S13: =N13 -> CAT - II | T13: Submitted - Under Review | U13: =U1-L14 -> 102
K14: R1 | L14: 45751 | O14: =O1-L14 -> 102
A15: 8 | B15: General | C15: Survey & Studies | D15: Soil resistivity test report (ERT) | E15: SECI-RG300-PL-CIV-008 | F15: Information | G15: 45771 | H15: 45771 | K15: R0 | L15: 45772 | O15: =O1-L15 -> 81 | R15: SECI | T15: Submitted - Under Review | U15: =U1-L15 -> 81
A16: 9 | B16: General | C16: Survey & Studies | D16: Water Test Report | E16: SECI-RG300-PL-CIV-009 | F16: Information | K16: R0 | R16: Approved | S16: CAT - I | T16: Approved
A17: 10 | B17: General | C17: Survey & Studies | D17: Concrete Mix Design Report | E17: SECI-RG300-PL-CIV-010 | F17: Information | G17: 45772 | H17: 45772 | K17: R0 | L17: 45772 | M17: 45778 | N17: CAT -IV R | O17: =M17-L17 -> 6 | R17: ARIPL | S17: =N17 -> CAT -IV R | T17: Re-Submission | U17: =U1-M17 -> 75
A18: 11 | B18: General | C18: Survey & Studies | D18: Pile Pull out and Lateral Test Layout & Procedure | E18: SECI-RG300-PL-CIV-011 | F18: Approval | G18: 45769 | H18: =L18 -> 45769 | K18: R0 | L18: 45769 | M18: 45771 | N18: CAT - III | O18: =M18-L18 -> 2 | P18: =L19-M18 -> 6 | Q18: =M20 -> 45793 | R18: SECI | S18: =N20 -> CAT - I | T18: Approved | U18: =M20-L20 -> 7
K19: R1 | L19: 45777 | M19: 45778 | N19: CAT - II | O19: =M19-L19 -> 1 | P19: =L20-M19 -> 8
K20: R2 | L20: 45786 | M20: 45793 | N20: CAT - I | O20: =M20-L20 -> 7
A21: 12 | B21: General | C21: Survey & Studies | D21: Pile Pull out and Lateral Test Report | E21: SECI-RG300-PL-CIV-012 | F21: Information | G21: 45801 | H21: 45843
A22: 13 | B22: General | C22: Survey & Studies | D22: SoP for Site Cleaning & Grading | E22: SECI-RG300-PL-CIV-013 | F22: Information
A23: 14 | B23: General | C23: Survey & Studies | D23: Design Basis Study Report for Civil & Structural | E23: SECI-RG300-PL-CIV-014 | F23: Approval
A24: 1 | B24: Civil | C24: Civil & Structural (MMS) | D24: MMS - Structural Design Calculations & Staad report (2PX26) | E24: SECI-RG300-PL-CIV-101 | F24: Approval | G24: 45727 | H24: =L24 -> 45727 | K24: R0 | L24: 45727 | M24: 45736 | N24: CAT - III | O24: =M24-L24 -> 9 | P24: =L25-M24 -> 19 | R24: Approved | S24: =N26 -> CAT - I | T24: Approved | U24: =U1-L26 -> 48
K25: R1 | L25: 45755 | M25: 45758 | N25: CAT - II | O25: =M25-L25 -> 3 | P25: =L26-M25 -> 47
K26: R2 | L26: 45805 | M26: 45810 | N26: CAT - I | O26: =M26-L26 -> 5
A27: 2 | B27: Civil | C27: Civil & Structural (MMS) | D27: MMS - Structural Design Calculations & Staad report (2PX14 & 2PX28) | E27: SECI-RG300-PL-CIV-102 | F27: Approval | G27: 45805 | H27: =L27 -> 45811 | K27: R0 | L27: 45811 | M27: 45818 | N27: CAT - III | O27: =O1-L27 -> 42 | R27: ARIPL | S27: =N27 -> CAT - III | T27: Re-Submission | U27: =U1-L27 -> 42
A28: 3 | B28: Civil | C28: Civil & Structural (MMS) | D28: MMS - Pile Foundation Design Calculation | E28: SECI-RG300-PL-CIV-103 | F28: Approval | G28: 45795 | H28: =L28 -> 45786 | K28: R0 | L28: 45786 | O28: =O1-L28 -> 67 | R28: SECI | T28: Submitted - Under Review | U28: =U1-L28 -> 67
