Workbook
Name projectStatus: #REF!
Name projectStatus: #REF!

Sheet Construction DASHBOARD
A1: Daily Progress Report
A2: Project Name | B2: 300MW SECI Solar Project Ramagiri | N2: Week | O2: Month
A3: Project Capacity (in MWp) | B3: 390 | N3: 45901 | O3: 45901
A4: Project Start Date | B4: 45694 | N4: =N3+5 -> 45906 | O4: 45930
A5: Project Finish Date | B5: 46058 | K5: Week Cycle | L5: Month Cycle
A6: Date | B6: 45903 | K6: =N3 -> 45901 | L6: 45901
K7: =N4 -> 45906 | L7: =L6+29 -> 45930
A8: Description | B8: Scope | C8: UoM | D8: Completed | E8: Balance | F8: Weightage (in %) | G8: Progress as per weightage (in %) | H8: Actual Progress (in %) | I8: Day- Actual | J8: Today-Plan | K8: Week- Actual | L8: Month-Actual
A10: Land Development
A11: Bush removal | B11: 1033 | C11: Acre | D11: ='Construction Status'!S4 -> 946.23 | E11: =B11-D11 -> 86.77 | F11: 0.01 | G11: =F11*H11 -> 0.0091600194 | H11: =D11/B11 -> 0.91600194 | I11: 1 | J11: 3 | K11: 3 | L11: {=SUMPRODUCT(('Construction Status'!$U$4:$DF$120)*('Construction Status'!$D$4:$D$120='Construction DASHBOARD'!A11)*('Construction Status'!$U$2:$DF$2>='Construction DASHBOARD'!$O$3)*('Construction Status'!$U$2:$DF$2<='Construction DASHBOARD'!$O$4))} -> 0 | N11: 45894 | O11: 1
A12: Land grading | B12: 1033 | C12: Acre | D12: ='Construction Status'!S5 -> 938.83 | E12: =B12-D12 -> 94.17 | F12: 0.01 | G12: =F12*H12 -> 0.0090883833 | H12: =D12/B12 -> 0.90883833 | I12: =SUMIF('Construction Status'!$U$2:$DF$2,'Construction DASHBOARD'!$B$6,'Construction Status'!U5:DF5) -> 0 | J12: 5 | K12: 3 | L12: {=SUMPRODUCT(('Construction Status'!$U$4:$DF$120)*('Construction Status'!$D$4:$D$120='Construction DASHBOARD'!A12)*('Construction Status'!$U$2:$DF$2>='Construction DASHBOARD'!$O$3)*('Construction Status'!$U$2:$DF$2<='Construction DASHBOARD'!$O$4))} -> 0 | N12: 45895
A13: Site Initials | N13: 45896 | O13: 1
A14: Boundry Coordinate capturing | B14: ='Construction Status'!K6 -> 1 | C14: Lot | D14: ='Construction Status'!Q6 -> 1 | E14: =B14-D14 -> 0 | F14: 0.006 | G14: =F14*H14 -> 0.006 | H14: =D14/B14 -> 1 | I14: =SUMIF('Construction Status'!$U$2:$DF$2,'Construction DASHBOARD'!$B$6,'Construction Status'!U6:DF6) -> 0 | J14: 0 | K14: {=SUMPRODUCT(('Construction Status'!$U$4:$DF$120)*('Construction Status'!$D$4:$D$120='Construction DASHBOARD'!A14)*('Construction Status'!$U$2:$DF$2>='Construction DASHBOARD'!$N$3)*('Construction Status'!$U$2:$DF$2<='Construction DASHBOARD'!$N$4))} -> 0 | L14: {=SUMPRODUCT(('Construction Status'!$U$4:$DF$120)*('Construction Status'!$D$4:$D$120='Construction DASHBOARD'!A14)*('Construction Status'!$U$2:$DF$2>='Construction DASHBOARD'!$O$3)*('Construction Status'!$U$2:$DF$2<='Construction DASHBOARD'!$O$4))} -> 0 | N14: 45897 | O14: 1
A15: Topo Survey | B15: ='Construction Status'!K7 -> 1 | C15: Lot | D15: ='Construction Status'!Q7 -> 1 | E15: =B15-D15 -> 0 | F15: 0.0075 | G15: =F15*H15 -> 0.0075 | H15: =D15/B15 -> 1 | I15: =SUMIF('Construction Status'!$U$2:$DF$2,'Construction DASHBOARD'!$B$6,'Construction Status'!U7:DF7) -> 0 | J15: 0 | K15: {=SUMPRODUCT(('Construction Status'!$U$4:$DF$120)*('Construction Status'!$D$4:$D$120='Construction DASHBOARD'!A15)*('Construction Status'!$U$2:$DF$2>='Construction DASHBOARD'!$N$3)*('Construction Status'!$U$2:$DF$2<='Construction DASHBOARD'!$N$4))} -> 0 | L15: {=SUMPRODUCT(('Construction Status'!$U$4:$DF$120)*('Construction Status'!$D$4:$D$120='Construction DASHBOARD'!A15)*('Construction Status'!$U$2:$DF$2>='Construction DASHBOARD'!$O$3)*('Construction Status'!$U$2:$DF$2<='Construction DASHBOARD'!$O$4))} -> 0 | N15: 45898 | O15: 1
A16: Soil Investigation | B16: 79 | C16: Lot | D16: ='Construction Status'!Q8 -> 79 | E16: =B16-D16 -> 0 | F16: 0.005 | G16: =F16*H16 -> 0.005 | H16: =D16/B16 -> 1 | I16: =SUMIF('Construction Status'!$U$2:$DF$2,'Construction DASHBOARD'!$B$6,'Construction Status'!U8:DF8) -> 0 | J16: 0 | K16: {=SUMPRODUCT(('Construction Status'!$U$4:$DF$120)*('Construction Status'!$D$4:$D$120='Construction DASHBOARD'!A16)*('Construction Status'!$U$2:$DF$2>='Construction DASHBOARD'!$N$3)*('Construction Status'!$U$2:$DF$2<='Construction DASHBOARD'!$N$4))} -> 0 | L16: {=SUMPRODUCT(('Construction Status'!$U$4:$DF$120)*('Construction Status'!$D$4:$D$120='Construction DASHBOARD'!A16)*('Construction Status'!$U$2:$DF$2>='Construction DASHBOARD'!$O$3)*('Construction Status'!$U$2:$DF$2<='Construction DASHBOARD'!$O$4))} -> 0 | N16: 45899 | O16: 2
A17: ERT Test | B17: ='Construction Status'!K9 -> 36 | C17: Lot | D17: ='Construction Status'!Q9 -> 36 | E17: =B17-D17 -> 0 | F17: 0.0025 | G17: =F17*H17 -> 0.0025 | H17: =D17/B17 -> 1 | I17: =SUMIF('Construction Status'!$U$2:$DF$2,'Construction DASHBOARD'!$B$6,'Construction Status'!U9:DF9) -> 0 | J17: 0 | K17: {=SUMPRODUCT(('Construction Status'!$U$4:$DF$120)*('Construction Status'!$D$4:$D$120='Construction DASHBOARD'!A17)*('Construction Status'!$U$2:$DF$2>='Construction DASHBOARD'!$N$3)*('Construction Status'!$U$2:$DF$2<='Construction DASHBOARD'!$N$4))} -> 0 | L17: {=SUMPRODUCT(('Construction Status'!$U$4:$DF$120)*('Construction Status'!$D$4:$D$120='Construction DASHBOARD'!A17)*('Construction Status'!$U$2:$DF$2>='Construction DASHBOARD'!$O$3)*('Construction Status'!$U$2:$DF$2<='Construction DASHBOARD'!$O$4))} -> 0 | N17: 45900 | O17: 2
A18: Test Pile Casting | B18: ='Construction Status'!K10 -> 240 | C18: Lot | D18: ='Construction Status'!Q10 -> 240 | E18: =B18-D18 -> 0 | F18: 0.002 | G18: =F18*H18 -> 0.002 | H18: =D18/B18 -> 1 | I18: =SUMIF('Construction Status'!$U$2:$DF$2,'Construction DASHBOARD'!$B$6,'Construction Status'!U10:DF10) -> 0 | J18: 0 | K18: {=SUMPRODUCT(('Construction Status'!$U$4:$DF$120)*('Construction Status'!$D$4:$D$120='Construction DASHBOARD'!A18)*('Construction Status'!$U$2:$DF$2>='Construction DASHBOARD'!$N$3)*('Construction Status'!$U$2:$DF$2<='Construction DASHBOARD'!$N$4))} -> 0 | L18: {=SUMPRODUCT(('Construction Status'!$U$4:$DF$120)*('Construction Status'!$D$4:$D$120='Construction DASHBOARD'!A18)*('Construction Status'!$U$2:$DF$2>='Construction DASHBOARD'!$O$3)*('Construction Status'!$U$2:$DF$2<='Construction DASHBOARD'!$O$4))} -> 0 | O18: 1
A19: Pile Testing | B19: ='Construction Status'!K11 -> 180 | C19: Lot | D19: ='Construction Status'!Q11 -> 180 | E19: =B19-D19 -> 0 | F19: 0.002 | G19: =F19*H19 -> 0.002 | H19: =D19/B19 -> 1 | I19: =SUMIF('Construction Status'!$U$2:$DF$2,'Construction DASHBOARD'!$B$6,'Construction Status'!U11:DF11) -> 0 | J19: 0 | K19: {=SUMPRODUCT(('Construction Status'!$U$4:$DF$120)*('Construction Status'!$D$4:$D$120='Construction DASHBOARD'!A19)*('Construction Status'!$U$2:$DF$2>='Construction DASHBOARD'!$N$3)*('Construction Status'!$U$2:$DF$2<='Construction DASHBOARD'!$N$4))} -> 0 | L19: {=SUMPRODUCT(('Construction Status'!$U$4:$DF$120)*('Construction Status'!$D$4:$D$120='Construction DASHBOARD'!A19)*('Construction Status'!$U$2:$DF$2>='Construction DASHBOARD'!$O$3)*('Construction Status'!$U$2:$DF$2<='Construction DASHBOARD'!$O$4))} -> 0 | O19: 1
A20: Civil
A21: Pile - Marking, Drilling & Casting | B21: 116500 | C21: Nos. | D21: ='Construction Status'!Q14 -> 14362 | E21: =B21-D21 -> 102138 | F21: 0.21 | G21: =F21*H21 -> 0.025888584 | H21: =D21/B21 -> 0.12327897 | I21: 500 | J21: 1100 | K21: 839 | L21: 839
A22: Equipments Foundation | B22: 24 | C22: Block | D22: 0 | E22: =B22-D22 -> 24 | F22: 0.05 | G22: =F22*H22 -> 0 | H22: =D22/B22 -> 0 | K22: {=SUMPRODUCT(('Construction Status'!$U$4:$DF$120)*('Construction Status'!$D$4:$D$120='Construction DASHBOARD'!A22)*('Construction Status'!$U$2:$DF$2>='Construction DASHBOARD'!$N$3)*('Construction Status'!$U$2:$DF$2<='Construction DASHBOARD'!$N$4))} -> 0 | L22: {=SUMPRODUCT(('Construction Status'!$U$4:$DF$120)*('Construction Status'!$D$4:$D$120='Construction DASHBOARD'!A22)*('Construction Status'!$U$2:$DF$2>='Construction DASHBOARD'!$O$3)*('Construction Status'!$U$2:$DF$2<='Construction DASHBOARD'!$O$4))} -> 0 | O22: 4
A23: Excavation For Trenches | B23: 24 | C23: Block | D23: 0 | E23: =B23-D23 -> 24 | F23: 0.05 | G23: =F23*H23 -> 0 | H23: =D23/B23 -> 0 | K23: {=SUMPRODUCT(('Construction Status'!$U$4:$DF$120)*('Construction Status'!$D$4:$D$120='Construction DASHBOARD'!A23)*('Construction Status'!$U$2:$DF$2>='Construction DASHBOARD'!$N$3)*('Construction Status'!$U$2:$DF$2<='Construction DASHBOARD'!$N$4))} -> 0 | L23: {=SUMPRODUCT(('Construction Status'!$U$4:$DF$120)*('Construction Status'!$D$4:$D$120='Construction DASHBOARD'!A23)*('Construction Status'!$U$2:$DF$2>='Construction DASHBOARD'!$O$3)*('Construction Status'!$U$2:$DF$2<='Construction DASHBOARD'!$O$4))} -> 0 | O23: 4
A24: MCR Civil Works | B24: 1 | C24: Lot | D24: 0.2 | E24: =B24-D24 -> 0.8 | F24: 0.06 | G24: =F24*H24 -> 0.012 | H24: =D24/B24 -> 0.2 | K24: {=SUMPRODUCT(('Construction Status'!$U$4:$DF$120)*('Construction Status'!$D$4:$D$120='Construction DASHBOARD'!A24)*('Construction Status'!$U$2:$DF$2>='Construction DASHBOARD'!$N$3)*('Construction Status'!$U$2:$DF$2<='Construction DASHBOARD'!$N$4))} -> 0 | L24: {=SUMPRODUCT(('Construction Status'!$U$4:$DF$120)*('Construction Status'!$D$4:$D$120='Construction DASHBOARD'!A24)*('Construction Status'!$U$2:$DF$2>='Construction DASHBOARD'!$O$3)*('Construction Status'!$U$2:$DF$2<='Construction DASHBOARD'!$O$4))} -> 0 | O24: 4
A25: Road Work | B25: 1 | C25: km | D25: ='Construction Status'!Q17 -> 0 | E25: 1 | F25: 0.02 | K25: {=SUMPRODUCT(('Construction Status'!$U$4:$DF$120)*('Construction Status'!$D$4:$D$120='Construction DASHBOARD'!A25)*('Construction Status'!$U$2:$DF$2>='Construction DASHBOARD'!$N$3)*('Construction Status'!$U$2:$DF$2<='Construction DASHBOARD'!$N$4))} -> 0 | L25: {=SUMPRODUCT(('Construction Status'!$U$4:$DF$120)*('Construction Status'!$D$4:$D$120='Construction DASHBOARD'!A25)*('Construction Status'!$U$2:$DF$2>='Construction DASHBOARD'!$O$3)*('Construction Status'!$U$2:$DF$2<='Construction DASHBOARD'!$O$4))} -> 0 | O25: 4
A26: Fencing Pole Casting | B26: 21000 | C26: M | D26: ='Construction Status'!Q35 -> 6295 | F26: 0.02 | G26: =F26*H26 -> 0.0059952381 | H26: =D26/B26 -> 0.2997619 | I26: 100 | J26: 500 | K26: 238 | L26: 238 | O26: 4
A27: MMS | O27: 6
A28: Module Mounting Structures | B28: 24 | C28: Block | F28: 0.08 | O28: 6
A29: PV Modules | B29: 24 | C29: Block | F29: 0.06 | O29: 6
A30: DC | O30: 6
A31: Solar Cables (Interconnection after module installation) | B31: 1360 | C31: SCB | F31: 0.02 | O31: 4
A32: SCB-MOUNTING | B32: 1360 | C32: SCB | F32: 0.02
A33: Array & Module Earthing | B33: 1360 | C33: SCB | F33: 0.03
A34: SCB Installation | B34: 1360 | C34: SCB | F34: 0.025
A35: DC Power Cables | B35: 1360 | C35: SCB | F35: 0.04
A36: DC Power Cables Terminations | B36: 1360 | C36: SCB | F36: 0.02
A37: DC Earthing | B37: 1360 | C37: SCB | F37: 0.02
A38: AC
A39: Equipment Installation | B39: 24 | C39: Block | F39: 0.02
A40: Cable Tray Works | B40: 24 | C40: Block | F40: 0.02
A41: HT&LT Cable Laying | B41: 24 | C41: Block | F41: 0.04
...

Sheet MDL
A1: MDL SUMMARY - 300MW SECI PV | I1: =TODAY() -> 45903 | M1: Color Code | N1: Re-submission | O1: Under SECI Review | P1: Approved | V1: =TODAY() -> 45903
A2: Sl.No. | B2: Discipline | C2: Discipline | D2: Document Title | E2: Document Number | F2: Approval Catogery | G2: Planned R0 Submission | H2: Approval Planned Date | I2: Actual R0 Submission | J2: Submission Delay | K2: Approval Delay | L2: Revision | M2: Submission Date | N2: Response date | O2: Client Comments in CAT | P2: Under SECI Review in days | Q2: Re-Submission by ARIPL in Days | R2: Approved date | S2: Submission/Review By | T2: Approved/ Commented Category | U2: Status
A3: 1 | B3: General | C3: Survey & Studies | D3: SoW & Method Statement for Topography and Contour Survey | E3: SECI-RG300-PL-CIV-001 | F3: Approval | G3: 45698 | H3: =G3+15 -> 45713 | I3: 45698 | J3: =I3-G3 -> 0 | L3: R0 | M3: 45698 | S3: Approved | T3: CAT - III | U3: Submitted - Under Review
L4: R1 | M4: 45700 | N4: 45700 | P4: =N4-M4 -> 0 | Q4: =M5-N4 -> 2 | Y4: Submitted - Under Review
L5: R2 | M5: 45702 | N5: 45705 | P5: =N5-M5 -> 3 | Q5: =M6-N5 -> 2 | Y5: Approved
L6: R3 | M6: 45707 | P6: =I1-M6 -> 196 | Y6: Re-Submission
A7: 2 | B7: General | C7: Survey & Studies | D7: Topography and Contour Report | E7: SECI-RG300-PL-CIV-002 | F7: Information | G7: 45740 | H7: =G7+15 -> 45755 | I7: 45740 | J7: =I7-G7 -> 0 | K7: =R7-H7 -> 0 | L7: R0 | M7: 45740 | N7: 45743 | O7: CAT -IV R | P7: =N7-M7 -> 3 | Q7: =M8-N7 -> 6 | R7: =N8 -> 45755 | S7: =U7 -> Approved | T7: =O8 -> CAT -IV | U7: Approved | Y7: Yet to be submitted
L8: R1 | M8: 45749 | N8: 45755 | O8: CAT -IV | P8: =N8-M8 -> 6
A9: 3 | B9: General | C9: Survey & Studies | D9: SoW & Method Statement for Geotechnical Investigation | E9: SECI-RG300-PL-CIV-003 | F9: Approval | G9: 45740 | H9: =G9+15 -> 45755 | L9: R0 | U9: Approved
A10: 4 | B10: General | C10: Survey & Studies | D10: Geotechnical Investigation Report (Soil Test, CBR, Chemical Analysis & Thermal Resistivity) | E10: SECI-RG300-PL-CIV-004 | F10: Information | G10: 45768 | H10: =G10+21 -> 45789 | I10: 45768 | J10: =I10-G10 -> 0 | K10: =I1-H10 -> 114 | L10: R0 | M10: 45768 | N10: 45776 | O10: CAT -IV R | P10: =N10-M10 -> 8 | Q10: =M11-N10 -> 51 | S10: SECI | T10: =O10 -> CAT -IV R | U10: Re-Submission
L11: R1 | M11: 45827 | N11: 45866 | O11: CAT -IV R | P11: =N11-M11 -> 39 | Q11: =I1-N11 -> 37
A12: 5 | B12: General | C12: Survey & Studies | D12: SoW & Method Statement for Hydrology Investigation | E12: SECI-RG300-PL-CIV-005 | F12: Information | G12: 45814 | H12: =G12+15 -> 45829 | K12: =I1-H12 -> 74
A13: 6 | B13: General | C13: Survey & Studies | D13: Hydrology Investigation Report | E13: SECI-RG300-PL-CIV-006 | F13: Information | G13: 45814 | H13: =G13+14 -> 45828 | I13: 45815 | J13: =I13-G13 -> 1 | K13: =R13-H13 -> 18 | L13: R0 | M13: 45815 | N13: 45828 | O13: CAT -IV R | P13: =N13-M13 -> 13 | Q13: =M14-N13 -> 6 | R13: =N14 -> 45846 | S13: Approved | T13: CAT -IV | U13: Approved
L14: R1 | M14: 45834 | N14: 45846 | O14: CAT -IV | P14: =N14-M14 -> 12
A15: 7 | B15: General | C15: Survey & Studies | D15: SoW & Method Statement for Soil resistivity test (ERT) | E15: SECI-RG300-PL-CIV-007 | F15: Approval | G15: 45742 | H15: =G15+15 -> 45757 | I15: 45742 | J15: =I15-G15 -> 0 | K15: =R15-H15 -> 76 | L15: R0 | M15: 45742 | N15: 45751 | O15: CAT - II | P15: =N15-M15 -> 9 | Q15: =M16-N15 -> 0 | R15: =N16 -> 45833 | S15: Approved | T15: =O16 -> CAT - I | U15: Approved
L16: R1 | M16: 45751 | N16: 45833 | O16: CAT - I | P16: =N16-M16 -> 82
A17: 8 | B17: General | C17: Survey & Studies | D17: Soil resistivity test report (ERT) | E17: SECI-RG300-PL-CIV-008 | F17: Information | G17: 45771 | H17: =G17+21 -> 45792 | I17: =M17 -> 45772 | J17: =I17-G17 -> 1 | K17: =I1-H17 -> 111 | L17: R0 | M17: 45772 | N17: 45833 | O17: CAT -IV R | P17: =N17-M17 -> 61 | Q17: =I1-N17 -> 70 | S17: ARIPL | T17: =O17 -> CAT -IV R | U17: Re-Submission
A18: 9 | B18: General | C18: Survey & Studies | D18: Water Test Report | E18: SECI-RG300-PL-CIV-009 | F18: Information
A19: 10 | B19: General | C19: Survey & Studies | D19: Concrete Mix Design Report | E19: SECI-RG300-PL-CIV-010 | F19: Information | G19: 45772 | H19: =G19+7 -> 45779 | I19: 45772 | J19: =I19-G19 -> 0 | K19: =R19-H19 -> 88 | L19: R0 | M19: 45772 | N19: 45778 | O19: CAT -IV R | P19: =N19-M19 -> 6 | Q19: =M20-N19 -> 70 | R19: =N22 -> 45867 | S19: SECI | T19: =O22 -> CAT -IV | U19: Approved
L20: R1 | M20: 45848 | N20: 45850 | O20: CAT -IV R | P20: =I1-M20 -> 55
L21: R2 | M21: 45862 | N21: 45863 | O21: CAT -IV R
L22: R3 | M22: 45866 | N22: 45867 | O22: CAT -IV
A23: 11 | B23: General | C23: Survey & Studies | D23: Pile Pull out and Lateral Test Layout & Procedure | E23: SECI-RG300-PL-CIV-011 | F23: Approval | G23: 45769 | H23: =G23+21 -> 45790 | I23: 45769 | J23: =I23-G23 -> 0 | K23: =R23-H23 -> 3 | L23: R0 | M23: 45769 | N23: 45771 | O23: CAT - III | P23: =N23-M23 -> 2 | Q23: =M24-N23 -> 6 | R23: =N25 -> 45793 | S23: SECI | T23: =O25 -> CAT - I | U23: Approved
L24: R1 | M24: 45777 | N24: 45778 | O24: CAT - II | P24: =N24-M24 -> 1 | Q24: =M25-N24 -> 8
L25: R2 | M25: 45786 | N25: 45793 | O25: CAT - I | P25: =N25-M25 -> 7
A26: 12 | B26: General | C26: Survey & Studies | D26: Pile Pull out and Lateral Test Report | E26: SECI-RG300-PL-CIV-012 | F26: Information | G26: 45801 | H26: =G26+21 -> 45822 | I26: 45843 | J26: =I26-G26 -> 42 | K26: =R26-H26 -> 23 | L26: R0 | M26: 45843 | N26: 45845 | O26: CAT -IV | P26: =N26-M26 -> 2 | R26: =N26 -> 45845 | S26: SECI | T26: =T23 -> CAT - I | U26: Approved
A27: 13 | B27: General | C27: Survey & Studies | D27: SoP for Site Cleaning & Grading | E27: SECI-RG300-PL-CIV-013 | F27: Information | G27: 45741 | H27: =G27+15 -> 45756 | K27: =$I$1-H27 -> 147
A28: 14 | B28: General | C28: Survey & Studies | D28: Design Basis Study Report for Civil & Structural | E28: SECI-RG300-PL-CIV-014 | F28: Approval | G28: 45741 | H28: =G28+14 -> 45755 | K28: =$I$1-H28 -> 148
A29: 1 | B29: Civil | C29: Civil & Structural (MMS) | D29: MMS - Structural Design Calculations & Staad report (2PX26) | E29: SECI-RG300-PL-CIV-101 | F29: Approval | G29: 45727 | H29: =G29+21 -> 45748 | I29: 45727 | J29: =I29-G29 -> 0 | K29: =R29-H29 -> 62 | L29: R0 | M29: 45727 | N29: 45736 | O29: CAT - III | P29: =N29-M29 -> 9 | Q29: =M30-N29 -> 19 | R29: =N31 -> 45810 | S29: Approved | T29: =O31 -> CAT - I | U29: Approved
L30: R1 | M30: 45755 | N30: 45758 | O30: CAT - II | P30: =N30-M30 -> 3 | Q30: =M31-N30 -> 47
L31: R2 | M31: 45805 | N31: 45810 | O31: CAT - I | P31: =N31-M31 -> 5
A32: 2 | B32: Civil | C32: Civil & Structural (MMS) | D32: MMS - Structural Design Calculations & Staad report (2PX14 & 2PX28) | E32: SECI-RG300-PL-CIV-102 | F32: Approval | G32: 45805 | H32: =G32+21 -> 45826 | I32: 45811 | J32: =I32-G32 -> 6 | K32: =R32-H32 -> 20 | L32: R0 | M32: 45811 | N32: 45818 | O32: CAT - III | P32: =N32-M32 -> 7 | Q32: =M33-N32 -> 15 | R32: =N33 -> 45846 | S32: Approved | T32: =O33 -> CAT - I | U32: Approved
L33: R1 | M33: 45833 | N33: 45846 | O33: CAT - I | P33: =I1-M33 -> 70
A34: 3 | B34: Civil | C34: Civil & Structural (MMS) | D34: MMS - Pile Foundation Design Calculation | E34: SECI-RG300-PL-CIV-103 | F34: Approval | G34: 45795 | H34: =G34+21 -> 45816 | I34: 45813 | J34: =I34-G34 -> 18 | K34: =R34-H34 -> 52 | L34: R0 | M34: 45813 | N34: 45828 | O34: CAT - I | P34: =N34-M34 -> 15 | Q34: =M35-N34 -> 21 | R34: =N35 -> 45868 | S34: Approved | T34: =O34 -> CAT - I | U34: Approved
L35: R1 | M35: 45849 | N35: 45868 | P35: =I1-M35 -> 54
A36: 4 | B36: Civil | C36: Civil & Structural (MMS) | D36: MMS - Structure GA drawings(2PX26) | E36: SECI-RG300-PL-CIV-104 | F36: Approval | G36: 45751 | H36: =G36+21 -> 45772 | I36: 45727 | J36: =I36-G36 -> -24 | K36: =R36-H36 -> 53 | L36: R0 | M36: 45727 | N36: 45736 | O36: CAT - II | P36: =N36-M36 -> 9 | Q36: =M37-N36 -> 19 | R36: =N40 -> 45825 | S36: Approved | T36: =O41 -> CAT - I | U36: Approved
L37: R1 | M37: 45755 | N37: 45758 | O37: CAT - I | P37: =N37-M37 -> 3 | Q37: =M38-N37 -> 25
L38: R2 | M38: 45783 | N38: 45784 | O38: CAT - I | P38: =N38-M38 -> 1 | Q38: =M39-N38 -> 21
L39: R3 | M39: 45805 | N39: 45807 | O39: CAT - II | P39: =N39-M39 -> 2
L40: R4 | M40: 45825 | N40: 45825 | O40: CAT - I | P40: =N40-M40 -> 0
...

Sheet Sheet1
A2: Date | B2: 45754 | C2: 45755 | D2: 45756 | E2: 45757 | F2: 45758 | G2: 45759 | H2: 45760 | I2: 45761 | J2: 45762 | K2: 45763 | L2: 45764 | M2: 45765 | N2: 45766 | O2: 45767 | P2: 45768 | Q2: 45769 | R2: 45770 | S2: 45771 | T2: 45772 | U2: 45773 | V2: 45774 | W2: 45775 | X2: 45776 | Y2: 45777 | Z2: 45778 | AA2: 45779 | AB2: 45780 | AC2: 45781 | AD2: 45782 | AE2: 45783 | AF2: 45784 | AG2: 45785 | AH2: 45786 | AI2: 45787 | AJ2: 45788 | AK2: 45789 | AL2: 45790 | AM2: 45791
A3: No. of JCBs | B3: 1 | C3: 1 | D3: 1 | E3: 1 | F3: 2 | G3: 2 | H3: 1 | I3: 1 | L3: 4 | M3: 4 | N3: 4 | O3: 4 | P3: 4 | Q3: 6 | R3: 6 | S3: 6 | T3: 6 | U3: 4 | V3: 4 | W3: 4 | X3: 6 | Y3: 6 | Z3: 4 | AA3: 4 | AB3: 6 | AC3: 6 | AD3: 6 | AE3: 5 | AF3: 4 | AG3: 3 | AH3: 5 | AI3: 5 | AJ3: 5 | AK3: 4 | AL3: 6 | AP3: =SUM(B3:AK3) -> 135
A4: Bush Cutting | B4: ='Construction Status'!Z4 -> 1.5 | C4: ='Construction Status'!AA4 -> 3.5 | D4: ='Construction Status'!AB4 -> 4 | E4: ='Construction Status'!AC4 -> 4 | F4: ='Construction Status'!AD4 -> 4 | G4: ='Construction Status'!AE4 -> 4 | H4: ='Construction Status'!AF4 -> 3 | I4: ='Construction Status'!AG4 -> 2 | J4: ='Construction Status'!AH4 -> 0 | K4: ='Construction Status'!AI4-10 -> 0 | L4: ='Construction Status'!AJ4 -> 20 | M4: ='Construction Status'!AK4 -> 20 | N4: ='Construction Status'!AL4+5 -> 25 | O4: ='Construction Status'!AM4+5 -> 26 | P4: ='Construction Status'!AN4 -> 40 | Q4: ='Construction Status'!AO4 -> 40 | R4: ='Construction Status'!AP4 -> 40 | S4: ='Construction Status'!AQ4 -> 38 | T4: ='Construction Status'!AR4 -> 0 | U4: ='Construction Status'!AS4 -> 0 | V4: ='Construction Status'!AT4 -> 0 | W4: ='Construction Status'!AU4 -> 0 | ... AC4: ='Construction Status'!BA4 -> 0 | AF4: 5 | AG4: 10 | AH4: 10 | AI4: 5 | AJ4: 7 | AK4: 5 | AP4: =SUM(B4:AK4) -> 317 | AQ4: =AP4/AP3 -> 2.3481481
A5: Land Grading | B5: ='Construction Status'!Z5 -> 0 | C5: ='Construction Status'!AA5 -> 0 | D5: ='Construction Status'!AB5 -> 0 | E5: ='Construction Status'!AC5 -> 0 | F5: ='Construction Status'!AD5 -> 0 | G5: ='Construction Status'!AE5 -> 0 | H5: ='Construction Status'!AF5 -> 0 | I5: ='Construction Status'!AG5 -> 0 | ... AC5: ='Construction Status'!BA5 -> 20 | AD5: 14 | AE5: 16 | AF5: 16 | AG5: 10 | AH5: 10 | AI5: 5 | AJ5: 7 | AK5: 5 | AP5: =SUM(T3:AK3) -> 87
A6: Per Day Producticity | AP6: =SUM(B5:AK5) -> 201 | AQ6: =AP6/AP5 -> 2.3103448
A7: Bush Cutting | B7: =B4/B3 -> 1.5 | C7: =C4/C3 -> 3.5 | D7: =D4/D3 -> 4 | E7: =E4/E3 -> 4 | F7: =F4/F3 -> 2 | G7: =G4/G3 -> 2 | H7: =H4/H3 -> 3 | I7: =I4/I3 -> 2 | L7: =L4/L3 -> 5 | M7: =M4/M3 -> 5 | N7: =N4/N3 -> 6.25 | O7: =O4/O3 -> 6.5 | P7: =P4/P3 -> 10 | Q7: =Q4/Q3 -> 6.6666667 | R7: =R4/R3 -> 6.6666667 | S7: =S4/S3 -> 6.3333333
A8: Land Grading | T8: =T5/T3 -> 1.6666667 | U8: =U5/U3 -> 2.5 | V8: =V5/V3 -> 2.5 | W8: =W5/W3 -> 2.5 | X8: =X5/X3 -> 2 | Y8: =Y5/Y3 -> 2.1666667 | Z8: =Z5/Z3 -> 2.5 | AA8: =AA5/AA3 -> 3 | ... AM8: =AM5/AM3 -> #DIV/0!
A10: Manpower
A11: Land Development | AA11: 6 | AB11: 8 | AC11: 8 | AD11: 8 | AE11: 6 | AF11: 6 | AG11: 6 | AH11: 5 | AI11: 8 | AJ11: 8 | AK11: 7 | AL11: 9
AC13: Bushing | AE13: Balance | AF13: Remaining days | AG13: Per day requirement
J14: 250 | K14: 47 | AC14: 250 | AD14: 47 | AE14: =AC14-AD14 -> 203 | AF14: 19 | AG14: =AE14/AF14 -> 10.684211
AC16: Grading
AC17: 250 | AD17: 121 | AE17: =AC17-AD17 -> 129 | AF17: =AF14 -> 19 | AG17: =AE17/AF17 -> 6.7894737

Sheet Ordering
A1: # | B1: Ordering | C1: Make/ OEM | D1: Planned | E1: Actual/ Expected | F1: Remarks
A2: 1 | B2: Module Mounting Structure | C2: Pennar | D2: 45757 | E2: 45759 | F2: Completed
A3: 2 | B3: Inverter Duty Transformer | C3: T&R | D3: 45757 | E3: 45747 | F3: Completed
A4: 3 | B4: NIFPS | D4: 45780 | E4: 45838
A5: 4 | B5: ICOG/RMU PANEL | C5: Trisquare | D5: 45768 | E5: 45797 | F5: Completed
A6: 5 | B6: Main HT Switchgear Panel | C6: Trisquare | D6: 45768 | E6: 45797 | F6: Completed
A7: 6 | B7: Auxiliary LT Panel | C7: M/S ALNICO ELECTRIC PVT LTD | D7: 45784 | E7: 45848 | F7: Completed
A8: 7 | B8: Auxiliary Transformer | D8: 45784 | E8: 45835
A9: 8 | B9: Central Inverter(PCU) | C9: Fimer | D9: 45760 | E9: 45747 | F9: Completed
A10: 9 | B10: String Combiner Box (SCB) | C10: Trinity Touch | D10: 45757 | E10: 45838 | F10: Completed
A11: 10 | B11: DC string cable | C11: Polycab | D11: 45783 | E11: 45845 | F11: Completed
A12: 11 | B12: DC power cable | C12: Gemscab/ Special | D12: 45768 | E12: 45845 | F12: Completed
A13: 12 | B13: LT AC power cable | D13: 45768 | E13: 45845
A14: 13 | B14: HT AC power cable | D14: 45783 | E14: 45845
A15: 14 | B15: LT power and control cables | D15: 45783 | E15: 45845
A16: 15 | B16: Communication cables | D16: 45783 | E16: 45845
A17: 16 | B17: SCADA system | C17: Adaptive | D17: 45768 | E17: 45815 | F17: Completed
A18: 17 | B18: UPS and Battery System | C18: M/s Fuji Electric | D18: 45783 | E18: 45857 | F18: Completed
A19: 18 | B19: SVG | C19: M/S Guangdong Mingyang Longyuan Power Electronics Co.Ltd | D19: 45784 | E19: 45849 | F19: Completed
A20: 19 | B20: Harmonic Filter and its Acessories | D20: 45803 | E20: 45853
A21: 20 | B21: Other BOQ (Lighting, Gland, Lungs, HT termination KIT etc.) | D21: 45839 | E21: 45839

Sheet Preliminary Activity
A1: # | B1: Contract Signing & Key Preliminary Activities | C1: Planned | D1: Actual/ Expected | E1: Status
A2: 1 | B2: Project Start Date | C2: 45694 | D2: 45694
A3: 2 | B3: Contract Agreement Signing | C3: 45698 | D3: 45698 | E3: Completed
A4: 3 | B4: Kick Off meeting_SECI HO | C4: 45698 | D4: 45698 | E4: Completed
A5: 4 | B5: PBG Submission | C5: 45721 | D5: 45721 | E5: Completed
A6: 5 | B6: ABG Submission | C6: 45730 | D6: 45730 | E6: Completed
A7: 6 | B7: Boundary Coordinates Capturing | C7: 45709 | D7: 45709 | E7: Completed
A8: 7 | B8: Labor License related documents (Form 2, Form 5) | C8: 45733 | D8: 45733 | E8: Completed
A9: 8 | B9: Labor License | C9: 45758 | D9: 45749 | E9: Completed
A10: 9 | B10: Customer GST commercial registration & Address (Billing & Delivery) Details | C10: 45754 | D10: 45793 | E10: Completed
A11: 10 | B11: Topography Survey | C11: 45730 | D11: 45730 | E11: Completed
A12: 11 | B12: Soil Test (5m) | C12: 45735 | D12: 45735 | E12: Completed
A13: 12 | B13: Soil Test (10m) | C13: 45762 | D13: 45777 | E13: Completed
A14: 13 | B14: ERT Test | C14: 45760 | D14: 45757 | E14: Completed
A15: 14 | B15: Test Pile Casting | C15: 45773 | D15: 45815 | E15: Completed
A16: 15 | B16: Pile Testing | C16: =C15+28 -> 45801 | D16: 45837 | E16: Completed
A17: # | B17: Site Establishment | C17: Planned | D17: Actual/ Expected | E17: Status
A18: 1 | B18: Area development | C18: 45760 | D18: 45752 | E18: Completed
A19: =+SUM(A18+1) -> 2 | B19: Store Yard Fencing Work | C19: 45833 | D19: 45837 | E19: Completed
A20: =+SUM(A19+1) -> 3 | B20: Delivery of office cabins/ Toilets/ Security cabins | C20: 45783 | D20: 45838 | E20: Completed
A21: =+SUM(A20+1) -> 4 | B21: Construction Power arrangement | C21: 45767 | D21: 45767 | E21: Completed
A22: =+SUM(A21+1) -> 5 | B22: Internet availability | C22: 45767 | D22: 45752 | E22: Completed
A23: =+SUM(A22+1) -> 6 | B23: Placement of security personnel | C23: 45762 | D23: 45740 | E23: Security personal deployed at Site
A24: =+SUM(A23+1) -> 7 | B24: Set up of Quality Lab | C24: 45774 | D24: 45844 | E24: Completed
A25: =+SUM(A24+1) -> 8 | B25: Set up of safety induction room | C25: 45774 | D25: 45838 | E25: Completed
A26: =+SUM(A25+1) -> 9 | B26: Set up of material storage | C26: 45764 | D26: 45838 | E26: Completed
A27: # | B27: Civil Activities | C27: Planned | D27: Actual/ Expected | E27: Status
A28: 1 | B28: Peripherial Boundary Fencing | D28: 45836 | E28: Work in Progress

Sheet Manpower
A1: Project Name : | B1: 300MW SECI RAMAGIRI PROJECT
A2: Project Size : | B2: 300MW AC Capacity & 390 Mwp DC Capacity
A3: Date of Report: | B3: ='[1]Project Overview'!P1 -> 45702
A5: S No. | B5: Contractor Name | C5: Resources Category | D5: Manpower Description | E5: =B3 -> 45702 | F5: Cum. Nos | G5: 45703 | H5: =G5+1 -> 45704 | I5: =H5+1 -> 45705 | J5: =I5+1 -> 45706 | K5: =J5+1 -> 45707 | L5: =K5+1 -> 45708 | M5: =L5+1 -> 45709 | N5: =M5+1 -> 45710 | O5: =N5+1 -> 45711 | ... MM5: =ML5+1 -> 46047
E6: =SUM(E7:E139) -> 1 | F6: =SUM(G6:MM6) -> 0 | G6: =SUM(G7:G139) -> 0 | H6: =SUM(H7:H139) -> 0 | I6: =SUM(I7:I139) -> 0 | J6: =SUM(J7:J139) -> 0 | K6: =SUM(K7:K139) -> 0 | L6: =SUM(L7:L139) -> 0 | M6: =SUM(M7:M139) -> 0 | N6: =SUM(N7:N139) -> 0 | ... BZ6: =SUM(BZ7:BZ139) -> 0 | CA6: =SUM(CA8:CA139) -> 0 | CB6: =SUM(CB8:CB139) -> 0 | CC6: =SUM(CC8:CC139) -> 0 | CD6: =SUM(CD8:CD139) -> 0 | CE6: =SUM(CE8:CE139) -> 0 | CF6: =SUM(CF8:CF139) -> 0 | CG6: =SUM(CG9:CG139) -> 0 | CH6: =SUM(CH8:CH139) -> 0 | CI6: =SUM(CI8:CI139) -> 0 | CJ6: =SUM(CJ8:CJ139) -> 0 | CK6: =SUM(CK8:CK139) -> 0 | CL6: =SUM(CL8:CL139) -> 0 | CM6: =SUM(CM8:CM139) -> 0 | CN6: =SUM(CN8:CN139) -> 0 | CO6: =SUM(CO8:CO139) -> 0 | ... DC6: =SUM(DC8:DC139) -> 0 | DD6: =SUM(DD8:DD141) -> 0 | DE6: =SUM(DE8:DE141) -> 0 | DF6: =SUM(DF8:DF141) -> 0 | DG6: =SUM(DG8:DG141) -> 0 | DH6: =SUM(DH8:DH141) -> 0 | DI6: =SUM(DI8:DI141) -> 0 | DJ6: =SUM(DJ8:DJ141) -> 0 | DK6: =SUM(DK8:DK141) -> 0 | ... FT6: =SUM(FT8:FT141) -> 0 | FU6: =SUM(FU8:FU139) -> 0 | FV6: =SUM(FV8:FV139) -> 0 | FW6: =SUM(FW8:FW139) -> 0 | FX6: =SUM(FX8:FX139) -> 0 | FY6: =SUM(FY8:FY139) -> 0 | FZ6: =SUM(FZ8:FZ139) -> 0 | GA6: =SUM(GA8:GA139) -> 0 | GB6: =SUM(GB8:GB139) -> 0 | ... MM6: =SUM(MM8:MM139) -> 0
A7: 1 | D7: Staff | E7: =SUMIFS(G7:XFD7,$G$5:$XFD$5,$E$5) -> 0 | F7: =SUM(G7:MM7) -> 0
A8: 2 | C8: Surveying | D8: Suveryor | E8: =SUMIFS(G8:XFD8,$G$5:$XFD$5,$E$5) -> 0
A9: 3 | D9: Suveryor | E9: =SUMIFS(G9:XFD9,$G$5:$XFD$5,$E$5) -> 0 | F9: =SUM(G9:MM9) -> 0
A10: 4 | C10: Surveying | D10: Suveryor | E10: =SUMIFS(G10:XFD10,$G$5:$XFD$5,$E$5) -> 0 | F10: =SUM(G10:MM10) -> 0
A11: 5 | D11: Suveryor | E11: =SUMIFS(G11:XFD11,$G$5:$XFD$5,$E$5) -> 0 | F11: =SUM(G11:MM11) -> 0
A12: 6 | C12: Security | D12: Security | E12: 1 | F12: =SUM(G12:MM12) -> 0
A13: 7 | C13: Grading | D13: Engineers / Supervisors | E13: =SUMIFS(G13:XFD13,$G$5:$XFD$5,$E$5) -> 0 | F13: =SUM(G13:MM13) -> 0
A14: 8 | D14: Workers - Skilled | E14: =SUMIFS(G14:XFD14,$G$5:$XFD$5,$E$5) -> 0 | F14: =SUM(G14:MM14) -> 0
A15: 9 | D15: Workers - Unskilled | E15: =SUMIFS(G15:XFD15,$G$5:$XFD$5,$E$5) -> 0 | F15: =SUM(G15:MM15) -> 0
A16: 10 | C16: Piling | D16: Engineers / Supervisors | E16: =SUMIFS(G16:XFD16,$G$5:$XFD$5,$E$5) -> 0 | F16: =SUM(G16:MM16) -> 0
A17: 11 | D17: Workers - Skilled | E17: =SUMIFS(G17:XFD17,$G$5:$XFD$5,$E$5) -> 0 | F17: =SUM(G17:MM17) -> 0
A18: 12 | D18: Workers - Unskilled | E18: =SUMIFS(G18:XFD18,$G$5:$XFD$5,$E$5) -> 0 | F18: =SUM(G18:MM18) -> 0
A19: 13 | C19: Grading | D19: Engineers / Supervisors | E19: =SUMIFS(G19:XFD19,$G$5:$XFD$5,$E$5) -> 0 | F19: =SUM(G19:MM19) -> 0
A20: 14 | D20: Workers - Skilled | E20: =SUMIFS(G20:XFD20,$G$5:$XFD$5,$E$5) -> 0 | F20: =SUM(G20:MM20) -> 0
A21: 15 | D21: Workers - Unskilled | E21: =SUMIFS(G21:XFD21,$G$5:$XFD$5,$E$5) -> 0 | F21: =SUM(G21:MM21) -> 0
A22: 16 | C22: Piling | D22: Engineers / Supervisors | E22: =SUMIFS(G22:XFD22,$G$5:$XFD$5,$E$5) -> 0 | F22: =SUM(G22:MM22) -> 0
A23: 17 | D23: Workers - Skilled | E23: =SUMIFS(G23:XFD23,$G$5:$XFD$5,$E$5) -> 0 | F23: =SUM(G23:MM23) -> 0
A24: 18 | D24: Workers - Unskilled | E24: =SUMIFS(G24:XFD24,$G$5:$XFD$5,$E$5) -> 0 | F24: =SUM(G24:MM24) -> 0
A25: 19 | C25: Grading | D25: Engineers / Supervisors | E25: =SUMIFS(G25:XFD25,$G$5:$XFD$5,$E$5) -> 0 | F25: =SUM(G25:MM25) -> 0
A26: 20 | D26: Workers - Skilled | E26: =SUMIFS(G26:XFD26,$G$5:$XFD$5,$E$5) -> 0 | F26: =SUM(G26:MM26) -> 0
A27: 21 | D27: Workers - Unskilled | E27: =SUMIFS(G27:XFD27,$G$5:$XFD$5,$E$5) -> 0 | F27: =SUM(G27:MM27) -> 0
A28: 22 | C28: Piling | D28: Engineers / Supervisors | E28: =SUMIFS(G28:XFD28,$G$5:$XFD$5,$E$5) -> 0 | F28: =SUM(G28:MM28) -> 0
A29: 23 | D29: Workers - Skilled | E29: =SUMIFS(G29:XFD29,$G$5:$XFD$5,$E$5) -> 0 | F29: =SUM(G29:MM29) -> 0
A30: 24 | D30: Workers - Unskilled | E30: =SUMIFS(G30:XFD30,$G$5:$XFD$5,$E$5) -> 0 | F30: =SUM(G30:MM30) -> 0
A31: 25 | C31: Grading | D31: Engineers / Supervisors | E31: =SUMIFS(G31:XFD31,$G$5:$XFD$5,$E$5) -> 0 | F31: =SUM(G31:MM31) -> 0
A32: 26 | D32: Workers - Skilled | E32: =SUMIFS(G32:XFD32,$G$5:$XFD$5,$E$5) -> 0 | F32: =SUM(G32:MM32) -> 0
A33: 27 | D33: Workers - Unskilled | E33: =SUMIFS(G33:XFD33,$G$5:$XFD$5,$E$5) -> 0 | F33: =SUM(G33:MM33) -> 0
A34: 28 | C34: Piling | D34: Engineers / Supervisors | E34: =SUMIFS(G34:XFD34,$G$5:$XFD$5,$E$5) -> 0 | F34: =SUM(G34:MM34) -> 0
A35: 29 | D35: Workers - Skilled | E35: =SUMIFS(G35:XFD35,$G$5:$XFD$5,$E$5) -> 0 | F35: =SUM(G35:MM35) -> 0
A36: 30 | D36: Workers - Unskilled | E36: =SUMIFS(G36:XFD36,$G$5:$XFD$5,$E$5) -> 0 | F36: =SUM(G36:MM36) -> 0
A37: 31 | C37: Grading | D37: Engineers / Supervisors | E37: =SUMIFS(G37:XFD37,$G$5:$XFD$5,$E$5) -> 0 | F37: =SUM(G37:MM37) -> 0
A38: 32 | D38: Workers - Skilled | E38: =SUMIFS(G38:XFD38,$G$5:$XFD$5,$E$5) -> 0 | F38: =SUM(G38:MM38) -> 0
A39: 33 | D39: Workers - Unskilled | E39: =SUMIFS(G39:XFD39,$G$5:$XFD$5,$E$5) -> 0 | F39: =SUM(G39:MM39) -> 0
A40: 34 | C40: Piling | D40: Engineers / Supervisors | E40: =SUMIFS(G40:XFD40,$G$5:$XFD$5,$E$5) -> 0 | F40: =SUM(G40:MM40) -> 0
A41: 35 | D41: Workers - Skilled | E41: =SUMIFS(G41:XFD41,$G$5:$XFD$5,$E$5) -> 0 | F41: =SUM(G41:MM41) -> 0
...

Sheet Machinery
A1: Project Name : | B1: 300MW SECI RAMAGIRI PROJECT
A2: Project Size : | B2: 300MW AC Capacity & 390 Mwp DC Capacity
A3: Date of Report: | B3: 45703
A5: S No. | B5: Contractor Name | C5: Resources Category | D5: Resources Description | E5: =B3 -> 45703 | F5: Cum. Nos | G5: 45703 | H5: =G5+1 -> 45704 | I5: =H5+1 -> 45705 | J5: =I5+1 -> 45706 | K5: =J5+1 -> 45707 | L5: =K5+1 -> 45708 | M5: =L5+1 -> 45709 | N5: =M5+1 -> 45710 | O5: =N5+1 -> 45711 | ... LN5: =LM5+1 -> 46022
E6: =SUM(E10:E42) -> 0 | F6: =SUM(G6:LN6) -> 0 | G6: =SUM(G10:G42) -> 0 | H6: =SUM(H10:H42) -> 0 | I6: =SUM(I10:I42) -> 0 | J6: =SUM(J10:J42) -> 0 | K6: =SUM(K10:K42) -> 0 | L6: =SUM(L10:L42) -> 0 | M6: =SUM(M10:M42) -> 0 | N6: =SUM(N10:N42) -> 0 | ... BZ6: =SUM(BZ10:BZ42) -> 0 | CA6: =SUM(CA11:CA42) -> 0 | CB6: =SUM(CB11:CB42) -> 0 | CC6: =SUM(CC11:CC42) -> 0 | CD6: =SUM(CD11:CD42) -> 0 | CE6: =SUM(CE11:CE42) -> 0 | CF6: =SUM(CF11:CF42) -> 0 | CG6: =SUM(CG11:CG42) -> 0 | CH6: =SUM(CH11:CH42) -> 0 | ... DC6: =SUM(DC11:DC42) -> 0 | DD6: =SUM(DD11:DD44) -> 0 | DE6: =SUM(DE11:DE44) -> 0 | DF6: =SUM(DF11:DF44) -> 0 | DG6: =SUM(DG11:DG44) -> 0 | DH6: =SUM(DH11:DH44) -> 0 | DI6: =SUM(DI11:DI44) -> 0 | DJ6: =SUM(DJ11:DJ44) -> 0 | DK6: =SUM(DK11:DK44) -> 0 | ... FT6: =SUM(FT11:FT44) -> 0 | FU6: =SUM(FU11:FU42) -> 0 | FV6: =SUM(FV11:FV42) -> 0 | FW6: =SUM(FW11:FW42) -> 0 | FX6: =SUM(FX11:FX42) -> 0 | FY6: =SUM(FY11:FY42) -> 0 | FZ6: =SUM(FZ11:FZ42) -> 0 | GA6: =SUM(GA11:GA42) -> 0 | GB6: =SUM(GB11:GB42) -> 0 | ... LN6: =SUM(LN11:LN42) -> 0
A7: 1 | B7: PR Construction | D7: JCB | F7: =SUM(G7:LN7) -> 58 | BF7: 1 | BG7: 1 | BH7: 1 | BI7: 1 | BJ7: 2 | BK7: 2 | BL7: 1 | BM7: 1 | BP7: 4 | BQ7: 4 | BR7: 4 | BS7: 4 | BT7: 4 | BU7: 6 | BV7: 6 | BW7: 6 | BX7: 6 | BY7: 4
A8: =A7+1 -> 2 | D8: Tractor | F8: =SUM(G8:LN8) -> 0
A9: =A8+1 -> 3 | D9: Farana | F9: =SUM(G9:LN9) -> 0
A10: =ROW()-8 -> 2 | D10: Hire Vehicle | E10: =SUMIFS(G10:XFD10,$G$5:$XFD$5,$E$5) -> 0 | F10: =SUM(G10:LN10) -> 0
A11: =A10+1 -> 3 | B11: Boundary wall works | D11: Manual Loading Transit mixer | F11: =SUM(G11:LN11) -> 0
A12: =A11+1 -> 4 | D12: Tractor mounted auger | F12: =SUM(G12:LN12) -> 0
A13: =A12+1 -> 5 | D13: Tractor with trolly | F13: =SUM(G13:LN13) -> 0
A14: =A13+1 -> 6 | D14: Water tanker | F14: =SUM(G14:LN14) -> 0
A15: =A14+1 -> 7 | D15: Pickup | F15: =SUM(G15:LN15) -> 0
A16: 13 | B16: Bush cleaning | D16: JCB | F16: =SUM(G16:LN16) -> 0
A17: 14 | D17: Tractor with trolly | F17: =SUM(G17:LN17) -> 0
A18: 18 | B18: Internal Road works | D18: JCB / Grader | F18: =SUM(G18:LN18) -> 0
A19: 19 | D19: Tractor Trolley | F19: =SUM(G19:LN19) -> 0
A20: 20 | D20: Roller | F20: =SUM(G20:LN20) -> 0
A21: 21 | D21: Dumper | F21: =SUM(G21:LN21) -> 0
A22: 22 | D22: Water tanker | F22: =SUM(G22:LN22) -> 0
A23: 23 | B23: Approach Road works | D23: JCB / Grader | F23: =SUM(G23:LN23) -> 0
A24: 24 | D24: Tractor Trolley | F24: =SUM(G24:LN24) -> 0
A25: 25 | D25: Roller | F25: =SUM(G25:LN25) -> 0
A26: 26 | D26: DG | F26: =SUM(G26:LN26) -> 0
A27: 27 | D27: Water tanker | F27: =SUM(G27:LN27) -> 0
A28: 33 | B28: Piling | D28: DTH | F28: =SUM(G28:LN28) -> 0
A29: 34 | D29: Tractor Augur | F29: =SUM(G29:LN29) -> 0
A30: 35 | D30: Water tanker | F30: =SUM(G30:LN30) -> 0
A31: 36 | D31: Tractor with trolly | F31: =SUM(G31:LN31) -> 0
A32: 37 | D32: JCB | F32: =SUM(G32:LN32) -> 0
A33: 38 | D33: DG | F33: =SUM(G33:LN33) -> 0
A34: 77 | B34: ICR Building | D34: Total Station | F34: =SUM(G34:LN34) -> 0
A35: 78 | D35: Tractor with trolly | F35: =SUM(G35:LN35) -> 0
A36: 79 | D36: Water tanker | F36: =SUM(G36:LN36) -> 0
A37: 80 | D37: Tractor mounted auger | F37: =SUM(G37:LN37) -> 0
A38: 68 | B38: MCR CIVIL | D38: Tractor mounted auger | F38: =SUM(G38:LN38) -> 0
A39: 69 | D39: Water tanker | F39: =SUM(G39:LN39) -> 0
A40: 70 | D40: Tractor with trolly | F40: =SUM(G40:LN40) -> 0
A41: 71 | D41: JCB | F41: =SUM(G41:LN41) -> 0
...

Sheet Construction Status
C1: Date | D1: ='Construction DASHBOARD'!B6 -> 45903
B2: Section | C2: S.No | D2: Site Activity | E2: Planned Start | F2: Planned Finish | G2: No. of Days | H2: Actual/ Expected Start | I2: Actual/ Expected Finish | J2: UoM | K2: Qty | L2: Start Date | M2: Actual/ Expected Finish Date | N2: No of Days | O2: Avg/Day | P2: Actual as on Date (%) | Q2: Comp. | R2: Bal | S2: Actual as on date | T2: Till Last Month | U2: 45746 | V2: 45750 | W2: 45751 | X2: 45752 | Y2: 45753 | Z2: 45754 | AA2: 45755 | AB2: 45756 | AC2: 45757 | AD2: 45758 | AE2: 45759 | AF2: 45760 | AG2: 45761 | AH2: 45762 | AI2: 45763 | AJ2: 45764 | AK2: 45765 | AL2: 45766 | AM2: 45767 | AN2: 45768 | AO2: 45769 | AP2: 45770 | AQ2: 45771 | AR2: 45772 | AS2: 45773 | AT2: 45774 | AU2: 45775 | AV2: 45776 | AW2: 45777 | AX2: 45778 | AY2: 45779 | AZ2: 45780 | BA2: 45781 | BB2: 45782 | BC2: 45783 | BD2: 45784 | BE2: 45785 | BF2: 45786 | BG2: 45787 | BH2: 45788 | BI2: 45789 | BJ2: 45790 | BK2: 45791 | BL2: 45792 | BM2: 45793 | BN2: 45794 | BO2: 45795 | BP2: 45796 | BQ2: 45797 | BR2: 45798 | BS2: 45799 | BT2: 45800 | BU2: 45801 | BV2: 45802 | BW2: 45803 | BX2: 45804 | BY2: 45805 | BZ2: 45806 | CA2: 45807 | CB2: 45808 | CC2: 45809 | CD2: 45810 | CE2: 45811 | CF2: 45812 | CG2: 45813 | CH2: 45814 | CI2: 45815 | CJ2: 45816 | CK2: 45817 | CL2: 45818 | CM2: 45819 | CN2: 45820 | CO2: 45821 | CP2: 45822 | CQ2: 45823 | CR2: 45824 | CS2: 45825 | CT2: 45826 | CU2: 45827 | CV2: 45828 | CW2: 45829 | CX2: 45830 | CY2: 45831 | CZ2: 45832 | DA2: 45833 | DB2: 45834 | DC2: 45835 | DD2: 45836 | DE2: 45837 | DF2: 45838 | DG2: 45839 | DH2: 45840 | DI2: 45841 | DJ2: 45842 | DK2: 45843 | DL2: 45844 | DM2: 45845 | DN2: 45846 | DO2: 45847 | DP2: 45848 | DQ2: 45849 | DR2: 45850 | DS2: 45851 | DT2: 45852 | DU2: 45853 | DV2: 45854 | DW2: 45855 | DX2: 45856 | DY2: 45857 | DZ2: 45858 | EA2: 45859 | EB2: 45860 | EC2: 45861 | ED2: 45862 | EE2: 45863 | EF2: 45864 | EG2: 45865 | EH2: 45866 | EI2: 45867 | EJ2: 45868 | EK2: 45869 | EL2: 45870 | EM2: 45871 | EN2: 45872 | EO2: 45873 | EP2: 45874 | EQ2: 45875 | ER2: 45876 | ES2: 45877 | ET2: 45878 | EU2: 45879 | EV2: 45880 | EW2: 45881 | EX2: 45882 | EY2: 45883 | EZ2: 45884 | FA2: 45885 | FB2: 45886 | FC2: 45887 | FD2: 45888 | FE2: 45889 | FF2: 45890 | FG2: 45891 | FH2: 45892 | FI2: 45893 | FJ2: 45894 | FK2: 45895 | FL2: 45896 | FM2: 45897 | FN2: 45898 | FO2: 45899 | FP2: 45900 | FQ2: 45901 | FR2: 45902 | FS2: 45903 | FT2: 45904 | FU2: 45905 | FV2: 45906 | FW2: 45907 | FX2: 45908 | FY2: 45909 | FZ2: 45910 | GA2: 45911 | GB2: 45912 | GC2: 45913 | GD2: 45914 | GE2: 45915 | GF2: 45916 | GG2: 45917 | GH2: 45918 | GI2: 45919 | GJ2: 45920 | GK2: 45921 | GL2: 45922 | GM2: 45923 | GN2: 45924 | GO2: 45925 | GP2: 45926 | GQ2: 45927 | GR2: 45928 | GS2: 45929 | GT2: 45930
U3: =TEXT(U2,"ddd") -> Sun | V3: =TEXT(V2,"ddd") -> Thu | W3: =TEXT(W2,"ddd") -> Fri | X3: =TEXT(X2,"ddd") -> Sat | Y3: =TEXT(Y2,"ddd") -> Sun | Z3: =TEXT(Z2,"ddd") -> Mon | AA3: =TEXT(AA2,"ddd") -> Tue | AB3: =TEXT(AB2,"ddd") -> Wed | ... GT3: =TEXT(GT2,"ddd") -> Tue
B4: L & G | C4: 1 | D4: Bush removal | E4: 45750 | F4: 45870 | G4: =F4-E4 -> 120 | H4: 45754 | I4: 45870 | J4: Acre | K4: 1033 | L4: 45754 | M4: 45796 | N4: =IF(OR(M4="",L4=""),"",INT(M4-L4+1)) -> 43 | O4: =IFERROR(K4/N4,"-") -> 24.023256 | P4: =Q4/K4 -> 0.91600194 | Q4: =S4 -> 946.23 | R4: =K4-Q4 -> 86.77 | S4: =SUM(U4:XFD4) -> 946.23 | T4: =SUM(U4:EK4) -> 877.2 | U4: 0 | V4: 0 | Z4: 1.5 | AA4: 3.5 | AB4: 4 | AC4: 4 | AD4: 4 | AE4: 4 | AF4: 3 | AG4: 2 | AI4: 10 | AJ4: 20 | AK4: 20 | AL4: 20 | AM4: 21 | AN4: 40 | AO4: 40 | AP4: 40 | AQ4: 38 | BC4: 5 | BD4: 10 | BE4: 10 | BF4: 10 | BG4: 5 | BH4: 7 | BI4: 5 | BJ4: 0 | BK4: 0 | BL4: 7 | BM4: 0 | BN4: 17 | BO4: 19 | BP4: 24 | BQ4: 9 | BR4: 12 | BS4: 0 | BT4: 16 | BU4: 0 | BV4: 0 | BW4: 0 | BX4: 0 | BY4: 6 | BZ4: 16 | CA4: 15 | CB4: 18 | CC4: 14 | CD4: 16 | CE4: 15 | CF4: 14 | CG4: 18 | CH4: 14 | CI4: 15 | CJ4: 10 | CK4: 11 | CL4: 16 | CM4: 13 | CN4: 15 | CO4: 17 | CP4: 5 | CQ4: 14 | CR4: 16 | CS4: 13 | CT4: 13 | CU4: 11 | CV4: 7 | CW4: 5 | CX4: 5 | CY4: 5 | CZ4: 5 | DA4: 5 | DB4: 7 | DC4: 10 | DD4: 7 | DE4: 6 | DF4: 5 | DG4: 7 | DH4: 12 | DI4: 9 | DJ4: 8 | DK4: 7 | DL4: 7 | DM4: 9 | DN4: 0 | DO4: 0 | DP4: 0 | DQ4: 0 | DR4: 0 | DS4: 0 | DT4: 0 | DU4: 0 | DV4: 0 | DW4: 0 | DX4: 0 | DY4: 0 | DZ4: 0 | EA4: 0 | EB4: 0 | EC4: 0 | ED4: 0 | EE4: 0 | EF4: 0 | EG4: 0 | EH4: 3 | EI4: 0.6 | EJ4: 1.6 | EK4: 0 | EL4: 0 | EM4: 0 | EN4: 0 | EO4: 0 | EP4: 0 | EQ4: 0 | ER4: 0 | ES4: 0 | ET4: 0 | EU4: 0 | EV4: 0 | EW4: 0 | EX4: 0 | EY4: 3 | EZ4: 1 | FA4: 3 | FB4: 1 | FC4: 0 | FD4: 30 | FE4: 20 | FF4: 3 | FG4: 1.03 | FH4: 1 | FI4: 1 | FJ4: 1 | FK4: 1 | FL4: 1 | FM4: 1 | FN4: 1 | FO4: 0 | FP4: 0 | FQ4: 0 | FR4: 0
C5: 2 | D5: Land grading | E5: 45750 | F5: 45870 | G5: =F5-E5 -> 120 | H5: 45754 | I5: 45870 | J5: Acre | K5: 1033 | L5: 45754 | M5: 45796 | N5: =IF(OR(M5="",L5=""),"",INT(M5-L5+1)) -> 43 | O5: =IFERROR(K5/N5,"-") -> 24.023256 | P5: =Q5/K5 -> 0.90883833 | Q5: =S5 -> 938.83 | R5: =K5-Q5 -> 94.17 | S5: =SUM(U5:XFD5) -> 938.83 | T5: =SUM(U5:EK5) -> 872 | AR5: 10 | AS5: 10 | AT5: 10 | AU5: 10 | AV5: 12 | AW5: 13 | AX5: 10 | AY5: 12 | AZ5: 11 | BA5: 20 | BB5: 14 | BC5: 16 | BD5: 10 | BE5: 6 | BF5: 10 | BG5: 5 | BH5: 7 | BI5: 5 | BJ5: 7 | BK5: 7 | BL5: 7 | BM5: 12 | BN5: 17 | BO5: 19 | BP5: 24 | BQ5: 9 | BR5: 12 | BS5: 18 | BT5: 16 | BU5: 15 | BV5: 23 | BW5: 22 | BX5: 20 | BY5: 18 | BZ5: 16 | CA5: 15 | CB5: 18 | CC5: 14 | CD5: 16 | CE5: 15 | CF5: 14 | CG5: 18 | CH5: 14 | CI5: 15 | CJ5: 10 | CK5: 11 | CL5: 16 | CM5: 13 | CN5: 15 | CO5: 17 | CP5: 5 | CQ5: 14 | CR5: 16 | CS5: 13 | CT5: 13 | CU5: 11 | CV5: 7 | CW5: 5 | CX5: 5 | CY5: 5 | CZ5: 5 | DA5: 5 | DB5: 7 | DC5: 10 | DD5: 7 | DE5: 6 | DF5: 5 | DG5: 7 | DH5: 12 | DI5: 9 | DJ5: 8 | DK5: 7 | DL5: 7 | DM5: 9 | DN5: 0 | DO5: 0 | DP5: 0 | DQ5: 0 | DR5: 0 | DS5: 0 | DT5: 0 | DU5: 0 | DV5: 0 | DW5: 0 | DX5: 0 | DY5: 0 | DZ5: 0 | EA5: 0 | EB5: 0 | EC5: 0 | ED5: 0 | EE5: 0 | EF5: 0 | EG5: 0 | EH5: 0 | EI5: 0 | EJ5: 0 | EK5: 0 | EL5: 0 | EM5: 0 | EN5: 0 | EO5: 1.8 | EP5: 0 | EQ5: 0 | ER5: 0 | ES5: 0 | ET5: 0 | EU5: 0 | EV5: 0 | EW5: 0 | EX5: 0 | EY5: 3 | EZ5: 1 | FA5: 3 | FB5: 1 | FC5: 0 | FD5: 30 | FE5: 20 | FF5: 3 | FG5: 1.03 | FH5: 1 | FI5: 1 | FJ5: 1 | FK5: 0 | FL5: 0 | FM5: 0 | FN5: 0 | FO5: 0 | FP5: 0 | FQ5: 0 | FR5: 0
B6: Site Initials | C6: 3 | D6: Boundry Coordinate capturing | E6: 45700 | F6: 45709 | G6: =F6-E6 -> 9 | H6: 45700 | I6: 45709 | J6: Lot. | K6: 1 | L6: 45700 | M6: 45710 | N6: =IF(OR(M6="",L6=""),"",INT(M6-L6+1)) -> 11 | O6: =IFERROR(K6/N6,"-") -> 0.090909091 | P6: =IFERROR(SUMIF($U$2:$AT$2,"<="&$D$1,U6:BN6)/K6,"-") -> 1 | Q6: =SUMIF($U$2:$CC$2,"<="&$D$1,U6:CC6) -> 1 | R6: =K6-Q6 -> 0 | S6: =SUM(U6:XFD6) -> 1 | T6: =SUM(U6:EK6) -> 1 | U6: 1 | DG6: 0 | DH6: 0 | DI6: 0 | DJ6: 0 | DK6: 0 | DL6: 0 | DM6: 0 | DN6: 0 | DO6: 0 | DP6: 0 | DQ6: 0 | DR6: 0 | DS6: 0 | DT6: 0 | DU6: 0 | DV6: 0 | DW6: 0 | DX6: 0 | DY6: 0 | DZ6: 0 | EA6: 0 | EB6: 0 | EC6: 0 | ED6: 0 | EE6: 0 | EF6: 0 | EG6: 0 | EH6: 0 | EI6: 0 | EJ6: 0 | EK6: 0 | EL6: 0 | EM6: 0 | EN6: 0 | EO6: 0 | EP6: 0 | EQ6: 0 | ER6: 0 | ES6: 0 | ET6: 0 | EU6: 0 | EV6: 0 | EW6: 0 | EX6: 0 | EY6: 0 | EZ6: 0 | FA6: 0 | FB6: 0 | FC6: 0 | FD6: 0 | FE6: 0 | FF6: 0 | FG6: 0 | FH6: 0 | FI6: 0 | FJ6: 0 | FK6: 0 | FL6: 0 | FM6: 0 | FN6: 0 | FO6: 0 | FP6: 0 | FQ6: 0 | FR6: 0
C7: 4 | D7: Topo Survey | E7: 45711 | F7: 45730 | G7: =F7-E7 -> 19 | H7: 45711 | I7: 45730 | J7: Lot. | K7: 1 | L7: 45703 | M7: 45730 | N7: =IF(OR(M7="",L7=""),"",INT(M7-L7+1)) -> 28 | O7: =IFERROR(K7/N7,"-") -> 0.035714286 | P7: =IFERROR(SUMIF($U$2:$AT$2,"<="&$D$1,U7:BN7)/K7,"-") -> 1 | Q7: =SUMIF($U$2:$CC$2,"<="&$D$1,U7:CC7) -> 1 | R7: =K7-Q7 -> 0 | S7: =SUM(U7:XFD7) -> 1 | T7: =SUM(U7:EK7) -> 1 | U7: 1 | DG7: 0 | DH7: 0 | DI7: 0 | DJ7: 0 | DK7: 0 | DL7: 0 | DM7: 0 | DN7: 0 | DO7: 0 | DP7: 0 | DQ7: 0 | DR7: 0 | DS7: 0 | DT7: 0 | DU7: 0 | DV7: 0 | DW7: 0 | DX7: 0 | DY7: 0 | DZ7: 0 | EA7: 0 | EB7: 0 | EC7: 0 | ED7: 0 | EE7: 0 | EF7: 0 | EG7: 0 | EH7: 0 | EI7: 0 | EJ7: 0 | EK7: 0 | EL7: 0 | EM7: 0 | EN7: 0 | EO7: 0 | EP7: 0 | EQ7: 0 | ER7: 0 | ES7: 0 | ET7: 0 | EU7: 0 | EV7: 0 | EW7: 0 | EX7: 0 | EY7: 0 | EZ7: 0 | FA7: 0 | FB7: 0 | FC7: 0 | FD7: 0 | FE7: 0 | FF7: 0 | FG7: 0 | FH7: 0 | FI7: 0 | FJ7: 0 | FK7: 0 | FL7: 0 | FM7: 0 | FN7: 0 | FO7: 0 | FP7: 0 | FQ7: 0 | FR7: 0
C8: 5 | D8: Soil Investigation | E8: 45703 | F8: 45762 | G8: =F8-E8 -> 59 | H8: 45703 | I8: 45776 | J8: Nos. | K8: 79 | L8: 45711 | M8: 45778 | N8: =IF(OR(M8="",L8=""),"",INT(M8-L8+1)) -> 68 | O8: =IFERROR(K8/N8,"-") -> 1.1617647 | P8: =Q8/K8 -> 1 | Q8: =SUMIF($U$2:$CC$2,"<="&$D$1,U8:CC8) -> 79 | R8: =K8-Q8 -> 0 | S8: =SUM(U8:XFD8) -> 79 | T8: =SUM(U8:EK8) -> 79 | U8: 52 | V8: 2 | W8: 2 | X8: 2 | Y8: 2 | Z8: 2 | AA8: 1 | AB8: 1 | AC8: 1 | AD8: 1 | AE8: 1 | AF8: 1 | AH8: 1 | AI8: 1 | AL8: 1 | AM8: 1 | AN8: 1 | AO8: 1 | AP8: 1 | AS8: 1 | AT8: 1 | AU8: 1 | AV8: 1 | DG8: 0 | DH8: 0 | DI8: 0 | DJ8: 0 | DK8: 0 | DL8: 0 | DM8: 0 | DN8: 0 | DO8: 0 | DP8: 0 | DQ8: 0 | DR8: 0 | DS8: 0 | DT8: 0 | DU8: 0 | DV8: 0 | DW8: 0 | DX8: 0 | DY8: 0 | DZ8: 0 | EA8: 0 | EB8: 0 | EC8: 0 | ED8: 0 | EE8: 0 | EF8: 0 | EG8: 0 | EH8: 0 | EI8: 0 | EJ8: 0 | EK8: 0 | EL8: 0 | EM8: 0 | EN8: 0 | EO8: 0 | EP8: 0 | EQ8: 0 | ER8: 0 | ES8: 0 | ET8: 0 | EU8: 0 | EV8: 0 | EW8: 0 | EX8: 0 | EY8: 0 | EZ8: 0 | FA8: 0 | FB8: 0 | FC8: 0 | FD8: 0 | FE8: 0 | FF8: 0 | FG8: 0 | FH8: 0 | FI8: 0 | FJ8: 0 | FK8: 0 | FL8: 0 | FM8: 0 | FN8: 0 | FO8: 0 | FP8: 0 | FQ8: 0 | FR8: 0
C9: 6 | D9: ERT Test | E9: 45749 | F9: 45760 | G9: =F9-E9 -> 11 | H9: 45753 | I9: 45757 | J9: Lot. | K9: 36 | L9: 45753 | M9: 45757 | N9: =IF(OR(M9="",L9=""),"",INT(M9-L9+1)) -> 5 | O9: =IFERROR(K9/N9,"-") -> 7.2 | P9: =IFERROR(SUMIF($U$2:$AT$2,"<="&$D$1,U9:BN9)/K9,"-") -> 1 | Q9: =SUMIF($U$2:$CC$2,"<="&$D$1,U9:CC9) -> 36 | R9: =K9-Q9 -> 0 | S9: =SUM(U9:XFD9) -> 36 | T9: =SUM(U9:EK9) -> 36 | U9: 0 | V9: 0 | Y9: 4 | Z9: 8 | AA9: 8 | AB9: 10 | AC9: 6 | DG9: 0 | DH9: 0 | DI9: 0 | DJ9: 0 | DK9: 0 | DL9: 0 | DM9: 0 | DN9: 0 | DO9: 0 | DP9: 0 | DQ9: 0 | DR9: 0 | DS9: 0 | DT9: 0 | DU9: 0 | DV9: 0 | DW9: 0 | DX9: 0 | DY9: 0 | DZ9: 0 | EA9: 0 | EB9: 0 | EC9: 0 | ED9: 0 | EE9: 0 | EF9: 0 | EG9: 0 | EH9: 0 | EI9: 0 | EJ9: 0 | EK9: 0 | EL9: 0 | EM9: 0 | EN9: 0 | EO9: 0 | EP9: 0 | EQ9: 0 | ER9: 0 | ES9: 0 | ET9: 0 | EU9: 0 | EV9: 0 | EW9: 0 | EX9: 0 | EY9: 0 | EZ9: 0 | FA9: 0 | FB9: 0 | FC9: 0 | FD9: 0 | FE9: 0 | FF9: 0 | FG9: 0 | FH9: 0 | FI9: 0 | FJ9: 0 | FK9: 0 | FL9: 0 | FM9: 0 | FN9: 0 | FO9: 0 | FP9: 0 | FQ9: 0 | FR9: 0
C10: 7 | D10: Test Pile Casting | E10: 45759 | F10: 45773 | G10: =F10-E10 -> 14 | H10: 45806 | I10: 45811 | J10: Lot. | K10: 240 | N10: =IF(OR(M10="",L10=""),"",INT(M10-L10+1)) | O10: =IFERROR(K10/N10,"-") -> - | P10: =Q10/K10 -> 1 | Q10: =S10 -> 240 | R10: =K10-Q10 -> 0 | S10: =SUM(U10:XFD10) -> 240 | T10: =SUM(U10:EK10) -> 240 | U10: 0 | V10: 0 | BZ10: 34 | CA10: 38 | CB10: 36 | CC10: 40 | CG10: 40 | CH10: 32 | CI10: 20 | DG10: 0 | DH10: 0 | DI10: 0 | DJ10: 0 | DK10: 0 | DL10: 0 | DM10: 0 | DN10: 0 | DO10: 0 | DP10: 0 | DQ10: 0 | DR10: 0 | DS10: 0 | DT10: 0 | DU10: 0 | DV10: 0 | DW10: 0 | DX10: 0 | DY10: 0 | DZ10: 0 | EA10: 0 | EB10: 0 | EC10: 0 | ED10: 0 | EE10: 0 | EF10: 0 | EG10: 0 | EH10: 0 | EI10: 0 | EJ10: 0 | EK10: 0 | EL10: 0 | EM10: 0 | EN10: 0 | EO10: 0 | EP10: 0 | EQ10: 0 | ER10: 0 | ES10: 0 | ET10: 0 | EU10: 0 | EV10: 0 | EW10: 0 | EX10: 0 | EY10: 0 | EZ10: 0 | FA10: 0 | FB10: 0 | FC10: 0 | FD10: 0 | FE10: 0 | FF10: 0 | FG10: 0 | FH10: 0 | FI10: 0 | FJ10: 0 | FK10: 0 | FL10: 0 | FM10: 0 | FN10: 0 | FO10: 0 | FP10: 0 | FQ10: 0 | FR10: 0
C11: 8 | D11: Pile Testing | E11: =F10+28 -> 45801 | F11: =E11+G11-1 -> 45807 | G11: 7 | H11: 45824 | I11: =H11+60 -> 45884 | J11: Lot. | K11: 180 | N11: =IF(OR(M11="",L11=""),"",INT(M11-L11+1)) | O11: =IFERROR(K11/N11,"-") -> - | P11: =Q11/K11 -> 1 | Q11: =S11 -> 180 | R11: =K11-Q11 -> 0 | S11: =SUM(U11:XFD11) -> 180 | T11: =SUM(U11:CB11) -> 0 | U11: 0 | V11: 0 | CV11: 3 | CW11: 4 | CX11: 4 | CY11: 4 | CZ11: 0 | DA11: 6 | DB11: 2 | DC11: 2 | DD11: 0 | DE11: 7 | DF11: 4 | DG11: 4 | DH11: 3 | DI11: 6 | DJ11: 0 | DK11: 3 | DL11: 0 | DM11: 1 | DN11: 1 | DO11: 0 | DP11: 0 | DQ11: 0 | DR11: 0 | DS11: 2 | DT11: 7 | DU11: 4 | DV11: 13 | DW11: 3 | DX11: 3 | DY11: 10 | DZ11: 14 | EA11: 8 | EB11: 5 | EC11: 9 | ED11: 2 | EE11: 8 | EF11: 9 | EG11: 0 | EH11: 9 | EI11: 10 | EJ11: 10 | EK11: 0 | EL11: 0 | EM11: 0 | EN11: 0 | EO11: 0 | EP11: 0 | EQ11: 0 | ER11: 0 | ES11: 0 | ET11: 0 | EU11: 0 | EV11: 0 | EW11: 0 | EX11: 0 | EY11: 0 | EZ11: 0 | FA11: 0 | FB11: 0 | FC11: 0 | FD11: 0 | FE11: 0 | FF11: 0 | FG11: 0 | FH11: 0 | FI11: 0 | FJ11: 0 | FK11: 0 | FL11: 0 | FM11: 0 | FN11: 0 | FO11: 0 | FP11: 0 | FQ11: 0 | FR11: 0
B12: Array Yard Civil Works | C12: 9 | D12: Pile Marking | E12: 45824 | F12: 45971 | G12: =F12-E12 -> 147 | H12: 45838 | I12: 45971 | J12: nos. | K12: 116500 | N12: =IF(OR(M12="",L12=""),"",INT(M12-L12+1)) | O12: =IFERROR(K12/N12,"-") -> - | P12: =Q12/K12 -> 0.22858369 | Q12: =S12 -> 26630 | R12: =K12-Q12 -> 89870 | S12: =SUM(U12:XFD12) -> 26630 | T12: =SUM(U12:CB12) -> 0 | DG12: 0 | DH12: 0 | DI12: 0 | DJ12: 0 | DK12: 0 | DL12: 0 | DM12: 0 | DN12: 0 | DO12: 0 | DP12: 0 | DQ12: 0 | DR12: 0 | DS12: 300 | DT12: 430 | DU12: 350 | DV12: 280 | DW12: 293 | DX12: 527 | DY12: 622 | DZ12: 288 | EA12: 141 | EB12: 484 | EC12: 660 | ED12: 898 | EE12: 943 | EF12: 846 | EG12: 167 | EH12: 929 | EI12: 763 | EJ12: 596 | EK12: 976 | EL12: 953 | EM12: 405 | EN12: 335 | EO12: 536 | EP12: 162 | EQ12: 225 | ER12: 108 | ES12: 216 | ET12: 108 | EU12: 18 | EV12: 108 | EW12: 403 | EX12: 0 | EY12: 0 | EZ12: 0 | FA12: 495 | FB12: 463 | FC12: 665 | FD12: 389 | FE12: 593 | FF12: 889 | FG12: 602 | FH12: 952 | FI12: 564 | FJ12: 1095 | FK12: 1034 | FL12: 252 | FM12: 639 | FN12: 782 | FO12: 1077 | FP12: 1082 | FQ12: 564 | FR12: 423
C13: 10 | D13: Pile -Drilling | E13: 45848 | F13: 45976 | G13: =F13-E13 -> 128 | H13: =E13 -> 45848 | I13: =F13 -> 45976 | J13: nos. | K13: 116500 | N13: =IF(OR(M13="",L13=""),"",INT(M13-L13+1)) | O13: =IFERROR(K13/N13,"-") -> - | P13: =Q13/K13 -> 0.15788841 | Q13: =S13 -> 18394 | R13: =K13-Q13 -> 98106 | S13: =SUM(U13:XFD13) -> 18394 | T13: =SUM(U13:CB13) -> 0 | DG13: 0 | DH13: 0 | DI13: 0 | DJ13: 0 | DK13: 0 | DL13: 0 | DM13: 0 | DN13: 0 | DO13: 0 | DP13: 0 | DQ13: 0 | DR13: 0 | DS13: 0 | DT13: 0 | DU13: 0 | DV13: 0 | DW13: 263 | DX13: 640 | DY13: 580 | DZ13: 583 | EA13: 301 | EB13: 670 | EC13: 105 | ED13: 245 | EE13: 574 | EF13: 15 | EG13: 0 | EH13: 0 | EI13: 0 | EJ13: 37 | EK13: 356 | EL13: 325 | EM13: 0 | EN13: 0 | EO13: 110 | EP13: 0 | EQ13: 0 | ER13: 0 | ES13: 0 | ET13: 44 | EU13: 0 | EV13: 401 | EW13: 267 | EX13: 876 | EY13: 260 | EZ13: 0 | FA13: 467 | FB13: 238 | FC13: 825 | FD13: 402 | FE13: 570 | FF13: 704 | FG13: 854 | FH13: 1065 | FI13: 896 | FJ13: 1008 | FK13: 1144 | FL13: 458 | FM13: 1314 | FN13: 534 | FO13: 243 | FP13: 235 | FQ13: 180 | FR13: 605
C14: 11 | D14: Pile- Casting | E14: 45858 | F14: 45986 | G14: =F14-E14 -> 128 | H14: =E14 -> 45858 | I14: =F14 -> 45986 | J14: nos. | K14: 116500 | N14: =IF(OR(M14="",L14=""),"",INT(M14-L14+1)) | O14: =IFERROR(K14/N14,"-") -> - | P14: =IFERROR(SUMIF($U$2:$AT$2,"<="&$D$1,U14:BN14)/K14,"-") -> 0 | Q14: =S14 -> 14362 | R14: =K14-Q14 -> 102138 | S14: =SUM(U14:XFD14) -> 14362 | T14: =SUM(U14:CB14) -> 0 | DG14: 0 | DH14: 0 | DI14: 0 | DJ14: 0 | DK14: 0 | DL14: 0 | DM14: 0 | DN14: 0 | DO14: 0 | DP14: 0 | DQ14: 0 | DR14: 0 | DS14: 0 | DT14: 0 | DU14: 0 | DV14: 0 | DW14: 0 | DX14: 0 | DY14: 0 | DZ14: 35 | EA14: 0 | EB14: 0 | EC14: 0 | ED14: 27 | EE14: 31 | EF14: 86 | EG14: 29 | EH14: 103 | EI14: 106 | EJ14: 92 | EK14: 56 | EL14: 61 | EM14: 109 | EN14: 143 | EO14: 0 | EP14: 151 | EQ14: 156 | ER14: 188 | ES14: 250 | ET14: 249 | EU14: 379 | EV14: 359 | EW14: 347 | EX14: 451 | EY14: 282 | EZ14: 0 | FA14: 509 | FB14: 268 | FC14: 166 | FD14: 510 | FE14: 749 | FF14: 750 | FG14: 862 | FH14: 790 | FI14: 924 | FJ14: 664 | FK14: 579 | FL14: 397 | FM14: 1127 | FN14: 682 | FO14: 471 | FP14: 385 | FQ14: 339 | FR14: 500
C15: 12 | D15: Pile-Capping | E15: 45863 | F15: 45995 | G15: =F15-E15 -> 132 | H15: =E15 -> 45863 | I15: =F15 -> 45995 | J15: nos. | K15: 116500 | N15: =IF(OR(M15="",L15=""),"",INT(M15-L15+1)) | O15: =IFERROR(K15/N15,"-") -> - | P15: =IFERROR(SUMIF($U$2:$AT$2,"<="&$D$1,U15:BN15)/K15,"-") -> 0 | Q15: =S15 -> 1472 | R15: =K15-Q15 -> 115028 | S15: =SUM(U15:XFD15) -> 1472 | T15: =SUM(U15:CB15) -> 0 | DG15: 0 | DH15: 0 | DI15: 0 | DJ15: 0 | DK15: 0 | DL15: 0 | DM15: 0 | DN15: 0 | DO15: 0 | DP15: 0 | DQ15: 0 | DR15: 0 | DS15: 0 | DT15: 0 | DU15: 0 | DV15: 0 | DW15: 0 | DX15: 0 | DY15: 0 | DZ15: 0 | EA15: 0 | EB15: 0 | EC15: 0 | ED15: 0 | EE15: 0 | EF15: 0 | EG15: 0 | EH15: 0 | EI15: 0 | EJ15: 0 | EK15: 0 | EL15: 0 | EM15: 0 | EN15: 0 | EO15: 0 | EP15: 0 | EQ15: 0 | ER15: 0 | ES15: 0 | ET15: 0 | EU15: 0 | EV15: 0 | EW15: 0 | EX15: 0 | EY15: 0 | EZ15: 0 | FA15: 0 | FB15: 0 | FC15: 0 | FD15: 22 | FE15: 0 | FF15: 0 | FG15: 0 | FH15: 0 | FI15: 0 | FJ15: 132 | FK15: 129 | FL15: 0 | FM15: 0 | FN15: 0 | FO15: 93 | FP15: 349 | FQ15: 432 | FR15: 315
B16: ICR Civil Works | C16: 13 | D16: ICR Marking & Excavation | E16: 45821 | F16: 45923 | G16: =F16-E16 -> 102 | H16: =E16 -> 45821 | I16: =F16 -> 45923 | J16: Block | K16: 26 | N16: =IF(OR(M16="",L16=""),"",INT(M16-L16+1)) | O16: =IFERROR(K16/N16,"-") -> - | P16: =IFERROR(SUMIF($U$2:$AT$2,"<="&$D$1,U16:BN16)/K16,"-") -> 0 | Q16: =S16 -> 3 | R16: =K16-Q16 -> 23 | S16: =SUM(U16:XFD16) -> 3 | T16: =SUM(U16:CB16) -> 0 | DG16: 0 | DH16: 0 | DI16: 0 | DJ16: 0 | DK16: 0 | DL16: 0 | DM16: 0 | DN16: 0 | DO16: 0 | DP16: 0 | DQ16: 0 | DR16: 0 | DS16: 0 | DT16: 0 | DU16: 0 | DV16: 0 | DW16: 0 | DX16: 0 | DY16: 0 | DZ16: 0 | EA16: 0 | EB16: 0 | EC16: 0 | ED16: 0 | EE16: 0 | EF16: 0 | EG16: 0 | EH16: 0 | EI16: 0 | EJ16: 0 | EK16: 0 | EL16: 0 | EM16: 0 | EN16: 0 | EO16: 0 | EP16: 0 | EQ16: 0 | ER16: 0 | ES16: 0 | ET16: 0 | EU16: 0 | EV16: 0 | EW16: 0 | EX16: 0 | EY16: 0 | EZ16: 0 | FA16: 0 | FB16: 0 | FC16: 0 | FD16: 3 | FE16: 0 | FF16: 0 | FG16: 0 | FH16: 0 | FI16: 0 | FJ16: 0 | FK16: 0 | FL16: 0 | FM16: 0 | FN16: 0 | FO16: 0 | FP16: 0 | FQ16: 0 | FR16: 0
C17: 14 | D17: ICR PCC | E17: 45840 | F17: =F16+6 -> 45929 | G17: =F17-E17 -> 89 | H17: =E17 -> 45840 | I17: =F17 -> 45929 | J17: Block | K17: 26 | N17: =IF(OR(M17="",L17=""),"",INT(M17-L17+1)) | O17: =IFERROR(K17/N17,"-") -> - | P17: =IFERROR(SUMIF($U$2:$AT$2,"<="&$D$1,U17:BN17)/K17,"-") -> 0 | Q17: =S17 -> 0 | R17: =K17-Q17 -> 26 | S17: =SUM(U17:XFD17) -> 0 | T17: =SUM(U17:CB17) -> 0 | DG17: 0 | DH17: 0 | DI17: 0 | DJ17: 0 | DK17: 0 | DL17: 0 | DM17: 0 | DN17: 0 | DO17: 0 | DP17: 0 | DQ17: 0 | DR17: 0 | DS17: 0 | DT17: 0 | DU17: 0 | DV17: 0 | DW17: 0 | DX17: 0 | DY17: 0 | DZ17: 0 | EA17: 0 | EB17: 0 | EC17: 0 | ED17: 0 | EE17: 0 | EF17: 0 | EG17: 0 | EH17: 0 | EI17: 0 | EJ17: 0 | EK17: 0 | EL17: 0 | EM17: 0 | EN17: 0 | EO17: 0 | EP17: 0 | EQ17: 0 | ER17: 0 | ES17: 0 | ET17: 0 | EU17: 0 | EV17: 0 | EW17: 0 | EX17: 0 | EY17: 0 | EZ17: 0 | FA17: 0 | FB17: 0 | FC17: 0 | FD17: 0 | FE17: 0 | FF17: 0 | FG17: 0 | FH17: 0 | FI17: 0 | FJ17: 0 | FK17: 0 | FL17: 0 | FM17: 0 | FN17: 0 | FO17: 0 | FP17: 0 | FQ17: 0 | FR17: 0
C18: 15 | D18: ICR Footing Casting | E18: =E17+7 -> 45847 | F18: =F17+7 -> 45936 | G18: =F18-E18 -> 89 | H18: =E18 -> 45847 | I18: =F18 -> 45936 | J18: Block | K18: 26 | N18: =IF(OR(M18="",L18=""),"",INT(M18-L18+1)) | O18: =IFERROR(K18/N18,"-") -> - | P18: =IFERROR(SUMIF($U$2:$AT$2,"<="&$D$1,U18:BN18)/K18,"-") -> 0 | Q18: =S18 -> 0 | R18: =K18-Q18 -> 26 | S18: =SUM(U18:XFD18) -> 0 | T18: =SUM(U18:CB18) -> 0 | DG18: 0 | DH18: 0 | DI18: 0 | DJ18: 0 | DK18: 0 | DL18: 0 | DM18: 0 | DN18: 0 | DO18: 0 | DP18: 0 | DQ18: 0 | DR18: 0 | DS18: 0 | DT18: 0 | DU18: 0 | DV18: 0 | DW18: 0 | DX18: 0 | DY18: 0 | DZ18: 0 | EA18: 0 | EB18: 0 | EC18: 0 | ED18: 0 | EE18: 0 | EF18: 0 | EG18: 0 | EH18: 0 | EI18: 0 | EJ18: 0 | EK18: 0 | EL18: 0 | EM18: 0 | EN18: 0 | EO18: 0 | EP18: 0 | EQ18: 0 | ER18: 0 | ES18: 0 | ET18: 0 | EU18: 0 | EV18: 0 | EW18: 0 | EX18: 0 | EY18: 0 | EZ18: 0 | FA18: 0 | FB18: 0 | FC18: 0 | FD18: 0 | FE18: 0 | FF18: 0 | FG18: 0 | FH18: 0 | FI18: 0 | FJ18: 0 | FK18: 0 | FL18: 0 | FM18: 0 | FN18: 0 | FO18: 0 | FP18: 0 | FQ18: 0 | FR18: 0
C19: 16 | D19: ICR Column Casting | E19: =E18+15 -> 45862 | F19: =F18+15 -> 45951 | G19: =F19-E19 -> 89 | H19: =E19 -> 45862 | I19: =F19 -> 45951 | J19: Block | K19: 26 | N19: =IF(OR(M19="",L19=""),"",INT(M19-L19+1)) | O19: =IFERROR(K19/N19,"-") -> - | P19: =IFERROR(SUMIF($U$2:$AT$2,"<="&$D$1,U19:BN19)/K19,"-") -> 0 | Q19: =S19 -> 0 | R19: =K19-Q19 -> 26 | S19: =SUM(U19:XFD19) -> 0 | T19: =SUM(U19:CB19) -> 0 | DG19: 0 | DH19: 0 | DI19: 0 | DJ19: 0 | DK19: 0 | DL19: 0 | DM19: 0 | DN19: 0 | DO19: 0 | DP19: 0 | DQ19: 0 | DR19: 0 | DS19: 0 | DT19: 0 | DU19: 0 | DV19: 0 | DW19: 0 | DX19: 0 | DY19: 0 | DZ19: 0 | EA19: 0 | EB19: 0 | EC19: 0 | ED19: 0 | EE19: 0 | EF19: 0 | EG19: 0 | EH19: 0 | EI19: 0 | EJ19: 0 | EK19: 0 | EL19: 0 | EM19: 0 | EN19: 0 | EO19: 0 | EP19: 0 | EQ19: 0 | ER19: 0 | ES19: 0 | ET19: 0 | EU19: 0 | EV19: 0 | EW19: 0 | EX19: 0 | EY19: 0 | EZ19: 0 | FA19: 0 | FB19: 0 | FC19: 0 | FD19: 0 | FE19: 0 | FF19: 0 | FG19: 0 | FH19: 0 | FI19: 0 | FJ19: 0 | FK19: 0 | FL19: 0 | FM19: 0 | FN19: 0 | FO19: 0 | FP19: 0 | FQ19: 0 | FR19: 0
C20: 17 | D20: ICR Beam Slab Casting | E20: =E19+21 -> 45883 | F20: =F19+21 -> 45972 | G20: =F20-E20 -> 89 | H20: =E20 -> 45883 | I20: =F20 -> 45972 | J20: Block | K20: 26 | N20: =IF(OR(M20="",L20=""),"",INT(M20-L20+1)) | O20: =IFERROR(K20/N20,"-") -> - | P20: =IFERROR(SUMIF($U$2:$AT$2,"<="&$D$1,U20:BN20)/K20,"-") -> 0 | Q20: =S20 -> 0 | R20: =K20-Q20 -> 26 | S20: =SUM(U20:XFD20) -> 0 | T20: =SUM(U20:CB20) -> 0 | DG20: 0 | DH20: 0 | DI20: 0 | DJ20: 0 | DK20: 0 | DL20: 0 | DM20: 0 | DN20: 0 | DO20: 0 | DP20: 0 | DQ20: 0 | DR20: 0 | DS20: 0 | DT20: 0 | DU20: 0 | DV20: 0 | DW20: 0 | DX20: 0 | DY20: 0 | DZ20: 0 | EA20: 0 | EB20: 0 | EC20: 0 | ED20: 0 | EE20: 0 | EF20: 0 | EG20: 0 | EH20: 0 | EI20: 0 | EJ20: 0 | EK20: 0 | EL20: 0 | EM20: 0 | EN20: 0 | EO20: 0 | EP20: 0 | EQ20: 0 | ER20: 0 | ES20: 0 | ET20: 0 | EU20: 0 | EV20: 0 | EW20: 0 | EX20: 0 | EY20: 0 | EZ20: 0 | FA20: 0 | FB20: 0 | FC20: 0 | FD20: 0 | FE20: 0 | FF20: 0 | FG20: 0 | FH20: 0 | FI20: 0 | FJ20: 0 | FK20: 0 | FL20: 0 | FM20: 0 | FN20: 0 | FO20: 0 | FP20: 0 | FQ20: 0 | FR20: 0
C21: 18 | D21: Transformer Marking & Excavation | E21: 45838 | F21: 45925 | G21: =F21-E21 -> 87 | H21: =E21 -> 45838 | I21: =F21 -> 45925 | J21: Block | K21: 26 | N21: =IF(OR(M21="",L21=""),"",INT(M21-L21+1)) | O21: =IFERROR(K21/N21,"-") -> - | P21: =IFERROR(SUMIF($U$2:$AT$2,"<="&$D$1,U21:BN21)/K21,"-") -> 0 | Q21: =S21 -> 0 | R21: =K21-Q21 -> 26 | S21: =SUM(U21:XFD21) -> 0 | T21: =SUM(U21:CB21) -> 0 | DG21: 0 | DH21: 0 | DI21: 0 | DJ21: 0 | DK21: 0 | DL21: 0 | DM21: 0 | DN21: 0 | DO21: 0 | DP21: 0 | DQ21: 0 | DR21: 0 | DS21: 0 | DT21: 0 | DU21: 0 | DV21: 0 | DW21: 0 | DX21: 0 | DY21: 0 | DZ21: 0 | EA21: 0 | EB21: 0 | EC21: 0 | ED21: 0 | EE21: 0 | EF21: 0 | EG21: 0 | EH21: 0 | EI21: 0 | EJ21: 0 | EK21: 0 | EL21: 0 | EM21: 0 | EN21: 0 | EO21: 0 | EP21: 0 | EQ21: 0 | ER21: 0 | ES21: 0 | ET21: 0 | EU21: 0 | EV21: 0 | EW21: 0 | EX21: 0 | EY21: 0 | EZ21: 0 | FA21: 0 | FB21: 0 | FC21: 0 | FD21: 0 | FE21: 0 | FF21: 0 | FG21: 0 | FH21: 0 | FI21: 0 | FJ21: 0 | FK21: 0 | FL21: 0 | FM21: 0 | FN21: 0 | FO21: 0 | FP21: 0 | FQ21: 0 | FR21: 0
