Workbook
Name \0: #REF!
Name \a: #REF!
Name \b: #REF!
Name \c: #REF!
Name \d: #REF!
Name \e: #REF!
Name \f: #REF!
Name \m: #REF!
Name \p: #REF!
Name \v: #REF!
Name ___INDEX_SHEET___ASAP_Utilities: #REF!
Name _0: #N/A
Name _05通知ﾃﾞｰﾀ: #REF!
Name _8Estimate: #REF!
Name _9Plan: #REF!
Name _ACT2: #N/A
Name _am67000: #REF!
Name _am68000: #REF!
Name _am70000: #REF!
Name _ATT2: #REF!
Name _b: #N/A
Name _B90776: #REF!
Name _bal1: #REF!
Name _bom1: #REF!
Name _BUD0001: #REF!
Name _C3200_BL: #REF!
Name _C3200_order: #REF!
Name _C3200_sales: #REF!
Name _CUT1: #REF!
Name _d1: #REF!
Name _d2: #N/A
Name _DAS2: #REF!
Name _DAT1: #REF!
Name _DAT10: #REF!
Name _DAT11: #REF!
Name _DAT12: #REF!
Name _DAT13: #REF!
Name _DAT14: #REF!
Name _DAT15: #REF!
Name _DAT16: #REF!
Name _DAT17: #REF!
Name _DAT18: #REF!
Name _DAT19: #REF!
Name _DAT2: #REF!
Name _DAT20: #REF!
Name _DAT21: #REF!
Name _DAT22: #REF!
Name _DAT23: #REF!
Name _DAT24: #REF!
Name _DAT25: #REF!
Name _DAT26: #REF!
Name _DAT27: #REF!
Name _DAT28: #REF!
Name _DAT29: #REF!
Name _DAT3: #REF!
Name _DAT30: #REF!
Name _DAT31: #REF!
Name _DAT32: #REF!
Name _DAT33: #REF!
Name _DAT34: #REF!

Sheet Project Dashbord
C2: Project Progress Report | L2: =+"PROGRESS ON: "&TEXT(TODAY()-1,"DD-MMM-YYY") -> PROGRESS ON: 11-Sep-2025
C3: Project Name : | E3: 25 MW (AC) Solar PV Power Plant (50 MWp DC) with 20 MW / 50 MWh Battery Energy Storage System at Taru, Leh, UT of Ladakh, India
C4: Client : | E4: Solar Energy Corporation of India Ltd
C5: SPV : | E5: Prozeal Green Energy Limited
C6: Project Start Date | E6: 45616
C7: Project COD | E7: =E6+(36*30) -> 46696
C8: Sr. No | D8: Description | E8: Scope | F8: UOM | G8: Completed | H8: Balance | I8: Actual Progress Front Wise (in %) | J8: Scope Weightage % | K8: Progress as per weightage (in %) | L8: Overall Project Completion Status
C9: 1 | D9: Plant Boundary Fencing | E9: =2276*2.5 -> 5690 | F9: RM | G9: ='Civil Progress'!F5 -> 4889.5 | H9: =E9-G9 -> 800.5 | I9: =ROUND(G9/E9,3) -> 0.859 | J9: =60%*2% -> 0.012 | K9: =ROUND(I9*J9,3) -> 0.01
C10: 2 | D10: MCR Civil Work | E10: 1 | F10: Lot | G10: ='Progress Abstract'!G39 -> 0.23076923 | H10: =E10-G10 -> 0.76923077 | I10: =ROUND(G10/E10,3) -> 0.231 | J10: =60%*15% -> 0.09 | K10: =ROUND(I10*J10,3) -> 0.021
C11: 3 | D11: MMS Pilling | E11: 1 | F11: Lot | G11: ='Progress Abstract'!G59 -> 0.050804094 | H11: =E11-G11 -> 0.94919591 | I11: =ROUND(G11/E11,3) -> 0.051 | J11: =60%*38% -> 0.228 | K11: =ROUND(I11*J11,3) -> 0.012
C12: 4 | D12: Switch Yard | E12: 1 | F12: Lot | G12: 0 | H12: =E12-G12 -> 1 | I12: =ROUND(G12/E12,3) -> 0 | J12: =60%*15% -> 0.09 | K12: =ROUND(I12*J12,3) -> 0
C13: 5 | D13: IDT - Solar | E13: 4 | F13: Lot | G13: ='Civil Progress'!F71 -> 3 | H13: =E13-G13 -> 1 | I13: =ROUND(G13/E13,3) -> 0.75 | J13: =60%*2% -> 0.012 | K13: =ROUND(I13*J13,3) -> 0.009
C14: 6 | D14: IDT - BESS | E14: 5 | F14: Lot | G14: ='Civil Progress'!F96 -> 0 | H14: =E14-G14 -> 5 | I14: =ROUND(G14/E14,3) -> 0 | J14: =60%*2% -> 0.012 | K14: =ROUND(I14*J14,3) -> 0
C15: 7 | D15: BESS-Civil | E15: 1 | F15: Lot | G15: ='Progress Abstract'!G79 -> 0.15 | H15: =E15-G15 -> 0.85 | I15: =ROUND(G15/E15,3) -> 0.15 | J15: =60%*6% -> 0.036 | K15: =ROUND(I15*J15,3) -> 0.005
C16: 8 | D16: LCR | E16: 4 | F16: Lot | G16: 0 | H16: =E16-G16 -> 4 | I16: =ROUND(G16/E16,3) -> 0 | J16: =60%*4% -> 0.024 | K16: =ROUND(I16*J16,3) -> 0
C17: 9 | D17: MMS Structure | E17: 3934 | F17: Table | G17: 0 | H17: =E17-G17 -> 3934 | I17: =ROUND(G17/E17,3) -> 0 | J17: =60%*12% -> 0.072 | K17: =ROUND(I17*J17,3) -> 0
C18: 10 | D18: Road | E18: 3000 | F18: Mtr. | G18: 0 | H18: =E18-G18 -> 3000 | I18: =ROUND(G18/E18,3) -> 0 | J18: =60%*2% -> 0.012 | K18: =ROUND(I18*J18,3) -> 0
C19: 11 | D19: Drain | E19: 1000 | F19: Mtr. | G19: 0 | H19: =E19-G19 -> 1000 | I19: =ROUND(G19/E19,3) -> 0 | J19: =60%*1% -> 0.006 | K19: =ROUND(I19*J19,3) -> 0
C20: 12 | D20: Misc Work | E20: 1 | F20: Lot | G20: 0.2 | H20: =E20-G20 -> 0.8 | I20: =ROUND(G20/E20,3) -> 0.2 | J20: =60%*1% -> 0.006 | K20: =ROUND(I20*J20,3) -> 0.001
C21: 13 | D21: AC-Electrical | E21: 1 | F21: Lot | G21: 0 | H21: =E21-G21 -> 1 | I21: =ROUND(G21/E21,3) -> 0 | J21: =37%*20% -> 0.074 | K21: =ROUND(I21*J21,3) -> 0
C22: 14 | D22: DC- Electrical | E22: 1 | F22: Lot | G22: 0 | H22: =E22-G22 -> 1 | I22: =ROUND(G22/E22,3) -> 0 | J22: =37%*20% -> 0.074 | K22: =ROUND(I22*J22,3) -> 0
C23: 15 | D23: Switchtard - Electrical | E23: 1 | F23: Lot | G23: 0 | H23: =E23-G23 -> 1 | I23: =ROUND(G23/E23,3) -> 0 | J23: =37%*20% -> 0.074 | K23: =ROUND(I23*J23,3) -> 0
C24: 16 | D24: MCR - Electrical | E24: 1 | F24: Lot | G24: 0 | H24: =E24-G24 -> 1 | I24: =ROUND(G24/E24,3) -> 0 | J24: =37%*10% -> 0.037 | K24: =ROUND(I24*J24,3) -> 0
C25: 17 | D25: Module Erection | E25: =3934*24 -> 94416 | F25: Nos | G25: 0 | H25: =E25-G25 -> 94416 | I25: =ROUND(G25/E25,3) -> 0 | J25: =37%*20% -> 0.074 | K25: =ROUND(I25*J25,3) -> 0
C26: 18 | D26: BESS - Electrical | E26: 1 | F26: Lot | G26: 0 | H26: =E26-G26 -> 1 | I26: =ROUND(G26/E26,3) -> 0 | J26: =37%*10% -> 0.037 | K26: =ROUND(I26*J26,3) -> 0
C27: 19 | D27: Transmission Line | E27: 1 | F27: Lot | G27: 0 | H27: =E27-G27 -> 1 | I27: =ROUND(G27/E27,3) -> 0 | J27: 0.01 | K27: =ROUND(I27*J27,3) -> 0
C28: 20 | D28: Project Charging & Commisioning | E28: 1 | F28: Lot | G28: 0 | H28: =E28-G28 -> 1 | I28: =ROUND(G28/E28,3) -> 0 | J28: 0.02 | K28: =ROUND(I28*J28,3) -> 0
C29: Overall Project Completion Status | J29: =SUM(J9:J28) -> 1 | K29: =SUM(K9:K28) -> 0.058

Sheet MDL Status
C3: Project Drawings Approval Report | T3: =+"PROGRESS ON: "&TEXT(TODAY()-1,"DD-MMM-YYY") -> PROGRESS ON: 11-Sep-2025
C5: Client Name | D5: =[1]Coverpage!D4 -> Solar Energy Corporation of India Ltd | R5: Total Documents | S5: Submitted | T5: Approved | U5: Sub. Approved | V5: Commented | W5: Pending for Submission
C6: EPC Contractor | D6: Prozeal Green Energy Limited | R6: =R7/$R$7 -> 1 | S6: =S7/$R$7 -> 0.46524064 | T6: =T7/$R$7 -> 0.16042781 | U6: =U7/$R$7 -> 0.080213904 | V6: =V7/$R$7 -> 0.12834225 | W6: =W7/$R$7 -> 0.53475936
C7: Project Name | D7: =[1]Coverpage!D5 -> 25 MW (AC) Solar PV Power Plant (50 MWp DC) with 20 MW / 50 MWh Battery Energy Storage System at Taru, Leh, UT of Ladakh, India | R7: =D28 -> 187 | S7: =M28 -> 87 | T7: =I28+J28 -> 30 | U7: =H28 -> 15 | V7: =F28 -> 24 | W7: =L28 -> 100
C8: Project Capacity | D8: 25 MW (AC) Solar PV Power Plant (50 MWp DC) with 20 MW / 50 MWh Battery Energy Storage System | R8: Only apporval category
C9: Particulars | D9: Total Documents | N9: Remaining Documents | O9: Total Received (%) | P9: Engineering completion (%)
E10: VOID | F10: UNDER EPC | G10: UNDER OE | H10: SUB. APPROVED | I10: APPROVED | J10: NOTED FOR INFORMATION | K10: NOT APPROVED | L10: PENDING | M10: Total Sub
C11: I. Review Engineering Electrical
C12: =[1]MDL!A11 -> A.Basic Engineering | D12: =SUM(E12:L12) -> 11 | E12: 0 | F12: 3 | G12: 2 | H12: 0 | I12: 2 | J12: 4 | K12: 0 | L12: 0 | M12: =SUM(E12:K12) -> 11 | N12: =(D12-E12)-M12 -> 0 | O12: =((D12-E12)-N12)/(D12-E12) -> 1 | P12: =(((F12+G12)*$E$18+H12*$E$19+I12*$E$20+J12*$E$21)/(D12-E12)) -> 0
C13: =[1]MDL!A23 -> B.Major Electrical Equipments (GTP, GA, Type Test Reports and QAP) | D13: =SUM(E13:L13) -> 4 | E13: 0 | F13: 1 | G13: 0 | H13: 0 | I13: 0 | J13: 0 | K13: 0 | L13: 3 | M13: =SUM(E13:K13) -> 1 | N13: =(D13-E13)-M13 -> 3 | O13: =((D13-E13)-N13)/(D13-E13) -> 0.25 | P13: =(((F13+G13)*$E$18+H13*$E$19+I13*$E$20+J13*$E$21)/(D13-E13)) -> 0
C14: =[1]MDL!A27 -> C.Cable sizing documents | D14: =SUM(E14:L14) -> 4 | E14: 0 | F14: 0 | G14: 0 | H14: 1 | I14: 3 | J14: 0 | K14: 0 | L14: 0 | M14: =SUM(E14:K14) -> 4 | N14: =(D14-E14)-M14 -> 0 | O14: =((D14-E14)-N14)/(D14-E14) -> 1 | P14: =(((F14+G14)*$E$18+H14*$E$19+I14*$E$20+J14*$E$21)/(D14-E14)) -> 0
C15: =[1]MDL!A32 -> D.Cable GTPs, Type Test Reports and QAP | D15: =SUM(E15:L15) -> 7 | E15: 0 | F15: 0 | G15: 1 | H15: 1 | I15: 2 | J15: 0 | K15: 0 | L15: 3 | M15: =SUM(E15:K15) -> 4 | N15: =(D15-E15)-M15 -> 3 | O15: =((D15-E15)-N15)/(D15-E15) -> 0.57142857 | P15: =(((F15+G15)*$E$18+H15*$E$19+I15*$E$20+J15*$E$21)/(D15-E15)) -> 0
C16: =[1]MDL!A40 -> E.Battery Energy Storage System (BESS) | D16: =SUM(E16:L16) -> 17 | E16: 0 | F16: 2 | G16: 4 | H16: 0 | I16: 4 | J16: 3 | K16: 0 | L16: 4 | M16: =SUM(E16:K16) -> 13 | N16: =(D16-E16)-M16 -> 4 | O16: =((D16-E16)-N16)/(D16-E16) -> 0.76470588 | P16: =(((F16+G16)*$E$18+H16*$E$19+I16*$E$20+J16*$E$21)/(D16-E16)) -> 0
C17: =[1]MDL!A59 -> F.Module Mounting structure | D17: =SUM(E17:L17) -> 12 | E17: 0 | F17: 1 | G17: 0 | H17: 7 | I17: 0 | J17: 4 | K17: 0 | L17: 0 | M17: =SUM(E17:K17) -> 12 | N17: =(D17-E17)-M17 -> 0 | O17: =((D17-E17)-N17)/(D17-E17) -> 1 | P17: =(((F17+G17)*$E$18+H17*$E$19+I17*$E$20+J17*$E$21)/(D17-E17)) -> 0
C18: =[1]MDL!A67 -> G.MCR Building | D18: =SUM(E18:L18) -> 11 | E18: 0 | F18: 1 | G18: 1 | H18: 1 | I18: 4 | J18: 0 | K18: 0 | L18: 4 | M18: =SUM(E18:K18) -> 7 | N18: =(D18-E18)-M18 -> 4 | O18: =((D18-E18)-N18)/(D18-E18) -> 0.63636364 | P18: =(((F18+G18)*$E$18+H18*$E$19+I18*$E$20+J18*$E$21)/(D18-E18)) -> 0
C19: =[1]MDL!A79 -> H.Open Plinth for LCR Equipment | D19: =SUM(E19:L19) -> 6 | E19: 0 | F19: 0 | G19: 0 | H19: 0 | I19: 0 | J19: 0 | K19: 0 | L19: 6 | M19: =SUM(E19:K19) -> 0 | N19: =(D19-E19)-M19 -> 6 | O19: =((D19-E19)-N19)/(D19-E19) -> 0 | P19: =(((F19+G19)*$E$18+H19*$E$19+I19*$E$20+J19*$E$21)/(D19-E19)) -> 0
C20: =[1]MDL!A84 -> I.BESS Foundation | D20: =SUM(E20:L20) -> 7 | E20: 0 | F20: 2 | G20: 0 | H20: 2 | I20: 0 | J20: 0 | K20: 0 | L20: 3 | M20: =SUM(E20:K20) -> 4 | N20: =(D20-E20)-M20 -> 3 | O20: =((D20-E20)-N20)/(D20-E20) -> 0.57142857 | P20: =(((F20+G20)*$E$18+H20*$E$19+I20*$E$20+J20*$E$21)/(D20-E20)) -> 0
C21: =[1]MDL!A92 -> J.Equipment foundations | D21: =SUM(E21:L21) -> 4 | E21: 0 | F21: 0 | G21: 0 | H21: 0 | I21: 0 | J21: 0 | K21: 0 | L21: 4 | M21: =SUM(E21:K21) -> 0 | N21: =(D21-E21)-M21 -> 4 | O21: =((D21-E21)-N21)/(D21-E21) -> 0 | P21: =(((F21+G21)*$E$18+H21*$E$19+I21*$E$20+J21*$E$21)/(D21-E21)) -> 0
C22: =[1]MDL!A97 -> K.Layout, Ancillary Equipment GTP and DBR | D22: =SUM(E22:L22) -> 24 | E22: 0 | F22: 1 | G22: 1 | H22: 1 | I22: 1 | J22: 0 | K22: 0 | L22: 20 | M22: =SUM(E22:K22) -> 4 | N22: =(D22-E22)-M22 -> 20 | O22: =((D22-E22)-N22)/(D22-E22) -> 0.16666667 | P22: =(((F22+G22)*$E$18+H22*$E$19+I22*$E$20+J22*$E$21)/(D22-E22)) -> 0
C23: =[1]MDL!A122 -> M.Ancillary Systems | D23: =SUM(E23:L23) -> 10 | E23: 0 | F23: 0 | G23: 0 | H23: 0 | I23: 0 | J23: 0 | K23: 0 | L23: 10 | M23: =SUM(E23:K23) -> 0 | N23: =(D23-E23)-M23 -> 10 | O23: =((D23-E23)-N23)/(D23-E23) -> 0 | P23: =(((F23+G23)*$E$18+H23*$E$19+I23*$E$20+J23*$E$21)/(D23-E23)) -> 0
C24: =[1]MDL!A133 -> N.Cable Schedules | D24: =SUM(E24:L24) -> 7 | E24: 0 | F24: 0 | G24: 0 | H24: 0 | I24: 0 | J24: 0 | K24: 0 | L24: 7 | M24: =SUM(E24:K24) -> 0 | N24: =(D24-E24)-M24 -> 7 | O24: =((D24-E24)-N24)/(D24-E24) -> 0 | P24: =(((F24+G24)*$E$18+H24*$E$19+I24*$E$20+J24*$E$21)/(D24-E24)) -> 0
C25: =[1]MDL!A142 -> O.System Drawings and Layouts | D25: =SUM(E25:L25) -> 14 | E25: 0 | F25: 2 | G25: 1 | H25: 2 | I25: 2 | J25: 0 | K25: 0 | L25: 7 | M25: =SUM(E25:K25) -> 7 | N25: =(D25-E25)-M25 -> 7 | O25: =((D25-E25)-N25)/(D25-E25) -> 0.5 | P25: =(((F25+G25)*$E$18+H25*$E$19+I25*$E$20+J25*$E$21)/(D25-E25)) -> 0
C26: =[1]MDL!A157 -> P.Equipment GTPs, Type test reports and Inspection Reports | D26: =SUM(E26:L26) -> 24 | E26: 0 | F26: 2 | G26: 6 | H26: 0 | I26: 1 | J26: 0 | K26: 0 | L26: 15 | M26: =SUM(E26:K26) -> 9 | N26: =(D26-E26)-M26 -> 15 | O26: =((D26-E26)-N26)/(D26-E26) -> 0.375 | P26: =(((F26+G26)*$E$18+H26*$E$19+I26*$E$20+J26*$E$21)/(D26-E26)) -> 0
C27: =[1]MDL!A182 -> Q.Equipment Foundation Drawings and Cable Schedules | D27: =SUM(E27:L27) -> 25 | E27: 0 | F27: 9 | G27: 2 | H27: 0 | I27: 0 | J27: 0 | K27: 0 | L27: 14 | M27: =SUM(E27:K27) -> 11 | N27: =(D27-E27)-M27 -> 14 | O27: =((D27-E27)-N27)/(D27-E27) -> 0.44 | P27: =(((F27+G27)*$E$18+H27*$E$19+I27*$E$20+J27*$E$21)/(D27-E27)) -> 0
C28: Total documents | D28: =SUM(D12:D27)-E28 -> 187 | E28: =SUM(E12:E21) -> 0 | F28: =SUM(F12:F27) -> 24 | G28: =SUM(G12:G27) -> 18 | H28: =SUM(H12:H27) -> 15 | I28: =SUM(I12:I27) -> 19 | J28: =SUM(J12:J27) -> 11 | K28: =SUM(K12:K27) -> 0 | L28: =SUM(L12:L27) -> 100 | M28: =SUM(M12:M27) -> 87 | N28: =SUM(N12:N27) -> 100 | O28: =((D28-E28)-N28)/(D28-E28) -> 0.46524064 | P28: =(((F28+G28)*$E$18+H28*$E$19+I28*$E$20+J28*$E$21)/(D28-E28)) -> 0
D29: =D28 -> 187 | E29: =I28+J28 -> 30 | F29: 1 | G29: =E29/D29 -> 0.16042781

Sheet Under OE details
C3: S.No. | D3: Drawing/Document Title | E3: Pre-requisites | F3: Department | G3: Approval Category_x000D_ I - Information_x000D_ A - Approval | H3: Document Type | I3: SECI Drawing/Document No. | J3: Submission Status | K3: Approval Status Category2
C4: 1 | D4: Power Conditioning Unit (Central) | E4: NA | F4: Electrical | G4: A | H4: GTP | I4: SECI-LEH25MW-GTP-ELE-2 | J4: UNDER OE
C5: 2 | D5: System Design Basis Report _x000D_ (including Energy Yield Simulation and shadow analysis report) | E5: NA | F5: Electrical | G5: A | H5: DBR | I5: SECI-LEH25MW-DBR-ELE-3 | J5: UNDER OE | K5: CAT-III
C6: 3 | D6: DC cable (from SCB to PCU) | E6: LT Cable Sizing DBR | F6: Electrical | G6: A | H6: GTP | I6: SECI-LEH25MW-GTP-ELE-21 | J6: UNDER OE
C7: 4 | D7: Overall System Schematic, Equipment Layout and BoM | E7: BESS sizing DBR | F7: Electrical | G7: A | H7: DWG | I7: SECI-LEH25MW-DWG-ELE-29 | J7: UNDER OE
C8: 5 | D8: Battery Bank (GTP, Drawings, Type Test Report and QAP) Along with Battery Container GA | E8: BESS sizing DBR, Schematics | F8: Electrical | G8: A | H8: GTP | I8: SECI-LEH25MW-GTP-ELE-30 | J8: UNDER OE
C9: 6 | D9: Power Conditioning System (GTP, Drawings, Type Test Report and QAP) | E9: BESS sizing DBR, Schematics | F9: Electrical | G9: A | H9: GTP | I9: SECI-LEH25MW-GTP-ELE-32 | J9: UNDER OE | K9: CAT-II
C10: 7 | D10: PCS Transformer (GTP, Drawings, Type Test Report and QAP) | E10: BESS sizing DBR, Schematics | F10: Electrical | G10: A | H10: GTP | I10: SECI-LEH25MW-GTP-ELE-33 | J10: UNDER OE
C11: 8 | D11: MCR - Cable Trench General Arrangement and Reinforcement Details | E11: MCR Arch. Dwg | F11: Civil | G11: A | H11: DWG | I11: SECI-LEH25MW-DWG-CIV-61 | J11: UNDER OE
C12: 9 | D12: Cable trench Layout and Cross section (DC, AC, Lighting and CCTV system etc) | E12: Cable GTPs | F12: Electrical | G12: A | H12: DWG | I12: SECI-LEH25MW-DWG-ELE-77 | J12: UNDER OE
C13: 10 | D13: Plant End Substation Earthing Layout | E13: Plant End Substation Earthing DBR | F13: Electrical | G13: A | H13: DWG | I13: SECI-LEH25MW-DWG-ELE-127 | J13: UNDER OE
C14: 11 | D14: Lightning Arrestor - GTP and Drawing | E14: Power Evacuation SLD, DBR for Power Evacuation System | F14: Electrical | G14: I | H14: GTP | I14: SECI-LEH25MW-GTP-ELE-134 | J14: UNDER OE
C15: 12 | D15: Isolator - GTP and Drawing | E15: Power Evacuation SLD, DBR for Power Evacuation System | F15: Electrical | G15: I | H15: GTP | I15: SECI-LEH25MW-GTP-ELE-135 | J15: UNDER OE
C16: 13 | D16: Current Transformer (Metering) - GTP and Drawing | E16: Power Evacuation SLD, DBR for Power Evacuation System | F16: Electrical | G16: I | H16: GTP | I16: SECI-LEH25MW-GTP-ELE-138 | J16: UNDER OE
C17: 14 | D17: Voltage Transformer (Metering) - GTP and Drawing | E17: Power Evacuation SLD, DBR for Power Evacuation System | F17: Electrical | G17: I | H17: GTP | I17: SECI-LEH25MW-GTP-ELE-139 | J17: UNDER OE
C18: 15 | D18: Protection CT - GTP and drawing | E18: - | F18: Electrical | G18: I | H18: GTP | I18: SECI-LEH25MW-GTP-ELE-145 | J18: UNDER OE
C19: 16 | D19: Protection PT/CVT - GTP and drawing | E19: - | F19: Electrical | G19: I | H19: GTP | I19: SECI-LEH25MW-GTP-ELE-146 | J19: UNDER OE
C20: 17 | D20: Gantry - GA and Foundation (as applicable) | E20: NA | F20: Civil | G20: I | H20: DWG | I20: SECI-LEH25MW-DWG-CIV-168 | J20: UNDER OE
C21: 18 | D21: Switchyard DSLP Layout & Calculation | E21: - | F21: Electrical | G21: I | H21: DWG | I21: SECI-LEH25MW-DWG-ELE-169 | J21: UNDER OE

Sheet Sheet1
C3: Sl. No. | D3: Drawing/Document Title | E3: Approval Category | F3: Date Of Approval | G3: Darwing Number | H3: Approval Status | I3: Proposed Submission Date
C4: 1 | D4: Photovoltaic Module | F4: 45715 | G4: SECI-LEH25MW-GTP-ELE-1 | H4: PGEL | J4: Basic Engineering | M4: Approved
C5: 2 | D5: Power Conditioning Unit (Central) | F5: 45681 | G5: SECI-LEH25MW-GTP-ELE-2 | H5: PGEL | M5: Re-Submission
C6: 3 | D6: System Design Basis Report _x000D_ (including Energy Yield Simulation and shadow analysis report) | E6: CAT-III | F6: 45805 | G6: SECI-LEH25MW-DBR-ELE-3 | H6: PGEL | M6: PGEL
C7: 4 | D7: DC SLD | E7: CAT-IV | F7: 45792 | G7: SECI-LEH25MW-DWG-ELE-4 | H7: Approved | M7: SECI-Review
C8: 5 | D8: AC SLD including BESS (upto 11 kV) | E8: CAT-IV | F8: 45862 | G8: SECI-LEH25MW-DWG-ELE-5 | H8: Approved | M8: Yet To Submit
C9: 6 | D9: Topographical Survey | E9: CAT-IV | F9: 45818 | G9: SECI-LEH25MW-DWG-CIV-6 | H9: Approved
C10: 7 | D10: Concrete Mix Design Report | F10: 45859 | G10: SECI-LEH25MW-IR-CIV-7 | H10: PGEL
C11: 8 | D11: Grading and Levelling Plan | F11: 45849 | G11: SECI-LEH25MW-DWG-CIV-8 | H11: PGEL
C12: 9 | D12: Overall Plant Layout covering Array layout, Buildings (MCR and LCR) marking, Road Layout, Lightning protection layout, WMS Location, etc. | E12: CAT-III | F12: 45841 | G12: SECI-LEH25MW-DWG-ELE-9 | H12: PGEL
C13: 10 | D13: Plant Boundary Fencing Layout and Details | E13: CAT-I | F13: 45804 | G13: SECI-LEH25MW-DWG-CIV-10 | H13: Approved
C14: 11 | D14: Plant Main Gate - General Arrangement and Details | E14: CAT-I | F14: 45842 | G14: SECI-LEH25MW-DWG-CIV-11 | H14: Approved
C15: 12 | D15: String Combiner Box (SCB) | G15: SECI-LEH25MW-GTP-ELE-12 | H15: Yet To Submit | J15: Major Electrical Equipments (GTP, GA, Type Test Reports and QAP)
C16: 13 | D16: Inverter Duty Transformer (IDT) | G16: SECI-LEH25MW-GTP-ELE-13 | H16: Yet To Submit
C17: 14 | D17: 11kV HT ICOG Panel | G17: SECI-LEH25MW-GTP-ELE-14 | H17: SECI-Review
C18: 15 | D18: 11kV HT Combiner Panel | G18: SECI-LEH25MW-GTP-ELE-15 | H18: Yet To Submit
C19: 16 | D19: Solar cable (PV module to SCB) | E19: CAT-II | G19: SECI-LEH25MW-GTP-ELE-16 | H19: Approved | J19: Cable sizing documents
C20: 17 | D20: DC cable (from SCB to PCU) | E20: CAT-I | G20: SECI-LEH25MW-GTP-ELE-17 | H20: Approved
C21: 18 | D21: LT cable (from PCU to IDT) | E21: CAT-I | G21: SECI-LEH25MW-GTP-ELE-18 | H21: Approved
C22: 19 | D22: 11kV LT Power Cable | E22: CAT-I | G22: SECI-LEH25MW-GTP-ELE-19 | H22: Approved
C23: 20 | D23: Solar cable (PV module to SCB) | E23: CAT-II | G23: SECI-LEH25MW-GTP-ELE-20 | H23: Approved | J23: Cable GTPs, Type Test Reports and QAP | K23: SUB. APPROVED
C24: 21 | D24: DC cable (from SCB to PCU) | G24: SECI-LEH25MW-GTP-ELE-21 | H24: Re-Submission | K24: UNDER OE
C25: 22 | D25: LT cable (from PCU to IDT) | E25: CAT-I | G25: SECI-LEH25MW-GTP-ELE-22 | H25: Approved | K25: APPROVED
C26: 23 | D26: 11kV LT Power Cable | E26: CAT-I | G26: SECI-LEH25MW-GTP-ELE-23 | H26: Approved | K26: APPROVED
C27: 24 | D27: Communication Cable | G27: SECI-LEH25MW-GTP-ELE-24 | H27: Yet To Submit | K27: PENDING
C28: 25 | D28: LT Auxiliary Power Cable | G28: SECI-LEH25MW-GTP-ELE-25 | H28: Yet To Submit | K28: PENDING
C29: 26 | D29: Control Cable | G29: SECI-LEH25MW-GTP-ELE-26 | H29: Yet To Submit | K29: PENDING
C30: 27 | D30: Design Basis Report for BESS with BESS PQR | G30: SECI-LEH25MW-DBR-ELE-27 | H30: SECI-Review | J30: Battery Energy Storage System (BESS) | K30: UNDER OE
C31: 28 | D31: Battery Sizing Calculation | E31: CAT-I | G31: SECI-LEH25MW-DBR-ELE-28 | H31: Approved | K31: APPROVED
C32: 29 | D32: Overall System Schematic, Equipment Layout and BoM | G32: SECI-LEH25MW-DWG-ELE-29 | H32: Yet To Submit | K32: PENDING
C33: 30 | D33: Battery Bank (GTP, Drawings, Type Test Report and QAP) Along with Battery Container GA | G33: SECI-LEH25MW-GTP-ELE-30 | H33: PGEL | K33: UNDER EPC
C34: 31 | D34: Battery Management System (GTP and Drawings) | G34: SECI-LEH25MW-GTP-ELE-31 | H34: PGEL | K34: UNDER EPC
C35: 32 | D35: Power Conditioning System (GTP, Drawings, Type Test Report and QAP) | G35: SECI-LEH25MW-GTP-ELE-32 | H35: SECI-Review | K35: UNDER OE
C36: 33 | D36: PCS Transformer (GTP, Drawings, Type Test Report and QAP) | G36: SECI-LEH25MW-GTP-ELE-33 | H36: Yet To Submit | K36: PENDING
C37: 34 | D37: PCS Transformer NIFPS (GTP, Drawings and QAP) (If Applicable) | G37: SECI-LEH25MW-GTP-ELE-34 | H37: Yet To Submit | K37: PENDING
C38: 35 | D38: HVAC System (General Arrangement and Details) | G38: SECI-LEH25MW-DWG-ELE-35 | H38: SECI-Review | K38: UNDER OE
C39: 36 | D39: BESS Auxiliary System SLD and DB Details | G39: SECI-LEH25MW-GTP-ELE-36 | H39: PGEL | K39: UNDER EPC
C40: 37 | D40: BESS Earthing Scheme | G40: SECI-LEH25MW-DWG-ELE-37 | H40: Yet To Submit | K40: PENDING
C41: 38 | D41: BESS Fire Protection Systems | E41: CAT-III | G41: SECI-LEH25MW-DWG-ELE-38 | H41: PGEL | K41: UNDER EPC
C42: 39 | D42: Auxiliary Power Consumption Calculation | E42: CAT-IV | G42: SECI-LEH25MW-DBR-ELE-39 | H42: Approved | K42: NOTED FOR INFORMATION
...

Sheet Procurement Status
A1: Sl No | B1: PO NO | C1: PO Release Date | D1: PO Amendment | E1: Vendor Name | F1: Project Name | G1: Material Details | H1: Material Status & Remarks | I1: Expected Delivery
A2: 1 | B2: PGEL/25-26/2954 | C2: 19.06.2025 | D2: 27.08.25 | E2: Fimer India Pvt.Ltd | F2: SECI, LEH | G2: INVERTER & CONVERTER | H2: Document approval stage | I2: 46143
A3: =A2+1 -> 2 | B3: PGEL/25-26/3389 | C3: 14.07.2025 | D3: N/A | E3: ELEKTROLITES POWER (P) LTD | F3: SECI, LEH | G3: LA | H3: Production approval pending | I3: 46143
A4: =A3+1 -> 3 | B4: PGEL/25-26/3390 | C4: 14.07.2025 | D4: N/A | E4: ELEKTROLITES POWER (P) LTD | F4: SECI, LEH | G4: Isolator | H4: Production approval pending | I4: 46143
A5: =A4+1 -> 4 | B5: PGEL/25-26/1250 | C5: 13.05.2025 | D5: N/A | E5: Atlanta Electricals Pvt Ltd | F5: SECI, LEH | G5: Power Transformer | H5: CAT-II Approval Received | I5: 46143
A6: =A5+1 -> 5 | B6: PGEL/25-26/2918 | D6: 13.08.2025 | E6: Strolar Mounting Systems | F6: SECI, LEH | G6: Exterior Column Post | H6: Lot 1 has been delivered and the rest of the quantity is under production | I6: 45901
A7: =A6+1 -> 6 | B7: PGEL/25-26/4044 | C7: 21.08.2025 | D7: N/A | E7: Strolar Mounting Systems | F7: SECI, LEH | G7: Exterior Superstructure | H7: Under fabrication
A8: =A7+1 -> 7 | B8: PGEL/25-26/4045 | C8: 19.08.2025 | D8: N/A | E8: Strolar Mounting Systems | F8: SECI, LEH | G8: Interior Column Post | H8: Under fabrication
A9: =A8+1 -> 8 | B9: PGEL/25-26/3576 | C9: 21.07.2025 | D9: 23.07.2025 | E9: PARLAX INFRASTRUCTURES PRIVATE | F9: SECI, LEH | G9: MCR Work | H9: Work in Progress
A10: =A9+1 -> 9 | B10: PGEL/25-26/3231 | C10: 03.07.2025 | D10: N/A | E10: Transformers & Rectifiers (India) Limited | F10: SECI, LEH | G10: IDT | H10: Document approval stage | I10: 46143
A11: =A10+1 -> 10 | B11: PGEL/25-26/3017 | C11: 24.06.2025 | D11: N/A | E11: Technocrafts Electric Private Limited | F11: SECI, LEH | G11: ICOG & SWBD Panel | H11: Under the documentation stage
A12: =A11+1 -> 11 | B12: PGEL/25-26/60 | C12: 19.04.2025 | D12: N/A | E12: Vijayshree Steel Industries | F12: SECI, LEH | G12: Fencing | H12: Delivered
A13: =A12+1 -> 12 | B13: PGEL/25-26/59 | C13: 8.4.2025 | D13: N/A | E13: Strolar Mounting Systems | F13: SECI, LEH | G13: Fencing | H13: Delivered
A14: =A13+1 -> 13 | B14: PGEL/25-26/3597 | C14: 24.07.2025 | D14: N/A | E14: KWALITY FORGE | F14: SECI, LEH | G14: EXT Column to Column Connector Fasteners | H14: Delivered | I14: 45839
A15: =A14+1 -> 14 | B15: PGEL/25-26/4043 | C15: 20.08.2025 | D15: N/A | E15: KWALITY FORGE | F15: SECI, LEH | G15: INT Column to Column Connector Fasteners | H15: Under the Manufacturing process | I15: 45926
A16: =A15+1 -> 15 | B16: PGEL/25-26/3016 | C16: 26.06.2025 | D16: N/A | E16: Wanbang Digital Energy Co. Ltd. | F16: SECI, LEH | G16: Battery Energy Storage System | H16: Under Document Approval process | I16: 46138
A17: =A16+1 -> 16 | B17: PGEL/25-26/3561 | C17: 21.07.2025 | D17: N/A | E17: NAWANG RINCHEN GOVT.CONTRACTOR | F17: SECI, LEH | G17: BOREWELL WORK | H17: Work Completed
A18: =A17+1 -> 17 | B18: PGEL/25-26/3595 | C18: 24.07.2025 | D18: N/A | E18: M.S.T construction | F18: SECI, LEH | G18: MMS PILING WORK | H18: Work is in progress
A19: =A18+1 -> 18 | B19: PGEL/25-26/2142 | C19: 29.05.2025 | D19: N/A | E19: Yash construction company | F19: SECI, LEH | G19: MMS PILING WORK | H19: Work is in progress
A20: =A19+1 -> 19 | B20: PGEL/25-26/4244 | C20: 01.09.2025 | D20: N/A | E20: CG POWER AND INDUSTRIAL SOLUTIONS | F20: SECI, LEH | G20: CT & PT | H20: Document approval stage | I20: 46143

Sheet Progress Abstract
B2: Daily Progress Report | N2: Date:- | O2: =TODAY()-1 -> 45911
B3: Project Name : | D3: 25 MW (AC) Solar PV Power Plant (50 MWp DC) with 20 MW / 50 MWh Battery Energy Storage System at Taru, Leh, UT of Ladakh, India
B4: Client : | D4: Solar Energy Corporation of India Ltd
B5: SPV : | D5: Prozeal Green Energy Limited | R5: =0.71*5500 -> 3905
B6: Project Start Date | D6: 45616
B7: Project COD | D7: =D6+(36*30) -> 46696 | P7: =D7-D6 -> 1080 | Q7: =D7-O2 -> 785
B8: Sr. No | C8: Description | D8: Work Status | E8: UOM | F8: Scope | G8: Progress | H8: Balance | I8: %age | J8: Status | K8: Dashboard
B9: CIVIL Package | P9: COMP
B10: 1 | C10: Boundary Fencing | D10: ='Civil Progress'!C6 -> Boundary Demarcation and marking | E10: ='Civil Progress'!D6 -> Rm | F10: ='Civil Progress'!E6 -> 5690 | G10: ='Civil Progress'!F6 -> 5690 | H10: =F10-G10 -> 0 | I10: =G10/F10 -> 1 | J10: COMP | P10: WIP
D11: ='Civil Progress'!C7 -> Plie Boring | E11: ='Civil Progress'!D7 -> Rm | F11: ='Civil Progress'!E7 -> 5690 | G11: ='Civil Progress'!F7 -> 4957.5 | H11: =F11-G11 -> 732.5 | I11: =G11/F11 -> 0.87126538 | J11: WIP | P11: Yet to Start
D12: ='Civil Progress'!C8 -> Fence post Allignment and Concrete Pouring | E12: ='Civil Progress'!D8 -> Rm | F12: ='Civil Progress'!E8 -> 5690 | G12: ='Civil Progress'!F8 -> 5150 | H12: =F12-G12 -> 540 | I12: =G12/F12 -> 0.90509666 | J12: WIP | R12: =AVERAGE(G15,G21,G39,G46,G54,G66,G79) -> 0.39793405 | S12: =AVERAGE(H15,H21,H39,H46,H54,H66,H79) -> 0.60206595 | T12: =AVERAGE(I15,I21,I39,I46,I54,I59,I66,I79) -> 0.35454281
D13: ='Civil Progress'!C9 -> Barbed wire installation | E13: ='Civil Progress'!D9 -> Rm | F13: ='Civil Progress'!E9 -> 5690 | G13: ='Civil Progress'!F9 -> 4315 | H13: =F13-G13 -> 1375 | I13: =G13/F13 -> 0.75834798 | J13: WIP
D14: ='Civil Progress'!C10 -> Mesh installation with connecting strip and tightening | E14: ='Civil Progress'!D10 -> Rm | F14: ='Civil Progress'!E10 -> 5690 | G14: ='Civil Progress'!F10 -> 4335 | H14: =F14-G14 -> 1355 | I14: =G14/F14 -> 0.76186292 | J14: WIP
D15: Weightage Progress | F15: 1 | G15: ='Civil Progress'!H5 -> 0.85931459 | H15: =F15-G15 -> 0.14068541 | I15: =G15/F15 -> 0.85931459
B16: 2 | C16: Main Gate | D16: ='Civil Progress'!C12 -> Foundation Excavation | E16: ='Civil Progress'!D12 -> Nos | F16: ='Civil Progress'!E12 -> 3 | G16: ='Civil Progress'!F12 -> 3 | H16: =F16-G16 -> 0 | I16: =G16/F16 -> 1 | J16: COMP
D17: ='Civil Progress'!C13 -> Foundation PCC | E17: ='Civil Progress'!D13 -> Nos | F17: ='Civil Progress'!E13 -> 3 | G17: ='Civil Progress'!F13 -> 3 | H17: =F17-G17 -> 0 | I17: =G17/F17 -> 1 | J17: COMP
D18: ='Civil Progress'!C14 -> Foundation RCC | E18: ='Civil Progress'!D14 -> Nos | F18: ='Civil Progress'!E14 -> 3 | G18: ='Civil Progress'!F14 -> 3 | H18: =F18-G18 -> 0 | I18: =G18/F18 -> 1 | J18: COMP
D19: ='Civil Progress'!C15 -> Columns | E19: ='Civil Progress'!D15 -> Nos | F19: ='Civil Progress'!E15 -> 3 | G19: ='Civil Progress'!F15 -> 3 | H19: =F19-G19 -> 0 | I19: =G19/F19 -> 1 | J19: COMP
D20: ='Civil Progress'!C16 -> Gate Febrication and Installation | E20: ='Civil Progress'!D16 -> Nos | F20: ='Civil Progress'!E16 -> 2 | G20: ='Civil Progress'!F16 -> 2 | H20: =F20-G20 -> 0 | I20: ='Civil Progress'!H31 -> 0 | J20: Yet to Start
D21: Weightage Progress | F21: 1 | G21: ='Civil Progress'!H11 -> 1 | H21: =F21-G21 -> 0 | I21: =G21/F21 -> 1
B22: 3 | C22: MCR | D22: ='Civil Progress'!C21 -> Excavation | E22: ='Civil Progress'!D21 -> No's | F22: ='Civil Progress'!E21 -> 33 | G22: ='Civil Progress'!F21 -> 33 | H22: =F22-G22 -> 0 | I22: =G22/F22 -> 1 | J22: COMP
D23: ='Civil Progress'!C22 -> Foundation PCC | E23: ='Civil Progress'!D22 -> No's | F23: ='Civil Progress'!E22 -> 33 | G23: ='Civil Progress'!F22 -> 33 | H23: =F23-G23 -> 0 | I23: =G23/F23 -> 1 | J23: WIP
D24: ='Civil Progress'!C25 -> Footing Foundation casting | E24: ='Civil Progress'!D25 -> No's | F24: =AVERAGE('Civil Progress'!E23:E25) -> 33 | G24: =AVERAGE('Civil Progress'!F23:F25) -> 33 | H24: =F24-G24 -> 0 | I24: =G24/F24 -> 1 | J24: WIP
D25: ='Civil Progress'!C27 -> Column upto Plinth Beam | E25: ='Civil Progress'!D31 -> No's | F25: ='Civil Progress'!E27 -> 33 | G25: ='Civil Progress'!F27 -> 0 | H25: =F25-G25 -> 33 | I25: =G25/F25 -> 0 | J25: Yet to Start
D26: ='Civil Progress'!C30 -> Plinth Beam Casting | E26: ='Civil Progress'!D30 -> Mtr | F26: =AVERAGE('Civil Progress'!E28:E30) -> 322 | G26: =AVERAGE('Civil Progress'!F28:F30) -> 0 | H26: =F26-G26 -> 322 | I26: =G26/F26 -> 0 | J26: Yet to Start
D27: ='Civil Progress'!C31 -> Column upto Lintel Beam | E27: ='Civil Progress'!D31 -> No's | F27: ='Civil Progress'!E31 -> 33 | G27: ='Civil Progress'!F31 -> 0 | H27: =F27-G27 -> 33 | I27: =G27/F27 -> 0 | J27: Yet to Start
D28: ='Civil Progress'!C33 -> Lintel and sunshade casting | E28: ='Civil Progress'!D33 -> Mtr | F28: ='Civil Progress'!E33 -> 132 | G28: ='Civil Progress'!F33 -> 0 | H28: ='Civil Progress'!G33 -> 132 | I28: =G28/F28 -> 0 | J28: Yet to Start
D29: ='Civil Progress'!C38 -> Column upto Roof Beam | E29: ='Civil Progress'!D38 -> No's | F29: ='Civil Progress'!E38 -> 33 | G29: ='Civil Progress'!F38 -> 0 | H29: ='Civil Progress'!G38 -> 33 | I29: =G29/F29 -> 0 | J29: Yet to Start
D30: ='Civil Progress'!C41 -> Roof Beam & Slab Casting | E30: ='Civil Progress'!D41 -> Ls | F30: ='Civil Progress'!E42 -> 1 | G30: ='Civil Progress'!F42 -> 0 | H30: ='Civil Progress'!G42 -> 1 | I30: =G30/F30 -> 0 | J30: Yet to Start
D31: ='Civil Progress'!C36 -> Cable Trench Raft Casting | E31: ='Civil Progress'!D36 -> Mtr | F31: ='Civil Progress'!E36 -> 50 | G31: ='Civil Progress'!F36 -> 0 | H31: ='Civil Progress'!G36 -> 50 | I31: =G31/F31 -> 0 | J31: Yet to Start
D32: ='Civil Progress'!C37 -> Cable Trench Wall casting | E32: ='Civil Progress'!D37 -> Mtr | F32: ='Civil Progress'!E37 -> 100 | G32: ='Civil Progress'!F37 -> 0 | H32: ='Civil Progress'!G37 -> 100 | I32: =G32/F32 -> 0 | J32: Yet to Start
D33: ='Civil Progress'!C42 -> Floor Slab Casting | E33: ='Civil Progress'!D42 -> Ls | F33: ='Civil Progress'!E42 -> 1 | G33: ='Civil Progress'!F42 -> 0 | H33: ='Civil Progress'!G42 -> 1 | I33: =G33/F33 -> 0 | J33: Yet to Start
D34: ='Civil Progress'!C43 -> Brick Masonry Work | E34: ='Civil Progress'!D43 -> Cu. Mtr | F34: ='Civil Progress'!E43 -> 310 | G34: ='Civil Progress'!F43 -> 0 | H34: ='Civil Progress'!G43 -> 310 | I34: =G34/F34 -> 0 | J34: Yet to Start
D35: ='Civil Progress'!C44 -> Wall & Celling Plaster | E35: ='Civil Progress'!D44 -> Sq. Mtr | F35: ='Civil Progress'!E44 -> 2380 | G35: ='Civil Progress'!F44 -> 0 | H35: ='Civil Progress'!G44 -> 2380 | I35: =G35/F35 -> 0 | J35: Yet to Start
D36: ='Civil Progress'!C45 -> Flooring | E36: ='Civil Progress'!D45 -> No's | F36: ='Civil Progress'!E45 -> 8 | G36: ='Civil Progress'!F45 -> 0 | H36: ='Civil Progress'!G45 -> 0 | I36: =G36/F36 -> 0 | J36: Yet to Start
D37: ='Civil Progress'!C54 -> Putty & Paint work | E37: ='Civil Progress'!D54 -> No's | F37: ='Civil Progress'!E54 -> 8 | G37: ='Civil Progress'!F54 -> 0 | H37: ='Civil Progress'!G54 -> 0 | I37: =G37/F37 -> 0 | J37: Yet to Start
D38: ='Civil Progress'!C63 -> Misc Work | E38: ='Civil Progress'!D63 -> LS | F38: ='Civil Progress'!E63 -> 1 | G38: ='Civil Progress'!F63 -> 0 | H38: ='Civil Progress'!G63 -> 0 | I38: =G38/F38 -> 0 | J38: Yet to Start
D39: Weightage Progress | F39: 1 | G39: ='Civil Progress'!H20 -> 0.23076923 | H39: =F39-G39 -> 0.76923077 | I39: =G39/F39 -> 0.23076923
B40: 4 | C40: IDT- Solar | D40: ='Civil Progress'!C72 -> Excavation | E40: ='Civil Progress'!D72 -> No's | F40: ='Civil Progress'!E72 -> 4 | G40: ='Civil Progress'!F72 -> 3 | H40: =F40-G40 -> 1 | I40: =G40/F40 -> 0.75 | J40: WIP
D41: ='Civil Progress'!C73 -> Foundation PCC | E41: ='Civil Progress'!D73 -> No's | F41: ='Civil Progress'!E73 -> 4 | G41: ='Civil Progress'!F73 -> 3 | H41: =F41-G41 -> 1 | I41: =G41/F41 -> 0.75 | J41: WIP
...

Sheet Civil Progress
B2: Civil Progress | J2: DAILY PROGRESS
B3: Sr.no. | C3: Description | D3: UOM | E3: Scope | F3: Progress | G3: Balance | H3: % Progress | J3: Cummulative | K3: 45782 | L3: 45783 | M3: 45784 | N3: 45785 | O3: 45786 | P3: 45787 | Q3: 45788 | R3: 45789 | S3: 45790 | T3: 45791 | U3: 45792 | V3: 45793 | W3: 45794 | X3: 45795 | Y3: 45796 | Z3: 45797 | AA3: 45798 | AB3: 45799 | AC3: 45800 | AD3: 45801 | AE3: 45802 | AF3: 45803 | AG3: 45804 | AH3: 45805 | AI3: 45806 | AJ3: 45807 | AK3: 45808 | AL3: 45809 | AM3: 45810 | AN3: 45811 | AO3: 45812 | AP3: 45813 | AQ3: 45814 | AR3: 45815 | AS3: 45816 | AT3: 45817 | AU3: 45818 | AV3: 45819 | AW3: 45820 | AX3: 45821 | AY3: 45822 | AZ3: 45823 | BA3: 45824 | BB3: 45825 | BC3: 45826 | BD3: 45827 | BE3: 45828 | BF3: 45829 | BG3: 45830 | BH3: 45831 | BI3: 45832 | BJ3: 45833 | BK3: 45834 | BL3: 45835 | BM3: 45836 | BN3: 45837 | BO3: 45838 | BP3: 45839 | BQ3: 45840 | BR3: 45841 | BS3: 45842 | BT3: 45843 | BU3: 45844 | BV3: 45845 | BW3: 45846 | BX3: 45847 | BY3: 45848 | BZ3: 45849 | CA3: 45850 | CB3: 45851 | CC3: 45852 | CD3: 45853 | CE3: 45854 | CF3: 45855 | CG3: 45856 | CH3: 45857 | CI3: 45858 | CJ3: 45859 | CK3: 45860 | CL3: 45861 | CM3: 45862 | CN3: 45863 | CO3: 45864 | CP3: 45865 | CQ3: 45866 | CR3: 45867 | CS3: 45868 | CT3: 45869 | CU3: 45870 | CV3: 45871 | CW3: 45872 | CX3: 45873 | CY3: 45874 | CZ3: 45875 | DA3: 45876 | DB3: 45877 | DC3: 45878 | DD3: 45879 | DE3: 45880 | DF3: 45881 | DG3: 45882 | DH3: 45883 | DI3: 45884 | DJ3: 45885 | DK3: 45886 | DL3: 45887 | DM3: 45888 | DN3: 45889 | DO3: 45890 | DP3: 45891 | DQ3: 45892 | DR3: 45893 | DS3: 45894 | DT3: 45895 | DU3: 45896 | DV3: 45897 | DW3: 45898 | DX3: 45899 | DY3: 45900 | DZ3: 45901 | EA3: 45902 | EB3: 45903 | EC3: 45904 | ED3: 45905 | EE3: 45906 | EF3: 45907 | EG3: 45908 | EH3: 45909 | EI3: 45910 | EJ3: 45911 | EK3: 45912 | EL3: 45913 | EM3: 45914 | EN3: 45915 | EO3: 45916 | EP3: 45917 | EQ3: 45918 | ER3: 45919 | ES3: 45920 | ET3: 45921 | EU3: 45922 | EV3: 45923 | EW3: 45924 | EX3: 45925 | EY3: 45926 | EZ3: 45927 | FA3: 45928 | FB3: 45929 | FC3: 45930 | FD3: 45931 | FE3: 45932 | FF3: 45933 | FG3: 45934 | FH3: 45935 | FI3: 45936 | FJ3: 45937 | FK3: 45938 | FL3: 45939 | FM3: 45940 | FN3: 45941 | FO3: 45942 | FP3: 45943 | FQ3: 45944 | FR3: 45945 | FS3: 45946 | FT3: 45947 | FU3: 45948 | FV3: 45949 | FW3: 45950 | FX3: 45951 | FY3: 45952 | FZ3: 45953 | GA3: 45954 | GB3: 45955 | GC3: 45956 | GD3: 45957 | GE3: 45958 | GF3: 45959 | GG3: 45960 | GH3: 45961
B5: Boundary Fencing | D5: Rm | E5: =AVERAGE(E6:E10) -> 5690 | F5: =AVERAGE(F6:F10) -> 4889.5 | G5: =AVERAGE(G6:G10) -> 800.5 | H5: =AVERAGE(H6:H10) -> 0.85931459
B6: 1 | C6: Boundary Demarcation and marking | D6: Rm | E6: =2276*2.5 -> 5690 | F6: =J6 -> 5690 | G6: =E6-F6 -> 0 | H6: =F6/E6 -> 1 | J6: =SUM(K6:KBF6) -> 5690 | K6: 0 | L6: 0 | M6: 0 | N6: 0 | O6: 0 | P6: 0 | Q6: 0 | R6: 0 | S6: 0 | T6: 0 | U6: 0 | V6: 0 | W6: 0 | X6: 0 | Y6: 0 | Z6: 0 | AA6: 0 | AB6: 0 | AC6: 0 | AD6: 0 | AE6: 0 | AF6: 0 | AG6: 0 | AH6: 0 | AI6: 0 | AJ6: 0 | AK6: 0 | AL6: 0 | AM6: 0 | AN6: 0 | AO6: 0 | AP6: 0 | AQ6: 0 | AR6: 0 | AS6: 0 | AT6: 0 | AU6: 0 | AV6: 0 | AW6: 0 | AX6: 0 | AY6: 0 | AZ6: 0 | BA6: 0 | BB6: 0 | BC6: 0 | BD6: 0 | BE6: 0 | BF6: 0 | BG6: 0 | BH6: 0 | BI6: =2100*2.5 -> 5250 | BJ6: 0 | BK6: 0 | BL6: 0 | BM6: 0 | BN6: 0 | BO6: 0 | BP6: 0 | BQ6: 300 | BR6: 140
B7: 2 | C7: Plie Boring | D7: Rm | E7: =2276*2.5 -> 5690 | F7: =J7 -> 4957.5 | G7: =E7-F7 -> 732.5 | H7: =F7/E7 -> 0.87126538 | J7: =SUM(K7:KBF7) -> 4957.5 | K7: 0 | L7: 0 | M7: 0 | N7: 0 | O7: 0 | P7: 0 | Q7: 0 | R7: 0 | S7: 0 | T7: 0 | U7: 0 | V7: 0 | W7: 0 | X7: 0 | Y7: 0 | Z7: 0 | AA7: 0 | AB7: 0 | AC7: 0 | AD7: 0 | AE7: 0 | AF7: 0 | AG7: 0 | AH7: 0 | AI7: 0 | AJ7: 0 | AK7: 0 | AL7: 0 | AM7: 0 | AN7: 0 | AO7: 0 | AP7: 0 | AQ7: 0 | AR7: 0 | AS7: 0 | AT7: 0 | AU7: 0 | AV7: 0 | AW7: 0 | AX7: 0 | AY7: 0 | AZ7: 0 | BA7: 0 | BB7: 0 | BC7: 0 | BD7: 0 | BE7: 0 | BF7: 0 | BG7: 0 | BH7: 0 | BI7: =1983*2.5 -> 4957.5 | BJ7: 0 | BK7: 0 | BL7: 0 | BM7: 0 | BN7: 0 | BO7: 0 | BP7: 0 | BQ7: 0 | BR7: 0 | BS7: 0 | BT7: 0 | BU7: 0 | BV7: 0 | BW7: 0 | BX7: 0 | BY7: 0 | BZ7: 0 | CA7: 0 | CB7: 0 | CC7: 0 | CD7: 0 | CE7: 0 | CF7: 0 | CG7: 0 | CH7: 0 | CI7: 0 | CJ7: 0 | CK7: 0 | CL7: 0 | CM7: 0 | CN7: 0 | CO7: 0 | CP7: 0 | CQ7: 0 | CR7: 0 | CS7: 0 | CT7: 0 | CU7: 0 | CV7: 0 | CW7: 0 | CX7: 0 | CY7: 0 | CZ7: 0 | DA7: 0 | DB7: 0 | DC7: 0 | DD7: 0 | DE7: 0 | DF7: 0 | DG7: 0 | DH7: 0 | DI7: 0 | DJ7: 0 | DK7: 0 | DL7: 0
B8: 3 | C8: Fence post Allignment and Concrete Pouring | D8: Rm | E8: =2276*2.5 -> 5690 | F8: =J8 -> 5150 | G8: =E8-F8 -> 540 | H8: =F8/E8 -> 0.90509666 | J8: =SUM(K8:KBF8) -> 5150 | K8: 0 | L8: 0 | M8: 0 | N8: 0 | O8: 0 | P8: 0 | Q8: 0 | R8: 0 | S8: 0 | T8: 0 | U8: 0 | V8: 0 | W8: 0 | X8: 0 | Y8: 0 | Z8: 0 | AA8: 0 | AB8: 0 | AC8: 0 | AD8: 0 | AE8: 0 | AF8: 0 | AG8: 0 | AH8: 0 | AI8: 0 | AJ8: 0 | AK8: 0 | AL8: 0 | AM8: 0 | AN8: 0 | AO8: 0 | AP8: 0 | AQ8: 0 | AR8: 0 | AS8: 0 | AT8: 0 | AU8: 0 | AV8: 0 | AW8: 0 | AX8: 0 | AY8: 0 | AZ8: 0 | BA8: 0 | BB8: 0 | BC8: 0 | BD8: 0 | BE8: 0 | BF8: 0 | BG8: 0 | BH8: 0 | BI8: =657*2.5 -> 1642.5 | BJ8: 0 | BK8: 0 | BL8: 0 | BM8: 0 | BN8: 0 | BO8: 0 | BP8: 0 | BQ8: 0 | BR8: 52 | BS8: 0 | BT8: 0 | BU8: 75.5 | BV8: 0 | BW8: 250 | BX8: 250 | BY8: 225 | BZ8: 272.5 | CA8: 200 | CB8: 250 | CC8: 225 | CD8: =70*2.5 -> 175 | CE8: =77*2.5 -> 192.5 | CF8: 0 | CG8: =70*2.5 -> 175 | CH8: =75*2.5 -> 187.5 | CI8: 0 | CJ8: =62*2.5 -> 155 | CK8: 0 | CL8: =75*2.5 -> 187.5 | CM8: 0 | CN8: 0 | CO8: 0 | CP8: 0 | CQ8: 0 | CR8: 0 | CS8: 0 | CT8: 0 | CU8: 0 | CV8: 0 | CW8: 0 | CX8: 0 | CY8: 0 | CZ8: 0 | DA8: 35 | DB8: 200 | DC8: 200 | DD8: 200 | DE8: 0 | DF8: 0 | DG8: 0 | DH8: 0 | DI8: 0 | DJ8: 0 | DK8: 0 | DL8: 0
B9: 4 | C9: Barbed wire installation | D9: Rm | E9: =2276*2.5 -> 5690 | F9: =J9 -> 4315 | G9: =E9-F9 -> 1375 | H9: =F9/E9 -> 0.75834798 | J9: =SUM(K9:KBF9) -> 4315 | K9: 0 | L9: 0 | M9: 0 | N9: 0 | O9: 0 | P9: 0 | Q9: 0 | R9: 0 | S9: 0 | T9: 0 | U9: 0 | V9: 0 | W9: 0 | X9: 0 | Y9: 0 | Z9: 0 | AA9: 0 | AB9: 0 | AC9: 0 | AD9: 0 | AE9: 0 | AF9: 0 | AG9: 0 | AH9: 0 | AI9: 0 | AJ9: 0 | AK9: 0 | AL9: 0 | AM9: 0 | AN9: 0 | AO9: 0 | AP9: 0 | AQ9: 0 | AR9: 0 | AS9: 0 | AT9: 0 | AU9: 0 | AV9: 0 | AW9: 0 | AX9: 0 | AY9: 0 | AZ9: 0 | BA9: 0 | BB9: 0 | BC9: 0 | BD9: 0 | BE9: 0 | BF9: 0 | BG9: 0 | BH9: 0 | BI9: 0 | BJ9: 0 | BK9: 0 | BL9: 0 | BM9: 0 | BN9: 0 | BO9: 0 | BP9: 0 | BQ9: 0 | BR9: 1300 | BS9: 180 | BT9: 0 | BU9: 0 | BV9: 0 | BW9: 0 | BX9: 0 | BY9: 0 | BZ9: 290 | CA9: 315 | CB9: 315 | CC9: 320 | CD9: 0 | CE9: 0 | CF9: 0 | CG9: 0 | CH9: 0 | CI9: 0 | CJ9: 0 | CK9: 0 | CL9: 0 | CM9: 0 | CN9: 0 | CO9: 0 | CP9: 0 | CQ9: 100 | CR9: 100 | CS9: 100 | CT9: 100 | CU9: 100 | CV9: 100 | CW9: 100 | CX9: 100 | CY9: 0 | CZ9: 0 | DA9: 0 | DB9: 0 | DC9: 0 | DD9: 195 | DE9: 300 | DF9: 300 | DG9: 0 | DH9: 0 | DI9: 0 | DJ9: 0 | DK9: 0 | DL9: 0
B10: 5 | C10: Mesh installation with connecting strip and tightening | D10: Rm | E10: =2276*2.5 -> 5690 | F10: =J10 -> 4335 | G10: =E10-F10 -> 1355 | H10: =F10/E10 -> 0.76186292 | J10: =SUM(K10:KBF10) -> 4335 | K10: 0 | L10: 0 | M10: 0 | N10: 0 | O10: 0 | P10: 0 | Q10: 0 | R10: 0 | S10: 0 | T10: 0 | U10: 0 | V10: 0 | W10: 0 | X10: 0 | Y10: 0 | Z10: 0 | AA10: 0 | AB10: 0 | AC10: 0 | AD10: 0 | AE10: 0 | AF10: 0 | AG10: 0 | AH10: 0 | AI10: 0 | AJ10: 0 | AK10: 0 | AL10: 0 | AM10: 0 | AN10: 0 | AO10: 0 | AP10: 0 | AQ10: 0 | AR10: 0 | AS10: 0 | AT10: 0 | AU10: 0 | AV10: 0 | AW10: 0 | AX10: 0 | AY10: 0 | AZ10: 0 | BA10: 0 | BB10: 0 | BC10: 0 | BD10: 0 | BE10: 0 | BF10: 0 | BG10: 0 | BH10: 0 | BI10: 0 | BJ10: 0 | BK10: 0 | BL10: 0 | BM10: 0 | BN10: 0 | BO10: 0 | BP10: 0 | BQ10: 0 | BR10: 1300 | BS10: 180 | BT10: 0 | BU10: 0 | BV10: 0 | BW10: 0 | BX10: 50 | BY10: 60 | BZ10: 210 | CA10: 180 | CB10: 180 | CC10: 220 | CD10: 105 | CE10: 0 | CF10: 0 | CG10: 150 | CH10: 165 | CI10: 0 | CJ10: 180 | CK10: 0 | CL10: 180 | CM10: 0 | CN10: 0 | CO10: 0 | CP10: 0 | CQ10: 100 | CR10: 100 | CS10: 100 | CT10: 100 | CU10: 100 | CV10: 100 | CW10: 100 | CX10: 100 | CY10: 0 | CZ10: 0 | DA10: 0 | DB10: 0 | DC10: 0 | DD10: 195 | DE10: 90 | DF10: 90 | DG10: 0 | DH10: 0 | DI10: 0 | DJ10: 0 | DK10: 0 | DL10: 0
B11: Main Gate | D11: Nos | E11: =AVERAGE(E12:E16) -> 2.8 | F11: =AVERAGE(F12:F16) -> 2.8 | G11: =AVERAGE(G12:G16) -> 0 | H11: =AVERAGE(H12:H16) -> 1
B12: 1 | C12: Foundation Excavation | D12: Nos | E12: 3 | F12: =J12 -> 3 | G12: =E12-F12 -> 0 | H12: =F12/E12 -> 1 | J12: =SUM(K12:KBF12) -> 3 | BI12: 0 | BJ12: 0 | BK12: 0 | BL12: 0 | BM12: 0 | BN12: 0 | BO12: 0 | BP12: 3
B13: 2 | C13: Foundation PCC | D13: Nos | E13: 3 | F13: =J13 -> 3 | G13: =E13-F13 -> 0 | H13: =F13/E13 -> 1 | J13: =SUM(K13:KBF13) -> 3 | BI13: 0 | BJ13: 0 | BK13: 0 | BL13: 0 | BM13: 0 | BN13: 0 | BO13: 0 | BP13: 0 | BQ13: 3
B14: 3 | C14: Foundation RCC | D14: Nos | E14: 3 | F14: =J14 -> 3 | G14: =E14-F14 -> 0 | H14: =F14/E14 -> 1 | J14: =SUM(K14:KBF14) -> 3 | BI14: 0 | BJ14: 0 | BK14: 0 | BL14: 0 | BM14: 0 | BN14: 0 | BO14: 0 | BP14: 0 | BQ14: 0 | BR14: 0 | BS14: 0 | BT14: 0 | BU14: 0 | BV14: 0 | BW14: 3
B15: 4 | C15: Columns | D15: Nos | E15: 3 | F15: =J15 -> 3 | G15: =E15-F15 -> 0 | H15: =F15/E15 -> 1 | J15: =SUM(K15:KBF15) -> 3 | BI15: 0 | BJ15: 0 | BK15: 0 | BL15: 0 | BM15: 0 | BN15: 0 | BO15: 0 | BP15: 0 | BQ15: 0 | BR15: 0 | BS15: 0 | BT15: 0 | BU15: 0 | BV15: 0 | BW15: 0 | BX15: 0 | BY15: 0 | BZ15: 1 | CA15: 2
B16: 5 | C16: Gate Febrication and Installation | D16: Nos | E16: 2 | F16: =J16 -> 2 | G16: =E16-F16 -> 0 | H16: =F16/E16 -> 1 | J16: =SUM(K16:KBF16) -> 2 | BI16: 0 | BJ16: 0 | BK16: 0 | BL16: 0 | BM16: 0 | BN16: 0 | BO16: 0 | BP16: 0 | BQ16: 0 | BR16: 0 | BS16: 0 | BT16: 0 | BU16: 0 | BV16: 0 | BW16: 0 | BX16: 0 | BY16: 0 | BZ16: 0 | CA16: 2
B17: Street light Work | D17: No's | E17: =AVERAGE(E18:E19) -> 175 | F17: =AVERAGE(F18:F19) -> 0 | G17: =AVERAGE(G18:G19) -> 175 | H17: =AVERAGE(H18:H19) -> 0
B18: 1 | C18: Pole Casting | D18: No's | E18: 175 | F18: 0 | G18: =E18-F18 -> 175 | H18: =F18/E18 -> 0 | J18: =SUM(K18:KBF18) -> 0
B19: 2 | C19: Light Erection | D19: No's | E19: 175 | F19: 0 | G19: =E19-F19 -> 175 | H19: =F19/G19 -> 0 | J19: =SUM(K19:KBF19) -> 0
B20: MCR | H20: =AVERAGE(H21:H44,H45,H54,H63) -> 0.23076923
B21: 1 | C21: Excavation | D21: No's | E21: 33 | F21: =J21 -> 33 | G21: =E21-F21 -> 0 | H21: =F21/E21 -> 1 | J21: =SUM(K21:KBF21) -> 33 | BI21: 33
B22: 2 | C22: Foundation PCC | D22: No's | E22: 33 | F22: =J22 -> 33 | G22: =E22-F22 -> 0 | H22: =F22/E22 -> 1 | J22: =SUM(K22:KBF22) -> 33 | BI22: 17 | BJ22: 0 | BK22: 0 | BL22: 0 | BM22: 0 | BN22: 0 | BO22: 0 | BP22: 0 | BQ22: 0 | BR22: 0 | BS22: 0 | BT22: 0 | BU22: 0 | BV22: 0 | BW22: 0 | BX22: 0 | BY22: 0 | BZ22: 0 | CA22: 0 | CB22: 0 | CC22: 0 | CD22: 0 | CE22: 0 | CF22: 0 | CG22: 0 | CH22: 0 | CI22: 5 | CJ22: 11
B23: 3 | C23: Foundation Reinforcement | D23: No's | E23: 33 | F23: =J23 -> 33 | G23: =E23-F23 -> 0 | H23: =F23/E23 -> 1 | J23: =SUM(K23:KBF23) -> 33 | BI23: 17 | BJ23: 0 | BK23: 0 | BL23: 0 | BM23: 0 | BN23: 0 | BO23: 0 | BP23: 0 | BQ23: 0 | BR23: 0 | BS23: 0 | BT23: 0 | BU23: 0 | BV23: 0 | BW23: 0 | BX23: 0 | BY23: 0 | BZ23: 0 | CA23: 0 | CB23: 0 | CC23: 0 | CD23: 0 | CE23: 0 | CF23: 0 | CG23: 0 | CH23: 0 | CI23: 0 | CJ23: 0 | CK23: 0 | CL23: 0 | CM23: 0 | CN23: 0 | CO23: 0 | CP23: 0 | CQ23: 0 | CR23: 0 | CS23: 0 | CT23: 0 | CU23: 0 | CV23: 0 | CW23: 0 | CX23: 0 | CY23: 0 | CZ23: 0 | DA23: 0 | DB23: 0 | DC23: 0 | DD23: 0 | DE23: 0 | DF23: 0 | DG23: 0 | DH23: 0 | DI23: 0 | DJ23: 0 | DK23: 0 | DL23: 0 | DM23: 0 | DN23: 10 | DO23: 0 | DP23: 0 | DQ23: 0 | DR23: 0 | DS23: 0 | DT23: 0 | DU23: 0 | DV23: 6 | DW23: 0 | DX23: 0 | DY23: 0 | DZ23: 0 | EA23: 0 | EB23: 0
B24: 4 | C24: Foundation Shuttering | D24: No's | E24: 33 | F24: =J24 -> 33 | G24: =E24-F24 -> 0 | H24: =F24/E24 -> 1 | J24: =SUM(K24:KBF24) -> 33 | BI24: 17 | BJ24: 0 | BK24: 0 | BL24: 0 | BM24: 0 | BN24: 0 | BO24: 0 | BP24: 0 | BQ24: 0 | BR24: 0 | BS24: 0 | BT24: 0 | BU24: 0 | BV24: 0 | BW24: 0 | BX24: 0 | BY24: 0 | BZ24: 0 | CA24: 0 | CB24: 0 | CC24: 0 | CD24: 0 | CE24: 0 | CF24: 0 | CG24: 0 | CH24: 0 | CI24: 0 | CJ24: 0 | CK24: 0 | CL24: 0 | CM24: 0 | CN24: 0 | CO24: 0 | CP24: 0 | CQ24: 0 | CR24: 0 | CS24: 0 | CT24: 0 | CU24: 0 | CV24: 0 | CW24: 0 | CX24: 0 | CY24: 0 | CZ24: 0 | DA24: 0 | DB24: 0 | DC24: 0 | DD24: 0 | DE24: 0 | DF24: 0 | DG24: 0 | DH24: 0 | DI24: 0 | DJ24: 0 | DK24: 0 | DL24: 0 | DM24: 0 | DN24: 0 | DO24: 5 | DP24: 5 | DQ24: 0 | DR24: 0 | DS24: 0 | DT24: 0 | DU24: 0 | DV24: 0 | DW24: 6 | DX24: 0 | DY24: 0 | DZ24: 0 | EA24: 0 | EB24: 0
B25: 5 | C25: Footing Foundation casting | D25: No's | E25: 33 | F25: =J25 -> 33 | G25: =E25-F25 -> 0 | H25: =F25/E25 -> 1 | J25: =SUM(K25:KBF25) -> 33 | BI25: 17 | BJ25: 0 | BK25: 0 | BL25: 0 | BM25: 0 | BN25: 0 | BO25: 0 | BP25: 0 | BQ25: 0 | BR25: 0 | BS25: 0 | BT25: 0 | BU25: 0 | BV25: 0 | BW25: 0 | BX25: 0 | BY25: 0 | BZ25: 0 | CA25: 0 | CB25: 0 | CC25: 0 | CD25: 0 | CE25: 0 | CF25: 0 | CG25: 0 | CH25: 0 | CI25: 0 | CJ25: 0 | CK25: 0 | CL25: 0 | CM25: 0 | CN25: 0 | CO25: 0 | CP25: 0 | CQ25: 0 | CR25: 0 | CS25: 0 | CT25: 0 | CU25: 0 | CV25: 0 | CW25: 0 | CX25: 0 | CY25: 0 | CZ25: 0 | DA25: 0 | DB25: 0 | DC25: 0 | DD25: 0 | DE25: 0 | DF25: 0 | DG25: 0 | DH25: 0 | DI25: 0 | DJ25: 0 | DK25: 0 | DL25: 0 | DM25: 0 | DN25: 0 | DO25: 0 | DP25: 0 | DQ25: 5 | DR25: 5 | DS25: 0 | DT25: 0 | DU25: 0 | DV25: 0 | DW25: 0 | DX25: 6 | DY25: 0 | DZ25: 0 | EA25: 0 | EB25: 0
B26: 6 | C26: Back filling | D26: No's | E26: 33 | F26: =J26 -> 33 | G26: =E26-F26 -> 0 | H26: =F26/E26 -> 1 | J26: =SUM(K26:KBF26) -> 33 | BI26: 0 | BJ26: 0 | BK26: 0 | BL26: 0 | BM26: 0 | BN26: 0 | BO26: 0 | BP26: 0 | BQ26: 0 | BR26: 0 | BS26: 0 | BT26: 0 | BU26: 0 | BV26: 0 | BW26: 0 | BX26: 0 | BY26: 0 | BZ26: 0 | CA26: 0 | CB26: 0 | CC26: 0 | CD26: 0 | CE26: 0 | CF26: 0 | CG26: 0 | CH26: 0 | CI26: 0 | CJ26: 0 | CK26: 0 | CL26: 0 | CM26: 0 | CN26: 0 | CO26: 0 | CP26: 0 | CQ26: 0 | CR26: 0 | CS26: 0 | CT26: 17 | CU26: 0 | CV26: 0 | CW26: 0 | CX26: 0 | CY26: 0 | CZ26: 0 | DA26: 0 | DB26: 0 | DC26: 0 | DD26: 0 | DE26: 0 | DF26: 0 | DG26: 0 | DH26: 0 | DI26: 0 | DJ26: 0 | DK26: 0 | DL26: 0 | DM26: 0 | DN26: 0 | DO26: 0 | DP26: 0 | DQ26: 0 | DR26: 0 | DS26: 0 | DT26: 0 | DU26: 0 | DV26: 0 | DW26: 0 | DX26: 0 | DY26: 6 | DZ26: 0 | EA26: 5 | EB26: 5
B27: 7 | C27: Column upto Plinth Beam | D27: No's | E27: 33 | F27: =J27 -> 0 | G27: =E27-F27 -> 33 | H27: =F27/E27 -> 0 | J27: =SUM(K27:KBF27) -> 0 | BI27: 0
B28: 8 | C28: Plinth Beam Reinforcement | D28: Mtr | E28: 322 | F28: =J28 -> 0 | G28: =E28-F28 -> 322 | H28: =F28/E28 -> 0 | J28: =SUM(K28:XFD28) -> 0 | BI28: 0
B29: 9 | C29: Plinth Beam shuttering | D29: Mtr | E29: 322 | F29: =J29 -> 0 | G29: =E29-F29 -> 322 | H29: =F29/E29 -> 0 | J29: =SUM(K29:KBF29) -> 0 | BI29: 0
B30: 10 | C30: Plinth Beam Casting | D30: Mtr | E30: 322 | F30: =J30 -> 0 | G30: =E30-F30 -> 322 | H30: =F30/E30 -> 0 | J30: =SUM(K30:KBF30) -> 0 | BI30: 0
B31: 11 | C31: Column upto Lintel Beam | D31: No's | E31: 33 | F31: =J31 -> 0 | G31: =E31-F31 -> 33 | H31: =F31/E31 -> 0 | J31: =SUM(K31:KBF31) -> 0 | BI31: 0
B32: 12 | C32: Lintel and sunshade reinforcement & shuttering | D32: Mtr | E32: 132 | F32: =J32 -> 0 | G32: =E32-F32 -> 132 | H32: =F32/E32 -> 0 | J32: =SUM(K32:KBF32) -> 0 | BI32: 0
B33: 13 | C33: Lintel and sunshade casting | D33: Mtr | E33: 132 | F33: =J33 -> 0 | G33: =E33-F33 -> 132 | H33: =F33/E33 -> 0 | J33: =SUM(K33:KBF33) -> 0 | BI33: 0
B34: 14 | C34: Cable Trench PCC Base | D34: Mtr | E34: 50 | F34: =J34 -> 0 | G34: =E34-F34 -> 50 | H34: =F34/E34 -> 0 | J34: =SUM(K34:KBF34) -> 0 | BI34: 0
B35: 15 | C35: Cable Trench Reinforcement & Shuttering | D35: Mtr | E35: 50 | F35: =J35 -> 0 | G35: =E35-F35 -> 50 | H35: =F35/E35 -> 0 | J35: =SUM(K35:KBF35) -> 0 | BI35: 0
B36: 16 | C36: Cable Trench Raft Casting | D36: Mtr | E36: 50 | F36: =J36 -> 0 | G36: =E36-F36 -> 50 | H36: =F36/E36 -> 0 | J36: =SUM(K36:KBF36) -> 0 | BI36: 0
B37: 17 | C37: Cable Trench Wall casting | D37: Mtr | E37: 100 | F37: =J37 -> 0 | G37: =E37-F37 -> 100 | H37: =F37/E37 -> 0 | J37: =SUM(K37:KBF37) -> 0 | BI37: 0
B38: 18 | C38: Column upto Roof Beam | D38: No's | E38: 33 | F38: =J38 -> 0 | G38: =E38-F38 -> 33 | H38: =F38/E38 -> 0 | J38: =SUM(K38:KBF38) -> 0 | BI38: 0
B39: 19 | C39: Roof Beam & Slab shuttering | D39: Ls | E39: 1 | F39: =J39 -> 0 | G39: =E39-F39 -> 1 | H39: =F39/E39 -> 0 | J39: =SUM(K39:KBF39) -> 0 | BI39: 0
B40: 20 | C40: Roof Beam & Slab reinforcement | D40: Ls | E40: 1 | F40: =J40 -> 0 | J40: =SUM(K40:KBF40) -> 0 | BI40: 0
B41: 21 | C41: Roof Beam & Slab Casting | D41: Ls | E41: 1 | F41: =J41 -> 0 | G41: =E41-F41 -> 1 | H41: =F41/E41 -> 0 | J41: =SUM(K41:KBF41) -> 0 | BI41: 0
B42: 22 | C42: Floor Slab Casting | D42: Ls | E42: 1 | F42: =J42 -> 0 | G42: =E42-F42 -> 1 | H42: =F42/E42 -> 0 | J42: =SUM(K42:KBF42) -> 0 | BI42: 0
...

Sheet ICR Pilling
B1: ICR NO. | C1: Scope | D1: Piling Progress | E1: Progress in % | F1: 45863 | G1: =F1+1 -> 45864 | H1: =G1+1 -> 45865 | I1: =H1+1 -> 45866 | J1: =I1+1 -> 45867 | K1: =J1+1 -> 45868 | L1: =K1+1 -> 45869 | M1: =L1+1 -> 45870 | N1: =M1+1 -> 45871 | ... CZ1: =CY1+1 -> 45961
B2: Total | C2: =SUM(C3:C6) -> 25992 | D2: =SUM(D3:D6) -> 204 | E2: =D2/C2 -> 0.0078485688 | F2: =SUM(F3:F6) -> 0 | G2: =SUM(G3:G6) -> 0 | H2: =SUM(H3:H6) -> 0 | I2: =SUM(I3:I6) -> 0 | J2: =SUM(J3:J6) -> 12 | K2: =SUM(K3:K6) -> 0 | L2: =SUM(L3:L6) -> 0 | M2: =SUM(M3:M6) -> 0 | ... CZ2: =SUM(CZ3:CZ6) -> 0
B3: 1 | C3: 6498 | D3: =SUM(F3:CZ3) -> 0 | E3: =D3/C3 -> 0 | F3: 0 | G3: 0 | H3: 0 | I3: 0 | J3: 0 | K3: 0 | L3: 0 | M3: 0 | N3: 0 | O3: 0 | P3: 0 | Q3: 0 | R3: 0 | S3: 0 | T3: 0 | U3: 0 | V3: 0
B4: 2 | C4: 6498 | D4: =SUM(F4:CZ4) -> 204 | E4: =D4/C4 -> 0.031394275 | F4: 0 | G4: 0 | H4: 0 | I4: 0 | J4: 12 | K4: 0 | L4: 0 | M4: 0 | N4: 12 | O4: 24 | P4: 0 | Q4: 0 | R4: 0 | S4: 0 | T4: 48 | U4: 24 | V4: 84
B5: 3 | C5: 6498 | D5: =SUM(F5:CZ5) -> 0 | E5: =D5/C5 -> 0 | F5: 0 | G5: 0 | H5: 0 | I5: 0 | J5: 0 | K5: 0 | L5: 0 | M5: 0 | N5: 0 | O5: 0 | P5: 0 | Q5: 0 | R5: 0 | S5: 0 | T5: 0 | U5: 0 | V5: 0
B6: 4 | C6: 6498 | D6: =SUM(F6:CZ6) -> 0 | E6: =D6/C6 -> 0 | F6: 0 | G6: 0 | H6: 0 | I6: 0 | J6: 0 | K6: 0 | L6: 0 | M6: 0 | N6: 0 | O6: 0 | P6: 0 | Q6: 0 | R6: 0 | S6: 0 | T6: 0 | U6: 0 | V6: 0

Sheet Cont Piling
A1: S.no. | B1: Contractor | C1: Activity | D1: Scope | E1: Progress | F1: 45887 | G1: =F1+1 -> 45888 | H1: =G1+1 -> 45889 | I1: =H1+1 -> 45890 | J1: =I1+1 -> 45891 | K1: =J1+1 -> 45892 | L1: =K1+1 -> 45893 | M1: =L1+1 -> 45894 | N1: =M1+1 -> 45895 | ... DM1: =DL1+1 -> 45998 | DN1: 45597 | DO1: 45598 | DP1: 45599 | DQ1: 45600 | DR1: 45601 | DS1: 45602 | DT1: 45603 | DU1: 45604 | DV1: 45605 | DW1: 45606 | DX1: 45607 | DY1: 45608 | DZ1: 45609 | EA1: 45610 | EB1: 45611 | EC1: 45612 | ED1: 45613 | EE1: 45614 | EF1: 45615 | EG1: 45616 | EH1: 45617 | EI1: 45618 | EJ1: 45619 | EK1: 45620 | EL1: 45621 | EM1: 45622 | EN1: 45623 | EO1: 45624 | EP1: 45625 | EQ1: 45626 | ER1: =EQ1+1 -> 45627 | ES1: =ER1+1 -> 45628 | ET1: =ES1+1 -> 45629 | EU1: =ET1+1 -> 45630 | EV1: =EU1+1 -> 45631 | EW1: =EV1+1 -> 45632 | EX1: =EW1+1 -> 45633 | EY1: =EX1+1 -> 45634 | ... JH1: =JG1+1 -> 45747
A2: Block-01 | B2: TBD | C2: Marking | D2: 6498 | E2: =SUM(F2:HE2) -> 0 | F2: 0 | G2: 0 | H2: 0 | I2: 0 | J2: 0 | K2: 0 | L2: 0 | M2: 0 | N2: 0 | O2: 0 | P2: 0 | Q2: 0 | R2: 0 | S2: 0 | T2: 0 | U2: 0 | V2: 0 | W2: 0 | X2: 0 | Y2: 0 | Z2: 0 | AA2: 0 | AB2: 0 | AC2: 0
C3: Boring | D3: 6498 | E3: =SUM(F3:HE3) -> 0 | F3: 0 | G3: 0 | H3: 0 | I3: 0 | J3: 0 | K3: 0 | L3: 0 | M3: 0 | N3: 0 | O3: 0 | P3: 0 | Q3: 0 | R3: 0 | S3: 0 | T3: 0 | U3: 0 | V3: 0 | W3: 0 | X3: 0 | Y3: 0 | Z3: 0 | AA3: 0 | AB3: 0 | AC3: 0
C4: Casting | D4: 6498 | E4: =SUM(F4:HE4) -> 0 | F4: 0 | G4: 0 | H4: 0 | I4: 0 | J4: 0 | K4: 0 | L4: 0 | M4: 0 | N4: 0 | O4: 0 | P4: 0 | Q4: 0 | R4: 0 | S4: 0 | T4: 0 | U4: 0 | V4: 0 | W4: 0 | X4: 0 | Y4: 0 | Z4: 0 | AA4: 0 | AB4: 0 | AC4: 0
C5: Capping | D5: 6498 | E5: =SUM(F5:HE5) -> 0 | F5: 0 | G5: 0 | H5: 0 | I5: 0 | J5: 0 | K5: 0 | L5: 0 | M5: 0 | N5: 0 | O5: 0 | P5: 0 | Q5: 0 | R5: 0 | S5: 0 | T5: 0 | U5: 0 | V5: 0 | W5: 0 | X5: 0 | Y5: 0 | Z5: 0 | AA5: 0 | AB5: 0 | AC5: 0
A6: Block-02 | B6: Yash Construction | C6: Marking | D6: 6498 | E6: =SUM(F6:HE6) -> 3294 | F6: 0 | G6: 0 | H6: 0 | I6: 0 | J6: 0 | K6: 0 | L6: 0 | M6: 0 | N6: 0 | O6: 0 | P6: 0 | Q6: 0 | R6: 0 | S6: 3244 | T6: 0 | U6: 0 | V6: 0 | W6: 0 | X6: 0 | Y6: 0 | Z6: 0 | AA6: 0 | AB6: 50 | AC6: 0
C7: Boring | D7: 6498 | E7: =SUM(F7:HE7) -> 903 | F7: 0 | G7: 0 | H7: 0 | I7: 0 | J7: 0 | K7: 0 | L7: 0 | M7: 0 | N7: 0 | O7: 0 | P7: 0 | Q7: 500 | R7: 0 | S7: 100 | T7: 100 | U7: 100 | V7: 35 | W7: 13 | X7: 0 | Y7: 0 | Z7: 0 | AA7: 30 | AB7: 25 | AC7: 0
C8: Casting | D8: 6498 | E8: =SUM(F8:HE8) -> 204 | F8: 0 | G8: 0 | H8: 0 | I8: 0 | J8: 0 | K8: 0 | L8: 0 | M8: 0 | N8: 0 | O8: 0 | P8: 0 | Q8: 12 | R8: 0 | S8: 0 | T8: 0 | U8: 12 | V8: 24 | W8: 0 | X8: 0 | Y8: 0 | Z8: 0 | AA8: 48 | AB8: 24 | AC8: 84
C9: Capping | D9: 6498 | E9: =SUM(F9:HE9) -> 0 | F9: 0 | G9: 0 | H9: 0 | I9: 0 | J9: 0 | K9: 0 | L9: 0 | M9: 0 | N9: 0 | O9: 0 | P9: 0 | Q9: 0 | R9: 0 | S9: 0 | T9: 0 | U9: 0 | V9: 0 | W9: 0 | X9: 0 | Y9: 0 | Z9: 0 | AA9: 0 | AB9: 0 | AC9: 0
A10: Block-03 | B10: MST | C10: Marking | D10: 6498 | E10: =SUM(F10:HE10) -> 0 | F10: 0 | G10: 0 | H10: 0 | I10: 0 | J10: 0 | K10: 0 | L10: 0 | M10: 0 | N10: 0 | O10: 0 | P10: 0 | Q10: 0 | R10: 0 | S10: 0 | T10: 0 | U10: 0 | V10: 0 | W10: 0 | X10: 0 | Y10: 0 | Z10: 0 | AA10: 0 | AB10: 0 | AC10: 0
C11: Boring | D11: 6498 | E11: =SUM(F11:HE11) -> 0 | F11: 0 | G11: 0 | H11: 0 | I11: 0 | J11: 0 | K11: 0 | L11: 0 | M11: 0 | N11: 0 | O11: 0 | P11: 0 | Q11: 0 | R11: 0 | S11: 0 | T11: 0 | U11: 0 | V11: 0 | W11: 0 | X11: 0 | Y11: 0 | Z11: 0 | AA11: 0 | AB11: 0 | AC11: 0
C12: Casting | D12: 6498 | E12: =SUM(F12:HE12) -> 0 | F12: 0 | G12: 0 | H12: 0 | I12: 0 | J12: 0 | K12: 0 | L12: 0 | M12: 0 | N12: 0 | O12: 0 | P12: 0 | Q12: 0 | R12: 0 | S12: 0 | T12: 0 | U12: 0 | V12: 0 | W12: 0 | X12: 0 | Y12: 0 | Z12: 0 | AA12: 0 | AB12: 0 | AC12: 0
C13: Capping | D13: 6498 | E13: =SUM(F13:HE13) -> 0 | F13: 0 | G13: 0 | H13: 0 | I13: 0 | J13: 0 | K13: 0 | L13: 0 | M13: 0 | N13: 0 | O13: 0 | P13: 0 | Q13: 0 | R13: 0 | S13: 0 | T13: 0 | U13: 0 | V13: 0 | W13: 0 | X13: 0 | Y13: 0 | Z13: 0 | AA13: 0 | AB13: 0 | AC13: 0
A14: Block-04 | B14: TBD | C14: Marking | D14: 6498 | E14: =SUM(F14:HE14) -> 670 | F14: 0 | G14: 0 | H14: 0 | I14: 0 | J14: 0 | K14: 0 | L14: 0 | M14: 0 | N14: 0 | O14: 0 | P14: 0 | Q14: 0 | R14: 0 | S14: 670 | T14: 0 | U14: 0 | V14: 0 | W14: 0 | X14: 0 | Y14: 0 | Z14: 0 | AA14: 0 | AB14: 0 | AC14: 0
C15: Boring | D15: 6498 | E15: =SUM(F15:HE15) -> 211 | F15: 0 | G15: 0 | H15: 0 | I15: 0 | J15: 0 | K15: 0 | L15: 0 | M15: 0 | N15: 0 | O15: 0 | P15: 0 | Q15: 0 | R15: 0 | S15: 211 | T15: 0 | U15: 0 | V15: 0 | W15: 0 | X15: 0 | Y15: 0 | Z15: 0 | AA15: 0 | AB15: 0 | AC15: 0
C16: Casting | D16: 6498 | E16: =SUM(F16:HE16) -> 0 | F16: 0 | G16: 0 | H16: 0 | I16: 0 | J16: 0 | K16: 0 | L16: 0 | M16: 0 | N16: 0 | O16: 0 | P16: 0 | Q16: 0 | R16: 0 | S16: 0 | T16: 0 | U16: 0 | V16: 0 | W16: 0 | X16: 0 | Y16: 0 | Z16: 0 | AA16: 0 | AB16: 0 | AC16: 0
C17: Capping | D17: 6498 | E17: =SUM(F17:HE17) -> 0 | F17: 0 | G17: 0 | H17: 0 | I17: 0 | J17: 0 | K17: 0 | L17: 0 | M17: 0 | N17: 0 | O17: 0 | P17: 0 | Q17: 0 | R17: 0 | S17: 0 | T17: 0 | U17: 0 | V17: 0 | W17: 0 | X17: 0 | Y17: 0 | Z17: 0 | AA17: 0 | AB17: 0 | AC17: 0
B19: Activity | C19: Scope | D19: Progress | E19: Progress in %
B20: Marking | C20: =D2+D6+D10+D14 -> 25992 | D20: =E2+E6+E10+E14 -> 3964 | E20: =D20/C20 -> 0.15250846
B21: Boring | C21: =D3+D7+D11+D15 -> 25992 | D21: =E3+E7+E11+E15 -> 1114 | E21: =D21/C21 -> 0.042859341
B22: Casting | C22: =D4+D8+D12+D16 -> 25992 | D22: =E4+E8+E12+E16 -> 204 | E22: =D22/C22 -> 0.0078485688
B23: Capping | C23: =D5+D9+D13+D17 -> 25992 | D23: =E5+E9+E13+E17 -> 0 | E23: =D23/C23 -> 0
E24: =AVERAGE(E20:E23) -> 0.050804094

Sheet SW Civil
B1: Switchyard Equipment Progress
B2: Sr. No. | C2: Description | D2: UOM | E2: Weightage Scope | F2: Weightage completion | G2: Equipments | H2: Foundation Scope (Nos) | I2: Excavation | M2: PCC | Q2: Raft Foundation | U2: Column casting/J-bolt fixing
I3: Start Date | J3: End Date | K3: Progress | L3: Percentage | M3: Start Date | N3: End Date | O3: Progress | P3: Percentage | Q3: Start Date | R3: End Date | S3: Progress | T3: Percentage | U3: Start Date | V3: End Date | W3: Progress | X3: Percentage | AJ3: Sr. No. | AK3: Description | AL3: Activity | AM3: Unit | AN3: Equipment | AO3: Foundation | AP3: Cummulative | AQ3: Balance | AS3: 45608 | AT3: =AS3+1 -> 45609 | AU3: =AT3+1 -> 45610 | AV3: =AU3+1 -> 45611 | AW3: =AV3+1 -> 45612 | AX3: =AW3+1 -> 45613 | AY3: =AX3+1 -> 45614 | AZ3: =AY3+1 -> 45615 | BA3: =AZ3+1 -> 45616 | ... HT3: =HS3+1 -> 45791
B4: 1 | C4: Tower Foundation | D4: Nos | E4: 0.15 | F4: =E4*(AVERAGE(K4,O4,S4,W4)/H4) -> 0 | G4: 14 | H4: 14 | K4: =AP4 -> 0 | L4: =K4/H4 -> 0 | M4: =I4+2 -> 2 | N4: =M4+25 -> 27 | O4: =AP5 -> 0 | P4: =O4/H4 -> 0 | Q4: =M4+25 -> 27 | R4: =Q4+20 -> 47 | S4: =AP6 -> 0 | T4: =S4/H4 -> 0 | U4: =Q4+10 -> 37 | V4: =U4+20 -> 57 | W4: =AP7 -> 0 | X4: =W4/H4 -> 0 | Z4: =AVERAGE(K4,O4,S4,W4)/H4 -> 0 | AJ4: 1 | AK4: Tower Foundation | AL4: EXC | AM4: Nos | AN4: 14 | AO4: 14 | AP4: =SUM(AS4:JG4) -> 0 | AQ4: =AO4-AP4 -> 14
B5: 2 | C5: Power Transformer | D5: Nos | E5: 0.15 | F5: =E5*(AVERAGE(K5,O5,S5,W5)/H5) -> 0 | G5: 2 | H5: 2 | K5: =AP8 -> 0 | L5: =K5/H5 -> 0 | M5: =J5 -> 0 | N5: =M5+6 -> 6 | O5: =AP9 -> 0 | P5: =O5/H5 -> 0 | Q5: =N5+10 -> 16 | R5: =Q5+10 -> 26 | S5: =AP10 -> 0 | T5: =S5/H5 -> 0 | U5: =R5+1 -> 27 | V5: =U5+25 -> 52 | W5: =AP11 -> 0 | X5: =W5/H5 -> 0 | Z5: =AVERAGE(K5,O5,S5,W5)/H5 -> 0 | AL5: PCC | AP5: =SUM(AS5:JG5) -> 0 | AQ5: =AO4-AP5 -> 14
B6: 3 | C6: LM Tower | D6: Nos | E6: 0.01 | F6: =E6*(AVERAGE(K6,O6,S6,W6)/H6) -> 0 | G6: 1 | H6: 1 | K6: =AP12 -> 0 | L6: =K6/H6 -> 0 | M6: =J6+1 -> 1 | N6: =M6+1 -> 2 | O6: =AP13 -> 0 | P6: =O6/H6 -> 0 | Q6: =R4+1 -> 48 | R6: =Q6+3 -> 51 | S6: =AP14 -> 0 | T6: =S6/H6 -> 0 | U6: =R6+2 -> 53 | V6: =U6+4 -> 57 | W6: =AP15 -> 0 | X6: =W6/H6 -> 0 | Z6: =AVERAGE(K6,O6,S6,W6)/H6 -> 0 | AL6: Raft | AP6: =SUM(AS6:JG6) -> 0 | AQ6: =AO4-AP6 -> 14
B7: 4 | C7: LA | D7: Nos | E7: 0.02 | F7: =E7*(AVERAGE(K7,O7,S7,W7)/H7) -> 0 | G7: 3 | H7: 3 | K7: =AP16 -> 0 | L7: =K7/H7 -> 0 | M7: =J7 -> 0 | N7: =M7+1 -> 1 | O7: =AP17 -> 0 | P7: =O7/H7 -> 0 | Q7: =N7+1 -> 2 | R7: =Q7+2 -> 4 | S7: =AP18 -> 0 | T7: =S7/H7 -> 0 | U7: =R7+1 -> 5 | V7: =U7+4 -> 9 | W7: =AP19 -> 0 | X7: =W7/H7 -> 0 | Z7: =AVERAGE(K7,O7,S7,W7)/H7 -> 0 | AL7: Column | AP7: =SUM(AS7:JG7) -> 0 | AQ7: =AO4-AP7 -> 14
B8: 5 | C8: HLA | D8: Nos | E8: 0.01 | F8: =E8*(AVERAGE(K8,O8,S8,W8)/H8) -> 0 | G8: 6 | H8: 6 | K8: =AP20 -> 0 | L8: =K8/H8 -> 0 | M8: =J8 -> 0 | N8: =M8+1 -> 1 | O8: =AP21 -> 0 | P8: =O8/H8 -> 0 | Q8: =N8+1 -> 2 | R8: =Q8+1 -> 3 | S8: =AP22 -> 0 | T8: =S8/H8 -> 0 | U8: =R8+1 -> 4 | V8: =U8+3 -> 7 | W8: =AP23 -> 0 | X8: =W8/H8 -> 0 | Z8: =AVERAGE(K8,O8,S8,W8)/H8 -> 0 | AJ8: 2 | AK8: Power Transformer | AL8: EXC | AM8: Nos | AN8: 2 | AO8: 2 | AP8: =SUM(AS8:JG8) -> 0 | AQ8: =AO8-AP8 -> 2
B9: 6 | C9: CB | D9: Nos | E9: 0.04 | F9: =E9*(AVERAGE(K9,O9,S9,W9)/H9) -> 0 | G9: 12 | H9: 12 | K9: =AP24 -> 0 | L9: =K9/H9 -> 0 | O9: =AP25 -> 0 | P9: =O9/H9 -> 0 | S9: =AP26 -> 0 | T9: =S9/H9 -> 0 | W9: =AP27 -> 0 | X9: =W9/H9 -> 0 | Z9: =AVERAGE(K9,O9,S9,W9)/H9 -> 0 | AL9: PCC | AP9: =SUM(AS9:JG9) -> 0 | AQ9: =AO8-AP9 -> 2
