Workbook

Sheet SECI O&M Dashboard
D2: SECI O&M Generation Data
D3: Date | E3: =TODAY()-1 -> 46027
B4: O&M Sites | C4: SOALR PERFORMANCE | K4: BESS PERFORMANCE | Q4: Remarks
C5: As on Date* | G5: Year Till date* (FY 2025-26) | I5: Last FY Performance^ | K5: As on Date* | M5: Year Till date* (FY 2025-26) | O5: Last FY Performance^
C6: GHI (Kwh/sq. m) | D6: Exported generation (MU) | E6: CUF (%) | F6: Peak Power (Mw) | G6: Exported generation (MU) | H6: CUF (%) | I6: Exported generation (MU) | J6: CUF (%) | K6: Net Energy Export (MwH) | L6: Net Energy Import (MwH) | M6: Net Energy Export (MwH) | N6: Net Energy Import (MwH) | O6: Net Energy Export (MwH) | P6: Net Energy FED (MwH)
B7: SECI 100 MW SPV with 40MW/120MWh BESS Rajnandgaon | C7: ='Rajnandgaon Dashboard'!B9 -> 4.17 | D7: ='Rajnandgaon Dashboard'!C9 -> 0.5852076 | E7: ='Rajnandgaon Dashboard'!D9 -> 0.2438365 | F7: ='Rajnandgaon Dashboard'!E9 -> 69.69 | G7: ='Rajnandgaon Dashboard'!H9 -> 164.49503 | H7: ='Rajnandgaon Dashboard'!I9 -> 0.24478427 | K7: ='Rajnandgaon Dashboard'!F9 -> 116.5 | L7: ='Rajnandgaon Dashboard'!G9 -> 130.1 | M7: ='Rajnandgaon Dashboard'!J9 -> 30197.958 | N7: ='Rajnandgaon Dashboard'!K9 -> 33501.13 | Q7: =IF(VLOOKUP(E3,'Rajnandgaon Data'!A:P,16,0)=0,"-",VLOOKUP(E3,'Rajnandgaon Data'!A:P,16,0)) -> -
B8: SECI 10MW Badi Sid | C8: ='BADI SID Dashboard'!B8 -> 3.41 | D8: ='BADI SID Dashboard'!C8 -> 0.0408 | E8: ='BADI SID Dashboard'!D8 -> 0.17 | F8: ='BADI SID Dashboard'!E8/1000 -> 8.95 | G8: ='BADI SID Dashboard'!F8 -> 13.079696 | H8: ='BADI SID Dashboard'!G8 -> 0.19463834 | Q8: =IF(VLOOKUP(E3,'BADI SID DATA'!A:K,11,0)=0,"-",VLOOKUP(E3,'BADI SID DATA'!A:K,11,0)) -> -
B9: SECI 10 MW DRDO, Kolar | C9: ='DRDO Kolar Dashboard'!B8 -> 0 | D9: ='DRDO Kolar Dashboard'!C8 -> 0.0624 | E9: ='DRDO Kolar Dashboard'!D8 -> 0.26 | F9: =('DRDO Kolar Dashboard'!E8)/1000 -> 8.98 | G9: ='DRDO Kolar Dashboard'!F8 -> 12.994908 | H9: ='DRDO Kolar Dashboard'!G8 -> 0.1933766 | Q9: =IF(VLOOKUP(E3,'DRDO Kolar Data'!A:K,11,0)=0,"-",VLOOKUP(E3,'DRDO Kolar Data'!A:K,11,0)) -> -
B10: SECI 1.4 MW SPV with 1.4 MWh BESS Kaveratti, Lakshdweep | C10: ='Kaveratti 1.4 MW Solar+BESS DB'!B9 -> 4.3 | D10: ='Kaveratti 1.4 MW Solar+BESS DB'!C9 -> 0.005537 | E10: ='Kaveratti 1.4 MW Solar+BESS DB'!D9 -> 0.16479167 | F10: ='Kaveratti 1.4 MW Solar+BESS DB'!E9/1000 -> 0.938 | G10: ='Kaveratti 1.4 MW Solar+BESS DB'!H9 -> 1.6155374 | H10: ='Kaveratti 1.4 MW Solar+BESS DB'!I9 -> 0.17171954 | K10: ='Kaveratti 1.4 MW Solar+BESS DB'!F9/1000 -> 1.275 | L10: ='Kaveratti 1.4 MW Solar+BESS DB'!G9/1000 -> 1.434 | M10: ='Kaveratti 1.4 MW Solar+BESS DB'!J9/1000&"^" -> 87.75261^ | N10: ='Kaveratti 1.4 MW Solar+BESS DB'!K9/1000&"^" -> 96.962^ | Q10: =IF(VLOOKUP(E3,'Kaveratti Data'!A:P,16,0)=0,"-",VLOOKUP(E3,'Kaveratti Data'!A:P,16,0)) -> -
B11: SECI 0.3 MW Agatti Lakshdweep | C11: ='Agatti Dashboard'!B8 -> 3.96 | D11: ='Agatti Dashboard'!C8 -> 0.001075 | E11: ='Agatti Dashboard'!D8 -> 0.14930556 | F11: ='Agatti Dashboard'!E8/1000 -> 0.19 | G11: ='Agatti Dashboard'!F8 -> 0.3459531 | H11: ='Agatti Dashboard'!G8 -> 0.17160372 | Q11: =IF(VLOOKUP(E3,'Agatti Data'!A:K,11,0)=0,"-",VLOOKUP(E3,'Agatti Data'!A:K,11,0)) -> -
B13: *Data is without considering radiation correction
B14: ^Data is from 21st October

Sheet DRDO Kolar Dashboard
B1: Date | C1: ='SECI O&M Dashboard'!E3 -> 46027
B4: SECI 10MW DRDO, Kolar
B5: Date* | D5: =C1 -> 46027 | F5: Year Till date* | H5: Last FY Performance^
B6: *Data is without considering radiation correction | H6: ^Data is with radiation correction
B7: GHI (Kwh/sq. m) | C7: Exported generation (MU) | D7: CUF (%) | E7: Peak Power (Kw) | F7: Exported generation (MU) | G7: CUF (%) | H7: Exported generation (MU) | J7: CUF (%)
B8: =VLOOKUP(C1,'DRDO Kolar Data'!A:D,4,0) -> 0 | C8: =VLOOKUP(C1,'DRDO Kolar Data'!A:C,3,FALSE)/10^6 -> 0.0624 | D8: =VLOOKUP(C1,'DRDO Kolar Data'!A:I,9,0) -> 0.26 | E8: =VLOOKUP(D5,'DRDO Kolar Data'!A:E,5,0)*1000 -> 8980 | F8: =VLOOKUP(C1,'DRDO Kolar Data'!A:H,8,0)/10^6 -> 12.994908 | G8: =VLOOKUP(C1,'DRDO Kolar Data'!A:J,10,0) -> 0.1933766
B11: Generation Data for last 7 days
B12: Date | C12: Radiation POA (Kwh/sq. m) | D12: Exported generation (KWh) | E12: CUF (%) | F12: Peak Power (Kw) | G12: Radiation POA (Kwh/sq. m) | H12: Exported generation (KWh) | I12: CUF (%) | J12: Peak Power (Kw)
C13: =YEAR(C1) -> 2026 | G13: =C13-1 -> 2025
B14: =C1-1 -> 46026 | C14: =VLOOKUP(B14,'DRDO Kolar Data'!A:D,4,0) -> 0 | D14: =VLOOKUP(B14,'DRDO Kolar Data'!A:C,3,0) -> 57000 | E14: =VLOOKUP('DRDO Kolar Dashboard'!B14,'DRDO Kolar Data'!A:I,9,0) -> 0.2375 | F14: =VLOOKUP(B14,'DRDO Kolar Data'!A:E,5,0)*1000 -> 9770 | G14: =VLOOKUP(B14-365,'DRDO Kolar Data'!A:D,4,0) -> 6.6 | H14: =VLOOKUP(B14-365,'DRDO Kolar Data'!A:C,3,0) -> 61754.55 | I14: =VLOOKUP(B14-365,'DRDO Kolar Data'!A:I,9,0) -> 0.25731062 | J14: =VLOOKUP(B14-365,'DRDO Kolar Data'!A:E,5,0)*1000 -> 10800
B15: =B14-1 -> 46025 | C15: =VLOOKUP(B15,'DRDO Kolar Data'!A:D,4,0) -> 0 | D15: =VLOOKUP(B15,'DRDO Kolar Data'!A:C,3,0) -> 52800 | E15: =VLOOKUP('DRDO Kolar Dashboard'!B15,'DRDO Kolar Data'!A:I,9,0) -> 0.22 | F15: =VLOOKUP(B15,'DRDO Kolar Data'!A:E,5,0)*1000 -> 9210 | G15: =VLOOKUP(B15-365,'DRDO Kolar Data'!A:D,4,0) -> 6.7 | H15: =VLOOKUP(B15-365,'DRDO Kolar Data'!A:C,3,0) -> 63048.7 | I15: =VLOOKUP(B15-365,'DRDO Kolar Data'!A:I,9,0) -> 0.26270292 | J15: =VLOOKUP(B15-365,'DRDO Kolar Data'!A:E,5,0)*1000 -> 10300
B16: =B15-1 -> 46024 | C16: =VLOOKUP(B16,'DRDO Kolar Data'!A:D,4,0) -> 0 | D16: =VLOOKUP(B16,'DRDO Kolar Data'!A:C,3,0) -> 43800 | E16: =VLOOKUP('DRDO Kolar Dashboard'!B16,'DRDO Kolar Data'!A:I,9,0) -> 0.1825 | F16: =VLOOKUP(B16,'DRDO Kolar Data'!A:E,5,0)*1000 -> 5330 | G16: =VLOOKUP(B16-365,'DRDO Kolar Data'!A:D,4,0) -> 6.62 | H16: =VLOOKUP(B16-365,'DRDO Kolar Data'!A:C,3,0) -> 61746.75 | I16: =VLOOKUP(B16-365,'DRDO Kolar Data'!A:I,9,0) -> 0.25727813 | J16: =VLOOKUP(B16-365,'DRDO Kolar Data'!A:E,5,0)*1000 -> 10600
B17: =B16-1 -> 46023 | C17: =VLOOKUP(B17,'DRDO Kolar Data'!A:D,4,0) -> 0 | D17: =VLOOKUP(B17,'DRDO Kolar Data'!A:C,3,0) -> 29739 | E17: =VLOOKUP('DRDO Kolar Dashboard'!B17,'DRDO Kolar Data'!A:I,9,0) -> 0.1239125 | F17: =VLOOKUP(B17,'DRDO Kolar Data'!A:E,5,0)*1000 -> 3600 | G17: =VLOOKUP(B17-365,'DRDO Kolar Data'!A:D,4,0) -> 6.56 | H17: =VLOOKUP(B17-365,'DRDO Kolar Data'!A:C,3,0) -> 61754.55 | I17: =VLOOKUP(B17-365,'DRDO Kolar Data'!A:I,9,0) -> 0.25731062 | J17: =VLOOKUP(B17-365,'DRDO Kolar Data'!A:E,5,0)*1000 -> 10100
B18: =B17-1 -> 46022 | C18: =VLOOKUP(B18,'DRDO Kolar Data'!A:D,4,0) -> 0 | D18: =VLOOKUP(B18,'DRDO Kolar Data'!A:C,3,0) -> 46800 | E18: =VLOOKUP('DRDO Kolar Dashboard'!B18,'DRDO Kolar Data'!A:I,9,0) -> 0.195 | F18: =VLOOKUP(B18,'DRDO Kolar Data'!A:E,5,0)*1000 -> 8720 | G18: =VLOOKUP(B18-365,'DRDO Kolar Data'!A:D,4,0) -> 7.06 | H18: =VLOOKUP(B18-365,'DRDO Kolar Data'!A:C,3,0) -> 65000 | I18: =VLOOKUP(B18-365,'DRDO Kolar Data'!A:I,9,0) -> 0.27083333 | J18: =VLOOKUP(B18-365,'DRDO Kolar Data'!A:E,5,0)*1000 -> 10900
B19: =B18-1 -> 46021 | C19: =VLOOKUP(B19,'DRDO Kolar Data'!A:D,4,0) -> 0 | D19: =VLOOKUP(B19,'DRDO Kolar Data'!A:C,3,0) -> 54000 | E19: =VLOOKUP('DRDO Kolar Dashboard'!B19,'DRDO Kolar Data'!A:I,9,0) -> 0.225 | F19: =VLOOKUP(B19,'DRDO Kolar Data'!A:E,5,0)*1000 -> 9390 | G19: =VLOOKUP(B19-365,'DRDO Kolar Data'!A:D,4,0) -> 3.65 | H19: =VLOOKUP(B19-365,'DRDO Kolar Data'!A:C,3,0) -> 36396.1 | I19: =VLOOKUP(B19-365,'DRDO Kolar Data'!A:I,9,0) -> 0.15165042 | J19: =VLOOKUP(B19-365,'DRDO Kolar Data'!A:E,5,0)*1000 -> 9100
B20: =B19-1 -> 46020 | C20: =VLOOKUP(B20,'DRDO Kolar Data'!A:D,4,0) -> 0 | D20: =VLOOKUP(B20,'DRDO Kolar Data'!A:C,3,0) -> 59400 | E20: =VLOOKUP('DRDO Kolar Dashboard'!B20,'DRDO Kolar Data'!A:I,9,0) -> 0.2475 | F20: =VLOOKUP(B20,'DRDO Kolar Data'!A:E,5,0)*1000 -> 8370 | G20: =VLOOKUP(B20-365,'DRDO Kolar Data'!A:D,4,0) -> 5.78 | H20: =VLOOKUP(B20-365,'DRDO Kolar Data'!A:C,3,0) -> 54605.2 | I20: =VLOOKUP(B20-365,'DRDO Kolar Data'!A:I,9,0) -> 0.22752167 | J20: =VLOOKUP(B20-365,'DRDO Kolar Data'!A:E,5,0)*1000 -> 10600

Sheet DRDO Kolar Data
A1: date | B1: Days | C1: generation (In Kwh) | D1: Radiation (Tilt), no normal GHI is there | E1: Peak Power (in Mw) | F1: machine_availability | G1: grid_availability | H1: cumulative(in KwH) | I1: CUF | J1: CUF till date W.o.C | K1: Weather Remark
A2: 44805 | B2: 1 | C2: 45499.35 | D2: 5.39 | E2: 11.1 | F2: 1 | G2: 0.97777778 | H2: =C2 -> 45499.35 | I2: =C2/(10*24*1000) -> 0.18958062 | J2: =H2/(24*B2*10*1000) -> 0.18958062 | K2: Mostly Cloudy and Rainy
A3: 44806 | B3: 2 | C3: 52649.35 | D3: 6 | E3: 11.1 | F3: 1 | G3: 0.97986111 | H3: =H2+C3 -> 98148.7 | I3: =C3/(10*24*1000) -> 0.21937229 | J3: =H3/(24*B3*10*1000) -> 0.20447646 | K3: Cloudy
A4: 44807 | B4: 3 | C4: 52650 | D4: 6 | E4: 11 | F4: 1 | G4: 1 | H4: =H3+C4 -> 150798.7 | I4: =C4/(10*24*1000) -> 0.219375 | J4: =H4/(24*B4*10*1000) -> 0.20944264 | K4: Cloudy and Rainy
A5: 44808 | B5: 4 | C5: 42900.65 | D5: 4.82 | E5: 11.1 | F5: 1 | G5: 1 | H5: =H4+C5 -> 193699.35 | I5: =C5/(10*24*1000) -> 0.17875271 | J5: =H5/(24*B5*10*1000) -> 0.20177016 | K5: Cloudy and Rainy
A6: 44809 | B6: 5 | C6: 65650 | D6: 6.99 | E6: 10 | F6: 1 | G6: 1 | H6: =H5+C6 -> 259349.35 | I6: =C6/(10*24*1000) -> 0.27354167 | J6: =H6/(24*B6*10*1000) -> 0.21612446 | K6: Partially Cloudy
A7: 44810 | B7: 6 | C7: 52650 | D7: 5.39 | E7: 10 | F7: 1 | G7: 1 | H7: =H6+C7 -> 311999.35 | I7: =C7/(10*24*1000) -> 0.219375 | J7: =H7/(24*B7*10*1000) -> 0.21666622 | K7: Cloudy and Rainy
A8: 44811 | B8: 7 | C8: 29250.65 | D8: 3.04 | E8: 10.3 | F8: 1 | G8: 1 | H8: =H7+C8 -> 341250 | I8: =C8/(10*24*1000) -> 0.12187771 | J8: =H8/(24*B8*10*1000) -> 0.203125 | K8: Mostly Cloudy
A9: 44812 | B9: 8 | C9: 24698.7 | D9: 2.64 | E9: 10.2 | F9: 1 | G9: 1 | H9: =H8+C9 -> 365948.7 | I9: =C9/(10*24*1000) -> 0.10291125 | J9: =H9/(24*B9*10*1000) -> 0.19059828 | K9: Mostly Cloudy and Rainy
A10: 44813 | B10: 9 | C10: 47450.65 | D10: 4.94 | E10: 10.6 | F10: 1 | G10: 1 | H10: =H9+C10 -> 413399.35 | I10: =C10/(10*24*1000) -> 0.19771104 | J10: =H10/(24*B10*10*1000) -> 0.19138859 | K10: Mostly Cloudy
A11: 44814 | B11: 10 | C11: 43550.65 | D11: 4.49 | E11: 10.1 | F11: 1 | G11: 1 | H11: =H10+C11 -> 456950 | I11: =C11/(10*24*1000) -> 0.18146104 | J11: =H11/(24*B11*10*1000) -> 0.19039583 | K11: Mostly Cloudy
A12: 44815 | B12: 11 | C12: 38350 | D12: 4.02 | E12: 10.4 | F12: 1 | G12: 1 | H12: =H11+C12 -> 495300 | I12: =C12/(10*24*1000) -> 0.15979167 | J12: =H12/(24*B12*10*1000) -> 0.18761364 | K12: Mostly Cloudy
A13: 44816 | B13: 12 | C13: 49398.7 | D13: 5.17 | E13: 10.8 | F13: 1 | G13: 1 | H13: =H12+C13 -> 544698.7 | I13: =C13/(10*24*1000) -> 0.20582792 | J13: =H13/(24*B13*10*1000) -> 0.18913149 | K13: Mostly Cloudy
A14: 44817 | B14: 13 | C14: 49400.65 | D14: 5.1 | E14: 10.2 | F14: 1 | G14: 1 | H14: =H13+C14 -> 594099.35 | I14: =C14/(10*24*1000) -> 0.20583604 | J14: =H14/(24*B14*10*1000) -> 0.19041646 | K14: Mostly Cloudy
... A213: 45016 | B213: 212 | C213: 40950.65 | D213: 5.41 | E213: 7.9 | F213: 1 | G213: 0.94375 | H213: =H212+C213 -> 10782855 | I213: =C213/(10*24*1000) -> 0.17062771 | J213: =H213/(24*B213*10*1000) -> 0.21192717 | K213: Cloudy
A214: 45017 | B214: =VLOOKUP(A214,'BADI SID DATA'!A:B,2,0) -> 1 | C214: 44199.35 | D214: 5.11 | E214: 9.7 | F214: 1 | G214: 1 | H214: =C214 -> 44199.35 | I214: =C214/(10*24*1000) -> 0.18416396 | J214: =H214/(24*B214*10*1000) -> 0.18416396 | K214: Cloudy
A215: 45018 | B215: =VLOOKUP(A215,'BADI SID DATA'!A:B,2,0) -> 2 | C215: 40300 | D215: 4.32 | E215: 10 | F215: 1 | G215: 1 | H215: =C215+H214 -> 84499.35 | I215: =C215/(10*24*1000) -> 0.16791667 | J215: =H215/(24*B215*10*1000) -> 0.17604031 | K215: Mostly Cloudy
A216: 45019 | B216: =VLOOKUP(A216,'BADI SID DATA'!A:B,2,0) -> 3 | C216: 44850 | D216: 5.04 | E216: 9.8 | F216: 1 | G216: 1 | H216: =C216+H215 -> 129349.35 | I216: =C216/(10*24*1000) -> 0.186875 | J216: =H216/(24*B216*10*1000) -> 0.17965188 | K216: Cloudy
A217: 45020 | B217: =VLOOKUP(A217,'BADI SID DATA'!A:B,2,0) -> 4 | C217: 47448.7 | D217: 5.44 | E217: 9.6 | F217: 1 | G217: 1 | H217: =C217+H216 -> 176798.05 | I217: =C217/(10*24*1000) -> 0.19770292 | J217: =H217/(24*B217*10*1000) -> 0.18416464 | K217: Cloudy
A218: 45021 | B218: =VLOOKUP(A218,'BADI SID DATA'!A:B,2,0) -> 5 | C218: 55899.35 | D218: 6.38 | E218: 8.9 | F218: 1 | G218: 1 | H218: =C218+H217 -> 232697.4 | I218: =C218/(10*24*1000) -> 0.23291396 | J218: =H218/(24*B218*10*1000) -> 0.1939145 | K218: Partially Cloudy
A219: 45022 | B219: =VLOOKUP(A219,'BADI SID DATA'!A:B,2,0) -> 6 | C219: 57200 | D219: 6.01 | E219: 9.2 | F219: 1 | G219: 1 | H219: =C219+H218 -> 289897.4 | I219: =C219/(10*24*1000) -> 0.23833333 | J219: =H219/(24*B219*10*1000) -> 0.20131764 | K219: Partially Cloudy
A220: 45023 | B220: =VLOOKUP(A220,'BADI SID DATA'!A:B,2,0) -> 7 | C220: 60449.35 | D220: 6.28 | E220: 9.1 | F220: 1 | G220: 1 | H220: =C220+H219 -> 350346.75 | I220: =C220/(10*24*1000) -> 0.25187229 | J220: =H220/(24*B220*10*1000) -> 0.20853973 | K220: Partially Cloudy
A221: 45024 | B221: =VLOOKUP(A221,'BADI SID DATA'!A:B,2,0) -> 8 | C221: 64349.35 | D221: 6.89 | E221: 9.5 | F221: 1 | G221: 1 | H221: =C221+H220 -> 414696.1 | I221: =C221/(10*24*1000) -> 0.26812229 | J221: =H221/(24*B221*10*1000) -> 0.21598755 | K221: Partially Cloudy
A222: 45025 | B222: =VLOOKUP(A222,'BADI SID DATA'!A:B,2,0) -> 9 | C222: 65000 | D222: 6.69 | E222: 9.1 | F222: 1 | G222: 1 | H222: =C222+H221 -> 479696.1 | I222: =C222/(10*24*1000) -> 0.27083333 | J222: =H222/(24*B222*10*1000) -> 0.22208153 | K222: Sunny
A223: 45026 | B223: =VLOOKUP(A223,'BADI SID DATA'!A:B,2,0) -> 10 | C223: 63051.95 | D223: 6.5 | E223: 9 | F223: 1 | G223: 1 | H223: =C223+H222 -> 542748.05 | I223: =C223/(10*24*1000) -> 0.26271646 | J223: =H223/(24*B223*10*1000) -> 0.22614502 | K223: Partially Cloudy
A224: 45027 | B224: =VLOOKUP(A224,'BADI SID DATA'!A:B,2,0) -> 11 | C224: 63048.7 | D224: 6.5 | E224: 8.9 | F224: 1 | G224: 1 | H224: =C224+H223 -> 605796.75 | I224: =C224/(10*24*1000) -> 0.26270292 | J224: =H224/(24*B224*10*1000) -> 0.22946847 | K224: Sunny
A225: 45028 | B225: =VLOOKUP(A225,'BADI SID DATA'!A:B,2,0) -> 12 | C225: 65000 | D225: 6.8 | E225: 9 | F225: 1 | G225: 1 | H225: =C225+H224 -> 670796.75 | I225: =C225/(10*24*1000) -> 0.27083333 | J225: =H225/(24*B225*10*1000) -> 0.23291554 | K225: Sunny
A226: 45029 | B226: =VLOOKUP(A226,'BADI SID DATA'!A:B,2,0) -> 13 | C226: 63051.95 | D226: 6.6 | E226: 8.7 | F226: 1 | G226: 1 | H226: =C226+H225 -> 733848.7 | I226: =C226/(10*24*1000) -> 0.26271646 | J226: =H226/(24*B226*10*1000) -> 0.23520792 | K226: Sunny
... A250: 45053 | B250: =VLOOKUP(A250,'BADI SID DATA'!A:B,2,0) -> 37 | C250: 52650 | D250: 5.16 | E250: 10.6 | F250: 1 | G250: 1 | H250: =C250+H249 -> 1913596.1 | I250: =C250/(10*24*1000) -> 0.219375 | J250: =H250/(24*B250*10*1000) -> 0.21549506 | K250: Cloudy
A251: 45054 | B251: =VLOOKUP(A251,'BADI SID DATA'!A:B,2,0) -> 38 | C251: 37701.3 | D251: =8.7-5.16 -> 3.54 | E251: 10.6 | F251: 1 | G251: 1 | H251: =C251+H250 -> 1951297.4 | I251: =C251/(10*24*1000) -> 0.15708875 | J251: =H251/(24*B251*10*1000) -> 0.21395805 | K251: Mostly Cloudy and Rainy
A252: 45055 | B252: =VLOOKUP(A252,'BADI SID DATA'!A:B,2,0) -> 39 | C252: 44850 | D252: 5.28 | E252: 9.8 | F252: 1 | G252: 0.96527778 | H252: =C252+H251 -> 1996147.4 | I252: =C252/(10*24*1000) -> 0.186875 | J252: =H252/(24*B252*10*1000) -> 0.21326361 | K252: Cloudy and Rainy
A253: 45056 | B253: =VLOOKUP(A253,'BADI SID DATA'!A:B,2,0) -> 40 | C253: 58501.3 | D253: 5.87 | E253: 9.3 | F253: 1 | G253: 1 | H253: =C253+H252 -> 2054648.7 | I253: =C253/(10*24*1000) -> 0.24375542 | J253: =H253/(24*B253*10*1000) -> 0.21402591 | K253: Partially Cloudy
A254: 45057 | B254: =VLOOKUP(A254,'BADI SID DATA'!A:B,2,0) -> 41 | C254: 48099.35 | D254: 5.31 | E254: 8.9 | F254: 1 | G254: 0.97361111 | H254: =C254+H253 -> 2102748 | I254: =C254/(10*24*1000) -> 0.20041396 | J254: =H254/(24*B254*10*1000) -> 0.21369391 | K254: Cloudy
A255: 45058 | B255: =VLOOKUP(A255,'BADI SID DATA'!A:B,2,0) -> 42 | C255: 52650 | D255: 5.26 | E255: 9.1 | F255: 1 | G255: 1 | H255: =C255+H254 -> 2155398 | I255: =C255/(10*24*1000) -> 0.219375 | J255: =H255/(24*B255*10*1000) -> 0.21382917 | K255: Partially Cloudy
A256: 45059 | B256: =VLOOKUP(A256,'BADI SID DATA'!A:B,2,0) -> 43 | C256: 44850 | D256: 5.04 | E256: 8.2 | F256: 1 | G256: 1 | H256: =C256+H255 -> 2200248 | I256: =C256/(10*24*1000) -> 0.186875 | J256: =H256/(24*B256*10*1000) -> 0.21320233 | K256: Cloudy
A257: 45060 | B257: =VLOOKUP(A257,'BADI SID DATA'!A:B,2,0) -> 44 | C257: 58501.95 | D257: 6.12 | E257: 9.6 | F257: 1 | G257: 1 | H257: =C257+H256 -> 2258750 | I257: =C257/(10*24*1000) -> 0.24375813 | J257: =H257/(24*B257*10*1000) -> 0.21389678 | K257: Partially Cloudy
A258: 45061 | B258: =VLOOKUP(A258,'BADI SID DATA'!A:B,2,0) -> 45 | C258: 40946.1 | D258: 4.23 | E258: 8 | F258: 1 | G258: 0.90416667 | H258: =C258+H257 -> 2299696.1 | I258: =C258/(10*24*1000) -> 0.17060875 | J258: =H258/(24*B258*10*1000) -> 0.21293482 | K258: Partially Cloudy
A259: 45062 | B259: =VLOOKUP(A259,'BADI SID DATA'!A:B,2,0) -> 46 | C259: 52650 | D259: 5.16 | E259: 9.2 | F259: 1 | G259: 0.98125 | H259: =C259+H258 -> 2352346.1 | I259: =C259/(10*24*1000) -> 0.219375 | J259: =H259/(24*B259*10*1000) -> 0.21307483 | K259: Partially Cloudy
A260: 45063 | B260: =VLOOKUP(A260,'BADI SID DATA'!A:B,2,0) -> 47 | C260: 52653.9 | D260: 5.16 | E260: 9.1 | F260: 1 | G260: 1 | H260: =C260+H259 -> 2405000 | I260: =C260/(10*24*1000) -> 0.21939125 | J260: =H260/(24*B260*10*1000) -> 0.21320922 | K260: Partially Cloudy
A261: 45064 | B261: =VLOOKUP(A261,'BADI SID DATA'!A:B,2,0) -> 48 | C261: 44199.35 | D261: 5.11 | E261: 8.1 | F261: 1 | G261: 1 | H261: =C261+H260 -> 2449199.3 | I261: =C261/(10*24*1000) -> 0.18416396 | J261: =H261/(24*B261*10*1000) -> 0.21260411 | K261: Cloudy
...

Sheet Agatti Dashboard
B1: Date | C1: ='SECI O&M Dashboard'!E3 -> 46027
B4: SECI 0.3 MW Agatti Lakshdweep
B5: Date* | D5: =C1 -> 46027 | F5: Year Till date* | H5: Last FY Performance^
B6: *Data is without considering radiation correction | H6: ^Data is with radiation correction
B7: GHI (Kwh/sq. m) | C7: Exported generation (MU) | D7: CUF (%) | E7: Peak Power (Kw) | F7: Exported generation (MU) | G7: CUF (%) | H7: Exported generation (MU) | J7: CUF (%)
B8: =VLOOKUP(C1,'Agatti Data'!A:D,4,0) -> 3.96 | C8: =VLOOKUP(C1,'Agatti Data'!A:C,3,FALSE)/10^6 -> 0.001075 | D8: =VLOOKUP(C1,'Agatti Data'!A:I,9,0) -> 0.14930556 | E8: =VLOOKUP(C1,'Agatti Data'!A:E,5,0) -> 190 | F8: =VLOOKUP(C1,'Agatti Data'!A:H,8,0)/10^6 -> 0.3459531 | G8: =VLOOKUP(C1,'Agatti Data'!A:J,10,0) -> 0.17160372
B11: Generation Data for last 7 days
B12: Date | C12: Radiation POA (Kwh/sq. m) | D12: Exported generation (KWh) | E12: CUF (%) | F12: Peak Power (Kw) | G12: Radiation POA (Kwh/sq. m) | H12: Exported generation (KWh) | I12: CUF (%) | J12: Peak Power (KwH)
C13: =YEAR(C1) -> 2026 | G13: =C13-1 -> 2025
B14: =C1-1 -> 46026 | C14: =VLOOKUP(B14,'Agatti Data'!A:D,4,0) -> 4.54 | D14: =VLOOKUP(B14,'Agatti Data'!A:C,3,0) -> 1233 | E14: =VLOOKUP('Agatti Dashboard'!B14,'Agatti Data'!A:I,9,0) -> 0.17125 | F14: =VLOOKUP(B14,'Agatti Data'!A:E,5,0) -> 210 | G14: =VLOOKUP(B14-365,'Agatti Data'!A:D,4,0) -> 3.75 | H14: =VLOOKUP(B14-365,'Agatti Data'!A:C,3,0) -> 1098.2 | I14: =VLOOKUP(B14-365,'Agatti Data'!A:I,9,0) -> 0.15252778 | J14: =VLOOKUP(B14-365,'Agatti Data'!A:E,5,0) -> 0
B15: =B14-1 -> 46025 | C15: =VLOOKUP(B15,'Agatti Data'!A:D,4,0) -> 4.09 | D15: =VLOOKUP(B15,'Agatti Data'!A:C,3,0) -> 1098 | E15: =VLOOKUP('Agatti Dashboard'!B15,'Agatti Data'!A:I,9,0) -> 0.1525 | F15: =VLOOKUP(B15,'Agatti Data'!A:E,5,0) -> 238 | G15: =VLOOKUP(B15-365,'Agatti Data'!A:D,4,0) -> 4.23 | H15: =VLOOKUP(B15-365,'Agatti Data'!A:C,3,0) -> 1214.7 | I15: =VLOOKUP(B15-365,'Agatti Data'!A:I,9,0) -> 0.16870833 | J15: =VLOOKUP(B15-365,'Agatti Data'!A:E,5,0) -> 0
B16: =B15-1 -> 46024 | C16: =VLOOKUP(B16,'Agatti Data'!A:D,4,0) -> 4.41 | D16: =VLOOKUP(B16,'Agatti Data'!A:C,3,0) -> 1193 | E16: =VLOOKUP('Agatti Dashboard'!B16,'Agatti Data'!A:I,9,0) -> 0.16569444 | F16: =VLOOKUP(B16,'Agatti Data'!A:E,5,0) -> 212 | G16: =VLOOKUP(B16-365,'Agatti Data'!A:D,4,0) -> 4.45 | H16: =VLOOKUP(B16-365,'Agatti Data'!A:C,3,0) -> 1131.7 | I16: =VLOOKUP(B16-365,'Agatti Data'!A:I,9,0) -> 0.15718056 | J16: =VLOOKUP(B16-365,'Agatti Data'!A:E,5,0) -> 0
B17: =B16-1 -> 46023 | C17: =VLOOKUP(B17,'Agatti Data'!A:D,4,0) -> 3.73 | D17: =VLOOKUP(B17,'Agatti Data'!A:C,3,0) -> 973 | E17: =VLOOKUP('Agatti Dashboard'!B17,'Agatti Data'!A:I,9,0) -> 0.13513889 | F17: =VLOOKUP(B17,'Agatti Data'!A:E,5,0) -> 213 | G17: =VLOOKUP(B17-365,'Agatti Data'!A:D,4,0) -> 4.78 | H17: =VLOOKUP(B17-365,'Agatti Data'!A:C,3,0) -> 1238.6 | I17: =VLOOKUP(B17-365,'Agatti Data'!A:I,9,0) -> 0.17202778 | J17: =VLOOKUP(B17-365,'Agatti Data'!A:E,5,0) -> 0
B18: =B17-1 -> 46022 | C18: =VLOOKUP(B18,'Agatti Data'!A:D,4,0) -> 3.39 | D18: =VLOOKUP(B18,'Agatti Data'!A:C,3,0) -> 932 | E18: =VLOOKUP('Agatti Dashboard'!B18,'Agatti Data'!A:I,9,0) -> 0.12944444 | F18: =VLOOKUP(B18,'Agatti Data'!A:E,5,0) -> 220 | G18: =VLOOKUP(B18-365,'Agatti Data'!A:D,4,0) -> 4.56 | H18: =VLOOKUP(B18-365,'Agatti Data'!A:C,3,0) -> 1248.5 | I18: =VLOOKUP(B18-365,'Agatti Data'!A:I,9,0) -> 0.17340278 | J18: =VLOOKUP(B18-365,'Agatti Data'!A:E,5,0) -> 0
B19: =B18-1 -> 46021 | C19: =VLOOKUP(B19,'Agatti Data'!A:D,4,0) -> 4.76 | D19: =VLOOKUP(B19,'Agatti Data'!A:C,3,0) -> 1296 | E19: =VLOOKUP('Agatti Dashboard'!B19,'Agatti Data'!A:I,9,0) -> 0.18 | F19: =VLOOKUP(B19,'Agatti Data'!A:E,5,0) -> 199 | G19: =VLOOKUP(B19-365,'Agatti Data'!A:D,4,0) -> 4.68 | H19: =VLOOKUP(B19-365,'Agatti Data'!A:C,3,0) -> 1267 | I19: =VLOOKUP(B19-365,'Agatti Data'!A:I,9,0) -> 0.17597222 | J19: =VLOOKUP(B19-365,'Agatti Data'!A:E,5,0) -> 0
B20: =B19-1 -> 46020 | C20: =VLOOKUP(B20,'Agatti Data'!A:D,4,0) -> 4.83 | D20: =VLOOKUP(B20,'Agatti Data'!A:C,3,0) -> 1296 | E20: =VLOOKUP('Agatti Dashboard'!B20,'Agatti Data'!A:I,9,0) -> 0.18 | F20: =VLOOKUP(B20,'Agatti Data'!A:E,5,0) -> 198 | G20: =VLOOKUP(B20-365,'Agatti Data'!A:D,4,0) -> 4.3 | H20: =VLOOKUP(B20-365,'Agatti Data'!A:C,3,0) -> 1182.8 | I20: =VLOOKUP(B20-365,'Agatti Data'!A:I,9,0) -> 0.16427778 | J20: =VLOOKUP(B20-365,'Agatti Data'!A:E,5,0) -> 0

Sheet Kaveratti 1.4 MW Solar+BESS DB
B1: Date | C1: ='SECI O&M Dashboard'!E3 -> 46027
B4: SECI 1.4 Mw SPV with 1.4 Mwh BESS Kaveratti, Lakshdweep
B5: As on Date* | E5: =C1 -> 46027 | H5: Year Till date* | L5: Last FY Performance^
B6: *Data is without considering radiation correction | L6: ^Data is with radiation correction
B7: Solar | F7: BESS | H7: Solar | J7: BESS | L7: Solar | N7: BESS
B8: GHI (Kwh/sq. m) | C8: Exported generation (MU) | D8: CUF (%) | E8: Peak Power (In MW) | F8: Net Energy Export (MwH) | G8: Net Energy FED (MwH) | H8: Exported generation (MU) | I8: CUF (%) | J8: Net Energy Export (MwH) | K8: Net Energy FED (MwH) | L8: Exported generation (MU) | M8: CUF (%) | N8: Net Energy Export (MwH) | O8: Net Energy FED (MwH)
B9: =VLOOKUP(C1,'Kaveratti Data'!A:D,4,0) -> 4.3 | C9: =VLOOKUP(C1,'Kaveratti Data'!A:C,3,0)/10^6 -> 0.005537 | D9: =VLOOKUP(C1,'Kaveratti Data'!A:N,14,0) -> 0.16479167 | E9: =VLOOKUP(C1,'Kaveratti Data'!A:E,5,0) -> 938 | F9: =VLOOKUP(C1,'Kaveratti Data'!A:G,6,0) -> 1275 | G9: =VLOOKUP(C1,'Kaveratti Data'!A:H,7,0) -> 1434 | H9: =VLOOKUP(C1,'Kaveratti Data'!A:K,11,0)/10^6 -> 1.6155374 | I9: =VLOOKUP(C1,'Kaveratti Data'!A:O,15,0) -> 0.17171954 | J9: =VLOOKUP(C1,'Kaveratti Data'!A:M,12,0) -> 87752.61 | K9: =VLOOKUP(C1,'Kaveratti Data'!A:M,13,0) -> 96962
B12: Generation Data for last 7 days
C13: Solar | G13: BESS | I13: Solar | M13: BESS
B14: Date | C14: GHI (Kwh/sq. m) | D14: Exported generation (KWh) | E14: CUF (%) | F14: Peak Power (In MW) | G14: Net Export (MwH) | H14: Net Energy FED (MwH) | I14: GHI (Kwh/sq. m) | J14: Exported generation (KWh) | K14: CUF (%) | L14: Peak Power (In MW) | M14: Net Export (MwH) | N14: Net Energy FED (MwH)
C15: =YEAR(C1) -> 2026 | I15: =C15-1 -> 2025
B16: =C1-1 -> 46026 | C16: =VLOOKUP(B16,'Kaveratti Data'!A:D,4,0) -> 4.47 | D16: =VLOOKUP(B16,'Kaveratti Data'!A:C,3,0) -> 5621 | E16: =VLOOKUP(B16,'Kaveratti Data'!A:N,14,0) -> 0.16729167 | F16: =VLOOKUP(B16,'Kaveratti Data'!A:E,5,0) -> 935 | G16: =VLOOKUP(B16,'Kaveratti Data'!A:G,6,0) -> 1143 | H16: =VLOOKUP(B16,'Kaveratti Data'!A:H,7,0) -> 1383 | I16: =VLOOKUP(B16-366,'Kaveratti Data'!A:D,4,0) -> 4.9 | J16: =VLOOKUP(B16-366,'Kaveratti Data'!A:C,3,0) -> 6073.6 | K16: =VLOOKUP(B16-366,'Kaveratti Data'!A:N,14,0) -> 0.1807619 | L16: =VLOOKUP(B16-366,'Kaveratti Data'!A:E,5,0) -> 0 | M16: =VLOOKUP(B16-366,'Kaveratti Data'!A:G,6,0) -> 0 | N16: =VLOOKUP(B16-366,'Kaveratti Data'!A:H,7,0) -> 0
B17: =B16-1 -> 46025 | C17: =VLOOKUP(B17,'Kaveratti Data'!A:D,4,0) -> 4 | D17: =VLOOKUP(B17,'Kaveratti Data'!A:C,3,0) -> 4941 | E17: =VLOOKUP(B17,'Kaveratti Data'!A:N,14,0) -> 0.14705357 | F17: =VLOOKUP(B17,'Kaveratti Data'!A:E,5,0) -> 1103 | G17: =VLOOKUP(B17,'Kaveratti Data'!A:G,6,0) -> 1131 | H17: =VLOOKUP(B17,'Kaveratti Data'!A:H,7,0) -> 1274 | I17: =VLOOKUP(B17-366,'Kaveratti Data'!A:D,4,0) -> 5.13 | J17: =VLOOKUP(B17-366,'Kaveratti Data'!A:C,3,0) -> 6401.4 | K17: =VLOOKUP(B17-366,'Kaveratti Data'!A:N,14,0) -> 0.19051786 | L17: =VLOOKUP(B17-366,'Kaveratti Data'!A:E,5,0) -> 0 | M17: =VLOOKUP(B17-366,'Kaveratti Data'!A:G,6,0) -> 0 | N17: =VLOOKUP(B17-366,'Kaveratti Data'!A:H,7,0) -> 0
B18: =B17-1 -> 46024 | C18: =VLOOKUP(B18,'Kaveratti Data'!A:D,4,0) -> 5.24 | D18: =VLOOKUP(B18,'Kaveratti Data'!A:C,3,0) -> 6537 | E18: =VLOOKUP(B18,'Kaveratti Data'!A:N,14,0) -> 0.19455357 | F18: =VLOOKUP(B18,'Kaveratti Data'!A:E,5,0) -> 1073 | G18: =VLOOKUP(B18,'Kaveratti Data'!A:G,6,0) -> 1337 | H18: =VLOOKUP(B18,'Kaveratti Data'!A:H,7,0) -> 1511 | I18: =VLOOKUP(B18-366,'Kaveratti Data'!A:D,4,0) -> 5.39 | J18: =VLOOKUP(B18-366,'Kaveratti Data'!A:C,3,0) -> 6691.3 | K18: =VLOOKUP(B18-366,'Kaveratti Data'!A:N,14,0) -> 0.19914583 | L18: =VLOOKUP(B18-366,'Kaveratti Data'!A:E,5,0) -> 0 | M18: =VLOOKUP(B18-366,'Kaveratti Data'!A:G,6,0) -> 0 | N18: =VLOOKUP(B18-366,'Kaveratti Data'!A:H,7,0) -> 0
B19: =B18-1 -> 46023 | C19: =VLOOKUP(B19,'Kaveratti Data'!A:D,4,0) -> 4.67 | D19: =VLOOKUP(B19,'Kaveratti Data'!A:C,3,0) -> 5913 | E19: =VLOOKUP(B19,'Kaveratti Data'!A:N,14,0) -> 0.17598214 | F19: =VLOOKUP(B19,'Kaveratti Data'!A:E,5,0) -> 994 | G19: =VLOOKUP(B19,'Kaveratti Data'!A:G,6,0) -> 1387 | H19: =VLOOKUP(B19,'Kaveratti Data'!A:H,7,0) -> 1491 | I19: =VLOOKUP(B19-366,'Kaveratti Data'!A:D,4,0) -> 4.97 | J19: =VLOOKUP(B19-366,'Kaveratti Data'!A:C,3,0) -> 6218.8 | K19: =VLOOKUP(B19-366,'Kaveratti Data'!A:N,14,0) -> 0.18508333 | L19: =VLOOKUP(B19-366,'Kaveratti Data'!A:E,5,0) -> 0 | M19: =VLOOKUP(B19-366,'Kaveratti Data'!A:G,6,0) -> 0 | N19: =VLOOKUP(B19-366,'Kaveratti Data'!A:H,7,0) -> 0
B20: =B19-1 -> 46022 | C20: =VLOOKUP(B20,'Kaveratti Data'!A:D,4,0) -> 4.15 | D20: =VLOOKUP(B20,'Kaveratti Data'!A:C,3,0) -> 5248 | E20: =VLOOKUP(B20,'Kaveratti Data'!A:N,14,0) -> 0.15619048 | F20: =VLOOKUP(B20,'Kaveratti Data'!A:E,5,0) -> 968 | G20: =VLOOKUP(B20,'Kaveratti Data'!A:G,6,0) -> 1223 | H20: =VLOOKUP(B20,'Kaveratti Data'!A:H,7,0) -> 1379 | I20: =VLOOKUP(B20-366,'Kaveratti Data'!A:D,4,0) -> 4.9 | J20: =VLOOKUP(B20-366,'Kaveratti Data'!A:C,3,0) -> 6097.8 | K20: =VLOOKUP(B20-366,'Kaveratti Data'!A:N,14,0) -> 0.18148214 | L20: =VLOOKUP(B20-366,'Kaveratti Data'!A:E,5,0) -> 0 | M20: =VLOOKUP(B20-366,'Kaveratti Data'!A:G,6,0) -> 0 | N20: =VLOOKUP(B20-366,'Kaveratti Data'!A:H,7,0) -> 0
B21: =B20-1 -> 46021 | C21: =VLOOKUP(B21,'Kaveratti Data'!A:D,4,0) -> 4.94 | D21: =VLOOKUP(B21,'Kaveratti Data'!A:C,3,0) -> 6218 | E21: =VLOOKUP(B21,'Kaveratti Data'!A:N,14,0) -> 0.18505952 | F21: =VLOOKUP(B21,'Kaveratti Data'!A:E,5,0) -> 943 | G21: =VLOOKUP(B21,'Kaveratti Data'!A:G,6,0) -> 1320 | H21: =VLOOKUP(B21,'Kaveratti Data'!A:H,7,0) -> 1490 | I21: =VLOOKUP(B21-366,'Kaveratti Data'!A:D,4,0) -> 3.52 | J21: =VLOOKUP(B21-366,'Kaveratti Data'!A:C,3,0) -> 4405.9 | K21: =VLOOKUP(B21-366,'Kaveratti Data'!A:N,14,0) -> 0.13112798 | L21: =VLOOKUP(B21-366,'Kaveratti Data'!A:E,5,0) -> 0 | M21: =VLOOKUP(B21-366,'Kaveratti Data'!A:G,6,0) -> 0 | N21: =VLOOKUP(B21-366,'Kaveratti Data'!A:H,7,0) -> 0
B22: =B21-1 -> 46020 | C22: =VLOOKUP(B22,'Kaveratti Data'!A:D,4,0) -> 4.86 | D22: =VLOOKUP(B22,'Kaveratti Data'!A:C,3,0) -> 6048 | E22: =VLOOKUP(B22,'Kaveratti Data'!A:N,14,0) -> 0.18 | F22: =VLOOKUP(B22,'Kaveratti Data'!A:E,5,0) -> 992 | G22: =VLOOKUP(B22,'Kaveratti Data'!A:G,6,0) -> 1336 | H22: =VLOOKUP(B22,'Kaveratti Data'!A:H,7,0) -> 1508 | I22: =VLOOKUP(B22-366,'Kaveratti Data'!A:D,4,0) -> 4.69 | J22: =VLOOKUP(B22-366,'Kaveratti Data'!A:C,3,0) -> 5981.1 | K22: =VLOOKUP(B22-366,'Kaveratti Data'!A:N,14,0) -> 0.17800893 | L22: =VLOOKUP(B22-366,'Kaveratti Data'!A:E,5,0) -> 0 | M22: =VLOOKUP(B22-366,'Kaveratti Data'!A:G,6,0) -> 0 | N22: =VLOOKUP(B22-366,'Kaveratti Data'!A:H,7,0) -> 0

Sheet Agatti Data
A1: date | B1: Days | C1: generation (In Kwh) | D1: radiation | E1: Peak Power (in Kw) | F1: machine_availability | G1: grid_availability | H1: cumulative(in KwH) | I1: CUF | J1: CUF till date W.o.C
A2: 45170 | B2: 1 | C2: 0 | F2: 1 | G2: 1 | H2: =C2 -> 0 | I2: =C2/(300*24) -> 0 | J2: =H2/(24*B2*300) -> 0
A3: 45171 | B3: 2 | C3: 0 | F3: 1 | G3: 1 | H3: =C3+H2 -> 0 | I3: =C3/(300*24) -> 0 | J3: =H3/(24*B3*300) -> 0
A4: 45172 | B4: 3 | C4: 0 | F4: 1 | G4: 1 | H4: =C4+H3 -> 0 | I4: =C4/(300*24) -> 0 | J4: =H4/(24*B4*300) -> 0
A5: 45173 | B5: =VLOOKUP(A5,'BADI SID DATA'!A:B,2,0) -> 157 | C5: 0 | F5: 1 | G5: 1 | H5: =C5+H4 -> 0 | I5: =C5/(300*24) -> 0 | J5: =H5/(24*B5*300) -> 0
A6: 45174 | B6: =VLOOKUP(A6,'BADI SID DATA'!A:B,2,0) -> 158 | C6: 0 | F6: 1 | G6: 1 | H6: =C6+H5 -> 0 | I6: =C6/(300*24) -> 0 | J6: =H6/(24*B6*300) -> 0
A7: 45175 | B7: =VLOOKUP(A7,'BADI SID DATA'!A:B,2,0) -> 159 | C7: 0 | F7: 1 | G7: 1 | H7: =C7+H6 -> 0 | I7: =C7/(300*24) -> 0 | J7: =H7/(24*B7*300) -> 0
A8: 45176 | B8: =VLOOKUP(A8,'BADI SID DATA'!A:B,2,0) -> 160 | C8: 0 | F8: 1 | G8: 1 | H8: =C8+H7 -> 0 | I8: =C8/(300*24) -> 0 | J8: =H8/(24*B8*300) -> 0
A9: 45177 | B9: =VLOOKUP(A9,'BADI SID DATA'!A:B,2,0) -> 161 | C9: 0 | F9: 1 | G9: 1 | H9: =C9+H8 -> 0 | I9: =C9/(300*24) -> 0 | J9: =H9/(24*B9*300) -> 0
A10: 45178 | B10: =VLOOKUP(A10,'BADI SID DATA'!A:B,2,0) -> 162 | C10: 0 | F10: 1 | G10: 1 | H10: =C10+H9 -> 0 | I10: =C10/(300*24) -> 0 | J10: =H10/(24*B10*300) -> 0
A11: 45179 | B11: =VLOOKUP(A11,'BADI SID DATA'!A:B,2,0) -> 163 | C11: 0 | F11: 1 | G11: 1 | H11: =C11+H10 -> 0 | I11: =C11/(300*24) -> 0 | J11: =H11/(24*B11*300) -> 0
A12: 45180 | B12: =VLOOKUP(A12,'BADI SID DATA'!A:B,2,0) -> 164 | C12: 0 | F12: 1 | G12: 1 | H12: =C12+H11 -> 0 | I12: =C12/(300*24) -> 0 | J12: =H12/(24*B12*300) -> 0
A13: 45181 | B13: =VLOOKUP(A13,'BADI SID DATA'!A:B,2,0) -> 165 | C13: 0 | F13: 1 | G13: 1 | H13: =C13+H12 -> 0 | I13: =C13/(300*24) -> 0 | J13: =H13/(24*B13*300) -> 0
A14: 45182 | B14: =VLOOKUP(A14,'BADI SID DATA'!A:B,2,0) -> 166 | C14: 0 | F14: 1 | G14: 1 | H14: =C14+H13 -> 0 | I14: =C14/(300*24) -> 0 | J14: =H14/(24*B14*300) -> 0
A15: 45183 | B15: =VLOOKUP(A15,'BADI SID DATA'!A:B,2,0) -> 167 | C15: 0 | F15: 1 | G15: 1 | H15: =C15+H14 -> 0 | I15: =C15/(300*24) -> 0 | J15: =H15/(24*B15*300) -> 0
A16: 45184 | B16: =VLOOKUP(A16,'BADI SID DATA'!A:B,2,0) -> 168 | C16: 0 | F16: 1 | G16: 1 | H16: =C16+H15 -> 0 | I16: =C16/(300*24) -> 0 | J16: =H16/(24*B16*300) -> 0
... A18: 45186 | B18: =VLOOKUP(A18,'BADI SID DATA'!A:B,2,0) -> 170 | C18: 0 | F18: 1 | G18: 1 | H18: =C18+H17 -> 0 | I18: =C18/(300*24) -> 0 | J18: =H18/(24*B18*300) -> 0
A19: 45187 | B19: 1 | C19: 1539.4 | F19: 1 | G19: 1 | H19: =C19+H18 -> 1539.4 | I19: =C19/(300*24) -> 0.21380556 | J19: =H19/(24*B19*300) -> 0.21380556
A20: 45188 | B20: 2 | C20: 1622.1 | F20: 1 | G20: 1 | H20: =C20+H19 -> 3161.5 | I20: =C20/(300*24) -> 0.22529167 | J20: =H20/(24*B20*300) -> 0.21954861
A21: 45189 | B21: 3 | C21: 1314.1 | F21: 1 | G21: 1 | H21: =C21+H20 -> 4475.6 | I21: =C21/(300*24) -> 0.18251389 | J21: =H21/(24*B21*300) -> 0.2072037
A22: 45190 | B22: 4 | C22: 581.6 | F22: 1 | G22: 1 | H22: =C22+H21 -> 5057.2 | I22: =C22/(300*24) -> 0.080777778 | J22: =H22/(24*B22*300) -> 0.17559722
A23: 45191 | B23: 5 | C23: 438.9 | F23: 1 | G23: 1 | H23: =C23+H22 -> 5496.1 | I23: =C23/(300*24) -> 0.060958333 | J23: =H23/(24*B23*300) -> 0.15266944
A24: 45192 | B24: 6 | C24: 1537.7 | F24: 1 | G24: 1 | H24: =C24+H23 -> 7033.8 | I24: =C24/(300*24) -> 0.21356944 | J24: =H24/(24*B24*300) -> 0.16281944
A25: 45193 | B25: 7 | C25: 1380.5 | F25: 1 | G25: 1 | H25: =C25+H24 -> 8414.3 | I25: =C25/(300*24) -> 0.19173611 | J25: =H25/(24*B25*300) -> 0.1669504
A26: 45194 | B26: 8 | C26: 1627.3 | F26: 1 | G26: 1 | H26: =C26+H25 -> 10041.6 | I26: =C26/(300*24) -> 0.22601389 | J26: =H26/(24*B26*300) -> 0.17433333
A27: 45195 | B27: 9 | C27: 1651.9 | F27: 1 | G27: 1 | H27: =C27+H26 -> 11693.5 | I27: =C27/(300*24) -> 0.22943056 | J27: =H27/(24*B27*300) -> 0.18045525
A28: 45196 | B28: 10 | C28: 1436.4 | F28: 1 | G28: 1 | H28: =C28+H27 -> 13129.9 | I28: =C28/(300*24) -> 0.1995 | J28: =H28/(24*B28*300) -> 0.18235972
A29: 45197 | B29: 11 | C29: 1020.2 | F29: 1 | G29: 1 | H29: =C29+H28 -> 14150.1 | I29: =C29/(300*24) -> 0.14169444 | J29: =H29/(24*B29*300) -> 0.17866288
A30: 45198 | B30: 12 | C30: 927.3 | F30: 1 | G30: 1 | H30: =C30+H29 -> 15077.4 | I30: =C30/(300*24) -> 0.12879167 | J30: =H30/(24*B30*300) -> 0.17450694
... A214: 45382 | B214: 196 | C214: 1581 | F214: 1 | G214: 1 | H214: =C214+H213 -> 239212.9 | I214: =C214/(300*24) -> 0.21958333 | J214: =H214/(24*B214*300) -> 0.16951027
A215: 45383 | B215: =VLOOKUP(A215,'BADI SID DATA'!A:B,2,0) -> 1 | C215: 1466 | F215: 1 | G215: 0.77083333 | H215: =C215 -> 1466 | I215: =C215/(300*24) -> 0.20361111 | J215: =H215/(24*B215*300) -> 0.20361111
A216: 45384 | B216: =VLOOKUP(A216,'BADI SID DATA'!A:B,2,0) -> 2 | C216: 1585 | F216: 1 | G216: 1 | H216: =C216+H215 -> 3051 | I216: =C216/(300*24) -> 0.22013889 | J216: =H216/(24*B216*300) -> 0.211875
A217: 45385 | B217: =VLOOKUP(A217,'BADI SID DATA'!A:B,2,0) -> 3 | C217: 1293 | F217: 1 | G217: 1 | H217: =C217+H216 -> 4344 | I217: =C217/(300*24) -> 0.17958333 | J217: =H217/(24*B217*300) -> 0.20111111
A218: 45386 | B218: =VLOOKUP(A218,'BADI SID DATA'!A:B,2,0) -> 4 | C218: 1610 | F218: 1 | G218: 1 | H218: =C218+H217 -> 5954 | I218: =C218/(300*24) -> 0.22361111 | J218: =H218/(24*B218*300) -> 0.20673611
A219: 45387 | B219: =VLOOKUP(A219,'BADI SID DATA'!A:B,2,0) -> 5 | C219: 1616 | F219: 1 | G219: 1 | H219: =C219+H218 -> 7570 | I219: =C219/(300*24) -> 0.22444444 | J219: =H219/(24*B219*300) -> 0.21027778
A220: 45388 | B220: =VLOOKUP(A220,'BADI SID DATA'!A:B,2,0) -> 6 | C220: 1430 | F220: 1 | G220: 0.78472222 | H220: =C220+H219 -> 9000 | I220: =C220/(300*24) -> 0.19861111 | J220: =H220/(24*B220*300) -> 0.20833333
A221: 45389 | B221: =VLOOKUP(A221,'BADI SID DATA'!A:B,2,0) -> 7 | C221: 1280 | F221: 1 | G221: 0.86388889 | H221: =C221+H220 -> 10280 | I221: =C221/(300*24) -> 0.17777778 | J221: =H221/(24*B221*300) -> 0.20396825
A222: 45390 | B222: =VLOOKUP(A222,'BADI SID DATA'!A:B,2,0) -> 8 | C222: 1548 | F222: 1 | G222: 1 | H222: =C222+H221 -> 11828 | I222: =C222/(300*24) -> 0.215 | J222: =H222/(24*B222*300) -> 0.20534722
A223: 45391 | B223: =VLOOKUP(A223,'BADI SID DATA'!A:B,2,0) -> 9 | C223: 1599 | F223: 1 | G223: 1 | H223: =C223+H222 -> 13427 | I223: =C223/(300*24) -> 0.22208333 | J223: =H223/(24*B223*300) -> 0.20720679
A224: 45392 | B224: =VLOOKUP(A224,'BADI SID DATA'!A:B,2,0) -> 10 | C224: 1566 | F224: 1 | G224: 1 | H224: =C224+H223 -> 14993 | I224: =C224/(300*24) -> 0.2175 | J224: =H224/(24*B224*300) -> 0.20823611
...

Sheet Kaveratti Data
A1: Date | B1: Days | C1: generation (In Mwh) | D1: radiation | E1: Peak Power (in Mw) | F1: BESS Export (In MWh) | G1: BESS import (In MWh) | H1: Plant Availability | I1: grid_availability | J1: BESS Availibilty | K1: cumulative(in KwH) | L1: cumulative BESS Export(in MwH) | M1: cumulative BESS Import(in MwH) | N1: Daily CUF WORC | O1: CUF till date W.o.RC
A2: 45195 | B2: 1 | C2: 1086.5 | H2: 1 | I2: 0.99875759 | K2: =C2 -> 1086.5 | N2: =C2/(1400*24) -> 0.03233631 | O2: =K2/(B2*1400*24) -> 0.03233631
A3: 45196 | B3: 2 | C3: 1112 | H3: 1 | I3: 1 | K3: =K2+C3 -> 2198.5 | N3: =C3/(1400*24) -> 0.033095238 | O3: =K3/(B3*1400*24) -> 0.032715774
A4: 45197 | B4: 3 | C4: 666.2 | H4: 1 | I4: 1 | K4: =K3+C4 -> 2864.7 | N4: =C4/(1400*24) -> 0.019827381 | O4: =K4/(B4*1400*24) -> 0.028419643
A5: 45198 | B5: 4 | C5: 1123.3 | H5: 1 | I5: 1 | K5: =K4+C5 -> 3988 | N5: =C5/(1400*24) -> 0.033431548 | O5: =K5/(B5*1400*24) -> 0.029672619
A6: 45199 | B6: 5 | C6: 1945.7 | H6: 1 | I6: 1 | K6: =K5+C6 -> 5933.7 | N6: =C6/(1400*24) -> 0.057907738 | O6: =K6/(B6*1400*24) -> 0.035319643
A7: 45200 | B7: 6 | C7: 2136.1 | H7: 1 | I7: 1 | K7: =K6+C7 -> 8069.8 | N7: =C7/(1400*24) -> 0.063574405 | O7: =K7/(B7*1400*24) -> 0.04002877
A8: 45201 | B8: 7 | C8: 1953.9 | H8: 1 | I8: 1 | K8: =K7+C8 -> 10023.7 | N8: =C8/(1400*24) -> 0.058151786 | O8: =K8/(B8*1400*24) -> 0.042617772
A9: 45202 | B9: 8 | C9: 2575.8 | H9: 1 | I9: 0.92811323 | K9: =K8+C9 -> 12599.5 | N9: =C9/(1400*24) -> 0.076660714 | O9: =K9/(B9*1400*24) -> 0.04687314
A10: 45203 | B10: 9 | C10: 3504.8 | H10: 1 | I10: 1 | K10: =K9+C10 -> 16104.3 | N10: =C10/(1400*24) -> 0.10430952 | O10: =K10/(B10*1400*24) -> 0.05325496
A11: 45204 | B11: 10 | C11: 3474.9 | H11: 1 | I11: 1 | K11: =K10+C11 -> 19579.2 | N11: =C11/(1400*24) -> 0.10341964 | O11: =K11/(B11*1400*24) -> 0.058271429
A12: 45205 | B12: 11 | C12: 3505.9 | H12: 1 | I12: 1 | K12: =K11+C12 -> 23085.1 | N12: =C12/(1400*24) -> 0.10434226 | O12: =K12/(B12*1400*24) -> 0.062459686
A13: 45206 | B13: 12 | C13: 3473.1 | H13: 1 | I13: 1 | K13: =K12+C13 -> 26558.2 | N13: =C13/(1400*24) -> 0.10336607 | O13: =K13/(B13*1400*24) -> 0.065868552
A14: 45207 | B14: 13 | C14: 3532 | H14: 1 | I14: 1 | K14: =K13+C14 -> 30090.2 | N14: =C14/(1400*24) -> 0.10511905 | O14: =K14/(B14*1400*24) -> 0.068887821
... A189: 45382 | B189: 188 | C189: 7537.3 | H189: 1 | I189: 1 | K189: =K188+C189 -> 968850.49 | N189: =C189/(1400*24) -> 0.2243244 | O189: =K189/(B189*1400*24) -> 0.15337679
A190: 45383 | B190: =VLOOKUP(A190,'BADI SID DATA'!A:B,2,0) -> 1 | C190: 7771.6 | H190: 1 | I190: 1 | K190: =K189+C190 -> 976622.09 | N190: =C190/(1400*24) -> 0.23129762 | O190: =K190/(B190*1400*24) -> 29.066134
A191: 45384 | B191: =VLOOKUP(A191,'BADI SID DATA'!A:B,2,0) -> 2 | C191: 7983 | H191: 1 | I191: 1 | K191: =K190+C191 -> 984605.09 | N191: =C191/(1400*24) -> 0.23758929 | O191: =K191/(B191*1400*24) -> 14.651861
A192: 45385 | B192: =VLOOKUP(A192,'BADI SID DATA'!A:B,2,0) -> 3 | C192: 7800.3 | H192: 1 | I192: 1 | K192: =K191+C192 -> 992405.39 | N192: =C192/(1400*24) -> 0.23215179 | O192: =K192/(B192*1400*24) -> 9.8452916
A193: 45386 | B193: =VLOOKUP(A193,'BADI SID DATA'!A:B,2,0) -> 4 | C193: 7888.2 | H193: 1 | I193: 1 | K193: =K192+C193 -> 1000293.6 | N193: =C193/(1400*24) -> 0.23476786 | O193: =K193/(B193*1400*24) -> 7.4426606
A194: 45387 | B194: =VLOOKUP(A194,'BADI SID DATA'!A:B,2,0) -> 5 | C194: 7850.5 | H194: 1 | I194: 1 | K194: =K193+C194 -> 1008144.1 | N194: =C194/(1400*24) -> 0.23364583 | O194: =K194/(B194*1400*24) -> 6.0008577
A195: 45388 | B195: =VLOOKUP(A195,'BADI SID DATA'!A:B,2,0) -> 6 | C195: 7267.8 | H195: 1 | I195: 1 | K195: =K194+C195 -> 1015411.9 | N195: =C195/(1400*24) -> 0.21630357 | O195: =K195/(B195*1400*24) -> 5.0367653
A196: 45389 | B196: =VLOOKUP(A196,'BADI SID DATA'!A:B,2,0) -> 7 | C196: 7685.3 | H196: 1 | I196: 1 | K196: =K195+C196 -> 1023097.2 | N196: =C196/(1400*24) -> 0.22872917 | O196: =K196/(B196*1400*24) -> 4.349903
A197: 45390 | B197: =VLOOKUP(A197,'BADI SID DATA'!A:B,2,0) -> 8 | C197: 7023 | H197: 1 | I197: 1 | K197: =K196+C197 -> 1030120.2 | N197: =C197/(1400*24) -> 0.20901786 | O197: =K197/(B197*1400*24) -> 3.8322924
A198: 45391 | B198: =VLOOKUP(A198,'BADI SID DATA'!A:B,2,0) -> 9 | C198: 7023 | H198: 1 | I198: 1 | K198: =K197+C198 -> 1037143.2 | N198: =C198/(1400*24) -> 0.20901786 | O198: =K198/(B198*1400*24) -> 3.4297063
A199: 45392 | B199: =VLOOKUP(A199,'BADI SID DATA'!A:B,2,0) -> 10 | C199: 7772.3 | H199: 1 | I199: 1 | K199: =K198+C199 -> 1044915.5 | N199: =C199/(1400*24) -> 0.23131845 | O199: =K199/(B199*1400*24) -> 3.1098675
A200: 45393 | B200: =VLOOKUP(A200,'BADI SID DATA'!A:B,2,0) -> 11 | C200: 7553.1 | H200: 1 | I200: 1 | K200: =K199+C200 -> 1052468.6 | N200: =C200/(1400*24) -> 0.22479464 | O200: =K200/(B200*1400*24) -> 2.8475882
A201: 45394 | B201: =VLOOKUP(A201,'BADI SID DATA'!A:B,2,0) -> 12 | C201: 7647.1 | H201: 1 | I201: 1 | K201: =K200+C201 -> 1060115.7 | N201: =C201/(1400*24) -> 0.22759226 | O201: =K201/(B201*1400*24) -> 2.6292552
... A207: 45400 | B207: =VLOOKUP(A207,'BADI SID DATA'!A:B,2,0) -> 18 | C207: 7356.8 | H207: 1 | I207: 1 | K207: =K206+C207 -> 1099894 | N207: =C207/(1400*24) -> 0.21895238 | O207: =K207/(B207*1400*24) -> 1.8186078
A208: 45401 | B208: =VLOOKUP(A208,'BADI SID DATA'!A:B,2,0) -> 19 | C208: 6531.8 | D208: 5.14 | H208: 1 | I208: 1 | K208: =K207+C208 -> 1106425.8 | N208: =C208/(1400*24) -> 0.19439881 | O208: =K208/(B208*1400*24) -> 1.7331231
A209: 45402 | B209: =VLOOKUP(A209,'BADI SID DATA'!A:B,2,0) -> 20 | C209: 6860 | D209: 5.42 | H209: 1 | I209: 1 | K209: =K208+C209 -> 1113285.8 | N209: =C209/(1400*24) -> 0.20416667 | O209: =K209/(B209*1400*24) -> 1.6566753
A210: 45403 | B210: =VLOOKUP(A210,'BADI SID DATA'!A:B,2,0) -> 21 | C210: 6854.4 | D210: 5.54 | H210: 1 | I210: 1 | K210: =K209+C210 -> 1120140.2 | N210: =C210/(1400*24) -> 0.204 | O210: =K210/(B210*1400*24) -> 1.5875003
A211: 45404 | B211: =VLOOKUP(A211,'BADI SID DATA'!A:B,2,0) -> 22 | C211: 7280.2 | D211: 5.88 | H211: 1 | I211: 1 | K211: =K210+C211 -> 1127420.4 | N211: =C211/(1400*24) -> 0.21667262 | O211: =K211/(B211*1400*24) -> 1.5251899
A212: 45405 | B212: =VLOOKUP(A212,'BADI SID DATA'!A:B,2,0) -> 23 | C212: 7314.2 | D212: 5.81 | H212: 1 | I212: 1 | K212: =K211+C212 -> 1134734.6 | N212: =C212/(1400*24) -> 0.21768452 | O212: =K212/(B212*1400*24) -> 1.4683419
A213: 45406 | B213: =VLOOKUP(A213,'BADI SID DATA'!A:B,2,0) -> 24 | C213: 7605.3 | D213: 6.15 | H213: 1 | I213: 1 | K213: =K212+C213 -> 1142339.9 | N213: =C213/(1400*24) -> 0.22634821 | O213: =K213/(B213*1400*24) -> 1.4165921
A214: 45407 | B214: =VLOOKUP(A214,'BADI SID DATA'!A:B,2,0) -> 25 | C214: 5347.1 | D214: 4.16 | H214: 1 | I214: 1 | K214: =K213+C214 -> 1147687 | N214: =C214/(1400*24) -> 0.15913988 | O214: =K214/(B214*1400*24) -> 1.366294
A215: 45408 | B215: =VLOOKUP(A215,'BADI SID DATA'!A:B,2,0) -> 26 | C215: 6368.4 | D215: 5.63 | H215: 1 | I215: 1 | K215: =K214+C215 -> 1154055.4 | N215: =C215/(1400*24) -> 0.18953571 | O215: =K215/(B215*1400*24) -> 1.3210341
A216: 45409 | B216: =VLOOKUP(A216,'BADI SID DATA'!A:B,2,0) -> 27 | C216: 7549.5 | D216: 6.02 | H216: 1 | I216: 1 | K216: =K215+C216 -> 1161604.9 | N216: =C216/(1400*24) -> 0.2246875 | O216: =K216/(B216*1400*24) -> 1.2804287
A217: 45410 | B217: =VLOOKUP(A217,'BADI SID DATA'!A:B,2,0) -> 28 | C217: 7310.9 | D217: 5.87 | H217: 1 | I217: 1 | K217: =K216+C217 -> 1168915.8 | N217: =C217/(1400*24) -> 0.21758631 | O217: =K217/(B217*1400*24) -> 1.24247
A218: 45411 | B218: =VLOOKUP(A218,'BADI SID DATA'!A:B,2,0) -> 29 | C218: 7283.7 | D218: 5.83 | H218: 1 | I218: 1 | K218: =K217+C218 -> 1176199.5 | N218: =C218/(1400*24) -> 0.21677679 | O218: =K218/(B218*1400*24) -> 1.2071013
A219: 45412 | B219: =VLOOKUP(A219,'BADI SID DATA'!A:B,2,0) -> 30 | C219: 5801.3 | D219: 4.52 | H219: 1 | I219: 1 | K219: =K218+C219 -> 1182000.8 | N219: =C219/(1400*24) -> 0.17265774 | O219: =K219/(B219*1400*24) -> 1.1726198
...

Sheet BADI SID Dashboard
B1: Date | C1: ='SECI O&M Dashboard'!E3 -> 46027
B4: SECI 10MW Badi Sid
B5: Date* | D5: =C1 -> 46027 | F5: Year Till date* | H5: Last FY Performance^
B6: *Data is without considering radiation correction | H6: ^Data is with radiation correction
B7: GHI (Kwh/sq. m) | C7: Exported generation (MU) | D7: CUF (%) | E7: Peak Power (Kw) | F7: Exported generation (MU) | G7: CUF (%) | H7: Exported generation (MU) | J7: CUF (%)
B8: =VLOOKUP(C1,'BADI SID DATA'!A:D,4,0) -> 3.41 | C8: =VLOOKUP(C1,'BADI SID DATA'!A:C,3,FALSE)/10^6 -> 0.0408 | D8: =VLOOKUP(C1,'BADI SID DATA'!A:I,9,0) -> 0.17 | E8: =VLOOKUP(C1,'BADI SID DATA'!A:E,5,0) -> 8950 | F8: =VLOOKUP(C1,'BADI SID DATA'!A:H,8,0)/10^6 -> 13.079696 | G8: =VLOOKUP(C1,'BADI SID DATA'!A:J,10,0) -> 0.19463834
B11: Generation Data for last 7 days
B12: Date | C12: Radiation POA (Kwh/sq. m) | D12: Exported generation (KWh) | E12: CUF (%) | F12: Peak Power (KwH) | G12: Radiation POA (Kwh/sq. m) | H12: Exported generation (KWh) | I12: CUF (%) | J12: Peak Power (KwH)
C13: =YEAR(C1) -> 2026 | G13: =C13-1 -> 2025
B14: =C1-1 -> 46026 | C14: =VLOOKUP(B14,'BADI SID DATA'!A:D,4,0) -> 3.78 | D14: =VLOOKUP(B14,'BADI SID DATA'!A:C,3,0) -> 46231.5 | E14: =VLOOKUP('BADI SID Dashboard'!B14,'BADI SID DATA'!A:I,9,0) -> 0.19263125 | F14: =VLOOKUP(B14,'BADI SID DATA'!A:E,5,0) -> 5954 | G14: =VLOOKUP(B14-365,'BADI SID DATA'!A:D,4,0) -> 3.66 | H14: =VLOOKUP(B14-365,'BADI SID DATA'!A:C,3,0) -> 43136 | I14: =VLOOKUP(B14-365,'BADI SID DATA'!A:I,9,0) -> 0.17973333 | J14: =VLOOKUP(B14-365,'BADI SID DATA'!A:E,5,0) -> 7798
B15: =B14-1 -> 46025 | C15: =VLOOKUP(B15,'BADI SID DATA'!A:D,4,0) -> 3.72 | D15: =VLOOKUP(B15,'BADI SID DATA'!A:C,3,0) -> 45979 | E15: =VLOOKUP('BADI SID Dashboard'!B15,'BADI SID DATA'!A:I,9,0) -> 0.19157917 | F15: =VLOOKUP(B15,'BADI SID DATA'!A:E,5,0) -> 7071 | G15: =VLOOKUP(B15-365,'BADI SID DATA'!A:D,4,0) -> 3.82 | H15: =VLOOKUP(B15-365,'BADI SID DATA'!A:C,3,0) -> 46942 | I15: =VLOOKUP(B15-365,'BADI SID DATA'!A:I,9,0) -> 0.19559167 | J15: =VLOOKUP(B15-365,'BADI SID DATA'!A:E,5,0) -> 7809
B16: =B15-1 -> 46024 | C16: =VLOOKUP(B16,'BADI SID DATA'!A:D,4,0) -> 3.89 | D16: =VLOOKUP(B16,'BADI SID DATA'!A:C,3,0) -> 29151 | E16: =VLOOKUP('BADI SID Dashboard'!B16,'BADI SID DATA'!A:I,9,0) -> 0.1214625 | F16: =VLOOKUP(B16,'BADI SID DATA'!A:E,5,0) -> 5954 | G16: =VLOOKUP(B16-365,'BADI SID DATA'!A:D,4,0) -> 3.23 | H16: =VLOOKUP(B16-365,'BADI SID DATA'!A:C,3,0) -> 38380 | I16: =VLOOKUP(B16-365,'BADI SID DATA'!A:I,9,0) -> 0.15991667 | J16: =VLOOKUP(B16-365,'BADI SID DATA'!A:E,5,0) -> 8459
B17: =B16-1 -> 46023 | C17: =VLOOKUP(B17,'BADI SID DATA'!A:D,4,0) -> 3.25 | D17: =VLOOKUP(B17,'BADI SID DATA'!A:C,3,0) -> 30475.5 | E17: =VLOOKUP('BADI SID Dashboard'!B17,'BADI SID DATA'!A:I,9,0) -> 0.12698125 | F17: =VLOOKUP(B17,'BADI SID DATA'!A:E,5,0) -> 6737 | G17: =VLOOKUP(B17-365,'BADI SID DATA'!A:D,4,0) -> 3.82 | H17: =VLOOKUP(B17-365,'BADI SID DATA'!A:C,3,0) -> 48847 | I17: =VLOOKUP(B17-365,'BADI SID DATA'!A:I,9,0) -> 0.20352917 | J17: =VLOOKUP(B17-365,'BADI SID DATA'!A:E,5,0) -> 8142
B18: =B17-1 -> 46022 | C18: =VLOOKUP(B18,'BADI SID DATA'!A:D,4,0) -> 2.29 | D18: =VLOOKUP(B18,'BADI SID DATA'!A:C,3,0) -> 23433 | E18: =VLOOKUP('BADI SID Dashboard'!B18,'BADI SID DATA'!A:I,9,0) -> 0.0976375 | F18: =VLOOKUP(B18,'BADI SID DATA'!A:E,5,0) -> 7374 | G18: =VLOOKUP(B18-365,'BADI SID DATA'!A:D,4,0) -> 3.41 | H18: =VLOOKUP(B18-365,'BADI SID DATA'!A:C,3,0) -> 32417 | I18: =VLOOKUP(B18-365,'BADI SID DATA'!A:I,9,0) -> 0.13507083 | J18: =VLOOKUP(B18-365,'BADI SID DATA'!A:E,5,0) -> 6879
B19: =B18-1 -> 46021 | C19: =VLOOKUP(B19,'BADI SID DATA'!A:D,4,0) -> 3.79 | D19: =VLOOKUP(B19,'BADI SID DATA'!A:C,3,0) -> 45538.5 | E19: =VLOOKUP('BADI SID Dashboard'!B19,'BADI SID DATA'!A:I,9,0) -> 0.18974375 | F19: =VLOOKUP(B19,'BADI SID DATA'!A:E,5,0) -> 7436 | G19: =VLOOKUP(B19-365,'BADI SID DATA'!A:D,4,0) -> 3.52 | H19: =VLOOKUP(B19-365,'BADI SID DATA'!A:C,3,0) -> 42620 | I19: =VLOOKUP(B19-365,'BADI SID DATA'!A:I,9,0) -> 0.17758333 | J19: =VLOOKUP(B19-365,'BADI SID DATA'!A:E,5,0) -> 8296
B20: =B19-1 -> 46020 | C20: =VLOOKUP(B20,'BADI SID DATA'!A:D,4,0) -> 3.79 | D20: =VLOOKUP(B20,'BADI SID DATA'!A:C,3,0) -> 47043 | E20: =VLOOKUP('BADI SID Dashboard'!B20,'BADI SID DATA'!A:I,9,0) -> 0.1960125 | F20: =VLOOKUP(B20,'BADI SID DATA'!A:E,5,0) -> 7464 | G20: =VLOOKUP(B20-365,'BADI SID DATA'!A:D,4,0) -> 3.7 | H20: =VLOOKUP(B20-365,'BADI SID DATA'!A:C,3,0) -> 46980 | I20: =VLOOKUP(B20-365,'BADI SID DATA'!A:I,9,0) -> 0.19575 | J20: =VLOOKUP(B20-365,'BADI SID DATA'!A:E,5,0) -> 7790

Sheet BADI SID DATA
A1: date | B1: Days | C1: generation (In Kwh) | D1: radiation | E1: Peak Power (in Kw) | F1: machine_availability | G1: grid_availability | H1: cumulative(in KwH) | I1: CUF | J1: CUF till date W.o.C
A2: 42736 | B2: 1 | C2: 33691 | D2: 2.73 | F2: 100 | G2: 100 | H2: =C2 -> 33691 | I2: =C2/(10*24*1000) -> 0.14037917 | J2: =H2/(24*B2*10*1000) -> 0.14037917
A3: 42737 | B3: 2 | C3: 30994 | D3: 2.49 | F3: 100 | G3: 100 | H3: =H2+C3 -> 64685 | I3: =C3/(10*24*1000) -> 0.12914167 | J3: =H3/(24*B3*10*1000) -> 0.13476042
A4: 42738 | B4: 3 | C4: 45405 | D4: 3.71 | F4: 100 | G4: 100 | H4: =H3+C4 -> 110090 | I4: =C4/(10*24*1000) -> 0.1891875 | J4: =H4/(24*B4*10*1000) -> 0.15290278
A5: 42739 | B5: 4 | C5: 41084 | D5: 3.19 | F5: 100 | G5: 100 | H5: =H4+C5 -> 151174 | I5: =C5/(10*24*1000) -> 0.17118333 | J5: =H5/(24*B5*10*1000) -> 0.15747292
A6: 42740 | B6: 5 | C6: 38229 | D6: 2.96 | F6: 100 | G6: 100 | H6: =H5+C6 -> 189403 | I6: =C6/(10*24*1000) -> 0.1592875 | J6: =H6/(24*B6*10*1000) -> 0.15783583
A7: 42741 | B7: 6 | C7: 24843 | D7: 2.2 | F7: 99.305556 | G7: 100 | H7: =H6+C7 -> 214246 | I7: =C7/(10*24*1000) -> 0.1035125 | J7: =H7/(24*B7*10*1000) -> 0.14878194
A8: 42742 | B8: 7 | C8: 41517 | D8: 3.23 | F8: 100 | G8: 100 | H8: =H7+C8 -> 255763 | I8: =C8/(10*24*1000) -> 0.1729875 | J8: =H8/(24*B8*10*1000) -> 0.15223988
A9: 42743 | B9: 8 | C9: 42701 | D9: 3.23 | F9: 100 | G9: 100 | H9: =H8+C9 -> 298464 | I9: =C9/(10*24*1000) -> 0.17792083 | J9: =H9/(24*B9*10*1000) -> 0.15545
A10: 42744 | B10: 9 | C10: 25285 | D10: 2.02 | F10: 100 | G10: 100 | H10: =H9+C10 -> 323749 | I10: =C10/(10*24*1000) -> 0.10535417 | J10: =H10/(24*B10*10*1000) -> 0.1498838
A11: 42745 | B11: 10 | C11: 55874 | D11: 4.2 | F11: 99.510604 | G11: 100 | H11: =H10+C11 -> 379623 | I11: =C11/(10*24*1000) -> 0.23280833 | J11: =H11/(24*B11*10*1000) -> 0.15817625
A12: 42746 | B12: 11 | C12: 55723 | D12: 4.32 | F12: 98.527005 | G12: 100 | H12: =H11+C12 -> 435346 | I12: =C12/(10*24*1000) -> 0.23217917 | J12: =H12/(24*B12*10*1000) -> 0.16490379
A13: 42747 | B13: 12 | C13: 57550 | D13: 4.26 | F13: 100 | G13: 100 | H13: =H12+C13 -> 492896 | I13: =C13/(10*24*1000) -> 0.23979167 | J13: =H13/(24*B13*10*1000) -> 0.17114444
A14: 42748 | B14: 13 | C14: 54436 | D14: 4.2 | F14: 100 | G14: 100 | H14: =H13+C14 -> 547332 | I14: =C14/(10*24*1000) -> 0.22681667 | J14: =H14/(24*B14*10*1000) -> 0.17542692
... A67: 42801 | B67: 66 | C67: 39808 | D67: 3.81 | F67: 100 | G67: 100 | H67: =H66+C67 -> 3366941 | I67: =C67/(10*24*1000) -> 0.16586667 | J67: =H67/(24*B67*10*1000) -> 0.21255941
A68: 42802 | B68: 67 | C68: 51233 | D68: WMS report not showing due to WMS troubleshooting work was goning on | F68: 100 | G68: 100 | H68: =H67+C68 -> 3418174 | I68: =C68/(10*24*1000) -> 0.21347083 | J68: =H68/(24*B68*10*1000) -> 0.21257301
A69: 42803 | B69: 68 | C69: 47296 | F69: 100 | G69: 100 | H69: =H68+C69 -> 3465470 | I69: =C69/(10*24*1000) -> 0.19706667 | J69: =H69/(24*B69*10*1000) -> 0.21234498
A70: 42804 | B70: 69 | C70: 57961 | F70: 100 | G70: 100 | H70: =H69+C70 -> 3523431 | I70: =C70/(10*24*1000) -> 0.24150417 | J70: =H70/(24*B70*10*1000) -> 0.21276757
A71: 42805 | B71: 70 | C71: 66378 | F71: 100 | G71: 100 | H71: =H70+C71 -> 3589809 | I71: =C71/(10*24*1000) -> 0.276575 | J71: =H71/(24*B71*10*1000) -> 0.21367911
A72: 42806 | B72: 71 | C72: 62905 | F72: 100 | G72: 100 | H72: =H71+C72 -> 3652714 | I72: =C72/(10*24*1000) -> 0.26210417 | J72: =H72/(24*B72*10*1000) -> 0.21436115
A73: 42807 | B73: 72 | C73: 66471 | F73: 100 | G73: 100 | H73: =H72+C73 -> 3719185 | I73: =C73/(10*24*1000) -> 0.2769625 | J73: =H73/(24*B73*10*1000) -> 0.21523061
A74: 42808 | B74: 73 | C74: 43058 | F74: 100 | G74: 100 | H74: =H73+C74 -> 3762243 | I74: =C74/(10*24*1000) -> 0.17940833 | J74: =H74/(24*B74*10*1000) -> 0.2147399
A75: 42809 | B75: 74 | C75: 51354 | D75: 5.16 | F75: 100 | G75: 100 | H75: =H74+C75 -> 3813597 | I75: =C75/(10*24*1000) -> 0.213975 | J75: =H75/(24*B75*10*1000) -> 0.21472956
A76: 42810 | B76: 75 | C76: 51157 | D76: 4.88 | F76: 100 | G76: 100 | H76: =H75+C76 -> 3864754 | I76: =C76/(10*24*1000) -> 0.21315417 | J76: =H76/(24*B76*10*1000) -> 0.21470856
A77: 42811 | B77: 76 | C77: 53050 | D77: 5.24 | F77: 100 | G77: 100 | H77: =H76+C77 -> 3917804 | I77: =C77/(10*24*1000) -> 0.22104167 | J77: =H77/(24*B77*10*1000) -> 0.21479189
A78: 42812 | B78: 77 | C78: 45759 | D78: 4.6 | F78: 100 | G78: 89.027778 | H78: =H77+C78 -> 3963563 | I78: =C78/(10*24*1000) -> 0.1906625 | J78: =H78/(24*B78*10*1000) -> 0.21447852
A79: 42813 | B79: 78 | C79: 61783 | D79: 5.89 | F79: 100 | G79: 100 | H79: =H78+C79 -> 4025346 | I79: =C79/(10*24*1000) -> 0.25742917 | J79: =H79/(24*B79*10*1000) -> 0.21502917
A80: 42814 | B80: 79 | C80: 63990 | D80: 6.22 | F80: 100 | G80: 100 | H80: =H79+C80 -> 4089336 | I80: =C80/(10*24*1000) -> 0.266625 | J80: =H80/(24*B80*10*1000) -> 0.21568228
A81: 42815 | B81: 80 | C81: 63434 | D81: 6.23 | F81: 100 | G81: 100 | H81: =H80+C81 -> 4152770 | I81: =C81/(10*24*1000) -> 0.26430833 | J81: =H81/(24*B81*10*1000) -> 0.2162901
A82: 42816 | B82: 81 | C82: 59173 | F82: 100 | G82: 87.013889 | H82: =H81+C82 -> 4211943 | I82: =C82/(10*24*1000) -> 0.24655417 | J82: =H82/(24*B82*10*1000) -> 0.21666373
A83: 42817 | B83: 82 | C83: 58693 | D83: 5.78 | F83: 100 | G83: 100 | H83: =H82+C83 -> 4270636 | I83: =C83/(10*24*1000) -> 0.24455417 | J83: =H83/(24*B83*10*1000) -> 0.21700386
A84: 42818 | B84: 83 | C84: 59028 | D84: 5.76 | F84: 100 | G84: 100 | H84: =H83+C84 -> 4329664 | I84: =C84/(10*24*1000) -> 0.24595 | J84: =H84/(24*B84*10*1000) -> 0.21735261
A85: 42819 | B85: 84 | C85: 60565 | D85: 6.08 | F85: 100 | G85: 100 | H85: =H84+C85 -> 4390229 | I85: =C85/(10*24*1000) -> 0.25235417 | J85: =H85/(24*B85*10*1000) -> 0.2177693
A86: 42820 | B86: 85 | C86: 62286 | D86: 6.2 | F86: 100 | G86: 97.708333 | H86: =H85+C86 -> 4452515 | I86: =C86/(10*24*1000) -> 0.259525 | J86: =H86/(24*B86*10*1000) -> 0.21826054
A87: 42821 | B87: 86 | C87: 62286 | D87: 6.79 | F87: 100 | G87: 100 | H87: =H86+C87 -> 4514801 | I87: =C87/(10*24*1000) -> 0.259525 | J87: =H87/(24*B87*10*1000) -> 0.21874036
A88: 42822 | B88: 87 | C88: 62216 | D88: 6.21 | F88: 100 | G88: 100 | H88: =H87+C88 -> 4577017 | I88: =C88/(10*24*1000) -> 0.25923333 | J88: =H88/(24*B88*10*1000) -> 0.2192058
A89: 42823 | B89: 88 | C89: 62813 | D89: 6.41 | F89: 100 | G89: 100 | H89: =H88+C89 -> 4639830 | I89: =C89/(10*24*1000) -> 0.26172083 | J89: =H89/(24*B89*10*1000) -> 0.21968892
A90: 42824 | B90: 89 | C90: 65423 | D90: 6.74 | F90: 99.810785 | G90: 93.75 | H90: =H89+C90 -> 4705253 | I90: =C90/(10*24*1000) -> 0.27259583 | J90: =H90/(24*B90*10*1000) -> 0.22028338
A91: 42825 | B91: 90 | C91: 61596 | D91: 6.25 | F91: 100 | G91: 100 | H91: =H90+C91 -> 4766849 | I91: =C91/(10*24*1000) -> 0.25665 | J91: =H91/(24*B91*10*1000) -> 0.22068745
A92: 42826 | B92: 1 | C92: 62389 | D92: 6.59 | F92: 100 | G92: 100 | H92: =C92 -> 62389 | I92: =C92/(10*24*1000) -> 0.25995417 | J92: =H92/(24*B92*10*1000) -> 0.25995417
...

Sheet Rajnandgaon Dashboard
B1: Date | C1: ='SECI O&M Dashboard'!E3 -> 46027
B4: SECI 100 Mw SPV with 40Mw/120MwH BESS Rajnandgaon
B5: As on Date* | E5: =C1 -> 46027 | H5: Year Till date* | L5: Last FY Performance^
B6: *Data is without considering radiation correction | L6: ^Data is with radiation correction
B7: Solar | F7: BESS | H7: Solar | J7: BESS | L7: Solar | N7: BESS
B8: GHI (Kwh/sq. m) | C8: Exported generation (MU) | D8: CUF (%) | E8: Peak Power (In MW) | F8: Net Energy Export (MwH) | G8: Net Energy FED (MwH) | H8: Exported generation (MU) | I8: CUF (%) | J8: Net Energy Export (MwH) | K8: Net Energy FED (MwH) | L8: Exported generation (MU) | M8: CUF (%) | N8: Net Energy Export (MwH) | O8: Net Energy FED (MwH)
B9: =VLOOKUP(C1,'Rajnandgaon Data'!A:D,4,0) -> 4.17 | C9: =VLOOKUP(C1,'Rajnandgaon Data'!A:C,3,0)/10^6 -> 0.5852076 | D9: =VLOOKUP(C1,'Rajnandgaon Data'!A:N,14,0) -> 0.2438365 | E9: =VLOOKUP(C1,'Rajnandgaon Data'!A:E,5,0) -> 69.69 | F9: =VLOOKUP(C1,'Rajnandgaon Data'!A:G,6,0) -> 116.5 | G9: =VLOOKUP(C1,'Rajnandgaon Data'!A:H,7,0) -> 130.1 | H9: =VLOOKUP(C1,'Rajnandgaon Data'!A:K,11,0)/10^6 -> 164.49503 | I9: =VLOOKUP(C1,'Rajnandgaon Data'!A:O,15,0) -> 0.24478427 | J9: =VLOOKUP(C1,'Rajnandgaon Data'!A:M,12,0) -> 30197.958 | K9: =VLOOKUP(C1,'Rajnandgaon Data'!A:M,13,0) -> 33501.13
B12: Generation Data for last 7 days
C13: Solar | G13: BESS | I13: Solar | M13: BESS
B14: Date | C14: GHI (Kwh/sq. m) | D14: Exported generation (KWh) | E14: CUF (%) | F14: Peak Power (In MW) | G14: Net Export (MwH) | H14: Net Energy FED (MwH) | I14: GHI (Kwh/sq. m) | J14: Exported generation (KWh) | K14: CUF (%) | L14: Peak Power (In MW) | M14: Net Export (MwH) | N14: Net Energy FED (MwH)
C15: =YEAR(C1) -> 2026 | I15: =C15-1 -> 2025
B16: =C1-1 -> 46026 | C16: =VLOOKUP(B16,'Rajnandgaon Data'!A:D,4,0) -> 3.77 | D16: =VLOOKUP(B16,'Rajnandgaon Data'!A:C,3,0) -> 462466.7 | E16: =VLOOKUP(B16,'Rajnandgaon Data'!A:N,14,0) -> 0.19269446 | F16: =VLOOKUP(B16,'Rajnandgaon Data'!A:E,5,0) -> 59.12 | G16: =VLOOKUP(B16,'Rajnandgaon Data'!A:G,6,0) -> 116.62 | H16: =VLOOKUP(B16,'Rajnandgaon Data'!A:H,7,0) -> 130.06 | I16: =VLOOKUP(B16-366,'Rajnandgaon Data'!A:D,4,0) -> 4.885 | J16: =VLOOKUP(B16-366,'Rajnandgaon Data'!A:C,3,0) -> 667600 | K16: =VLOOKUP(B16-366,'Rajnandgaon Data'!A:N,14,0) -> 0.27816667 | L16: =VLOOKUP(B16-366,'Rajnandgaon Data'!A:E,5,0) -> 85.78 | M16: =VLOOKUP(B16-366,'Rajnandgaon Data'!A:G,6,0) -> 121.05 | N16: =VLOOKUP(B16-366,'Rajnandgaon Data'!A:H,7,0) -> 133.64
B17: =B16-1 -> 46025 | C17: =VLOOKUP(B17,'Rajnandgaon Data'!A:D,4,0) -> 3.65 | D17: =VLOOKUP(B17,'Rajnandgaon Data'!A:C,3,0) -> 519109.7 | E17: =VLOOKUP(B17,'Rajnandgaon Data'!A:N,14,0) -> 0.21629571 | F17: =VLOOKUP(B17,'Rajnandgaon Data'!A:E,5,0) -> 62.86 | G17: =VLOOKUP(B17,'Rajnandgaon Data'!A:G,6,0) -> 116.2 | H17: =VLOOKUP(B17,'Rajnandgaon Data'!A:H,7,0) -> 129.21 | I17: =VLOOKUP(B17-366,'Rajnandgaon Data'!A:D,4,0) -> 4.97 | J17: =VLOOKUP(B17-366,'Rajnandgaon Data'!A:C,3,0) -> 678000 | K17: =VLOOKUP(B17-366,'Rajnandgaon Data'!A:N,14,0) -> 0.2825 | L17: =VLOOKUP(B17-366,'Rajnandgaon Data'!A:E,5,0) -> 87.98 | M17: =VLOOKUP(B17-366,'Rajnandgaon Data'!A:G,6,0) -> 121.45 | N17: =VLOOKUP(B17-366,'Rajnandgaon Data'!A:H,7,0) -> 134.17
B18: =B17-1 -> 46024 | C18: =VLOOKUP(B18,'Rajnandgaon Data'!A:D,4,0) -> 3.96 | D18: =VLOOKUP(B18,'Rajnandgaon Data'!A:C,3,0) -> 574497.7 | E18: =VLOOKUP(B18,'Rajnandgaon Data'!A:N,14,0) -> 0.23937404 | F18: =VLOOKUP(B18,'Rajnandgaon Data'!A:E,5,0) -> 71.46 | G18: =VLOOKUP(B18,'Rajnandgaon Data'!A:G,6,0) -> 116.17 | H18: =VLOOKUP(B18,'Rajnandgaon Data'!A:H,7,0) -> 129.28 | I18: =VLOOKUP(B18-366,'Rajnandgaon Data'!A:D,4,0) -> 4.99 | J18: =VLOOKUP(B18-366,'Rajnandgaon Data'!A:C,3,0) -> 680100 | K18: =VLOOKUP(B18-366,'Rajnandgaon Data'!A:N,14,0) -> 0.283375 | L18: =VLOOKUP(B18-366,'Rajnandgaon Data'!A:E,5,0) -> 90.11 | M18: =VLOOKUP(B18-366,'Rajnandgaon Data'!A:G,6,0) -> 121.16 | N18: =VLOOKUP(B18-366,'Rajnandgaon Data'!A:H,7,0) -> 135.25
B19: =B18-1 -> 46023 | C19: =VLOOKUP(B19,'Rajnandgaon Data'!A:D,4,0) -> 4.29 | D19: =VLOOKUP(B19,'Rajnandgaon Data'!A:C,3,0) -> 632612.6 | E19: =VLOOKUP(B19,'Rajnandgaon Data'!A:N,14,0) -> 0.26358858 | F19: =VLOOKUP(B19,'Rajnandgaon Data'!A:E,5,0) -> 78.52 | G19: =VLOOKUP(B19,'Rajnandgaon Data'!A:G,6,0) -> 116.31 | H19: =VLOOKUP(B19,'Rajnandgaon Data'!A:H,7,0) -> 129.35 | I19: =VLOOKUP(B19-366,'Rajnandgaon Data'!A:D,4,0) -> 4.545 | J19: =VLOOKUP(B19-366,'Rajnandgaon Data'!A:C,3,0) -> 610720 | K19: =VLOOKUP(B19-366,'Rajnandgaon Data'!A:N,14,0) -> 0.25446667 | L19: =VLOOKUP(B19-366,'Rajnandgaon Data'!A:E,5,0) -> 81.23 | M19: =VLOOKUP(B19-366,'Rajnandgaon Data'!A:G,6,0) -> 121.44 | N19: =VLOOKUP(B19-366,'Rajnandgaon Data'!A:H,7,0) -> 134.47
