Workbook

Sheet Sheet1
A1: Date | B1: Days | C1: generation (In Mwh) | D1: radiation | E1: Peak Power (in Mw) | F1: BESS Export (In MWh) | G1: BESS import (In MWh) | H1: Plant Availability | I1: grid_availability | J1: BESS Availibilty | K1: cumulative(in KwH) | L1: cumulative BESS Export(in MwH) | M1: cumulative BESS Import(in MwH) | N1: Daily CUF WORC | O1: CUF till date W.o.RC
A2: 45195 | B2: 1 | C2: 1086.5 | H2: 1 | I2: 0.99875759 | K2: =C2 -> 1086.5 | N2: =C2/(1400*24) -> 0.03233631 | O2: =K2/(B2*1400*24) -> 0.03233631
A3: 45196 | B3: 2 | C3: 1112 | H3: 1 | I3: 1 | K3: =K2+C3 -> 2198.5 | N3: =C3/(1400*24) -> 0.033095238 | O3: =K3/(B3*1400*24) -> 0.032715774
A4: 45197 | B4: 3 | C4: 666.2 | H4: 1 | I4: 1 | K4: =K3+C4 -> 2864.7 | N4: =C4/(1400*24) -> 0.019827381 | O4: =K4/(B4*1400*24) -> 0.028419643
A5: 45198 | B5: 4 | C5: 1123.3 | H5: 1 | I5: 1 | K5: =K4+C5 -> 3988 | N5: =C5/(1400*24) -> 0.033431548 | O5: =K5/(B5*1400*24) -> 0.029672619
A6: 45199 | B6: 5 | C6: 1945.7 | H6: 1 | I6: 1 | K6: =K5+C6 -> 5933.7 | N6: =C6/(1400*24) -> 0.057907738 | O6: =K6/(B6*1400*24) -> 0.035319643
A7: 45200 | B7: 6 | C7: 2136.1 | H7: 1 | I7: 1 | K7: =K6+C7 -> 8069.8 | N7: =C7/(1400*24) -> 0.063574405 | O7: =K7/(B7*1400*24) -> 0.04002877
A8: 45201 | B8: 7 | C8: 1953.9 | H8: 1 | I8: 1 | K8: =K7+C8 -> 10023.7 | N8: =C8/(1400*24) -> 0.058151786 | O8: =K8/(B8*1400*24) -> 0.042617772
A9: 45202 | B9: 8 | C9: 2575.8 | H9: 1 | I9: 0.92811323 | K9: =K8+C9 -> 12599.5 | N9: =C9/(1400*24) -> 0.076660714 | O9: =K9/(B9*1400*24) -> 0.04687314
A10: 45203 | B10: 9 | C10: 3504.8 | H10: 1 | I10: 1 | K10: =K9+C10 -> 16104.3 | N10: =C10/(1400*24) -> 0.10430952 | O10: =K10/(B10*1400*24) -> 0.05325496
A11: 45204 | B11: 10 | C11: 3474.9 | H11: 1 | I11: 1 | K11: =K10+C11 -> 19579.2 | N11: =C11/(1400*24) -> 0.10341964 | O11: =K11/(B11*1400*24) -> 0.058271429
A12: 45205 | B12: 11 | C12: 3505.9 | H12: 1 | I12: 1 | K12: =K11+C12 -> 23085.1 | N12: =C12/(1400*24) -> 0.10434226 | O12: =K12/(B12*1400*24) -> 0.062459686
A13: 45206 | B13: 12 | C13: 3473.1 | H13: 1 | I13: 1 | K13: =K12+C13 -> 26558.2 | N13: =C13/(1400*24) -> 0.10336607 | O13: =K13/(B13*1400*24) -> 0.065868552
A14: 45207 | B14: 13 | C14: 3532 | H14: 1 | I14: 1 | K14: =K13+C14 -> 30090.2 | N14: =C14/(1400*24) -> 0.10511905 | O14: =K14/(B14*1400*24) -> 0.068887821
... A189: 45382 | B189: 188 | C189: 7537.3 | H189: 1 | I189: 1 | K189: =K188+C189 -> 968850.49 | N189: =C189/(1400*24) -> 0.2243244 | O189: =K189/(B189*1400*24) -> 0.15337679
A190: 45383 | B190: =VLOOKUP(A190,'BADI SID DATA'!A:B,2,0) -> #REF! | C190: 7771.6 | H190: 1 | I190: 1 | K190: =K189+C190 -> 976622.09 | N190: =C190/(1400*24) -> 0.23129762 | O190: =K190/(B190*1400*24) -> #REF!
A191: 45384 | B191: =VLOOKUP(A191,'BADI SID DATA'!A:B,2,0) -> #REF! | C191: 7983 | H191: 1 | I191: 1 | K191: =K190+C191 -> 984605.09 | N191: =C191/(1400*24) -> 0.23758929 | O191: =K191/(B191*1400*24) -> #REF!
A192: 45385 | B192: =VLOOKUP(A192,'BADI SID DATA'!A:B,2,0) -> #REF! | C192: 7800.3 | H192: 1 | I192: 1 | K192: =K191+C192 -> 992405.39 | N192: =C192/(1400*24) -> 0.23215179 | O192: =K192/(B192*1400*24) -> #REF!
A193: 45386 | B193: =VLOOKUP(A193,'BADI SID DATA'!A:B,2,0) -> #REF! | C193: 7888.2 | H193: 1 | I193: 1 | K193: =K192+C193 -> 1000293.6 | N193: =C193/(1400*24) -> 0.23476786 | O193: =K193/(B193*1400*24) -> #REF!
A194: 45387 | B194: =VLOOKUP(A194,'BADI SID DATA'!A:B,2,0) -> #REF! | C194: 7850.5 | H194: 1 | I194: 1 | K194: =K193+C194 -> 1008144.1 | N194: =C194/(1400*24) -> 0.23364583 | O194: =K194/(B194*1400*24) -> #REF!
A195: 45388 | B195: =VLOOKUP(A195,'BADI SID DATA'!A:B,2,0) -> #REF! | C195: 7267.8 | H195: 1 | I195: 1 | K195: =K194+C195 -> 1015411.9 | N195: =C195/(1400*24) -> 0.21630357 | O195: =K195/(B195*1400*24) -> #REF!
A196: 45389 | B196: =VLOOKUP(A196,'BADI SID DATA'!A:B,2,0) -> #REF! | C196: 7685.3 | H196: 1 | I196: 1 | K196: =K195+C196 -> 1023097.2 | N196: =C196/(1400*24) -> 0.22872917 | O196: =K196/(B196*1400*24) -> #REF!
A197: 45390 | B197: =VLOOKUP(A197,'BADI SID DATA'!A:B,2,0) -> #REF! | C197: 7023 | H197: 1 | I197: 1 | K197: =K196+C197 -> 1030120.2 | N197: =C197/(1400*24) -> 0.20901786 | O197: =K197/(B197*1400*24) -> #REF!
A198: 45391 | B198: =VLOOKUP(A198,'BADI SID DATA'!A:B,2,0) -> #REF! | C198: 7023 | H198: 1 | I198: 1 | K198: =K197+C198 -> 1037143.2 | N198: =C198/(1400*24) -> 0.20901786 | O198: =K198/(B198*1400*24) -> #REF!
A199: 45392 | B199: =VLOOKUP(A199,'BADI SID DATA'!A:B,2,0) -> #REF! | C199: 7772.3 | H199: 1 | I199: 1 | K199: =K198+C199 -> 1044915.5 | N199: =C199/(1400*24) -> 0.23131845 | O199: =K199/(B199*1400*24) -> #REF!
A200: 45393 | B200: =VLOOKUP(A200,'BADI SID DATA'!A:B,2,0) -> #REF! | C200: 7553.1 | H200: 1 | I200: 1 | K200: =K199+C200 -> 1052468.6 | N200: =C200/(1400*24) -> 0.22479464 | O200: =K200/(B200*1400*24) -> #REF!
A201: 45394 | B201: =VLOOKUP(A201,'BADI SID DATA'!A:B,2,0) -> #REF! | C201: 7647.1 | H201: 1 | I201: 1 | K201: =K200+C201 -> 1060115.7 | N201: =C201/(1400*24) -> 0.22759226 | O201: =K201/(B201*1400*24) -> #REF!
... A207: 45400 | B207: =VLOOKUP(A207,'BADI SID DATA'!A:B,2,0) -> #REF! | C207: 7356.8 | H207: 1 | I207: 1 | K207: =K206+C207 -> 1099894 | N207: =C207/(1400*24) -> 0.21895238 | O207: =K207/(B207*1400*24) -> #REF!
A208: 45401 | B208: =VLOOKUP(A208,'BADI SID DATA'!A:B,2,0) -> #REF! | C208: 6531.8 | D208: 5.14 | H208: 1 | I208: 1 | K208: =K207+C208 -> 1106425.8 | N208: =C208/(1400*24) -> 0.19439881 | O208: =K208/(B208*1400*24) -> #REF!
A209: 45402 | B209: =VLOOKUP(A209,'BADI SID DATA'!A:B,2,0) -> #REF! | C209: 6860 | D209: 5.42 | H209: 1 | I209: 1 | K209: =K208+C209 -> 1113285.8 | N209: =C209/(1400*24) -> 0.20416667 | O209: =K209/(B209*1400*24) -> #REF!
A210: 45403 | B210: =VLOOKUP(A210,'BADI SID DATA'!A:B,2,0) -> #REF! | C210: 6854.4 | D210: 5.54 | H210: 1 | I210: 1 | K210: =K209+C210 -> 1120140.2 | N210: =C210/(1400*24) -> 0.204 | O210: =K210/(B210*1400*24) -> #REF!
A211: 45404 | B211: =VLOOKUP(A211,'BADI SID DATA'!A:B,2,0) -> #REF! | C211: 7280.2 | D211: 5.88 | H211: 1 | I211: 1 | K211: =K210+C211 -> 1127420.4 | N211: =C211/(1400*24) -> 0.21667262 | O211: =K211/(B211*1400*24) -> #REF!
A212: 45405 | B212: =VLOOKUP(A212,'BADI SID DATA'!A:B,2,0) -> #REF! | C212: 7314.2 | D212: 5.81 | H212: 1 | I212: 1 | K212: =K211+C212 -> 1134734.6 | N212: =C212/(1400*24) -> 0.21768452 | O212: =K212/(B212*1400*24) -> #REF!
A213: 45406 | B213: =VLOOKUP(A213,'BADI SID DATA'!A:B,2,0) -> #REF! | C213: 7605.3 | D213: 6.15 | H213: 1 | I213: 1 | K213: =K212+C213 -> 1142339.9 | N213: =C213/(1400*24) -> 0.22634821 | O213: =K213/(B213*1400*24) -> #REF!
A214: 45407 | B214: =VLOOKUP(A214,'BADI SID DATA'!A:B,2,0) -> #REF! | C214: 5347.1 | D214: 4.16 | H214: 1 | I214: 1 | K214: =K213+C214 -> 1147687 | N214: =C214/(1400*24) -> 0.15913988 | O214: =K214/(B214*1400*24) -> #REF!
A215: 45408 | B215: =VLOOKUP(A215,'BADI SID DATA'!A:B,2,0) -> #REF! | C215: 6368.4 | D215: 5.63 | H215: 1 | I215: 1 | K215: =K214+C215 -> 1154055.4 | N215: =C215/(1400*24) -> 0.18953571 | O215: =K215/(B215*1400*24) -> #REF!
A216: 45409 | B216: =VLOOKUP(A216,'BADI SID DATA'!A:B,2,0) -> #REF! | C216: 7549.5 | D216: 6.02 | H216: 1 | I216: 1 | K216: =K215+C216 -> 1161604.9 | N216: =C216/(1400*24) -> 0.2246875 | O216: =K216/(B216*1400*24) -> #REF!
A217: 45410 | B217: =VLOOKUP(A217,'BADI SID DATA'!A:B,2,0) -> #REF! | C217: 7310.9 | D217: 5.87 | H217: 1 | I217: 1 | K217: =K216+C217 -> 1168915.8 | N217: =C217/(1400*24) -> 0.21758631 | O217: =K217/(B217*1400*24) -> #REF!
A218: 45411 | B218: =VLOOKUP(A218,'BADI SID DATA'!A:B,2,0) -> #REF! | C218: 7283.7 | D218: 5.83 | H218: 1 | I218: 1 | K218: =K217+C218 -> 1176199.5 | N218: =C218/(1400*24) -> 0.21677679 | O218: =K218/(B218*1400*24) -> #REF!
A219: 45412 | B219: =VLOOKUP(A219,'BADI SID DATA'!A:B,2,0) -> #REF! | C219: 5801.3 | D219: 4.52 | H219: 1 | I219: 1 | K219: =K218+C219 -> 1182000.8 | N219: =C219/(1400*24) -> 0.17265774 | O219: =K219/(B219*1400*24) -> #REF!
...
